package io.github.ron1196.thelionking.world.feature;

import com.mojang.serialization.Codec;
import io.github.ron1196.thelionking.registry.LKBlocks;
import io.github.ron1196.thelionking.registry.EntityTypes;
import net.minecraft.core.BlockPos;
import net.minecraft.world.level.WorldGenLevel;
import net.minecraft.world.level.block.Blocks;
import net.minecraft.world.level.block.LeavesBlock;
import net.minecraft.world.level.block.state.BlockState;
import net.minecraft.world.level.levelgen.feature.Feature;
import net.minecraft.world.level.levelgen.feature.FeaturePlaceContext;
import net.minecraft.world.level.levelgen.feature.configurations.NoneFeatureConfiguration;

import org.slf4j.Logger;
import org.slf4j.LoggerFactory;

/**
 * Giant Rafiki Tree — the iconic landmark of the Pride Lands.
 * Direct 1:1 port of the original LKWorldGenRafiki.java (11,588 lines).
 * Uses the exact same Bresenham circle algorithm and block placements.
 */
public class RafikiTreeFeature extends Feature<NoneFeatureConfiguration> {

    private static final Logger LOGGER = LoggerFactory.getLogger(RafikiTreeFeature.class);

    private static final BlockState WOOD = LKBlocks.RAFIKI_WOOD.get().defaultBlockState();
    private static final BlockState LEAVES = LKBlocks.RAFIKI_LEAVES.get().defaultBlockState()
            .setValue(LeavesBlock.PERSISTENT, true);
    private static final BlockState TORCH = Blocks.TORCH.defaultBlockState();
    private static final BlockState PORTAL_FRAME = LKBlocks.OUTLANDS_PORTAL_FRAME.get().defaultBlockState();
    private static final BlockState AIR = Blocks.AIR.defaultBlockState();


    public RafikiTreeFeature(Codec<NoneFeatureConfiguration> codec) {
        super(codec);
    }

    @Override
    public boolean place(FeaturePlaceContext<NoneFeatureConfiguration> context) {
        WorldGenLevel level = context.level();
        BlockPos origin = context.origin();
        int i = origin.getX();
        int j = origin.getY();
        int k = origin.getZ();

        LOGGER.info("Rafiki Tree generating at ({}, {}, {})", i, j, k);

        // Trunk: 40 layers of filled circles with Bresenham algorithm
        for (int j1 = 0; j1 < 40; j1++) {
            for (int i1 = 0; i1 > -2; i1--) {
                for (int k1 = 0; k1 > -2; k1--) {
                    int lean = j1 / 6;
                    int radius = 20 - (j1 / 4);
                    generateCircle(level, i + i1 + lean, j + j1, k + k1, radius, WOOD, true);
                    generateCircle(level, i + i1 + lean, j + j1 - 1, k + k1, radius, WOOD, true);
                    generateCircle(level, i + i1 + lean, j + j1 - 2, k + k1, radius, WOOD, true);
                }
            }
        }

        // Bar at Y+38/39
        for (int i1 = -3; i1 < 15; i1++) {
            setBlock(level, i, j, k, i1, 39, 0, AIR);
            setBlock(level, i, j, k, i1, 38, 0, WOOD);
        }

        // Clear circles at Y+39
        generateCircle(level, i + 6, j + 39, k - 1, 8, AIR, true);
        generateCircle(level, i + 6, j + 39, k, 8, AIR, true);
        generateCircle(level, i + 5, j + 39, k - 1, 8, AIR, true);
        generateCircle(level, i + 5, j + 39, k, 8, AIR, true);

        // Platform at Y+38
        generateCircle(level, i + 6, j + 38, k, 10, WOOD, true);

        // Railing ring at Y+40 (outline only)
        for (int i1 = 0; i1 > -2; i1--) {
            for (int k1 = 0; k1 > -2; k1--) {
                generateCircle(level, i + i1 + 6, j + 40, k + k1, 11, WOOD, false);
            }
        }

        // Clear inside railing
        for (int i1 = 0; i1 > -2; i1--) {
            for (int k1 = 0; k1 > -2; k1--) {
                generateCircle(level, i + i1 + 6, j + 40, k + k1, 10, AIR, false);
            }
        }

        // Torches and all detail methods
        placeUpperTorches(level, i, j, k);
        finishGeneration1(level, i, j, k);
        finishGeneration2(level, i, j - 40, k);
        finishGeneration3(level, i, j, k);
        finishGeneration4(level, i, j, k);
        finishGeneration5(level, i, j, k);
        finishGeneration6(level, i, j, k);
        finishGeneration7(level, i, j, k);
        finishGeneration8(level, i, j, k);
        finishGeneration9(level, i, j, k);
        finishGeneration10(level, i, j, k);
        finishGeneration11(level, i, j, k);
        finishGeneration12(level, i, j, k);
        finishGeneration13(level, i, j, k);
        finishGeneration14(level, i, j, k);
        finishGeneration15(level, i, j, k);
        finishGeneration16(level, i, j, k);

        FeatureHelper.spawnEntity(level, EntityTypes.RAFIKI.get(), i + 0.5, j + 39, k + 0.5);

        return true;
    }

    private static void setBlock(WorldGenLevel level, int i, int j, int k, int dx, int dy, int dz, BlockState state) {
        placeAt(level, i + dx, j + dy, k + dz, state);
    }

    private static void placeAt(WorldGenLevel level, int x, int y, int z, BlockState state) {
        FeatureHelper.placeBlock(level, x, y, z, state);
    }

    /**
     * Bresenham midpoint circle algorithm — exact port from the original mod.
     */
    private void generateCircle(WorldGenLevel level, int x0, int j, int y0, int radius, BlockState block, boolean fill) {
        if (radius <= 0) {
            placeAt(level, x0, j, y0, block);
            return;
        }
        int f = 1 - radius;
        int ddFx = 1;
        int ddFy = -2 * radius;
        int x = 0;
        int y = radius;

        placeAt(level, x0, j, y0 + radius, block);
        placeAt(level, x0, j, y0 - radius, block);
        placeAt(level, x0 + radius, j, y0, block);
        placeAt(level, x0 - radius, j, y0, block);

        while (x < y) {
            if (f >= 0) {
                y--;
                ddFy += 2;
                f += ddFy;
            }
            x++;
            ddFx += 2;
            f += ddFx;
            if (fill) {
                for (int ix = x0 - x; ix <= x0 + x; ix++) {
                    placeAt(level, ix, j, y0 + y, block);
                }
                for (int ix = x0 - x; ix <= x0 + x; ix++) {
                    placeAt(level, ix, j, y0 - y, block);
                }
                for (int ix = x0 - y; ix <= x0 + y; ix++) {
                    placeAt(level, ix, j, y0 + x, block);
                }
                for (int ix = x0 - y; ix <= x0 + y; ix++) {
                    placeAt(level, ix, j, y0 - x, block);
                }
            } else {
                placeAt(level, x0 - x, j, y0 + y, block);
                placeAt(level, x0 + x, j, y0 + y, block);
                placeAt(level, x0 - x, j, y0 - y, block);
                placeAt(level, x0 + x, j, y0 - y, block);
                placeAt(level, x0 - y, j, y0 + x, block);
                placeAt(level, x0 + y, j, y0 + x, block);
                placeAt(level, x0 - y, j, y0 - x, block);
                placeAt(level, x0 + y, j, y0 - x, block);
            }
        }
    }

    private void placeUpperTorches(WorldGenLevel level, int i, int j, int k) {
        setBlock(level, i, j, k, -2, 39, -5, TORCH);
        setBlock(level, i, j, k, -3, 39, -3, TORCH);
        setBlock(level, i, j, k, -3, 39, 2, TORCH);
        setBlock(level, i, j, k, -2, 39, 4, TORCH);
        setBlock(level, i, j, k, 1, 39, 7, TORCH);
        setBlock(level, i, j, k, 3, 39, 8, TORCH);
        setBlock(level, i, j, k, 8, 39, 8, TORCH);
        setBlock(level, i, j, k, 10, 39, 7, TORCH);
        setBlock(level, i, j, k, 13, 39, 4, TORCH);
        setBlock(level, i, j, k, 14, 39, 2, TORCH);
        setBlock(level, i, j, k, 14, 39, -3, TORCH);
        setBlock(level, i, j, k, 13, 39, -5, TORCH);
        setBlock(level, i, j, k, 10, 39, -8, TORCH);
        setBlock(level, i, j, k, 8, 39, -9, TORCH);
        setBlock(level, i, j, k, 3, 39, -9, TORCH);
        setBlock(level, i, j, k, 1, 39, -8, TORCH);
        setBlock(level, i, j, k, -3, 40, -7, TORCH);
        setBlock(level, i, j, k, -4, 40, -5, TORCH);
        setBlock(level, i, j, k, -5, 40, -3, TORCH);
        setBlock(level, i, j, k, -5, 40, 2, TORCH);
        setBlock(level, i, j, k, -4, 40, 4, TORCH);
        setBlock(level, i, j, k, -3, 40, 6, TORCH);
        setBlock(level, i, j, k, -1, 40, 8, TORCH);
        setBlock(level, i, j, k, 1, 40, 9, TORCH);
        setBlock(level, i, j, k, 3, 40, 10, TORCH);
        setBlock(level, i, j, k, 8, 40, 10, TORCH);
        setBlock(level, i, j, k, 10, 40, 9, TORCH);
        setBlock(level, i, j, k, 12, 40, 8, TORCH);
        setBlock(level, i, j, k, 14, 40, 6, TORCH);
        setBlock(level, i, j, k, 15, 40, 4, TORCH);
        setBlock(level, i, j, k, 16, 40, 2, TORCH);
        setBlock(level, i, j, k, 16, 40, -3, TORCH);
        setBlock(level, i, j, k, 15, 40, -5, TORCH);
        setBlock(level, i, j, k, 14, 40, -7, TORCH);
        setBlock(level, i, j, k, 12, 40, -9, TORCH);
        setBlock(level, i, j, k, 10, 40, -10, TORCH);
        setBlock(level, i, j, k, 8, 40, -11, TORCH);
        setBlock(level, i, j, k, 3, 40, -11, TORCH);
        setBlock(level, i, j, k, 1, 40, -10, TORCH);
        setBlock(level, i, j, k, -1, 40, -9, TORCH);
    }

    private void finishGeneration1(WorldGenLevel level, int i, int j, int k) {
        setBlock(level, i, j, k, -2, 36, 9, WOOD);
        setBlock(level, i, j, k, -2, 36, 10, WOOD);
        setBlock(level, i, j, k, -3, 36, 10, WOOD);
        setBlock(level, i, j, k, -3, 36, 9, WOOD);
        setBlock(level, i, j, k, -4, 36, 9, WOOD);
        setBlock(level, i, j, k, -4, 36, 10, WOOD);
        setBlock(level, i, j, k, -3, 36, 11, WOOD);
        setBlock(level, i, j, k, -4, 36, 11, WOOD);
        setBlock(level, i, j, k, -5, 36, 10, WOOD);
        setBlock(level, i, j, k, -5, 36, 11, WOOD);
        setBlock(level, i, j, k, -4, 36, 12, WOOD);
        setBlock(level, i, j, k, -5, 36, 12, WOOD);
        setBlock(level, i, j, k, -4, 35, 10, WOOD);
        setBlock(level, i, j, k, -4, 35, 11, WOOD);
        setBlock(level, i, j, k, -4, 34, 10, WOOD);
        setBlock(level, i, j, k, -4, 33, 10, WOOD);
        setBlock(level, i, j, k, -5, 35, 10, WOOD);
        setBlock(level, i, j, k, -5, 34, 10, WOOD);
        setBlock(level, i, j, k, -5, 36, 9, WOOD);
        setBlock(level, i, j, k, -4, 37, 10, WOOD);
        setBlock(level, i, j, k, -5, 37, 10, WOOD);
        setBlock(level, i, j, k, -3, 37, 11, WOOD);
        setBlock(level, i, j, k, -5, 37, 11, WOOD);
        setBlock(level, i, j, k, -5, 37, 12, WOOD);
        setBlock(level, i, j, k, -4, 37, 11, WOOD);
        setBlock(level, i, j, k, -4, 37, 12, WOOD);
        setBlock(level, i, j, k, -6, 36, 11, WOOD);
        setBlock(level, i, j, k, -6, 36, 12, WOOD);
        setBlock(level, i, j, k, -6, 37, 11, WOOD);
        setBlock(level, i, j, k, -6, 37, 12, WOOD);
        setBlock(level, i, j, k, -5, 38, 12, WOOD);
        setBlock(level, i, j, k, -6, 38, 12, WOOD);
        setBlock(level, i, j, k, -5, 35, 9, WOOD);
        setBlock(level, i, j, k, -5, 34, 9, WOOD);
        setBlock(level, i, j, k, -5, 33, 9, WOOD);
        setBlock(level, i, j, k, -4, 32, 10, WOOD);
        setBlock(level, i, j, k, -3, 35, 11, WOOD);
        setBlock(level, i, j, k, -3, 34, 11, WOOD);
        setBlock(level, i, j, k, -3, 33, 11, WOOD);
        setBlock(level, i, j, k, -6, 38, 11, WOOD);
        setBlock(level, i, j, k, -5, 38, 11, WOOD);
        setBlock(level, i, j, k, -6, 39, 12, WOOD);
        setBlock(level, i, j, k, -7, 39, 12, WOOD);
        setBlock(level, i, j, k, -6, 39, 13, WOOD);
        setBlock(level, i, j, k, -7, 39, 13, WOOD);
        setBlock(level, i, j, k, -7, 40, 12, WOOD);
        setBlock(level, i, j, k, -7, 40, 13, WOOD);
        setBlock(level, i, j, k, -6, 40, 13, WOOD);
        setBlock(level, i, j, k, -6, 38, 13, WOOD);
        setBlock(level, i, j, k, -6, 37, 13, WOOD);
        setBlock(level, i, j, k, -7, 38, 12, WOOD);
        setBlock(level, i, j, k, -7, 38, 13, WOOD);
        setBlock(level, i, j, k, -6, 36, 11, AIR);
        setBlock(level, i, j, k, -7, 41, 13, WOOD);
        setBlock(level, i, j, k, -7, 42, 13, WOOD);
        setBlock(level, i, j, k, -7, 43, 13, WOOD);
        setBlock(level, i, j, k, -6, 40, 12, WOOD);
        setBlock(level, i, j, k, -6, 41, 13, WOOD);
        setBlock(level, i, j, k, -7, 41, 12, WOOD);
        setBlock(level, i, j, k, -7, 42, 12, WOOD);
        setBlock(level, i, j, k, -5, 39, 12, WOOD);
        setBlock(level, i, j, k, -6, 39, 11, WOOD);
        setBlock(level, i, j, k, -6, 37, 10, WOOD);
        setBlock(level, i, j, k, -6, 36, 10, WOOD);
        setBlock(level, i, j, k, -6, 36, 11, WOOD);
        setBlock(level, i, j, k, -5, 35, 11, WOOD);
        setBlock(level, i, j, k, -6, 42, 13, WOOD);
        setBlock(level, i, j, k, -5, 40, 13, WOOD);
        setBlock(level, i, j, k, -6, 41, 14, WOOD);
        setBlock(level, i, j, k, -7, 41, 14, WOOD);
        setBlock(level, i, j, k, -8, 41, 12, WOOD);
        setBlock(level, i, j, k, -8, 41, 13, WOOD);
        setBlock(level, i, j, k, -8, 40, 13, WOOD);
        setBlock(level, i, j, k, -8, 42, 12, WOOD);
        setBlock(level, i, j, k, -8, 42, 13, WOOD);
        setBlock(level, i, j, k, -8, 43, 13, WOOD);
        setBlock(level, i, j, k, -7, 42, 14, WOOD);
        setBlock(level, i, j, k, -7, 43, 14, WOOD);
        setBlock(level, i, j, k, -7, 44, 14, WOOD);
        setBlock(level, i, j, k, -3, 37, 9, WOOD);
        setBlock(level, i, j, k, -3, 37, 10, WOOD);
        setBlock(level, i, j, k, -2, 37, 9, WOOD);
        setBlock(level, i, j, k, -2, 37, 10, WOOD);
        setBlock(level, i, j, k, -2, 38, 9, WOOD);
        setBlock(level, i, j, k, -4, 36, 8, WOOD);
        setBlock(level, i, j, k, -4, 37, 9, WOOD);
        setBlock(level, i, j, k, -4, 36, 7, WOOD);
        setBlock(level, i, j, k, -4, 37, 8, WOOD);
        setBlock(level, i, j, k, -6, 35, 9, WOOD);
        setBlock(level, i, j, k, -6, 34, 8, WOOD);
        setBlock(level, i, j, k, -6, 35, 8, WOOD);
        setBlock(level, i, j, k, -7, 40, 14, WOOD);
        setBlock(level, i, j, k, -8, 42, 14, WOOD);
        setBlock(level, i, j, k, -8, 43, 14, WOOD);
        setBlock(level, i, j, k, -8, 44, 14, WOOD);
        setBlock(level, i, j, k, -8, 44, 13, WOOD);
        setBlock(level, i, j, k, -3, 38, 9, WOOD);
        setBlock(level, i, j, k, -2, 39, 9, WOOD);
        setBlock(level, i, j, k, -4, 38, 10, WOOD);
        setBlock(level, i, j, k, -9, 43, 14, WOOD);
        setBlock(level, i, j, k, -9, 44, 14, WOOD);
        setBlock(level, i, j, k, -8, 43, 15, WOOD);
        setBlock(level, i, j, k, -8, 44, 15, WOOD);
        setBlock(level, i, j, k, -8, 45, 15, WOOD);
        setBlock(level, i, j, k, -9, 44, 15, WOOD);
        setBlock(level, i, j, k, -9, 45, 15, WOOD);
        setBlock(level, i, j, k, -9, 46, 15, WOOD);
        setBlock(level, i, j, k, -9, 47, 15, WOOD);
        setBlock(level, i, j, k, -9, 45, 14, WOOD);
        setBlock(level, i, j, k, -8, 45, 14, WOOD);
        setBlock(level, i, j, k, -8, 46, 15, WOOD);
        setBlock(level, i, j, k, -8, 47, 15, WOOD);
        setBlock(level, i, j, k, -9, 46, 14, WOOD);
        setBlock(level, i, j, k, -9, 47, 14, WOOD);
        setBlock(level, i, j, k, -9, 48, 15, WOOD);
        setBlock(level, i, j, k, -9, 49, 15, WOOD);
        setBlock(level, i, j, k, -10, 47, 15, WOOD);
        setBlock(level, i, j, k, -10, 46, 14, WOOD);
        setBlock(level, i, j, k, -10, 46, 15, WOOD);
        setBlock(level, i, j, k, -9, 46, 16, WOOD);
        setBlock(level, i, j, k, -9, 47, 16, WOOD);
        setBlock(level, i, j, k, -10, 46, 14, AIR);
        setBlock(level, i, j, k, -10, 47, 16, WOOD);
        setBlock(level, i, j, k, -10, 48, 15, WOOD);
        setBlock(level, i, j, k, -10, 48, 16, WOOD);
        setBlock(level, i, j, k, -9, 48, 16, WOOD);
        setBlock(level, i, j, k, -10, 49, 15, WOOD);
        setBlock(level, i, j, k, -10, 49, 16, WOOD);
        setBlock(level, i, j, k, -9, 49, 16, WOOD);
        setBlock(level, i, j, k, -8, 46, 16, WOOD);
        setBlock(level, i, j, k, -8, 46, 17, WOOD);
        setBlock(level, i, j, k, -7, 46, 17, WOOD);
        setBlock(level, i, j, k, -7, 47, 17, WOOD);
        setBlock(level, i, j, k, -7, 46, 17, AIR);
        setBlock(level, i, j, k, -7, 47, 18, WOOD);
        setBlock(level, i, j, k, -6, 47, 18, WOOD);
        setBlock(level, i, j, k, -10, 45, 14, WOOD);
        setBlock(level, i, j, k, -11, 45, 14, WOOD);
        setBlock(level, i, j, k, -11, 45, 13, WOOD);
        setBlock(level, i, j, k, -11, 46, 13, WOOD);
        setBlock(level, i, j, k, -12, 46, 13, WOOD);
        setBlock(level, i, j, k, -12, 46, 12, WOOD);
        setBlock(level, i, j, k, -12, 46, 13, AIR);
        setBlock(level, i, j, k, -10, 50, 16, WOOD);
        setBlock(level, i, j, k, -3, 38, 10, WOOD);
        setBlock(level, i, j, k, -4, 38, 11, WOOD);
        setBlock(level, i, j, k, -4, 38, 9, WOOD);
        setBlock(level, i, j, k, -5, 38, 10, WOOD);
        setBlock(level, i, j, k, -4, 38, 8, WOOD);
        setBlock(level, i, j, k, -3, 39, 9, WOOD);
        setBlock(level, i, j, k, -4, 37, 7, WOOD);
        setBlock(level, i, j, k, -5, 37, 9, WOOD);
        setBlock(level, i, j, k, -5, 36, 8, WOOD);
        setBlock(level, i, j, k, -6, 36, 9, WOOD);
        setBlock(level, i, j, k, -5, 39, 11, WOOD);
        setBlock(level, i, j, k, -4, 39, 10, WOOD);
        setBlock(level, i, j, k, 5, 35, 13, WOOD);
        setBlock(level, i, j, k, 6, 35, 13, WOOD);
        setBlock(level, i, j, k, 7, 35, 13, WOOD);
        setBlock(level, i, j, k, 8, 35, 13, WOOD);
        setBlock(level, i, j, k, 4, 35, 13, WOOD);
        setBlock(level, i, j, k, 4, 36, 12, WOOD);
        setBlock(level, i, j, k, 4, 36, 13, WOOD);
        setBlock(level, i, j, k, 5, 36, 12, WOOD);
        setBlock(level, i, j, k, 5, 36, 13, WOOD);
        setBlock(level, i, j, k, 6, 36, 12, WOOD);
        setBlock(level, i, j, k, 6, 36, 13, WOOD);
        setBlock(level, i, j, k, 7, 36, 12, WOOD);
        setBlock(level, i, j, k, 7, 36, 13, WOOD);
        setBlock(level, i, j, k, 8, 36, 12, WOOD);
        setBlock(level, i, j, k, 8, 36, 13, WOOD);
        setBlock(level, i, j, k, 4, 36, 14, WOOD);
        setBlock(level, i, j, k, 5, 36, 14, WOOD);
        setBlock(level, i, j, k, 6, 36, 14, WOOD);
        setBlock(level, i, j, k, 7, 36, 14, WOOD);
        setBlock(level, i, j, k, 8, 36, 14, WOOD);
        setBlock(level, i, j, k, 4, 37, 12, WOOD);
        setBlock(level, i, j, k, 4, 37, 13, WOOD);
        setBlock(level, i, j, k, 4, 37, 14, WOOD);
        setBlock(level, i, j, k, 5, 37, 12, WOOD);
        setBlock(level, i, j, k, 5, 37, 13, WOOD);
        setBlock(level, i, j, k, 5, 37, 14, WOOD);
        setBlock(level, i, j, k, 5, 37, 15, WOOD);
        setBlock(level, i, j, k, 4, 37, 15, WOOD);
        setBlock(level, i, j, k, 6, 37, 13, WOOD);
        setBlock(level, i, j, k, 6, 37, 14, WOOD);
        setBlock(level, i, j, k, 6, 37, 15, WOOD);
        setBlock(level, i, j, k, 6, 37, 12, WOOD);
        setBlock(level, i, j, k, 7, 37, 12, WOOD);
        setBlock(level, i, j, k, 7, 37, 13, WOOD);
        setBlock(level, i, j, k, 7, 37, 14, WOOD);
        setBlock(level, i, j, k, 7, 37, 15, WOOD);
        setBlock(level, i, j, k, 8, 37, 12, WOOD);
        setBlock(level, i, j, k, 8, 37, 13, WOOD);
        setBlock(level, i, j, k, 8, 37, 14, WOOD);
        setBlock(level, i, j, k, 8, 37, 15, WOOD);
        setBlock(level, i, j, k, 5, 38, 14, WOOD);
        setBlock(level, i, j, k, 5, 38, 15, WOOD);
        setBlock(level, i, j, k, 6, 38, 13, WOOD);
        setBlock(level, i, j, k, 6, 38, 14, WOOD);
        setBlock(level, i, j, k, 6, 38, 15, WOOD);
        setBlock(level, i, j, k, 7, 38, 14, WOOD);
        setBlock(level, i, j, k, 7, 38, 15, WOOD);
        setBlock(level, i, j, k, 8, 38, 12, WOOD);
        setBlock(level, i, j, k, 8, 38, 13, WOOD);
        setBlock(level, i, j, k, 8, 38, 14, WOOD);
        setBlock(level, i, j, k, 8, 38, 15, WOOD);
        setBlock(level, i, j, k, 7, 38, 12, WOOD);
        setBlock(level, i, j, k, 7, 38, 13, WOOD);
        setBlock(level, i, j, k, 4, 38, 12, WOOD);
        setBlock(level, i, j, k, 4, 38, 13, WOOD);
        setBlock(level, i, j, k, 5, 38, 12, WOOD);
        setBlock(level, i, j, k, 5, 38, 13, WOOD);
        setBlock(level, i, j, k, 6, 38, 12, WOOD);
        setBlock(level, i, j, k, 4, 38, 14, WOOD);
        setBlock(level, i, j, k, 4, 38, 15, WOOD);
        setBlock(level, i, j, k, 3, 36, 12, WOOD);
        setBlock(level, i, j, k, 3, 37, 12, WOOD);
        setBlock(level, i, j, k, 3, 36, 13, WOOD);
        setBlock(level, i, j, k, 3, 35, 13, WOOD);
        setBlock(level, i, j, k, 2, 34, 13, WOOD);
        setBlock(level, i, j, k, 9, 37, 12, WOOD);
        setBlock(level, i, j, k, 9, 36, 12, WOOD);
        setBlock(level, i, j, k, 9, 35, 12, WOOD);
        setBlock(level, i, j, k, 9, 34, 12, WOOD);
        setBlock(level, i, j, k, 9, 38, 13, WOOD);
        setBlock(level, i, j, k, 9, 37, 13, WOOD);
        setBlock(level, i, j, k, 8, 39, 12, WOOD);
        setBlock(level, i, j, k, 8, 39, 13, WOOD);
        setBlock(level, i, j, k, 8, 39, 14, WOOD);
        setBlock(level, i, j, k, 8, 39, 15, WOOD);
        setBlock(level, i, j, k, 6, 39, 14, WOOD);
        setBlock(level, i, j, k, 6, 39, 15, WOOD);
        setBlock(level, i, j, k, 7, 39, 15, WOOD);
        setBlock(level, i, j, k, 5, 39, 15, WOOD);
        setBlock(level, i, j, k, 4, 39, 15, WOOD);
        setBlock(level, i, j, k, 3, 37, 13, WOOD);
        setBlock(level, i, j, k, 3, 38, 14, WOOD);
        setBlock(level, i, j, k, 3, 38, 15, WOOD);
        setBlock(level, i, j, k, 3, 37, 14, WOOD);
        setBlock(level, i, j, k, 3, 38, 13, WOOD);
        setBlock(level, i, j, k, 4, 38, 16, WOOD);
        setBlock(level, i, j, k, 4, 38, 17, WOOD);
        setBlock(level, i, j, k, 5, 38, 16, WOOD);
        setBlock(level, i, j, k, 6, 38, 16, WOOD);
        setBlock(level, i, j, k, 8, 38, 16, WOOD);
        setBlock(level, i, j, k, 7, 38, 16, WOOD);
        setBlock(level, i, j, k, 4, 38, 17, AIR);
        setBlock(level, i, j, k, 4, 39, 16, WOOD);
        setBlock(level, i, j, k, 5, 39, 16, WOOD);
        setBlock(level, i, j, k, 6, 39, 16, WOOD);
        setBlock(level, i, j, k, 7, 39, 16, WOOD);
        setBlock(level, i, j, k, 8, 39, 16, WOOD);
        setBlock(level, i, j, k, 4, 40, 16, WOOD);
        setBlock(level, i, j, k, 5, 40, 16, WOOD);
        setBlock(level, i, j, k, 6, 40, 16, WOOD);
        setBlock(level, i, j, k, 6, 40, 17, WOOD);
        setBlock(level, i, j, k, 8, 40, 16, WOOD);
        setBlock(level, i, j, k, 7, 40, 16, WOOD);
        setBlock(level, i, j, k, 6, 40, 17, AIR);
        setBlock(level, i, j, k, 3, 39, 15, WOOD);
        setBlock(level, i, j, k, 3, 40, 16, WOOD);
        setBlock(level, i, j, k, 4, 39, 12, WOOD);
        setBlock(level, i, j, k, 4, 39, 13, WOOD);
        setBlock(level, i, j, k, 3, 39, 13, WOOD);
        setBlock(level, i, j, k, 4, 39, 14, WOOD);
        setBlock(level, i, j, k, 3, 39, 14, WOOD);
        setBlock(level, i, j, k, 4, 40, 12, WOOD);
        setBlock(level, i, j, k, 4, 40, 13, WOOD);
        setBlock(level, i, j, k, 3, 40, 13, WOOD);
        setBlock(level, i, j, k, 4, 40, 12, AIR);
        setBlock(level, i, j, k, 7, 39, 12, WOOD);
        setBlock(level, i, j, k, 6, 39, 12, WOOD);
        setBlock(level, i, j, k, 6, 40, 12, WOOD);
        setBlock(level, i, j, k, 6, 40, 12, AIR);
        setBlock(level, i, j, k, 5, 39, 12, WOOD);
        setBlock(level, i, j, k, 5, 39, 13, WOOD);
        setBlock(level, i, j, k, 5, 39, 14, WOOD);
        setBlock(level, i, j, k, 6, 39, 13, WOOD);
        setBlock(level, i, j, k, 7, 39, 14, WOOD);
        setBlock(level, i, j, k, 7, 39, 13, WOOD);
        setBlock(level, i, j, k, 3, 40, 14, WOOD);
        setBlock(level, i, j, k, 3, 40, 15, WOOD);
        setBlock(level, i, j, k, 4, 40, 14, WOOD);
        setBlock(level, i, j, k, 4, 40, 15, WOOD);
        setBlock(level, i, j, k, 5, 40, 14, WOOD);
        setBlock(level, i, j, k, 6, 40, 14, WOOD);
        setBlock(level, i, j, k, 6, 40, 15, WOOD);
        setBlock(level, i, j, k, 8, 40, 13, WOOD);
        setBlock(level, i, j, k, 7, 40, 13, WOOD);
        setBlock(level, i, j, k, 7, 40, 14, WOOD);
        setBlock(level, i, j, k, 8, 40, 14, WOOD);
        setBlock(level, i, j, k, 8, 40, 15, WOOD);
        setBlock(level, i, j, k, 7, 40, 15, WOOD);
        setBlock(level, i, j, k, 5, 40, 15, WOOD);
        setBlock(level, i, j, k, 4, 40, 13, AIR);
        setBlock(level, i, j, k, 7, 40, 13, AIR);
        setBlock(level, i, j, k, 4, 38, 16, AIR);
        setBlock(level, i, j, k, 8, 38, 16, AIR);
        setBlock(level, i, j, k, 9, 38, 14, WOOD);
        setBlock(level, i, j, k, 8, 34, 13, WOOD);
        setBlock(level, i, j, k, 7, 34, 13, WOOD);
        setBlock(level, i, j, k, 3, 34, 13, WOOD);
        setBlock(level, i, j, k, 6, 34, 13, WOOD);
        setBlock(level, i, j, k, 6, 33, 13, WOOD);
        setBlock(level, i, j, k, 4, 41, 16, WOOD);
        setBlock(level, i, j, k, 5, 41, 16, WOOD);
        setBlock(level, i, j, k, 6, 41, 16, WOOD);
        setBlock(level, i, j, k, 7, 41, 16, WOOD);
        setBlock(level, i, j, k, 8, 41, 16, WOOD);
        setBlock(level, i, j, k, 3, 41, 16, WOOD);
        setBlock(level, i, j, k, 3, 41, 15, WOOD);
        setBlock(level, i, j, k, 3, 41, 14, WOOD);
        setBlock(level, i, j, k, 4, 41, 15, WOOD);
        setBlock(level, i, j, k, 5, 41, 15, WOOD);
        setBlock(level, i, j, k, 6, 41, 15, WOOD);
        setBlock(level, i, j, k, 7, 41, 15, WOOD);
        setBlock(level, i, j, k, 8, 41, 15, WOOD);
        setBlock(level, i, j, k, 8, 41, 14, WOOD);
        setBlock(level, i, j, k, 7, 41, 14, WOOD);
        setBlock(level, i, j, k, 5, 41, 14, WOOD);
        setBlock(level, i, j, k, 4, 41, 14, WOOD);
        setBlock(level, i, j, k, 5, 40, 13, WOOD);
        setBlock(level, i, j, k, 4, 40, 13, WOOD);
        setBlock(level, i, j, k, 7, 42, 15, WOOD);
        setBlock(level, i, j, k, 8, 42, 15, WOOD);
        setBlock(level, i, j, k, 7, 42, 16, WOOD);
        setBlock(level, i, j, k, 8, 42, 16, WOOD);
        setBlock(level, i, j, k, 7, 42, 17, WOOD);
        setBlock(level, i, j, k, 6, 42, 17, WOOD);
        setBlock(level, i, j, k, 5, 42, 17, WOOD);
        setBlock(level, i, j, k, 4, 42, 17, WOOD);
        setBlock(level, i, j, k, 3, 42, 17, WOOD);
        setBlock(level, i, j, k, 3, 42, 15, WOOD);
        setBlock(level, i, j, k, 3, 42, 16, WOOD);
        setBlock(level, i, j, k, 6, 42, 15, WOOD);
        setBlock(level, i, j, k, 5, 42, 15, WOOD);
        setBlock(level, i, j, k, 4, 42, 15, WOOD);
        setBlock(level, i, j, k, 6, 42, 16, WOOD);
        setBlock(level, i, j, k, 4, 42, 16, WOOD);
        setBlock(level, i, j, k, 5, 42, 16, WOOD);
        setBlock(level, i, j, k, 5, 41, 17, WOOD);
        setBlock(level, i, j, k, 6, 41, 17, WOOD);
        setBlock(level, i, j, k, 6, 40, 17, WOOD);
        setBlock(level, i, j, k, 7, 41, 17, WOOD);
        setBlock(level, i, j, k, 4, 43, 16, WOOD);
        setBlock(level, i, j, k, 3, 43, 17, WOOD);
        setBlock(level, i, j, k, 5, 43, 17, WOOD);
        setBlock(level, i, j, k, 4, 43, 17, WOOD);
        setBlock(level, i, j, k, 6, 43, 16, WOOD);
        setBlock(level, i, j, k, 6, 43, 17, WOOD);
        setBlock(level, i, j, k, 7, 43, 16, WOOD);
        setBlock(level, i, j, k, 7, 43, 17, WOOD);
        setBlock(level, i, j, k, 8, 43, 15, WOOD);
        setBlock(level, i, j, k, 8, 43, 16, WOOD);
        setBlock(level, i, j, k, 5, 43, 16, WOOD);
        setBlock(level, i, j, k, 3, 43, 15, WOOD);
        setBlock(level, i, j, k, 3, 43, 16, WOOD);
        setBlock(level, i, j, k, 4, 43, 18, WOOD);
        setBlock(level, i, j, k, 5, 43, 18, WOOD);
        setBlock(level, i, j, k, 6, 43, 18, WOOD);
        setBlock(level, i, j, k, 7, 43, 18, WOOD);
        setBlock(level, i, j, k, 8, 43, 17, WOOD);
        setBlock(level, i, j, k, 8, 43, 18, WOOD);
        setBlock(level, i, j, k, 3, 43, 18, WOOD);
        setBlock(level, i, j, k, 4, 41, 17, WOOD);
        setBlock(level, i, j, k, 4, 42, 18, WOOD);
        setBlock(level, i, j, k, 5, 42, 18, WOOD);
        setBlock(level, i, j, k, 6, 42, 18, WOOD);
        setBlock(level, i, j, k, 7, 42, 18, WOOD);
        setBlock(level, i, j, k, 8, 42, 17, WOOD);
        setBlock(level, i, j, k, 6, 39, 17, WOOD);
        setBlock(level, i, j, k, 5, 40, 17, WOOD);
        setBlock(level, i, j, k, 4, 34, 13, WOOD);
        setBlock(level, i, j, k, 5, 34, 13, WOOD);
        setBlock(level, i, j, k, 4, 32, 13, WOOD);
        setBlock(level, i, j, k, 5, 33, 13, WOOD);
        setBlock(level, i, j, k, 4, 33, 13, WOOD);
        setBlock(level, i, j, k, 5, 32, 13, WOOD);
        setBlock(level, i, j, k, 3, 32, 13, WOOD);
        setBlock(level, i, j, k, 6, 32, 13, WOOD);
        setBlock(level, i, j, k, 7, 32, 13, WOOD);
        setBlock(level, i, j, k, 3, 44, 18, WOOD);
        setBlock(level, i, j, k, 4, 44, 18, WOOD);
        setBlock(level, i, j, k, 5, 44, 18, WOOD);
        setBlock(level, i, j, k, 6, 44, 18, WOOD);
        setBlock(level, i, j, k, 7, 44, 18, WOOD);
        setBlock(level, i, j, k, 8, 44, 18, WOOD);
        setBlock(level, i, j, k, 8, 44, 17, WOOD);
        setBlock(level, i, j, k, 8, 44, 16, WOOD);
        setBlock(level, i, j, k, 7, 44, 17, WOOD);
        setBlock(level, i, j, k, 7, 44, 16, WOOD);
        setBlock(level, i, j, k, 6, 44, 17, WOOD);
        setBlock(level, i, j, k, 6, 44, 16, WOOD);
        setBlock(level, i, j, k, 5, 44, 16, WOOD);
        setBlock(level, i, j, k, 5, 44, 17, WOOD);
        setBlock(level, i, j, k, 4, 44, 17, WOOD);
        setBlock(level, i, j, k, 4, 44, 16, WOOD);
        setBlock(level, i, j, k, 3, 44, 17, WOOD);
        setBlock(level, i, j, k, 3, 44, 16, WOOD);
        setBlock(level, i, j, k, 2, 44, 18, WOOD);
        setBlock(level, i, j, k, 9, 44, 18, WOOD);
        setBlock(level, i, j, k, 9, 45, 18, WOOD);
        setBlock(level, i, j, k, 8, 45, 18, WOOD);
        setBlock(level, i, j, k, 7, 45, 18, WOOD);
        setBlock(level, i, j, k, 6, 45, 18, WOOD);
        setBlock(level, i, j, k, 5, 45, 18, WOOD);
        setBlock(level, i, j, k, 4, 45, 18, WOOD);
        setBlock(level, i, j, k, 3, 45, 18, WOOD);
        setBlock(level, i, j, k, 2, 45, 18, WOOD);
        setBlock(level, i, j, k, 2, 45, 19, WOOD);
        setBlock(level, i, j, k, 3, 45, 19, WOOD);
        setBlock(level, i, j, k, 3, 45, 20, WOOD);
        setBlock(level, i, j, k, 5, 45, 19, WOOD);
        setBlock(level, i, j, k, 4, 45, 19, WOOD);
        setBlock(level, i, j, k, 4, 45, 20, WOOD);
        setBlock(level, i, j, k, 6, 45, 19, WOOD);
        setBlock(level, i, j, k, 6, 45, 20, WOOD);
        setBlock(level, i, j, k, 5, 45, 20, WOOD);
        setBlock(level, i, j, k, 7, 45, 19, WOOD);
        setBlock(level, i, j, k, 7, 45, 20, WOOD);
        setBlock(level, i, j, k, 8, 45, 19, WOOD);
        setBlock(level, i, j, k, 4, 44, 19, WOOD);
        setBlock(level, i, j, k, 4, 43, 19, WOOD);
        setBlock(level, i, j, k, 5, 44, 19, WOOD);
        setBlock(level, i, j, k, 5, 43, 19, WOOD);
        setBlock(level, i, j, k, 5, 44, 20, WOOD);
        setBlock(level, i, j, k, 6, 44, 19, WOOD);
        setBlock(level, i, j, k, 6, 43, 19, WOOD);
        setBlock(level, i, j, k, 6, 44, 20, WOOD);
        setBlock(level, i, j, k, 7, 44, 19, WOOD);
        setBlock(level, i, j, k, 3, 46, 20, WOOD);
        setBlock(level, i, j, k, 4, 46, 20, WOOD);
        setBlock(level, i, j, k, 5, 46, 20, WOOD);
        setBlock(level, i, j, k, 6, 46, 20, WOOD);
        setBlock(level, i, j, k, 7, 46, 20, WOOD);
        setBlock(level, i, j, k, 8, 46, 19, WOOD);
        setBlock(level, i, j, k, 7, 46, 19, WOOD);
        setBlock(level, i, j, k, 6, 46, 19, WOOD);
        setBlock(level, i, j, k, 5, 46, 19, WOOD);
        setBlock(level, i, j, k, 4, 46, 19, WOOD);
        setBlock(level, i, j, k, 3, 46, 19, WOOD);
        setBlock(level, i, j, k, 2, 46, 19, WOOD);
        setBlock(level, i, j, k, 8, 45, 17, WOOD);
        setBlock(level, i, j, k, 3, 45, 17, WOOD);
        setBlock(level, i, j, k, 3, 46, 18, WOOD);
        setBlock(level, i, j, k, 8, 46, 18, WOOD);
        setBlock(level, i, j, k, 7, 46, 18, WOOD);
        setBlock(level, i, j, k, 4, 46, 18, WOOD);
        setBlock(level, i, j, k, 2, 45, 20, WOOD);
        setBlock(level, i, j, k, 1, 46, 19, WOOD);
        setBlock(level, i, j, k, 1, 45, 20, WOOD);
        setBlock(level, i, j, k, 0, 45, 20, WOOD);
        setBlock(level, i, j, k, 1, 45, 21, WOOD);
        setBlock(level, i, j, k, 0, 46, 20, WOOD);
        setBlock(level, i, j, k, 0, 46, 21, WOOD);
        setBlock(level, i, j, k, -1, 46, 21, WOOD);
        setBlock(level, i, j, k, -2, 46, 21, WOOD);
        setBlock(level, i, j, k, 0, 45, 21, WOOD);
        setBlock(level, i, j, k, -2, 46, 21, AIR);
        setBlock(level, i, j, k, -1, 46, 22, WOOD);
        setBlock(level, i, j, k, -1, 46, 22, AIR);
        setBlock(level, i, j, k, 0, 46, 22, WOOD);
        setBlock(level, i, j, k, -1, 47, 21, WOOD);
        setBlock(level, i, j, k, -2, 47, 21, WOOD);
        setBlock(level, i, j, k, -1, 47, 21, AIR);
        setBlock(level, i, j, k, 0, 47, 22, WOOD);
        setBlock(level, i, j, k, 0, 47, 23, WOOD);
        setBlock(level, i, j, k, 0, 47, 22, AIR);
        setBlock(level, i, j, k, 1, 46, 20, WOOD);
        setBlock(level, i, j, k, 0, 46, 23, WOOD);
        setBlock(level, i, j, k, -2, 46, 21, WOOD);
        setBlock(level, i, j, k, -3, 47, 21, WOOD);
        setBlock(level, i, j, k, -2, 47, 22, WOOD);
        setBlock(level, i, j, k, -1, 47, 23, WOOD);
        setBlock(level, i, j, k, 0, 47, 24, WOOD);
        setBlock(level, i, j, k, 1, 47, 23, WOOD);
        setBlock(level, i, j, k, 1, 48, 23, WOOD);
        setBlock(level, i, j, k, 0, 46, 23, AIR);
        setBlock(level, i, j, k, 1, 47, 23, AIR);
        setBlock(level, i, j, k, 0, 46, 23, WOOD);
        setBlock(level, i, j, k, -3, 48, 21, WOOD);
        setBlock(level, i, j, k, -3, 47, 21, AIR);
        setBlock(level, i, j, k, 1, 46, 23, WOOD);
        setBlock(level, i, j, k, 1, 46, 23, AIR);
        setBlock(level, i, j, k, 1, 47, 23, WOOD);
        setBlock(level, i, j, k, 0, 48, 23, WOOD);
        setBlock(level, i, j, k, -3, 47, 21, WOOD);
        setBlock(level, i, j, k, -2, 48, 21, WOOD);
        setBlock(level, i, j, k, -3, 48, 22, WOOD);
        setBlock(level, i, j, k, -4, 48, 22, WOOD);
        setBlock(level, i, j, k, -3, 48, 22, AIR);
        setBlock(level, i, j, k, 1, 47, 24, WOOD);
        setBlock(level, i, j, k, 1, 48, 24, WOOD);
        setBlock(level, i, j, k, 1, 47, 24, AIR);
        setBlock(level, i, j, k, 2, 48, 24, WOOD);
        setBlock(level, i, j, k, 2, 48, 25, WOOD);
        setBlock(level, i, j, k, 2, 48, 25, AIR);
        setBlock(level, i, j, k, 2, 48, 25, WOOD);
        setBlock(level, i, j, k, 3, 48, 24, WOOD);
        setBlock(level, i, j, k, 3, 48, 25, WOOD);
        setBlock(level, i, j, k, 3, 49, 25, WOOD);
        setBlock(level, i, j, k, 2, 48, 25, AIR);
        setBlock(level, i, j, k, 3, 48, 25, AIR);
        setBlock(level, i, j, k, 3, 48, 24, AIR);
        setBlock(level, i, j, k, 3, 48, 24, WOOD);
        setBlock(level, i, j, k, 2, 48, 25, WOOD);
        setBlock(level, i, j, k, 0, 46, 23, AIR);
        setBlock(level, i, j, k, -1, 47, 23, AIR);
        setBlock(level, i, j, k, 0, 48, 23, AIR);
        setBlock(level, i, j, k, 0, 47, 24, AIR);
        setBlock(level, i, j, k, 1, 47, 23, AIR);
        setBlock(level, i, j, k, 1, 48, 24, AIR);
        setBlock(level, i, j, k, 2, 48, 24, AIR);
        setBlock(level, i, j, k, 3, 48, 24, AIR);
        setBlock(level, i, j, k, 3, 49, 25, AIR);
        setBlock(level, i, j, k, 2, 48, 25, AIR);
        setBlock(level, i, j, k, -2, 48, 21, AIR);
        setBlock(level, i, j, k, -3, 48, 21, AIR);
        setBlock(level, i, j, k, -3, 47, 21, AIR);
        setBlock(level, i, j, k, -4, 48, 22, AIR);
        setBlock(level, i, j, k, -2, 47, 22, AIR);
        setBlock(level, i, j, k, -2, 47, 21, AIR);
        setBlock(level, i, j, k, -2, 46, 21, AIR);
        setBlock(level, i, j, k, 0, 47, 23, AIR);
        setBlock(level, i, j, k, 1, 48, 23, AIR);
        setBlock(level, i, j, k, -1, 47, 21, WOOD);
        setBlock(level, i, j, k, 0, 47, 21, WOOD);
        setBlock(level, i, j, k, 0, 47, 22, WOOD);
        setBlock(level, i, j, k, 1, 46, 21, WOOD);
        setBlock(level, i, j, k, 1, 47, 20, WOOD);
        setBlock(level, i, j, k, 4, 46, 21, WOOD);
        setBlock(level, i, j, k, 5, 46, 21, WOOD);
        setBlock(level, i, j, k, 6, 46, 21, WOOD);
        setBlock(level, i, j, k, 4, 47, 21, WOOD);
        setBlock(level, i, j, k, 5, 47, 21, WOOD);
        setBlock(level, i, j, k, 6, 47, 21, WOOD);
        setBlock(level, i, j, k, 7, 47, 21, WOOD);
        setBlock(level, i, j, k, 7, 47, 22, WOOD);
        setBlock(level, i, j, k, 8, 47, 22, WOOD);
        setBlock(level, i, j, k, 9, 47, 22, WOOD);
        setBlock(level, i, j, k, 8, 47, 21, WOOD);
        setBlock(level, i, j, k, 7, 46, 21, WOOD);
        setBlock(level, i, j, k, 9, 48, 22, WOOD);
        setBlock(level, i, j, k, 8, 48, 22, WOOD);
        setBlock(level, i, j, k, 8, 48, 23, WOOD);
        setBlock(level, i, j, k, 9, 48, 23, WOOD);
        setBlock(level, i, j, k, 10, 48, 22, WOOD);
        setBlock(level, i, j, k, 9, 47, 21, WOOD);
        setBlock(level, i, j, k, 8, 47, 20, WOOD);
        setBlock(level, i, j, k, 7, 47, 20, WOOD);
        setBlock(level, i, j, k, 8, 48, 21, WOOD);
        setBlock(level, i, j, k, 7, 48, 22, WOOD);
        setBlock(level, i, j, k, 9, 49, 23, WOOD);
        setBlock(level, i, j, k, 8, 49, 23, WOOD);
        setBlock(level, i, j, k, 8, 49, 24, WOOD);
        setBlock(level, i, j, k, 9, 49, 24, WOOD);
        setBlock(level, i, j, k, 10, 49, 23, WOOD);
        setBlock(level, i, j, k, 10, 49, 24, WOOD);
        setBlock(level, i, j, k, 9, 49, 25, WOOD);
        setBlock(level, i, j, k, 10, 49, 25, WOOD);
        setBlock(level, i, j, k, 10, 50, 25, WOOD);
        setBlock(level, i, j, k, 11, 49, 24, WOOD);
        setBlock(level, i, j, k, 11, 50, 24, WOOD);
        setBlock(level, i, j, k, 10, 50, 24, WOOD);
        setBlock(level, i, j, k, 9, 50, 24, WOOD);
        setBlock(level, i, j, k, 9, 50, 23, WOOD);
        setBlock(level, i, j, k, 9, 49, 22, WOOD);
        setBlock(level, i, j, k, 11, 49, 24, AIR);
        setBlock(level, i, j, k, 10, 49, 25, AIR);
        setBlock(level, i, j, k, -10, 48, 17, LEAVES);
        setBlock(level, i, j, k, -9, 48, 17, LEAVES);
        setBlock(level, i, j, k, -9, 48, 18, LEAVES);
        setBlock(level, i, j, k, -8, 47, 16, LEAVES);
        setBlock(level, i, j, k, -8, 47, 17, LEAVES);
        setBlock(level, i, j, k, -8, 47, 18, LEAVES);
        setBlock(level, i, j, k, -8, 47, 19, LEAVES);
        setBlock(level, i, j, k, -8, 47, 20, LEAVES);
        setBlock(level, i, j, k, -9, 47, 17, LEAVES);
        setBlock(level, i, j, k, -9, 47, 18, LEAVES);
        setBlock(level, i, j, k, -10, 47, 17, LEAVES);
        setBlock(level, i, j, k, -11, 47, 17, LEAVES);
        setBlock(level, i, j, k, -11, 47, 16, LEAVES);
        setBlock(level, i, j, k, -11, 47, 15, LEAVES);
        setBlock(level, i, j, k, -12, 47, 15, LEAVES);
        setBlock(level, i, j, k, -12, 47, 14, LEAVES);
        setBlock(level, i, j, k, -13, 47, 14, LEAVES);
        setBlock(level, i, j, k, -10, 47, 14, LEAVES);
        setBlock(level, i, j, k, -10, 47, 13, LEAVES);
        setBlock(level, i, j, k, -11, 47, 14, LEAVES);
        setBlock(level, i, j, k, -11, 47, 13, LEAVES);
        setBlock(level, i, j, k, -11, 47, 12, LEAVES);
        setBlock(level, i, j, k, -11, 46, 12, LEAVES);
        setBlock(level, i, j, k, -11, 46, 11, LEAVES);
        setBlock(level, i, j, k, -12, 46, 11, LEAVES);
        setBlock(level, i, j, k, -12, 46, 13, LEAVES);
        setBlock(level, i, j, k, -13, 46, 13, LEAVES);
        setBlock(level, i, j, k, -13, 46, 12, LEAVES);
        setBlock(level, i, j, k, -12, 46, 14, LEAVES);
        setBlock(level, i, j, k, -12, 46, 15, LEAVES);
        setBlock(level, i, j, k, -11, 46, 15, LEAVES);
        setBlock(level, i, j, k, -11, 46, 16, LEAVES);
        setBlock(level, i, j, k, -10, 46, 16, LEAVES);
        setBlock(level, i, j, k, -9, 46, 17, LEAVES);
        setBlock(level, i, j, k, -8, 46, 18, LEAVES);
        setBlock(level, i, j, k, -7, 46, 18, LEAVES);
        setBlock(level, i, j, k, -7, 46, 17, LEAVES);
        setBlock(level, i, j, k, -7, 46, 16, LEAVES);
        setBlock(level, i, j, k, -7, 46, 15, LEAVES);
        setBlock(level, i, j, k, -8, 46, 14, LEAVES);
        setBlock(level, i, j, k, -9, 46, 13, LEAVES);
        setBlock(level, i, j, k, -10, 46, 13, LEAVES);
        setBlock(level, i, j, k, -10, 46, 12, LEAVES);
        setBlock(level, i, j, k, -8, 47, 15, AIR);
        setBlock(level, i, j, k, -8, 47, 15, LEAVES);
        setBlock(level, i, j, k, -9, 47, 14, AIR);
        setBlock(level, i, j, k, -9, 47, 14, LEAVES);
        setBlock(level, i, j, k, -6, 46, 17, LEAVES);
        setBlock(level, i, j, k, -6, 46, 16, LEAVES);
        setBlock(level, i, j, k, -6, 46, 15, LEAVES);
        setBlock(level, i, j, k, -7, 47, 16, LEAVES);
        setBlock(level, i, j, k, -6, 47, 15, LEAVES);
        setBlock(level, i, j, k, -7, 46, 14, LEAVES);
        setBlock(level, i, j, k, -6, 47, 15, AIR);
        setBlock(level, i, j, k, -9, 46, 12, LEAVES);
        setBlock(level, i, j, k, -10, 46, 11, LEAVES);
        setBlock(level, i, j, k, -12, 47, 13, WOOD);
        setBlock(level, i, j, k, -12, 47, 12, WOOD);
        setBlock(level, i, j, k, -12, 47, 11, LEAVES);
        setBlock(level, i, j, k, -12, 47, 10, LEAVES);
        setBlock(level, i, j, k, -13, 47, 13, LEAVES);
        setBlock(level, i, j, k, -13, 47, 11, LEAVES);
        setBlock(level, i, j, k, -13, 47, 12, LEAVES);
        setBlock(level, i, j, k, -14, 47, 12, LEAVES);
        setBlock(level, i, j, k, -14, 47, 13, LEAVES);
        setBlock(level, i, j, k, -11, 48, 14, LEAVES);
        setBlock(level, i, j, k, -11, 48, 13, LEAVES);
        setBlock(level, i, j, k, -12, 48, 13, LEAVES);
        setBlock(level, i, j, k, -12, 48, 12, LEAVES);
        setBlock(level, i, j, k, -13, 48, 12, LEAVES);
        setBlock(level, i, j, k, -13, 48, 13, LEAVES);
        setBlock(level, i, j, k, -12, 48, 14, LEAVES);
        setBlock(level, i, j, k, -11, 48, 15, LEAVES);
        setBlock(level, i, j, k, -10, 48, 18, LEAVES);
        setBlock(level, i, j, k, -8, 48, 16, LEAVES);
        setBlock(level, i, j, k, -8, 48, 17, LEAVES);
        setBlock(level, i, j, k, -7, 48, 16, LEAVES);
        setBlock(level, i, j, k, -8, 47, 20, AIR);
        setBlock(level, i, j, k, -7, 47, 19, LEAVES);
        setBlock(level, i, j, k, -10, 51, 16, WOOD);
        setBlock(level, i, j, k, -11, 51, 16, WOOD);
        setBlock(level, i, j, k, -10, 51, 17, WOOD);
        setBlock(level, i, j, k, -11, 52, 16, WOOD);
        setBlock(level, i, j, k, -10, 52, 17, WOOD);
        setBlock(level, i, j, k, -11, 53, 16, WOOD);
        setBlock(level, i, j, k, -11, 53, 17, WOOD);
        setBlock(level, i, j, k, -11, 53, 17, AIR);
        setBlock(level, i, j, k, -10, 53, 17, WOOD);
        setBlock(level, i, j, k, -12, 53, 16, LEAVES);
        setBlock(level, i, j, k, -11, 53, 15, LEAVES);
        setBlock(level, i, j, k, -11, 53, 14, LEAVES);
        setBlock(level, i, j, k, -10, 53, 16, LEAVES);
        setBlock(level, i, j, k, -9, 53, 16, LEAVES);
        setBlock(level, i, j, k, -10, 53, 15, LEAVES);
        setBlock(level, i, j, k, -9, 53, 17, LEAVES);
        setBlock(level, i, j, k, -9, 53, 18, LEAVES);
        setBlock(level, i, j, k, -10, 53, 18, LEAVES);
        setBlock(level, i, j, k, -12, 53, 17, LEAVES);
        setBlock(level, i, j, k, -11, 53, 17, LEAVES);
        setBlock(level, i, j, k, -11, 53, 18, LEAVES);
        setBlock(level, i, j, k, -13, 53, 16, LEAVES);
        setBlock(level, i, j, k, -12, 53, 15, LEAVES);
        setBlock(level, i, j, k, -11, 54, 15, LEAVES);
        setBlock(level, i, j, k, -12, 54, 15, LEAVES);
        setBlock(level, i, j, k, -12, 54, 16, LEAVES);
        setBlock(level, i, j, k, -10, 54, 16, LEAVES);
        setBlock(level, i, j, k, -11, 54, 16, LEAVES);
        setBlock(level, i, j, k, -10, 54, 17, LEAVES);
        setBlock(level, i, j, k, -10, 54, 18, LEAVES);
        setBlock(level, i, j, k, -11, 54, 17, LEAVES);
        setBlock(level, i, j, k, -9, 54, 17, LEAVES);
        setBlock(level, i, j, k, -9, 54, 18, LEAVES);
        setBlock(level, i, j, k, -9, 53, 19, LEAVES);
        setBlock(level, i, j, k, -8, 53, 18, LEAVES);
        setBlock(level, i, j, k, -9, 54, 19, LEAVES);
        setBlock(level, i, j, k, -10, 53, 19, LEAVES);
        setBlock(level, i, j, k, -8, 53, 19, LEAVES);
        setBlock(level, i, j, k, -9, 53, 20, LEAVES);
        setBlock(level, i, j, k, -8, 54, 17, LEAVES);
        setBlock(level, i, j, k, -8, 54, 17, AIR);
        setBlock(level, i, j, k, -8, 53, 17, LEAVES);
        setBlock(level, i, j, k, -7, 53, 18, LEAVES);
        setBlock(level, i, j, k, -7, 53, 17, LEAVES);
        setBlock(level, i, j, k, -8, 53, 16, LEAVES);
        setBlock(level, i, j, k, -8, 54, 18, LEAVES);
        setBlock(level, i, j, k, -8, 54, 17, LEAVES);
        setBlock(level, i, j, k, -9, 54, 16, LEAVES);
        setBlock(level, i, j, k, -9, 53, 15, LEAVES);
        setBlock(level, i, j, k, 1, 45, 22, LEAVES);
        setBlock(level, i, j, k, 1, 45, 22, AIR);
        setBlock(level, i, j, k, 1, 46, 22, LEAVES);
        setBlock(level, i, j, k, 1, 46, 23, LEAVES);
        setBlock(level, i, j, k, 1, 46, 24, LEAVES);
        setBlock(level, i, j, k, 1, 46, 25, LEAVES);
        setBlock(level, i, j, k, 0, 46, 23, LEAVES);
        setBlock(level, i, j, k, 0, 46, 24, LEAVES);
        setBlock(level, i, j, k, 0, 46, 25, LEAVES);
        setBlock(level, i, j, k, -1, 46, 23, LEAVES);
        setBlock(level, i, j, k, -2, 46, 23, LEAVES);
        setBlock(level, i, j, k, -1, 46, 22, LEAVES);
        setBlock(level, i, j, k, -2, 46, 22, LEAVES);
        setBlock(level, i, j, k, -3, 46, 22, LEAVES);
        setBlock(level, i, j, k, -3, 46, 21, LEAVES);
        setBlock(level, i, j, k, -2, 46, 21, LEAVES);
        setBlock(level, i, j, k, -2, 46, 20, LEAVES);
        setBlock(level, i, j, k, -1, 46, 20, LEAVES);
        setBlock(level, i, j, k, -1, 46, 19, LEAVES);
        setBlock(level, i, j, k, 0, 46, 19, LEAVES);
        setBlock(level, i, j, k, 0, 46, 18, LEAVES);
        setBlock(level, i, j, k, 2, 46, 18, LEAVES);
        setBlock(level, i, j, k, 1, 46, 18, LEAVES);
        setBlock(level, i, j, k, 1, 45, 19, LEAVES);
        setBlock(level, i, j, k, 1, 45, 18, LEAVES);
        setBlock(level, i, j, k, 0, 45, 19, LEAVES);
        setBlock(level, i, j, k, 1, 45, 22, LEAVES);
        setBlock(level, i, j, k, 0, 45, 22, LEAVES);
        setBlock(level, i, j, k, -1, 45, 21, LEAVES);
        setBlock(level, i, j, k, -1, 45, 22, LEAVES);
        setBlock(level, i, j, k, -1, 45, 20, LEAVES);
        setBlock(level, i, j, k, -2, 45, 21, LEAVES);
        setBlock(level, i, j, k, -2, 45, 22, LEAVES);
        setBlock(level, i, j, k, -1, 45, 23, LEAVES);
        setBlock(level, i, j, k, 0, 45, 23, LEAVES);
        setBlock(level, i, j, k, 0, 44, 21, LEAVES);
        setBlock(level, i, j, k, 0, 44, 19, LEAVES);
        setBlock(level, i, j, k, 1, 44, 20, LEAVES);
        setBlock(level, i, j, k, 0, 44, 20, LEAVES);
        setBlock(level, i, j, k, 1, 44, 21, LEAVES);
        setBlock(level, i, j, k, 1, 44, 19, LEAVES);
        setBlock(level, i, j, k, -1, 44, 21, LEAVES);
        setBlock(level, i, j, k, -1, 43, 21, LEAVES);
        setBlock(level, i, j, k, -1, 43, 21, AIR);
        setBlock(level, i, j, k, -1, 44, 21, AIR);
        setBlock(level, i, j, k, -1, 44, 22, LEAVES);
        setBlock(level, i, j, k, -1, 46, 24, LEAVES);
        setBlock(level, i, j, k, -3, 46, 23, LEAVES);
        setBlock(level, i, j, k, -3, 47, 23, LEAVES);
        setBlock(level, i, j, k, -2, 46, 24, LEAVES);
        setBlock(level, i, j, k, -3, 47, 23, AIR);
        setBlock(level, i, j, k, -1, 47, 22, LEAVES);
        setBlock(level, i, j, k, -1, 47, 23, LEAVES);
        setBlock(level, i, j, k, -2, 47, 21, LEAVES);
        setBlock(level, i, j, k, -2, 47, 22, LEAVES);
        setBlock(level, i, j, k, 0, 47, 23, LEAVES);
        setBlock(level, i, j, k, 1, 47, 22, LEAVES);
        setBlock(level, i, j, k, 1, 47, 21, LEAVES);
        setBlock(level, i, j, k, 0, 47, 22, AIR);
        setBlock(level, i, j, k, 0, 47, 22, LEAVES);
        setBlock(level, i, j, k, 0, 47, 21, AIR);
        setBlock(level, i, j, k, 0, 47, 21, LEAVES);
        setBlock(level, i, j, k, -1, 47, 21, AIR);
        setBlock(level, i, j, k, -1, 47, 21, LEAVES);
        setBlock(level, i, j, k, 0, 47, 20, LEAVES);
        setBlock(level, i, j, k, 2, 46, 20, LEAVES);
        setBlock(level, i, j, k, 2, 46, 21, LEAVES);
        setBlock(level, i, j, k, 2, 46, 22, LEAVES);
        setBlock(level, i, j, k, 2, 46, 23, LEAVES);
        setBlock(level, i, j, k, 2, 46, 24, LEAVES);
        setBlock(level, i, j, k, 3, 46, 21, LEAVES);
        setBlock(level, i, j, k, 3, 46, 22, LEAVES);
        setBlock(level, i, j, k, 3, 46, 23, LEAVES);
        setBlock(level, i, j, k, 4, 46, 22, LEAVES);
        setBlock(level, i, j, k, 5, 46, 22, LEAVES);
        setBlock(level, i, j, k, 3, 47, 21, LEAVES);
        setBlock(level, i, j, k, 5, 47, 22, LEAVES);
        setBlock(level, i, j, k, 6, 47, 22, LEAVES);
        setBlock(level, i, j, k, -8, 45, 16, LEAVES);
        setBlock(level, i, j, k, -9, 45, 16, LEAVES);
        setBlock(level, i, j, k, -8, 45, 17, LEAVES);
        setBlock(level, i, j, k, -10, 45, 13, LEAVES);
        setBlock(level, i, j, k, -9, 45, 13, LEAVES);
        setBlock(level, i, j, k, -9, 44, 13, LEAVES);
        setBlock(level, i, j, k, 10, 51, 25, WOOD);
        setBlock(level, i, j, k, 10, 51, 24, WOOD);
        setBlock(level, i, j, k, 11, 51, 24, WOOD);
        setBlock(level, i, j, k, 10, 52, 25, WOOD);
        setBlock(level, i, j, k, 10, 52, 24, WOOD);
        setBlock(level, i, j, k, 11, 52, 24, WOOD);
        setBlock(level, i, j, k, 11, 52, 25, WOOD);
        setBlock(level, i, j, k, 10, 53, 25, WOOD);
        setBlock(level, i, j, k, 11, 53, 25, WOOD);
        setBlock(level, i, j, k, 11, 53, 24, WOOD);
        setBlock(level, i, j, k, 10, 53, 26, WOOD);
        setBlock(level, i, j, k, 11, 53, 26, WOOD);
        setBlock(level, i, j, k, 12, 53, 25, WOOD);
        setBlock(level, i, j, k, 11, 54, 26, WOOD);
        setBlock(level, i, j, k, 12, 54, 25, WOOD);
        setBlock(level, i, j, k, 12, 54, 26, WOOD);
        setBlock(level, i, j, k, 11, 55, 26, WOOD);
        setBlock(level, i, j, k, 12, 55, 26, WOOD);
        setBlock(level, i, j, k, 12, 55, 25, WOOD);
        setBlock(level, i, j, k, 11, 56, 26, WOOD);
        setBlock(level, i, j, k, 12, 56, 26, WOOD);
        setBlock(level, i, j, k, 12, 56, 25, WOOD);
        setBlock(level, i, j, k, 10, 50, 23, WOOD);
        setBlock(level, i, j, k, 11, 54, 25, WOOD);
        setBlock(level, i, j, k, 11, 54, 27, WOOD);
        setBlock(level, i, j, k, 10, 54, 26, WOOD);
        setBlock(level, i, j, k, 11, 54, 27, AIR);
        setBlock(level, i, j, k, 13, 54, 25, WOOD);
        setBlock(level, i, j, k, 13, 55, 25, WOOD);
        setBlock(level, i, j, k, 10, 48, 23, WOOD);
        setBlock(level, i, j, k, 8, 48, 24, WOOD);
        setBlock(level, i, j, k, 9, 48, 24, WOOD);
        setBlock(level, i, j, k, 9, 47, 23, WOOD);
        setBlock(level, i, j, k, 8, 46, 20, WOOD);
        setBlock(level, i, j, k, 8, 46, 21, WOOD);
        setBlock(level, i, j, k, 8, 45, 20, WOOD);
        setBlock(level, i, j, k, 7, 44, 20, WOOD);
        setBlock(level, i, j, k, 7, 43, 19, WOOD);
        setBlock(level, i, j, k, 7, 42, 19, WOOD);
        setBlock(level, i, j, k, 7, 41, 18, WOOD);
        setBlock(level, i, j, k, 6, 41, 18, WOOD);
        setBlock(level, i, j, k, 6, 40, 18, WOOD);
        setBlock(level, i, j, k, 7, 40, 17, WOOD);
        setBlock(level, i, j, k, 7, 39, 17, WOOD);
        setBlock(level, i, j, k, 8, 44, 19, WOOD);
        setBlock(level, i, j, k, 8, 43, 19, WOOD);
        setBlock(level, i, j, k, 8, 44, 20, WOOD);
        setBlock(level, i, j, k, 7, 45, 21, WOOD);
        setBlock(level, i, j, k, 7, 44, 21, WOOD);
        setBlock(level, i, j, k, 8, 45, 21, WOOD);
        setBlock(level, i, j, k, 8, 44, 21, WOOD);
        setBlock(level, i, j, k, 7, 43, 20, WOOD);
        setBlock(level, i, j, k, 6, 45, 21, WOOD);
        setBlock(level, i, j, k, 6, 43, 20, WOOD);
        setBlock(level, i, j, k, 6, 42, 19, WOOD);
        setBlock(level, i, j, k, 5, 41, 18, WOOD);
        setBlock(level, i, j, k, 7, 40, 18, WOOD);
        setBlock(level, i, j, k, 8, 41, 17, WOOD);
        setBlock(level, i, j, k, 8, 42, 18, WOOD);
        setBlock(level, i, j, k, 9, 43, 18, WOOD);
        setBlock(level, i, j, k, 9, 42, 17, WOOD);
        setBlock(level, i, j, k, 9, 41, 15, WOOD);
        setBlock(level, i, j, k, 9, 41, 16, WOOD);
        setBlock(level, i, j, k, 9, 43, 17, WOOD);
        setBlock(level, i, j, k, 9, 42, 16, WOOD);
        setBlock(level, i, j, k, 9, 46, 20, WOOD);
        setBlock(level, i, j, k, 9, 45, 19, WOOD);
        setBlock(level, i, j, k, 9, 51, 24, WOOD);
        setBlock(level, i, j, k, 9, 50, 25, WOOD);
        setBlock(level, i, j, k, 9, 51, 25, WOOD);
        setBlock(level, i, j, k, 9, 52, 25, WOOD);
        setBlock(level, i, j, k, 9, 53, 25, WOOD);
        setBlock(level, i, j, k, 9, 52, 24, WOOD);
        setBlock(level, i, j, k, 10, 54, 25, WOOD);
        setBlock(level, i, j, k, 9, 54, 25, WOOD);
        setBlock(level, i, j, k, 11, 55, 25, WOOD);
        setBlock(level, i, j, k, 10, 55, 25, WOOD);
        setBlock(level, i, j, k, 10, 55, 26, WOOD);
        setBlock(level, i, j, k, 10, 56, 26, WOOD);
        setBlock(level, i, j, k, 9, 55, 25, WOOD);
        setBlock(level, i, j, k, 10, 54, 24, WOOD);
        setBlock(level, i, j, k, 10, 53, 24, WOOD);
        setBlock(level, i, j, k, 9, 53, 24, WOOD);
        setBlock(level, i, j, k, 10, 51, 23, WOOD);
        setBlock(level, i, j, k, 10, 52, 23, WOOD);
        setBlock(level, i, j, k, 11, 54, 24, WOOD);
        setBlock(level, i, j, k, 11, 54, 23, WOOD);
        setBlock(level, i, j, k, 12, 54, 24, WOOD);
        setBlock(level, i, j, k, 11, 55, 24, WOOD);
        setBlock(level, i, j, k, 10, 55, 24, WOOD);
        setBlock(level, i, j, k, 9, 54, 24, WOOD);
        setBlock(level, i, j, k, 9, 55, 24, WOOD);
        setBlock(level, i, j, k, 8, 54, 25, WOOD);
        setBlock(level, i, j, k, 8, 53, 24, WOOD);
        setBlock(level, i, j, k, 8, 50, 24, WOOD);
        setBlock(level, i, j, k, 8, 51, 24, WOOD);
        setBlock(level, i, j, k, 8, 52, 24, WOOD);
        setBlock(level, i, j, k, 8, 53, 25, WOOD);
        setBlock(level, i, j, k, 8, 52, 25, WOOD);
        setBlock(level, i, j, k, 8, 51, 25, WOOD);
        setBlock(level, i, j, k, 8, 49, 25, WOOD);
        setBlock(level, i, j, k, 8, 50, 25, WOOD);
        setBlock(level, i, j, k, 9, 52, 26, WOOD);
        setBlock(level, i, j, k, 9, 51, 26, WOOD);
        setBlock(level, i, j, k, 9, 50, 26, WOOD);
        setBlock(level, i, j, k, 9, 54, 26, WOOD);
        setBlock(level, i, j, k, 9, 53, 26, WOOD);
        setBlock(level, i, j, k, 10, 52, 26, WOOD);
        setBlock(level, i, j, k, 7, 46, 22, WOOD);
        setBlock(level, i, j, k, 8, 46, 22, WOOD);
        setBlock(level, i, j, k, 7, 45, 22, WOOD);
        setBlock(level, i, j, k, 8, 45, 22, WOOD);
        setBlock(level, i, j, k, 8, 47, 23, WOOD);
        setBlock(level, i, j, k, 8, 46, 23, WOOD);
        setBlock(level, i, j, k, 8, 47, 24, WOOD);
        setBlock(level, i, j, k, 7, 47, 23, WOOD);
        setBlock(level, i, j, k, 7, 46, 23, WOOD);
        setBlock(level, i, j, k, 6, 46, 22, WOOD);
        setBlock(level, i, j, k, 8, 54, 26, LEAVES);
        setBlock(level, i, j, k, 7, 54, 26, LEAVES);
        setBlock(level, i, j, k, 6, 54, 26, LEAVES);
        setBlock(level, i, j, k, 6, 54, 27, LEAVES);
        setBlock(level, i, j, k, 7, 54, 27, LEAVES);
        setBlock(level, i, j, k, 8, 54, 27, LEAVES);
        setBlock(level, i, j, k, 9, 54, 27, LEAVES);
        setBlock(level, i, j, k, 10, 54, 27, LEAVES);
        setBlock(level, i, j, k, 11, 54, 27, LEAVES);
        setBlock(level, i, j, k, 12, 54, 27, LEAVES);
        setBlock(level, i, j, k, 12, 54, 28, LEAVES);
        setBlock(level, i, j, k, 11, 54, 28, LEAVES);
        setBlock(level, i, j, k, 9, 54, 28, LEAVES);
        setBlock(level, i, j, k, 8, 54, 28, LEAVES);
        setBlock(level, i, j, k, 7, 54, 28, LEAVES);
        setBlock(level, i, j, k, 7, 54, 25, LEAVES);
        setBlock(level, i, j, k, 6, 54, 25, LEAVES);
        setBlock(level, i, j, k, 8, 54, 24, LEAVES);
        setBlock(level, i, j, k, 7, 54, 24, LEAVES);
        setBlock(level, i, j, k, 6, 54, 24, LEAVES);
        setBlock(level, i, j, k, 6, 54, 23, LEAVES);
        setBlock(level, i, j, k, 5, 54, 24, LEAVES);
        setBlock(level, i, j, k, 4, 54, 24, LEAVES);
        setBlock(level, i, j, k, 5, 54, 25, LEAVES);
        setBlock(level, i, j, k, 4, 54, 25, LEAVES);
        setBlock(level, i, j, k, 5, 54, 26, LEAVES);
        setBlock(level, i, j, k, 5, 54, 27, LEAVES);
        setBlock(level, i, j, k, 6, 54, 28, LEAVES);
        setBlock(level, i, j, k, 10, 54, 28, LEAVES);
        setBlock(level, i, j, k, 9, 55, 26, LEAVES);
        setBlock(level, i, j, k, 8, 55, 25, LEAVES);
        setBlock(level, i, j, k, 8, 55, 26, LEAVES);
        setBlock(level, i, j, k, 8, 55, 27, LEAVES);
        setBlock(level, i, j, k, 7, 55, 25, LEAVES);
        setBlock(level, i, j, k, 7, 55, 26, LEAVES);
        setBlock(level, i, j, k, 7, 55, 27, LEAVES);
        setBlock(level, i, j, k, 6, 55, 25, LEAVES);
        setBlock(level, i, j, k, 6, 55, 26, LEAVES);
        setBlock(level, i, j, k, 5, 55, 25, LEAVES);
        setBlock(level, i, j, k, 8, 55, 24, LEAVES);
        setBlock(level, i, j, k, 7, 55, 24, LEAVES);
        setBlock(level, i, j, k, 6, 55, 24, LEAVES);
        setBlock(level, i, j, k, 7, 54, 23, LEAVES);
        setBlock(level, i, j, k, 8, 54, 23, LEAVES);
        setBlock(level, i, j, k, 9, 54, 23, LEAVES);
        setBlock(level, i, j, k, 10, 54, 23, LEAVES);
        setBlock(level, i, j, k, 10, 54, 22, LEAVES);
        setBlock(level, i, j, k, 11, 54, 22, LEAVES);
        setBlock(level, i, j, k, 12, 54, 22, LEAVES);
        setBlock(level, i, j, k, 12, 54, 23, LEAVES);
        setBlock(level, i, j, k, 13, 54, 24, LEAVES);
        setBlock(level, i, j, k, 13, 54, 23, LEAVES);
        setBlock(level, i, j, k, 14, 54, 24, LEAVES);
        setBlock(level, i, j, k, 14, 54, 25, LEAVES);
        setBlock(level, i, j, k, 14, 54, 26, LEAVES);
        setBlock(level, i, j, k, 13, 54, 26, LEAVES);
        setBlock(level, i, j, k, 13, 54, 27, LEAVES);
        setBlock(level, i, j, k, 14, 54, 27, LEAVES);
        setBlock(level, i, j, k, 15, 54, 26, LEAVES);
        setBlock(level, i, j, k, 15, 54, 25, LEAVES);
        setBlock(level, i, j, k, 16, 54, 25, LEAVES);
        setBlock(level, i, j, k, 15, 54, 24, LEAVES);
        setBlock(level, i, j, k, 16, 54, 24, LEAVES);
        setBlock(level, i, j, k, 15, 54, 23, LEAVES);
        setBlock(level, i, j, k, 14, 54, 23, LEAVES);
        setBlock(level, i, j, k, 13, 54, 22, LEAVES);
        setBlock(level, i, j, k, 14, 54, 22, LEAVES);
        setBlock(level, i, j, k, 12, 54, 21, LEAVES);
        setBlock(level, i, j, k, 11, 54, 21, LEAVES);
        setBlock(level, i, j, k, 10, 54, 21, LEAVES);
        setBlock(level, i, j, k, 9, 54, 22, LEAVES);
        setBlock(level, i, j, k, 8, 54, 22, LEAVES);
        setBlock(level, i, j, k, 7, 54, 22, LEAVES);
        setBlock(level, i, j, k, 11, 55, 23, LEAVES);
        setBlock(level, i, j, k, 10, 55, 23, LEAVES);
        setBlock(level, i, j, k, 9, 55, 23, LEAVES);
        setBlock(level, i, j, k, 8, 55, 23, LEAVES);
        setBlock(level, i, j, k, 7, 55, 23, LEAVES);
        setBlock(level, i, j, k, 10, 53, 23, LEAVES);
        setBlock(level, i, j, k, 11, 53, 23, LEAVES);
        setBlock(level, i, j, k, 12, 53, 23, LEAVES);
        setBlock(level, i, j, k, 12, 53, 24, LEAVES);
        setBlock(level, i, j, k, 13, 53, 24, LEAVES);
        setBlock(level, i, j, k, 13, 53, 25, LEAVES);
        setBlock(level, i, j, k, 12, 53, 26, LEAVES);
        setBlock(level, i, j, k, 11, 53, 27, LEAVES);
        setBlock(level, i, j, k, 9, 53, 27, LEAVES);
        setBlock(level, i, j, k, 10, 53, 27, LEAVES);
        setBlock(level, i, j, k, 12, 52, 25, LEAVES);
        setBlock(level, i, j, k, 12, 52, 24, LEAVES);
        setBlock(level, i, j, k, 11, 52, 23, LEAVES);
        setBlock(level, i, j, k, 9, 53, 23, LEAVES);
        setBlock(level, i, j, k, 11, 53, 22, LEAVES);
        setBlock(level, i, j, k, 10, 53, 22, LEAVES);
        setBlock(level, i, j, k, 8, 53, 23, LEAVES);
        setBlock(level, i, j, k, 7, 53, 24, LEAVES);
        setBlock(level, i, j, k, 9, 52, 23, LEAVES);
        setBlock(level, i, j, k, 7, 53, 25, LEAVES);
        setBlock(level, i, j, k, 8, 53, 26, LEAVES);
        setBlock(level, i, j, k, 8, 52, 26, LEAVES);
        setBlock(level, i, j, k, 9, 55, 27, LEAVES);
        setBlock(level, i, j, k, 10, 55, 27, LEAVES);
        setBlock(level, i, j, k, 6, 54, 29, LEAVES);
        setBlock(level, i, j, k, 7, 54, 29, LEAVES);
        setBlock(level, i, j, k, 7, 54, 30, LEAVES);
        setBlock(level, i, j, k, 9, 54, 29, LEAVES);
        setBlock(level, i, j, k, 8, 54, 29, LEAVES);
        setBlock(level, i, j, k, 10, 54, 29, LEAVES);
        setBlock(level, i, j, k, 10, 54, 30, LEAVES);
        setBlock(level, i, j, k, 8, 54, 30, LEAVES);
        setBlock(level, i, j, k, 9, 54, 30, LEAVES);
        setBlock(level, i, j, k, 11, 54, 29, LEAVES);
        setBlock(level, i, j, k, 12, 54, 29, LEAVES);
        setBlock(level, i, j, k, 11, 54, 30, LEAVES);
        setBlock(level, i, j, k, 13, 54, 28, LEAVES);
        setBlock(level, i, j, k, 13, 54, 29, LEAVES);
        setBlock(level, i, j, k, 11, 55, 27, LEAVES);
        setBlock(level, i, j, k, 12, 55, 27, LEAVES);
        setBlock(level, i, j, k, 8, 55, 28, LEAVES);
        setBlock(level, i, j, k, 9, 55, 28, LEAVES);
        setBlock(level, i, j, k, 10, 55, 28, LEAVES);
        setBlock(level, i, j, k, 8, 55, 29, LEAVES);
        setBlock(level, i, j, k, 9, 55, 29, LEAVES);
        setBlock(level, i, j, k, 10, 55, 29, LEAVES);
        setBlock(level, i, j, k, 11, 55, 28, LEAVES);
        setBlock(level, i, j, k, 11, 55, 29, LEAVES);
        setBlock(level, i, j, k, 12, 55, 28, LEAVES);
        setBlock(level, i, j, k, 13, 55, 26, LEAVES);
        setBlock(level, i, j, k, 13, 55, 27, LEAVES);
        setBlock(level, i, j, k, 14, 55, 25, LEAVES);
        setBlock(level, i, j, k, 14, 55, 26, LEAVES);
        setBlock(level, i, j, k, 12, 55, 24, LEAVES);
        setBlock(level, i, j, k, 13, 55, 24, LEAVES);
        setBlock(level, i, j, k, 12, 55, 23, LEAVES);
        setBlock(level, i, j, k, 13, 55, 23, LEAVES);
        setBlock(level, i, j, k, 14, 55, 24, LEAVES);
        setBlock(level, i, j, k, 14, 55, 23, LEAVES);
        setBlock(level, i, j, k, 15, 55, 25, LEAVES);
        setBlock(level, i, j, k, 15, 55, 24, LEAVES);
        setBlock(level, i, j, k, 7, 48, 21, LEAVES);
        setBlock(level, i, j, k, 6, 47, 21, AIR);
        setBlock(level, i, j, k, 6, 47, 21, LEAVES);
        setBlock(level, i, j, k, 5, 47, 21, AIR);
        setBlock(level, i, j, k, 5, 47, 21, LEAVES);
        setBlock(level, i, j, k, 6, 47, 20, LEAVES);
        setBlock(level, i, j, k, 4, 47, 21, AIR);
        setBlock(level, i, j, k, 4, 47, 21, LEAVES);
        setBlock(level, i, j, k, 3, 36, 14, WOOD);
        setBlock(level, i, j, k, 4, 35, 14, WOOD);
        setBlock(level, i, j, k, 4, 34, 14, WOOD);
        setBlock(level, i, j, k, 5, 35, 14, WOOD);
        setBlock(level, i, j, k, 5, 34, 14, WOOD);
        setBlock(level, i, j, k, 5, 33, 14, WOOD);
        setBlock(level, i, j, k, 6, 35, 14, WOOD);
        setBlock(level, i, j, k, 6, 34, 14, WOOD);
        setBlock(level, i, j, k, 7, 35, 14, WOOD);
        setBlock(level, i, j, k, 7, 34, 14, WOOD);
        setBlock(level, i, j, k, 8, 35, 14, WOOD);
        setBlock(level, i, j, k, 7, 33, 13, WOOD);
        setBlock(level, i, j, k, 5, 36, 15, WOOD);
        setBlock(level, i, j, k, 5, 35, 15, WOOD);
        setBlock(level, i, j, k, 6, 36, 15, WOOD);
        setBlock(level, i, j, k, 6, 36, 16, WOOD);
        setBlock(level, i, j, k, 6, 35, 15, WOOD);
        setBlock(level, i, j, k, 6, 36, 16, AIR);
        setBlock(level, i, j, k, 7, 36, 15, WOOD);
        setBlock(level, i, j, k, 7, 35, 15, WOOD);
        setBlock(level, i, j, k, 5, 37, 16, WOOD);
        setBlock(level, i, j, k, 5, 36, 16, WOOD);
        setBlock(level, i, j, k, 6, 37, 16, WOOD);
        setBlock(level, i, j, k, 6, 36, 16, WOOD);
        setBlock(level, i, j, k, -1, 46, 25, LEAVES);
        setBlock(level, i, j, k, 0, 47, 24, LEAVES);
        setBlock(level, i, j, k, 1, 47, 23, LEAVES);
        setBlock(level, i, j, k, 1, 47, 24, LEAVES);
        setBlock(level, i, j, k, 2, 47, 21, LEAVES);
        setBlock(level, i, j, k, 2, 47, 22, LEAVES);
        setBlock(level, i, j, k, 3, 47, 22, LEAVES);
        setBlock(level, i, j, k, 2, 46, 25, LEAVES);
        setBlock(level, i, j, k, 3, 46, 24, LEAVES);
        setBlock(level, i, j, k, 8, 53, 27, LEAVES);
        setBlock(level, i, j, k, 7, 53, 26, LEAVES);
        setBlock(level, i, j, k, 6, 53, 25, LEAVES);
        setBlock(level, i, j, k, 9, 53, 28, LEAVES);
        setBlock(level, i, j, k, 10, 53, 28, LEAVES);
        setBlock(level, i, j, k, 9, 53, 29, LEAVES);
        setBlock(level, i, j, k, 8, 53, 28, LEAVES);
        setBlock(level, i, j, k, 7, 53, 27, LEAVES);
        setBlock(level, i, j, k, 12, 53, 27, LEAVES);
        setBlock(level, i, j, k, 11, 56, 25, LEAVES);
        setBlock(level, i, j, k, 11, 56, 24, LEAVES);
        setBlock(level, i, j, k, 10, 56, 25, LEAVES);
        setBlock(level, i, j, k, 10, 56, 24, LEAVES);
        setBlock(level, i, j, k, 12, 56, 25, AIR);
        setBlock(level, i, j, k, 12, 56, 25, LEAVES);
        setBlock(level, i, j, k, 13, 55, 25, AIR);
        setBlock(level, i, j, k, 13, 55, 25, LEAVES);
        setBlock(level, i, j, k, 12, 56, 26, AIR);
        setBlock(level, i, j, k, 12, 56, 26, LEAVES);
        setBlock(level, i, j, k, 11, 56, 26, AIR);
        setBlock(level, i, j, k, 11, 56, 26, LEAVES);
        setBlock(level, i, j, k, 10, 56, 26, AIR);
        setBlock(level, i, j, k, 10, 56, 26, LEAVES);
        setBlock(level, i, j, k, 9, 56, 26, LEAVES);
        setBlock(level, i, j, k, 10, 56, 27, LEAVES);
        setBlock(level, i, j, k, 9, 56, 27, LEAVES);
        setBlock(level, i, j, k, 9, 55, 24, AIR);
        setBlock(level, i, j, k, 9, 55, 24, LEAVES);
        setBlock(level, i, j, k, 9, 55, 25, AIR);
        setBlock(level, i, j, k, 9, 55, 25, LEAVES);
        setBlock(level, i, j, k, 9, 56, 24, LEAVES);
        setBlock(level, i, j, k, 9, 56, 25, LEAVES);
        setBlock(level, i, j, k, 8, 56, 25, LEAVES);
        setBlock(level, i, j, k, 8, 56, 26, LEAVES);
        setBlock(level, i, j, k, -11, 53, 19, LEAVES);
        setBlock(level, i, j, k, -12, 53, 18, LEAVES);
        setBlock(level, i, j, k, -13, 53, 17, LEAVES);
        setBlock(level, i, j, k, -13, 53, 15, LEAVES);
        setBlock(level, i, j, k, -14, 53, 15, LEAVES);
        setBlock(level, i, j, k, -12, 53, 14, LEAVES);
        setBlock(level, i, j, k, -13, 53, 14, LEAVES);
        setBlock(level, i, j, k, -10, 53, 14, LEAVES);
        setBlock(level, i, j, k, -10, 54, 15, LEAVES);
        setBlock(level, i, j, k, -8, 54, 16, LEAVES);
        setBlock(level, i, j, k, -9, 54, 15, LEAVES);
        setBlock(level, i, j, k, -8, 53, 15, LEAVES);
        setBlock(level, i, j, k, -7, 53, 15, LEAVES);
        setBlock(level, i, j, k, -7, 53, 16, LEAVES);
        setBlock(level, i, j, k, -9, 53, 14, LEAVES);
        setBlock(level, i, j, k, -8, 53, 14, LEAVES);
        setBlock(level, i, j, k, -10, 53, 20, LEAVES);
        setBlock(level, i, j, k, -14, 53, 16, LEAVES);
        setBlock(level, i, j, k, -11, 50, 16, WOOD);
        setBlock(level, i, j, k, -10, 50, 17, WOOD);
        setBlock(level, i, j, k, -11, 49, 15, WOOD);
        setBlock(level, i, j, k, -11, 49, 16, WOOD);
        setBlock(level, i, j, k, -11, 49, 16, AIR);
        setBlock(level, i, j, k, -10, 50, 17, AIR);
        setBlock(level, i, j, k, -9, 50, 16, WOOD);
        setBlock(level, i, j, k, -9, 50, 16, AIR);
        setBlock(level, i, j, k, -9, 50, 16, WOOD);
        setBlock(level, i, j, k, -9, 50, 17, WOOD);
        setBlock(level, i, j, k, -9, 50, 16, AIR);
        setBlock(level, i, j, k, -9, 49, 17, WOOD);
        setBlock(level, i, j, k, -11, 52, 17, WOOD);
        setBlock(level, i, j, k, -11, 52, 17, AIR);
        setBlock(level, i, j, k, -11, 52, 17, LEAVES);
        setBlock(level, i, j, k, -11, 52, 16, AIR);
        setBlock(level, i, j, k, -11, 52, 16, LEAVES);
        setBlock(level, i, j, k, -12, 52, 16, LEAVES);
        setBlock(level, i, j, k, -10, 52, 16, LEAVES);
        setBlock(level, i, j, k, -9, 52, 17, LEAVES);
        setBlock(level, i, j, k, -10, 52, 15, LEAVES);
        setBlock(level, i, j, k, -9, 52, 16, LEAVES);
        setBlock(level, i, j, k, -10, 52, 18, LEAVES);
        setBlock(level, i, j, k, -10, 47, 18, LEAVES);
        setBlock(level, i, j, k, -10, 47, 19, LEAVES);
        setBlock(level, i, j, k, -10, 47, 20, LEAVES);
        setBlock(level, i, j, k, -9, 47, 19, LEAVES);
        setBlock(level, i, j, k, -9, 47, 20, LEAVES);
        setBlock(level, i, j, k, -11, 47, 18, LEAVES);
        setBlock(level, i, j, k, -11, 47, 19, LEAVES);
        setBlock(level, i, j, k, -12, 47, 19, LEAVES);
        setBlock(level, i, j, k, -12, 47, 16, LEAVES);
        setBlock(level, i, j, k, -13, 47, 16, LEAVES);
        setBlock(level, i, j, k, -12, 47, 17, LEAVES);
        setBlock(level, i, j, k, -12, 47, 18, LEAVES);
        setBlock(level, i, j, k, -13, 47, 17, LEAVES);
        setBlock(level, i, j, k, -13, 47, 18, LEAVES);
        setBlock(level, i, j, k, -13, 47, 15, LEAVES);
        setBlock(level, i, j, k, -14, 47, 14, LEAVES);
        setBlock(level, i, j, k, -14, 47, 15, LEAVES);
        setBlock(level, i, j, k, -14, 47, 16, LEAVES);
        setBlock(level, i, j, k, -14, 48, 16, LEAVES);
        setBlock(level, i, j, k, -14, 48, 16, AIR);
        setBlock(level, i, j, k, -14, 48, 16, LEAVES);
        setBlock(level, i, j, k, -14, 48, 16, AIR);
        setBlock(level, i, j, k, -14, 47, 17, LEAVES);
        setBlock(level, i, j, k, -12, 48, 15, LEAVES);
        setBlock(level, i, j, k, -13, 48, 14, LEAVES);
        setBlock(level, i, j, k, -13, 48, 15, LEAVES);
        setBlock(level, i, j, k, -11, 48, 16, LEAVES);
        setBlock(level, i, j, k, -12, 48, 16, LEAVES);
        setBlock(level, i, j, k, -13, 48, 16, LEAVES);
        setBlock(level, i, j, k, -11, 48, 17, LEAVES);
        setBlock(level, i, j, k, -12, 48, 17, LEAVES);
        setBlock(level, i, j, k, -12, 46, 16, LEAVES);
        setBlock(level, i, j, k, -10, 45, 15, LEAVES);
        setBlock(level, i, j, k, -11, 45, 15, LEAVES);
        setBlock(level, i, j, k, -10, 46, 17, LEAVES);
        setBlock(level, i, j, k, -12, 53, 19, LEAVES);
        setBlock(level, i, j, k, -13, 53, 18, LEAVES);
        setBlock(level, i, j, k, -13, 53, 19, LEAVES);
        setBlock(level, i, j, k, -12, 54, 17, LEAVES);
        setBlock(level, i, j, k, -14, 53, 17, LEAVES);
        setBlock(level, i, j, k, -11, 53, 20, LEAVES);
        setBlock(level, i, j, k, -12, 53, 20, LEAVES);
        setBlock(level, i, j, k, -11, 54, 18, LEAVES);
        setBlock(level, i, j, k, -12, 54, 18, LEAVES);
        setBlock(level, i, j, k, -10, 54, 19, LEAVES);
        setBlock(level, i, j, k, -11, 54, 19, LEAVES);
        setBlock(level, i, j, k, -12, 54, 19, LEAVES);
        setBlock(level, i, j, k, -13, 54, 16, LEAVES);
        setBlock(level, i, j, k, -13, 54, 17, LEAVES);
        setBlock(level, i, j, k, -14, 53, 18, LEAVES);
        setBlock(level, i, j, k, 6, 46, 18, WOOD);
        setBlock(level, i, j, k, 6, 47, 19, WOOD);
        setBlock(level, i, j, k, 6, 47, 18, WOOD);
        setBlock(level, i, j, k, 7, 47, 19, WOOD);
        setBlock(level, i, j, k, 7, 47, 18, WOOD);
        setBlock(level, i, j, k, 7, 48, 19, WOOD);
        setBlock(level, i, j, k, 7, 49, 19, WOOD);
        setBlock(level, i, j, k, 8, 49, 19, WOOD);
        setBlock(level, i, j, k, 7, 48, 18, WOOD);
        setBlock(level, i, j, k, 7, 49, 18, WOOD);
        setBlock(level, i, j, k, 8, 49, 18, WOOD);
        setBlock(level, i, j, k, 8, 50, 19, WOOD);
        setBlock(level, i, j, k, 8, 50, 18, WOOD);
        setBlock(level, i, j, k, 9, 50, 19, WOOD);
        setBlock(level, i, j, k, 9, 50, 18, WOOD);
        setBlock(level, i, j, k, 10, 50, 19, WOOD);
        setBlock(level, i, j, k, 10, 50, 18, WOOD);
        setBlock(level, i, j, k, 10, 51, 18, WOOD);
        setBlock(level, i, j, k, 11, 51, 18, WOOD);
        setBlock(level, i, j, k, 11, 51, 17, WOOD);
        setBlock(level, i, j, k, 11, 52, 17, WOOD);
        setBlock(level, i, j, k, 9, 49, 18, WOOD);
        setBlock(level, i, j, k, 8, 48, 18, WOOD);
        setBlock(level, i, j, k, 7, 49, 19, AIR);
        setBlock(level, i, j, k, 8, 50, 19, AIR);
        setBlock(level, i, j, k, 7, 45, 17, WOOD);
        setBlock(level, i, j, k, 6, 46, 17, WOOD);
        setBlock(level, i, j, k, 6, 45, 17, WOOD);
        setBlock(level, i, j, k, 5, 45, 17, WOOD);
        setBlock(level, i, j, k, 10, 51, 17, WOOD);
        setBlock(level, i, j, k, 10, 50, 18, AIR);
        setBlock(level, i, j, k, 10, 51, 17, AIR);
        setBlock(level, i, j, k, 10, 50, 18, WOOD);
        setBlock(level, i, j, k, 10, 50, 17, WOOD);
        setBlock(level, i, j, k, 10, 51, 17, WOOD);
        setBlock(level, i, j, k, 9, 49, 17, WOOD);
        setBlock(level, i, j, k, 8, 48, 17, WOOD);
        setBlock(level, i, j, k, 7, 47, 17, WOOD);
        setBlock(level, i, j, k, 10, 51, 16, LEAVES);
        setBlock(level, i, j, k, 11, 51, 16, LEAVES);
        setBlock(level, i, j, k, 10, 51, 15, LEAVES);
        setBlock(level, i, j, k, 11, 51, 15, LEAVES);
        setBlock(level, i, j, k, 12, 51, 17, LEAVES);
        setBlock(level, i, j, k, 12, 51, 16, LEAVES);
        setBlock(level, i, j, k, 12, 51, 18, LEAVES);
        setBlock(level, i, j, k, 11, 51, 19, LEAVES);
        setBlock(level, i, j, k, 12, 51, 19, LEAVES);
        setBlock(level, i, j, k, 13, 51, 18, LEAVES);
        setBlock(level, i, j, k, 13, 51, 17, LEAVES);
        setBlock(level, i, j, k, 11, 52, 17, AIR);
        setBlock(level, i, j, k, 11, 52, 17, LEAVES);
        setBlock(level, i, j, k, 11, 52, 18, LEAVES);
        setBlock(level, i, j, k, 10, 52, 18, LEAVES);
        setBlock(level, i, j, k, 10, 52, 17, LEAVES);
        setBlock(level, i, j, k, 10, 52, 16, LEAVES);
        setBlock(level, i, j, k, 9, 51, 17, LEAVES);
        setBlock(level, i, j, k, 9, 51, 16, LEAVES);
        setBlock(level, i, j, k, 8, 51, 17, LEAVES);
        setBlock(level, i, j, k, 8, 51, 16, LEAVES);
        setBlock(level, i, j, k, 9, 51, 18, LEAVES);
        setBlock(level, i, j, k, 8, 51, 18, LEAVES);
        setBlock(level, i, j, k, 9, 51, 15, LEAVES);
        setBlock(level, i, j, k, 9, 52, 16, LEAVES);
        setBlock(level, i, j, k, 9, 52, 17, LEAVES);
        setBlock(level, i, j, k, 9, 52, 18, LEAVES);
        setBlock(level, i, j, k, 10, 51, 19, LEAVES);
        setBlock(level, i, j, k, 9, 51, 19, LEAVES);
        setBlock(level, i, j, k, 8, 51, 19, LEAVES);
        setBlock(level, i, j, k, 7, 51, 18, LEAVES);
        setBlock(level, i, j, k, 7, 51, 19, LEAVES);
        setBlock(level, i, j, k, 9, 51, 20, LEAVES);
        setBlock(level, i, j, k, 8, 51, 20, LEAVES);
        setBlock(level, i, j, k, 8, 52, 18, LEAVES);
        setBlock(level, i, j, k, 9, 52, 19, LEAVES);
        setBlock(level, i, j, k, 8, 52, 19, LEAVES);
        setBlock(level, i, j, k, 7, 51, 17, LEAVES);
        setBlock(level, i, j, k, 10, 51, 20, LEAVES);
        setBlock(level, i, j, k, 11, 50, 18, LEAVES);
        setBlock(level, i, j, k, 11, 50, 17, LEAVES);
        setBlock(level, i, j, k, 10, 50, 17, AIR);
        setBlock(level, i, j, k, 10, 50, 17, LEAVES);
        setBlock(level, i, j, k, 9, 50, 17, LEAVES);
        setBlock(level, i, j, k, 1, 47, 20, AIR);
        setBlock(level, i, j, k, 1, 47, 20, LEAVES);
        setBlock(level, i, j, k, 1, 46, 19, AIR);
        setBlock(level, i, j, k, 1, 46, 19, LEAVES);
        setBlock(level, i, j, k, 2, 46, 19, AIR);
        setBlock(level, i, j, k, 2, 46, 19, LEAVES);
        setBlock(level, i, j, k, 3, 47, 20, LEAVES);
        setBlock(level, i, j, k, 2, 47, 20, LEAVES);
        setBlock(level, i, j, k, 7, 46, 17, WOOD);
        setBlock(level, i, j, k, 8, 47, 17, WOOD);
        setBlock(level, i, j, k, 8, 47, 18, WOOD);
        setBlock(level, i, j, k, 9, 48, 18, WOOD);
        setBlock(level, i, j, k, 9, 50, 16, LEAVES);
        setBlock(level, i, j, k, 10, 50, 16, LEAVES);
        setBlock(level, i, j, k, 8, 50, 17, LEAVES);
        setBlock(level, i, j, k, -5, 39, 13, WOOD);
        setBlock(level, i, j, k, -5, 39, 14, WOOD);
        setBlock(level, i, j, k, -5, 40, 14, WOOD);
        setBlock(level, i, j, k, -4, 40, 13, WOOD);
        setBlock(level, i, j, k, -4, 40, 14, WOOD);
        setBlock(level, i, j, k, -4, 40, 15, WOOD);
        setBlock(level, i, j, k, -4, 41, 15, WOOD);
        setBlock(level, i, j, k, -3, 41, 15, WOOD);
        setBlock(level, i, j, k, -3, 41, 16, WOOD);
        setBlock(level, i, j, k, -2, 41, 16, WOOD);
        setBlock(level, i, j, k, -2, 40, 16, WOOD);
        setBlock(level, i, j, k, -2, 40, 17, WOOD);
        setBlock(level, i, j, k, -2, 39, 17, WOOD);
        setBlock(level, i, j, k, -2, 40, 18, LEAVES);
        setBlock(level, i, j, k, -2, 39, 18, LEAVES);
        setBlock(level, i, j, k, -3, 40, 16, LEAVES);
        setBlock(level, i, j, k, -3, 39, 17, LEAVES);
        setBlock(level, i, j, k, -3, 40, 17, LEAVES);
        setBlock(level, i, j, k, -3, 39, 16, LEAVES);
        setBlock(level, i, j, k, -2, 39, 16, LEAVES);
        setBlock(level, i, j, k, -2, 40, 15, LEAVES);
        setBlock(level, i, j, k, -1, 40, 16, LEAVES);
        setBlock(level, i, j, k, -1, 39, 16, LEAVES);
        setBlock(level, i, j, k, -1, 40, 17, LEAVES);
        setBlock(level, i, j, k, -1, 39, 17, LEAVES);
        setBlock(level, i, j, k, -2, 41, 17, LEAVES);
        setBlock(level, i, j, k, -1, 41, 16, LEAVES);
        setBlock(level, i, j, k, -2, 41, 15, LEAVES);
        setBlock(level, i, j, k, -2, 41, 16, AIR);
        setBlock(level, i, j, k, -1, 41, 17, LEAVES);
        setBlock(level, i, j, k, -3, 42, 16, LEAVES);
        setBlock(level, i, j, k, -2, 41, 16, LEAVES);
        setBlock(level, i, j, k, -4, 41, 16, LEAVES);
        setBlock(level, i, j, k, -4, 40, 16, LEAVES);
        setBlock(level, i, j, k, -2, 38, 17, LEAVES);
        setBlock(level, i, j, k, -3, 38, 16, LEAVES);
        setBlock(level, i, j, k, -4, 39, 15, LEAVES);
        setBlock(level, i, j, k, -4, 38, 15, LEAVES);
        setBlock(level, i, j, k, -4, 38, 15, AIR);
        setBlock(level, i, j, k, -3, 40, 15, LEAVES);
        setBlock(level, i, j, k, -3, 39, 15, LEAVES);
        setBlock(level, i, j, k, -4, 39, 14, LEAVES);
        setBlock(level, i, j, k, -2, 38, 16, LEAVES);
        setBlock(level, i, j, k, -1, 40, 15, LEAVES);
        setBlock(level, i, j, k, 0, 40, 16, LEAVES);
        setBlock(level, i, j, k, 0, 40, 15, LEAVES);
        setBlock(level, i, j, k, -3, 40, 14, LEAVES);
        setBlock(level, i, j, k, -2, 40, 14, LEAVES);
        setBlock(level, i, j, k, -1, 40, 14, LEAVES);
        setBlock(level, i, j, k, -3, 41, 15, AIR);
        setBlock(level, i, j, k, -3, 41, 15, LEAVES);
        setBlock(level, i, j, k, -4, 41, 15, AIR);
        setBlock(level, i, j, k, -4, 41, 15, LEAVES);
        setBlock(level, i, j, k, -4, 42, 15, LEAVES);
        setBlock(level, i, j, k, -4, 42, 15, AIR);
        setBlock(level, i, j, k, -4, 41, 14, LEAVES);
        setBlock(level, i, j, k, -5, 40, 15, LEAVES);
        setBlock(level, i, j, k, -4, 40, 17, LEAVES);
        setBlock(level, i, j, k, -3, 41, 17, LEAVES);
        setBlock(level, i, j, k, -3, 40, 18, LEAVES);
        setBlock(level, i, j, k, -5, 40, 16, LEAVES);
        setBlock(level, i, j, k, -5, 40, 17, LEAVES);
        setBlock(level, i, j, k, -4, 40, 18, LEAVES);
        setBlock(level, i, j, k, -3, 42, 16, AIR);
        setBlock(level, i, j, k, -3, 41, 16, AIR);
        setBlock(level, i, j, k, -3, 41, 16, LEAVES);
        setBlock(level, i, j, k, -1, 40, 18, LEAVES);
        setBlock(level, i, j, k, 0, 40, 17, LEAVES);
        setBlock(level, i, j, k, -2, 39, 18, AIR);
        setBlock(level, i, j, k, -2, 38, 17, AIR);
        setBlock(level, i, j, k, -2, 39, 17, AIR);
        setBlock(level, i, j, k, -2, 39, 17, LEAVES);
        setBlock(level, i, j, k, -7, 36, -3, WOOD);
        setBlock(level, i, j, k, -8, 36, -3, WOOD);
        setBlock(level, i, j, k, -7, 36, -4, WOOD);
        setBlock(level, i, j, k, -8, 36, -4, WOOD);
        setBlock(level, i, j, k, -6, 36, -5, WOOD);
        setBlock(level, i, j, k, -7, 36, -5, WOOD);
        setBlock(level, i, j, k, -7, 36, -1, WOOD);
        setBlock(level, i, j, k, -7, 36, -2, WOOD);
        setBlock(level, i, j, k, -8, 36, -2, WOOD);
        setBlock(level, i, j, k, -8, 36, -1, WOOD);
        setBlock(level, i, j, k, -7, 36, 0, WOOD);
        setBlock(level, i, j, k, -8, 36, 0, WOOD);
        setBlock(level, i, j, k, -7, 36, 1, WOOD);
        setBlock(level, i, j, k, -7, 37, 1, WOOD);
        setBlock(level, i, j, k, -8, 36, 1, WOOD);
        setBlock(level, i, j, k, -7, 36, 2, WOOD);
        setBlock(level, i, j, k, -7, 37, 1, AIR);
        setBlock(level, i, j, k, -5, 36, -7, WOOD);
        setBlock(level, i, j, k, -6, 36, -7, WOOD);
        setBlock(level, i, j, k, -6, 37, -5, WOOD);
        setBlock(level, i, j, k, -6, 36, -6, WOOD);
        setBlock(level, i, j, k, -7, 36, -6, WOOD);
        setBlock(level, i, j, k, -6, 37, -6, WOOD);
        setBlock(level, i, j, k, -7, 32, -7, WOOD);
        setBlock(level, i, j, k, -7, 33, -7, WOOD);
        setBlock(level, i, j, k, -7, 34, -7, WOOD);
        setBlock(level, i, j, k, -8, 34, -7, WOOD);
        setBlock(level, i, j, k, -7, 35, -7, WOOD);
        setBlock(level, i, j, k, -8, 35, -6, WOOD);
        setBlock(level, i, j, k, -9, 35, -6, WOOD);
        setBlock(level, i, j, k, -8, 34, -6, WOOD);
        setBlock(level, i, j, k, -7, 34, -8, WOOD);
        setBlock(level, i, j, k, -7, 35, -8, WOOD);
        setBlock(level, i, j, k, -6, 34, -9, WOOD);
        setBlock(level, i, j, k, -6, 35, -9, WOOD);
        setBlock(level, i, j, k, -5, 35, -10, WOOD);
        setBlock(level, i, j, k, -4, 36, -9, WOOD);
        setBlock(level, i, j, k, -5, 36, -9, WOOD);
        setBlock(level, i, j, k, -4, 36, -8, WOOD);
        setBlock(level, i, j, k, -5, 36, -8, WOOD);
        setBlock(level, i, j, k, -6, 36, -8, WOOD);
        setBlock(level, i, j, k, -8, 35, -5, WOOD);
        setBlock(level, i, j, k, -9, 35, -5, WOOD);
        setBlock(level, i, j, k, -10, 35, -5, WOOD);
        setBlock(level, i, j, k, -9, 35, -4, WOOD);
        setBlock(level, i, j, k, -10, 35, -4, WOOD);
        setBlock(level, i, j, k, -11, 35, -4, WOOD);
        setBlock(level, i, j, k, -9, 35, -3, WOOD);
        setBlock(level, i, j, k, -10, 35, -3, WOOD);
        setBlock(level, i, j, k, -11, 35, -3, WOOD);
        setBlock(level, i, j, k, -9, 35, -2, WOOD);
        setBlock(level, i, j, k, -10, 35, -2, WOOD);
        setBlock(level, i, j, k, -11, 35, -2, WOOD);
        setBlock(level, i, j, k, -9, 35, -1, WOOD);
        setBlock(level, i, j, k, -10, 35, -1, WOOD);
        setBlock(level, i, j, k, -11, 35, -1, WOOD);
        setBlock(level, i, j, k, -12, 35, -1, WOOD);
        setBlock(level, i, j, k, -12, 35, -2, WOOD);
        setBlock(level, i, j, k, -9, 35, 0, WOOD);
        setBlock(level, i, j, k, -10, 35, 0, WOOD);
        setBlock(level, i, j, k, -11, 35, 0, WOOD);
        setBlock(level, i, j, k, -12, 35, 0, WOOD);
        setBlock(level, i, j, k, -9, 35, 1, WOOD);
        setBlock(level, i, j, k, -10, 35, 1, WOOD);
        setBlock(level, i, j, k, -11, 35, 1, WOOD);
        setBlock(level, i, j, k, -11, 35, 2, WOOD);
        setBlock(level, i, j, k, -12, 35, 1, WOOD);
        setBlock(level, i, j, k, -12, 35, 2, WOOD);
        setBlock(level, i, j, k, -9, 35, 2, WOOD);
        setBlock(level, i, j, k, -10, 35, 2, WOOD);
        setBlock(level, i, j, k, -9, 35, 3, WOOD);
        setBlock(level, i, j, k, -10, 35, 3, WOOD);
        setBlock(level, i, j, k, -11, 35, 3, WOOD);
        setBlock(level, i, j, k, -8, 35, 4, WOOD);
        setBlock(level, i, j, k, -9, 35, 4, WOOD);
        setBlock(level, i, j, k, -10, 35, 4, WOOD);
        setBlock(level, i, j, k, -11, 35, 4, WOOD);
        setBlock(level, i, j, k, -8, 35, 5, WOOD);
        setBlock(level, i, j, k, -9, 35, 5, WOOD);
        setBlock(level, i, j, k, -10, 35, 5, WOOD);
        setBlock(level, i, j, k, -10, 35, 6, WOOD);
        setBlock(level, i, j, k, -10, 35, 6, AIR);
        setBlock(level, i, j, k, -10, 35, 5, AIR);
        setBlock(level, i, j, k, -7, 35, 6, WOOD);
        setBlock(level, i, j, k, -8, 35, 6, WOOD);
        setBlock(level, i, j, k, -10, 35, 5, WOOD);
        setBlock(level, i, j, k, -8, 36, 2, WOOD);
        setBlock(level, i, j, k, -7, 36, 3, WOOD);
        setBlock(level, i, j, k, -6, 36, 6, WOOD);
        setBlock(level, i, j, k, -7, 36, 6, WOOD);
        setBlock(level, i, j, k, -8, 36, 6, WOOD);
        setBlock(level, i, j, k, -9, 36, 6, WOOD);
        setBlock(level, i, j, k, -9, 36, 5, WOOD);
        setBlock(level, i, j, k, -10, 36, 5, WOOD);
        setBlock(level, i, j, k, -11, 36, 5, WOOD);
        setBlock(level, i, j, k, -12, 36, 5, WOOD);
        setBlock(level, i, j, k, -11, 36, 4, WOOD);
        setBlock(level, i, j, k, -12, 36, 4, WOOD);
        setBlock(level, i, j, k, -11, 36, 3, WOOD);
        setBlock(level, i, j, k, -12, 36, 3, WOOD);
        setBlock(level, i, j, k, -13, 36, 3, WOOD);
        setBlock(level, i, j, k, -13, 36, 2, WOOD);
        setBlock(level, i, j, k, -13, 36, 1, WOOD);
        setBlock(level, i, j, k, -13, 36, 0, WOOD);
        setBlock(level, i, j, k, -13, 36, -1, WOOD);
        setBlock(level, i, j, k, -13, 36, -2, WOOD);
        setBlock(level, i, j, k, -13, 36, -3, WOOD);
        setBlock(level, i, j, k, -11, 36, -2, WOOD);
        setBlock(level, i, j, k, -11, 36, -3, WOOD);
        setBlock(level, i, j, k, -12, 36, -2, WOOD);
        setBlock(level, i, j, k, -12, 36, -3, WOOD);
        setBlock(level, i, j, k, -11, 36, -4, WOOD);
        setBlock(level, i, j, k, -11, 36, -5, WOOD);
        setBlock(level, i, j, k, -12, 36, -4, WOOD);
        setBlock(level, i, j, k, -7, 36, -7, WOOD);
        setBlock(level, i, j, k, -8, 36, -7, WOOD);
        setBlock(level, i, j, k, -8, 36, -5, WOOD);
        setBlock(level, i, j, k, -8, 36, -6, WOOD);
        setBlock(level, i, j, k, -9, 36, -6, WOOD);
        setBlock(level, i, j, k, -10, 36, -6, WOOD);
        setBlock(level, i, j, k, -8, 35, -7, WOOD);
        setBlock(level, i, j, k, -8, 34, -5, WOOD);
        setBlock(level, i, j, k, -8, 33, -5, WOOD);
        setBlock(level, i, j, k, -9, 33, -5, WOOD);
        setBlock(level, i, j, k, -9, 34, -5, WOOD);
        setBlock(level, i, j, k, -8, 32, -5, WOOD);
        setBlock(level, i, j, k, -8, 33, -6, WOOD);
        setBlock(level, i, j, k, -9, 34, -4, WOOD);
        setBlock(level, i, j, k, -9, 33, -4, WOOD);
        setBlock(level, i, j, k, -9, 32, -4, WOOD);
        setBlock(level, i, j, k, -9, 34, -3, WOOD);
        setBlock(level, i, j, k, -9, 33, -3, WOOD);
        setBlock(level, i, j, k, -10, 34, -4, WOOD);
        setBlock(level, i, j, k, -10, 34, -3, WOOD);
        setBlock(level, i, j, k, -9, 34, -2, WOOD);
        setBlock(level, i, j, k, -9, 33, -2, WOOD);
        setBlock(level, i, j, k, -9, 32, -3, WOOD);
        setBlock(level, i, j, k, -9, 32, -2, WOOD);
        setBlock(level, i, j, k, -10, 34, -2, WOOD);
        setBlock(level, i, j, k, -11, 34, -2, WOOD);
        setBlock(level, i, j, k, -10, 33, -2, WOOD);
        setBlock(level, i, j, k, -10, 32, -2, WOOD);
        setBlock(level, i, j, k, -10, 33, -3, WOOD);
        setBlock(level, i, j, k, -10, 34, -1, WOOD);
        setBlock(level, i, j, k, -10, 33, -1, WOOD);
        setBlock(level, i, j, k, -10, 32, -1, WOOD);
        setBlock(level, i, j, k, -10, 32, -1, AIR);
        setBlock(level, i, j, k, -10, 31, -1, WOOD);
        setBlock(level, i, j, k, -10, 31, 0, WOOD);
        setBlock(level, i, j, k, -10, 30, -1, WOOD);
        setBlock(level, i, j, k, -10, 30, 0, WOOD);
        setBlock(level, i, j, k, -10, 30, 1, WOOD);
        setBlock(level, i, j, k, -10, 30, 2, WOOD);
        setBlock(level, i, j, k, -10, 31, -2, WOOD);
        setBlock(level, i, j, k, -11, 47, 11, LEAVES);
        setBlock(level, i, j, k, -11, 47, 10, LEAVES);
        setBlock(level, i, j, k, -10, 47, 12, LEAVES);
        setBlock(level, i, j, k, -11, 47, 10, AIR);
        setBlock(level, i, j, k, -12, 47, 10, AIR);
        setBlock(level, i, j, k, -11, 48, 11, LEAVES);
        setBlock(level, i, j, k, -12, 47, 10, LEAVES);
        setBlock(level, i, j, k, -11, 47, 10, LEAVES);
        setBlock(level, i, j, k, -11, 48, 11, AIR);
        setBlock(level, i, j, k, -11, 36, -1, WOOD);
        setBlock(level, i, j, k, -12, 36, -1, WOOD);
        setBlock(level, i, j, k, -8, 37, -6, WOOD);
        setBlock(level, i, j, k, -9, 37, -6, WOOD);
        setBlock(level, i, j, k, -10, 37, -6, WOOD);
        setBlock(level, i, j, k, -11, 37, -5, WOOD);
        setBlock(level, i, j, k, -12, 37, -4, WOOD);
        setBlock(level, i, j, k, -13, 37, -3, WOOD);
        setBlock(level, i, j, k, -12, 37, -2, WOOD);
        setBlock(level, i, j, k, -13, 37, -2, WOOD);
        setBlock(level, i, j, k, -13, 37, -1, WOOD);
        setBlock(level, i, j, k, -13, 37, 0, WOOD);
        setBlock(level, i, j, k, -13, 37, 2, WOOD);
        setBlock(level, i, j, k, -13, 37, 3, WOOD);
        setBlock(level, i, j, k, -13, 37, 1, WOOD);
        setBlock(level, i, j, k, -11, 37, 4, WOOD);
        setBlock(level, i, j, k, -12, 37, 4, WOOD);
        setBlock(level, i, j, k, -10, 37, 5, WOOD);
        setBlock(level, i, j, k, -11, 37, 5, WOOD);
        setBlock(level, i, j, k, -12, 37, 5, WOOD);
        setBlock(level, i, j, k, -9, 37, 6, WOOD);
        setBlock(level, i, j, k, -9, 37, 7, WOOD);
        setBlock(level, i, j, k, -8, 37, 6, WOOD);
        setBlock(level, i, j, k, -9, 37, 7, AIR);
        setBlock(level, i, j, k, -5, 36, 6, WOOD);
        setBlock(level, i, j, k, -6, 37, 6, WOOD);
        setBlock(level, i, j, k, -7, 37, 6, WOOD);
        setBlock(level, i, j, k, -5, 37, 6, WOOD);
        setBlock(level, i, j, k, -6, 36, 5, WOOD);
        setBlock(level, i, j, k, -6, 36, 4, WOOD);
        setBlock(level, i, j, k, -7, 36, 5, WOOD);
        setBlock(level, i, j, k, -7, 36, 4, WOOD);
        setBlock(level, i, j, k, -8, 36, 5, WOOD);
        setBlock(level, i, j, k, -8, 36, 4, WOOD);
        setBlock(level, i, j, k, -8, 36, 3, WOOD);
        setBlock(level, i, j, k, -9, 36, 4, WOOD);
        setBlock(level, i, j, k, -9, 36, 3, WOOD);
        setBlock(level, i, j, k, -10, 36, 4, WOOD);
        setBlock(level, i, j, k, -10, 36, 3, WOOD);
        setBlock(level, i, j, k, -10, 36, 2, WOOD);
        setBlock(level, i, j, k, -9, 36, 2, WOOD);
        setBlock(level, i, j, k, -9, 36, 1, WOOD);
        setBlock(level, i, j, k, -10, 36, 1, WOOD);
        setBlock(level, i, j, k, -9, 36, 0, WOOD);
        setBlock(level, i, j, k, -9, 36, -1, WOOD);
        setBlock(level, i, j, k, -10, 36, -1, WOOD);
        setBlock(level, i, j, k, -9, 36, -3, WOOD);
        setBlock(level, i, j, k, -9, 36, -5, WOOD);
        setBlock(level, i, j, k, -10, 36, -5, WOOD);
        setBlock(level, i, j, k, -10, 36, -4, WOOD);
        setBlock(level, i, j, k, -9, 36, -4, WOOD);
        setBlock(level, i, j, k, -10, 36, -3, WOOD);
        setBlock(level, i, j, k, -10, 36, -2, WOOD);
        setBlock(level, i, j, k, -9, 36, -2, WOOD);
        setBlock(level, i, j, k, -11, 36, 1, WOOD);
        setBlock(level, i, j, k, -10, 36, 0, WOOD);
        setBlock(level, i, j, k, -11, 36, 2, WOOD);
        setBlock(level, i, j, k, -12, 36, 2, WOOD);
        setBlock(level, i, j, k, -11, 36, 0, WOOD);
        setBlock(level, i, j, k, -12, 36, 1, WOOD);
        setBlock(level, i, j, k, -12, 36, 0, WOOD);
        setBlock(level, i, j, k, -12, 37, 2, WOOD);
        setBlock(level, i, j, k, -12, 37, 1, WOOD);
        setBlock(level, i, j, k, -11, 37, 1, WOOD);
        setBlock(level, i, j, k, -12, 37, -1, WOOD);
        setBlock(level, i, j, k, -11, 37, -1, WOOD);
        setBlock(level, i, j, k, -12, 37, 0, WOOD);
        setBlock(level, i, j, k, -11, 37, 0, WOOD);
        setBlock(level, i, j, k, -12, 37, 3, WOOD);
        setBlock(level, i, j, k, -11, 37, 3, WOOD);
        setBlock(level, i, j, k, -11, 37, 2, WOOD);
        setBlock(level, i, j, k, -12, 37, -3, WOOD);
        setBlock(level, i, j, k, -11, 37, -2, WOOD);
        setBlock(level, i, j, k, -11, 37, -3, WOOD);
        setBlock(level, i, j, k, -11, 37, -4, WOOD);
        setBlock(level, i, j, k, -10, 37, -5, WOOD);
        setBlock(level, i, j, k, -10, 37, -4, WOOD);
        setBlock(level, i, j, k, -10, 37, -3, WOOD);
        setBlock(level, i, j, k, -10, 37, -2, WOOD);
        setBlock(level, i, j, k, -10, 37, -1, WOOD);
        setBlock(level, i, j, k, -10, 37, 4, WOOD);
        setBlock(level, i, j, k, -10, 37, 3, WOOD);
        setBlock(level, i, j, k, -10, 37, 2, WOOD);
        setBlock(level, i, j, k, -10, 37, 1, WOOD);
        setBlock(level, i, j, k, -10, 37, 0, WOOD);
        setBlock(level, i, j, k, -9, 37, 5, WOOD);
        setBlock(level, i, j, k, -9, 37, 4, WOOD);
        setBlock(level, i, j, k, -9, 37, 3, WOOD);
        setBlock(level, i, j, k, -9, 37, 2, WOOD);
        setBlock(level, i, j, k, -9, 37, 1, WOOD);
        setBlock(level, i, j, k, -9, 37, 0, WOOD);
        setBlock(level, i, j, k, -6, 37, 5, WOOD);
        setBlock(level, i, j, k, -6, 37, 4, WOOD);
        setBlock(level, i, j, k, -7, 37, 5, WOOD);
        setBlock(level, i, j, k, -7, 37, 4, WOOD);
        setBlock(level, i, j, k, -7, 37, 3, WOOD);
        setBlock(level, i, j, k, -8, 37, 5, WOOD);
        setBlock(level, i, j, k, -8, 37, 4, WOOD);
        setBlock(level, i, j, k, -8, 37, 3, WOOD);
        setBlock(level, i, j, k, -7, 37, 2, WOOD);
        setBlock(level, i, j, k, -7, 37, 1, WOOD);
        setBlock(level, i, j, k, -8, 37, 1, WOOD);
        setBlock(level, i, j, k, -8, 37, 0, WOOD);
        setBlock(level, i, j, k, -8, 37, -1, WOOD);
        setBlock(level, i, j, k, -8, 37, -2, WOOD);
        setBlock(level, i, j, k, -7, 37, 0, WOOD);
        setBlock(level, i, j, k, -7, 37, -1, WOOD);
        setBlock(level, i, j, k, -7, 37, -2, WOOD);
        setBlock(level, i, j, k, -7, 37, -3, WOOD);
        setBlock(level, i, j, k, -8, 37, -3, WOOD);
        setBlock(level, i, j, k, -9, 37, -1, WOOD);
        setBlock(level, i, j, k, -9, 37, -2, WOOD);
        setBlock(level, i, j, k, -9, 37, -3, WOOD);
        setBlock(level, i, j, k, -9, 37, -4, WOOD);
        setBlock(level, i, j, k, -8, 37, 2, WOOD);
        setBlock(level, i, j, k, -9, 37, -5, WOOD);
        setBlock(level, i, j, k, -7, 37, -4, WOOD);
        setBlock(level, i, j, k, -7, 37, -5, WOOD);
        setBlock(level, i, j, k, -8, 37, -5, WOOD);
        setBlock(level, i, j, k, -8, 37, -4, WOOD);
        setBlock(level, i, j, k, -7, 37, -6, WOOD);
        setBlock(level, i, j, k, -5, 37, -7, WOOD);
        setBlock(level, i, j, k, -6, 37, -7, WOOD);
    }

    private void finishGeneration2(WorldGenLevel level, int i, int j, int k) {
        setBlock(level, i, j, k, -5, 78, -7, WOOD);
        setBlock(level, i, j, k, -6, 78, -7, WOOD);
        setBlock(level, i, j, k, -7, 77, -7, WOOD);
        setBlock(level, i, j, k, -7, 78, -6, WOOD);
        setBlock(level, i, j, k, -8, 78, -6, WOOD);
        setBlock(level, i, j, k, -6, 79, -6, WOOD);
        setBlock(level, i, j, k, -6, 79, -6, AIR);
        setBlock(level, i, j, k, -6, 78, -6, WOOD);
        setBlock(level, i, j, k, -6, 78, -5, WOOD);
        setBlock(level, i, j, k, -7, 78, -4, WOOD);
        setBlock(level, i, j, k, -9, 78, -6, WOOD);
        setBlock(level, i, j, k, -10, 78, -6, WOOD);
        setBlock(level, i, j, k, -11, 78, -6, WOOD);
        setBlock(level, i, j, k, -11, 78, -5, WOOD);
        setBlock(level, i, j, k, -11, 78, -4, WOOD);
        setBlock(level, i, j, k, -12, 78, -4, WOOD);
        setBlock(level, i, j, k, -13, 78, -4, WOOD);
        setBlock(level, i, j, k, -13, 78, -3, WOOD);
        setBlock(level, i, j, k, -13, 78, -2, WOOD);
        setBlock(level, i, j, k, -14, 78, -2, WOOD);
        setBlock(level, i, j, k, -14, 78, -1, WOOD);
        setBlock(level, i, j, k, -14, 78, 0, WOOD);
        setBlock(level, i, j, k, -14, 78, 1, WOOD);
        setBlock(level, i, j, k, -14, 78, 2, WOOD);
        setBlock(level, i, j, k, -14, 78, 2, AIR);
        setBlock(level, i, j, k, -13, 78, 2, WOOD);
        setBlock(level, i, j, k, -13, 78, 3, WOOD);
        setBlock(level, i, j, k, -12, 78, 4, WOOD);
        setBlock(level, i, j, k, -13, 78, 4, WOOD);
        setBlock(level, i, j, k, -13, 78, 4, AIR);
        setBlock(level, i, j, k, -12, 78, 5, WOOD);
        setBlock(level, i, j, k, -10, 78, 5, WOOD);
        setBlock(level, i, j, k, -11, 78, 5, WOOD);
        setBlock(level, i, j, k, -9, 78, 6, WOOD);
        setBlock(level, i, j, k, -10, 78, 6, WOOD);
        setBlock(level, i, j, k, -6, 78, 6, WOOD);
        setBlock(level, i, j, k, -7, 78, 6, WOOD);
        setBlock(level, i, j, k, -8, 78, 6, WOOD);
        setBlock(level, i, j, k, -5, 78, 6, WOOD);
        setBlock(level, i, j, k, -5, 76, 7, WOOD);
        setBlock(level, i, j, k, -4, 78, 7, WOOD);
        setBlock(level, i, j, k, -5, 79, 6, WOOD);
        setBlock(level, i, j, k, -6, 79, 6, WOOD);
        setBlock(level, i, j, k, -4, 79, 7, WOOD);
        setBlock(level, i, j, k, -11, 78, -1, WOOD);
        setBlock(level, i, j, k, -12, 78, -1, WOOD);
        setBlock(level, i, j, k, -13, 78, -1, WOOD);
        setBlock(level, i, j, k, -11, 78, 0, WOOD);
        setBlock(level, i, j, k, -12, 78, 0, WOOD);
        setBlock(level, i, j, k, -13, 78, 0, WOOD);
        setBlock(level, i, j, k, -11, 78, 2, WOOD);
        setBlock(level, i, j, k, -12, 78, 2, WOOD);
        setBlock(level, i, j, k, -13, 78, 1, WOOD);
        setBlock(level, i, j, k, -12, 78, 1, WOOD);
        setBlock(level, i, j, k, -11, 78, 1, WOOD);
        setBlock(level, i, j, k, -11, 78, 4, WOOD);
        setBlock(level, i, j, k, -11, 78, 3, WOOD);
        setBlock(level, i, j, k, -12, 78, 3, WOOD);
        setBlock(level, i, j, k, -10, 78, 4, WOOD);
        setBlock(level, i, j, k, -10, 78, 3, WOOD);
        setBlock(level, i, j, k, -10, 78, 2, WOOD);
        setBlock(level, i, j, k, -10, 78, 0, WOOD);
        setBlock(level, i, j, k, -10, 78, 1, WOOD);
        setBlock(level, i, j, k, -7, 78, 1, WOOD);
        setBlock(level, i, j, k, -8, 78, 1, WOOD);
        setBlock(level, i, j, k, -9, 78, 1, WOOD);
        setBlock(level, i, j, k, -7, 78, 3, WOOD);
        setBlock(level, i, j, k, -8, 78, 2, WOOD);
        setBlock(level, i, j, k, -7, 78, 2, WOOD);
        setBlock(level, i, j, k, -8, 78, 3, WOOD);
        setBlock(level, i, j, k, -9, 78, 3, WOOD);
        setBlock(level, i, j, k, -9, 78, 2, WOOD);
        setBlock(level, i, j, k, -6, 78, 5, WOOD);
        setBlock(level, i, j, k, -6, 78, 4, WOOD);
        setBlock(level, i, j, k, -7, 78, 5, WOOD);
        setBlock(level, i, j, k, -7, 78, 4, WOOD);
