package lionking.common;
import net.minecraft.block.*;
import net.minecraft.block.material.*;
import net.minecraft.creativetab.*;
import net.minecraft.enchantment.*;
import net.minecraft.entity.*;
import net.minecraft.entity.ai.*;
import net.minecraft.entity.item.*;
import net.minecraft.entity.monster.*;
import net.minecraft.entity.passive.*;
import net.minecraft.entity.player.*;
import net.minecraft.entity.projectile.*;
import net.minecraft.inventory.*;
import net.minecraft.item.*;
import net.minecraft.item.crafting.*;
import net.minecraft.nbt.*;
import net.minecraft.network.packet.*;
import net.minecraft.pathfinding.*;
import net.minecraft.potion.*;
import net.minecraft.server.*;
import net.minecraft.server.management.*;
import net.minecraft.src.*;
import net.minecraft.stats.*;
import net.minecraft.tileentity.*;
import net.minecraft.util.*;
import net.minecraft.world.*;
import net.minecraft.world.biome.*;
import net.minecraft.world.gen.feature.*;
import net.minecraft.world.gen.layer.*;
import net.minecraft.world.storage.*;

import java.util.Random;

public class LKWorldGenRafiki extends WorldGenerator
{
	@Override
   	public boolean generate(World world, Random random, int i, int j, int k)
   	{
		for (int j1 = 0; j1 < 40; j1++)
		{
			for (int i1 = 0; i1 > -2; i1--)
			{
				for (int k1 = 0; k1 > -2; k1--)
				{
					generateCircle(world, i + i1 + MathHelper.floor_double(j1 / 6), j + j1, k + k1, 20 - MathHelper.floor_double(j1 / 4), mod_LionKing.rafikiWood.blockID, 0, true);
					generateCircle(world, i + i1 + MathHelper.floor_double(j1 / 6), j + j1 - 1, k + k1, 20 - MathHelper.floor_double(j1 / 4), mod_LionKing.rafikiWood.blockID, 0, true);
					generateCircle(world, i + i1 + MathHelper.floor_double(j1 / 6), j + j1 - 2, k + k1, 20 - MathHelper.floor_double(j1 / 4), mod_LionKing.rafikiWood.blockID, 0, true);
				}
			}
		}
		for (int i1 = -3; i1 < 15; i1++)
		{
			world.setBlock(i + i1, j + 39, k, 0, 0, 2);
			world.setBlock(i + i1, j + 38, k, mod_LionKing.rafikiWood.blockID, 2, 2);
		}
		generateCircle(world, i + 6, j + 39, k - 1, 8, 0, 0, true);
		generateCircle(world, i + 6, j + 39, k, 8, 0, 0, true);
		generateCircle(world, i + 5, j + 39, k - 1, 8, 0, 0, true);
		generateCircle(world, i + 5, j + 39, k, 8, 0, 0, true);
		generateCircle(world, i + 6, j + 38, k, 10, mod_LionKing.rafikiWood.blockID, 2, true);
		for (int i1 = 0; i1 > -2; i1--)
		{
			for (int k1 = 0; k1 > -2; k1--)
			{
				generateCircle(world, i + i1 + 6, j + 40, k + k1, 11, mod_LionKing.rafikiWood.blockID, 1, false);
			}
		}
		for (int i1 = 0; i1 > -2; i1--)
		{
			for (int k1 = 0; k1 > -2; k1--)
			{
				generateCircle(world, i + i1 + 6, j + 40, k + k1, 10, 0, 0, false);
			}
		}
		placeUpperTorches(world, i, j, k);
		finishGeneration1(world, i, j, k);
		LKEntityRafiki rafiki = new LKEntityRafiki(world);
		rafiki.setLocationAndAngles(i, j + 39, k, 0.0F, 0.0F);
		rafiki.isThisTheRealRafiki = true;
		world.spawnEntityInWorld(rafiki);
		return true;
   	}
	
	private void generateCircle(World world, int x0, int j, int y0, int radius, int blockID, int metadata, boolean fill)
	{
		int f = 1 - radius;
		int ddF_x = 1;
		int ddF_y = -2 * radius;
		int x = 0;
		int y = radius;
 
		world.setBlock(x0, j, y0 + radius, blockID, metadata, 2);
		world.setBlock(x0, j, y0 - radius, blockID, metadata, 2);
		world.setBlock(x0 + radius, j, y0, blockID, metadata, 2);
		world.setBlock(x0 - radius, j, y0, blockID, metadata, 2);
 
		while(x < y)
		{
			if (f >= 0) 
			{
				y--;
				ddF_y += 2;
				f += ddF_y;
			}
			x++;
			ddF_x += 2;
			f += ddF_x;
			if (fill)
			{
				for (int i = x0 - x; i <= x0 + x; i++)
				{
					world.setBlock(i, j, y0 + y, blockID, metadata, 2);
				}
				for (int i = x0 - x; i <= x0 + x; i++)
				{
					world.setBlock(i, j, y0 - y, blockID, metadata, 2);
				}
				for (int i = x0 - y; i <= x0 + y; i++)
				{
					world.setBlock(i, j, y0 + x, blockID, metadata, 2);
				}
				for (int i = x0 - y; i <= x0 + y; i++)
				{
					world.setBlock(i, j, y0 - x, blockID, metadata, 2);
				}
			}
			else
			{
				world.setBlock(x0 - x, j, y0 + y, blockID, metadata, 2);
				world.setBlock(x0 + x, j, y0 + y, blockID, metadata, 2);
				world.setBlock(x0 - x, j, y0 - y, blockID, metadata, 2);
				world.setBlock(x0 + x, j, y0 - y, blockID, metadata, 2);
				world.setBlock(x0 - y, j, y0 + x, blockID, metadata, 2);
				world.setBlock(x0 + y, j, y0 + x, blockID, metadata, 2);
				world.setBlock(x0 - y, j, y0 - x, blockID, metadata, 2);
				world.setBlock(x0 + y, j, y0 - x, blockID, metadata, 2);
			}
		}
	}
	
	private void placeUpperTorches(World world, int i, int j, int k)
	{
		world.setBlock(i - 2, j + 39, k - 5, Block.torchWood.blockID, 0, 2);
		world.setBlock(i - 3, j + 39, k - 3, Block.torchWood.blockID, 0, 2);
		world.setBlock(i - 3, j + 39, k + 2, Block.torchWood.blockID, 0, 2);
		world.setBlock(i - 2, j + 39, k + 4, Block.torchWood.blockID, 0, 2);
		world.setBlock(i + 1, j + 39, k + 7, Block.torchWood.blockID, 0, 2);
		world.setBlock(i + 3, j + 39, k + 8, Block.torchWood.blockID, 0, 2);
		world.setBlock(i + 8, j + 39, k + 8, Block.torchWood.blockID, 0, 2);
		world.setBlock(i + 10, j + 39, k + 7, Block.torchWood.blockID, 0, 2);
		world.setBlock(i + 13, j + 39, k + 4, Block.torchWood.blockID, 0, 2);
		world.setBlock(i + 14, j + 39, k + 2, Block.torchWood.blockID, 0, 2);
		world.setBlock(i + 14, j + 39, k - 3, Block.torchWood.blockID, 0, 2);
		world.setBlock(i + 13, j + 39, k - 5, Block.torchWood.blockID, 0, 2);
		world.setBlock(i + 10, j + 39, k - 8, Block.torchWood.blockID, 0, 2);
		world.setBlock(i + 8, j + 39, k - 9, Block.torchWood.blockID, 0, 2);
		world.setBlock(i + 3, j + 39, k - 9, Block.torchWood.blockID, 0, 2);
		world.setBlock(i + 1, j + 39, k - 8, Block.torchWood.blockID, 0, 2);
		world.setBlock(i - 3, j + 40, k - 7, Block.torchWood.blockID, 0, 2);
		world.setBlock(i - 4, j + 40, k - 5, Block.torchWood.blockID, 0, 2);
		world.setBlock(i - 5, j + 40, k - 3, Block.torchWood.blockID, 0, 2);
		world.setBlock(i - 5, j + 40, k + 2, Block.torchWood.blockID, 0, 2);
		world.setBlock(i - 4, j + 40, k + 4, Block.torchWood.blockID, 0, 2);
		world.setBlock(i - 3, j + 40, k + 6, Block.torchWood.blockID, 0, 2);
		world.setBlock(i - 1, j + 40, k + 8, Block.torchWood.blockID, 0, 2);
		world.setBlock(i + 1, j + 40, k + 9, Block.torchWood.blockID, 0, 2);
		world.setBlock(i + 3, j + 40, k + 10, Block.torchWood.blockID, 0, 2);
		world.setBlock(i + 8, j + 40, k + 10, Block.torchWood.blockID, 0, 2);
		world.setBlock(i + 10, j + 40, k + 9, Block.torchWood.blockID, 0, 2);
		world.setBlock(i + 12, j + 40, k + 8, Block.torchWood.blockID, 0, 2);
		world.setBlock(i + 14, j + 40, k + 6, Block.torchWood.blockID, 0, 2);
		world.setBlock(i + 15, j + 40, k + 4, Block.torchWood.blockID, 0, 2);
		world.setBlock(i + 16, j + 40, k + 2, Block.torchWood.blockID, 0, 2);
		world.setBlock(i + 16, j + 40, k - 3, Block.torchWood.blockID, 0, 2);
		world.setBlock(i + 15, j + 40, k - 5, Block.torchWood.blockID, 0, 2);
		world.setBlock(i + 14, j + 40, k - 7, Block.torchWood.blockID, 0, 2);
		world.setBlock(i + 12, j + 40, k - 9, Block.torchWood.blockID, 0, 2);
		world.setBlock(i + 10, j + 40, k - 10, Block.torchWood.blockID, 0, 2);
		world.setBlock(i + 8, j + 40, k - 11, Block.torchWood.blockID, 0, 2);
		world.setBlock(i + 3, j + 40, k - 11, Block.torchWood.blockID, 0, 2);
		world.setBlock(i + 1, j + 40, k - 10, Block.torchWood.blockID, 0, 2);
		world.setBlock(i - 1, j + 40, k - 9, Block.torchWood.blockID, 0, 2);
	}
	
	private void finishGeneration1(World world, int i, int j, int k)
	{
		world.setBlock(i - 2, j + 36, k + 9, mod_LionKing.rafikiWood.blockID, 0, 2);
		world.setBlock(i - 2, j + 36, k + 10, mod_LionKing.rafikiWood.blockID, 0, 2);
		world.setBlock(i - 3, j + 36, k + 10, mod_LionKing.rafikiWood.blockID, 0, 2);
		world.setBlock(i - 3, j + 36, k + 9, mod_LionKing.rafikiWood.blockID, 0, 2);
		world.setBlock(i - 4, j + 36, k + 9, mod_LionKing.rafikiWood.blockID, 0, 2);
		world.setBlock(i - 4, j + 36, k + 10, mod_LionKing.rafikiWood.blockID, 0, 2);
		world.setBlock(i - 3, j + 36, k + 11, mod_LionKing.rafikiWood.blockID, 0, 2);
		world.setBlock(i - 4, j + 36, k + 11, mod_LionKing.rafikiWood.blockID, 0, 2);
		world.setBlock(i - 5, j + 36, k + 10, mod_LionKing.rafikiWood.blockID, 0, 2);
		world.setBlock(i - 5, j + 36, k + 11, mod_LionKing.rafikiWood.blockID, 0, 2);
		world.setBlock(i - 4, j + 36, k + 12, mod_LionKing.rafikiWood.blockID, 0, 2);
		world.setBlock(i - 5, j + 36, k + 12, mod_LionKing.rafikiWood.blockID, 0, 2);
		world.setBlock(i - 4, j + 35, k + 10, mod_LionKing.rafikiWood.blockID, 0, 2);
		world.setBlock(i - 4, j + 35, k + 11, mod_LionKing.rafikiWood.blockID, 0, 2);
		world.setBlock(i - 4, j + 34, k + 10, mod_LionKing.rafikiWood.blockID, 0, 2);
		world.setBlock(i - 4, j + 33, k + 10, mod_LionKing.rafikiWood.blockID, 0, 2);
		world.setBlock(i - 5, j + 35, k + 10, mod_LionKing.rafikiWood.blockID, 0, 2);
		world.setBlock(i - 5, j + 34, k + 10, mod_LionKing.rafikiWood.blockID, 0, 2);
		world.setBlock(i - 5, j + 36, k + 9, mod_LionKing.rafikiWood.blockID, 0, 2);
		world.setBlock(i - 4, j + 37, k + 10, mod_LionKing.rafikiWood.blockID, 0, 2);
		world.setBlock(i - 5, j + 37, k + 10, mod_LionKing.rafikiWood.blockID, 0, 2);
		world.setBlock(i - 3, j + 37, k + 11, mod_LionKing.rafikiWood.blockID, 0, 2);
		world.setBlock(i - 5, j + 37, k + 11, mod_LionKing.rafikiWood.blockID, 0, 2);
		world.setBlock(i - 5, j + 37, k + 12, mod_LionKing.rafikiWood.blockID, 0, 2);
		world.setBlock(i - 4, j + 37, k + 11, mod_LionKing.rafikiWood.blockID, 0, 2);
		world.setBlock(i - 4, j + 37, k + 12, mod_LionKing.rafikiWood.blockID, 0, 2);
		world.setBlock(i - 6, j + 36, k + 11, mod_LionKing.rafikiWood.blockID, 0, 2);
		world.setBlock(i - 6, j + 36, k + 12, mod_LionKing.rafikiWood.blockID, 0, 2);
		world.setBlock(i - 6, j + 37, k + 11, mod_LionKing.rafikiWood.blockID, 0, 2);
		world.setBlock(i - 6, j + 37, k + 12, mod_LionKing.rafikiWood.blockID, 0, 2);
		world.setBlock(i - 5, j + 38, k + 12, mod_LionKing.rafikiWood.blockID, 0, 2);
		world.setBlock(i - 6, j + 38, k + 12, mod_LionKing.rafikiWood.blockID, 0, 2);
		world.setBlock(i - 5, j + 35, k + 9, mod_LionKing.rafikiWood.blockID, 0, 2);
		world.setBlock(i - 5, j + 34, k + 9, mod_LionKing.rafikiWood.blockID, 0, 2);
		world.setBlock(i - 5, j + 33, k + 9, mod_LionKing.rafikiWood.blockID, 0, 2);
		world.setBlock(i - 4, j + 32, k + 10, mod_LionKing.rafikiWood.blockID, 0, 2);
		world.setBlock(i - 3, j + 35, k + 11, mod_LionKing.rafikiWood.blockID, 0, 2);
		world.setBlock(i - 3, j + 34, k + 11, mod_LionKing.rafikiWood.blockID, 0, 2);
		world.setBlock(i - 3, j + 33, k + 11, mod_LionKing.rafikiWood.blockID, 0, 2);
		world.setBlock(i - 6, j + 38, k + 11, mod_LionKing.rafikiWood.blockID, 0, 2);
		world.setBlock(i - 5, j + 38, k + 11, mod_LionKing.rafikiWood.blockID, 0, 2);
		world.setBlock(i - 6, j + 39, k + 12, mod_LionKing.rafikiWood.blockID, 0, 2);
		world.setBlock(i - 7, j + 39, k + 12, mod_LionKing.rafikiWood.blockID, 0, 2);
		world.setBlock(i - 6, j + 39, k + 13, mod_LionKing.rafikiWood.blockID, 0, 2);
		world.setBlock(i - 7, j + 39, k + 13, mod_LionKing.rafikiWood.blockID, 0, 2);
		world.setBlock(i - 7, j + 40, k + 12, mod_LionKing.rafikiWood.blockID, 0, 2);
		world.setBlock(i - 7, j + 40, k + 13, mod_LionKing.rafikiWood.blockID, 0, 2);
		world.setBlock(i - 6, j + 40, k + 13, mod_LionKing.rafikiWood.blockID, 0, 2);
		world.setBlock(i - 6, j + 38, k + 13, mod_LionKing.rafikiWood.blockID, 0, 2);
		world.setBlock(i - 6, j + 37, k + 13, mod_LionKing.rafikiWood.blockID, 0, 2);
		world.setBlock(i - 7, j + 38, k + 12, mod_LionKing.rafikiWood.blockID, 0, 2);
		world.setBlock(i - 7, j + 38, k + 13, mod_LionKing.rafikiWood.blockID, 0, 2);
		world.setBlock(i - 6, j + 36, k + 11, 0, 0, 2);
		world.setBlock(i - 7, j + 41, k + 13, mod_LionKing.rafikiWood.blockID, 0, 2);
		world.setBlock(i - 7, j + 42, k + 13, mod_LionKing.rafikiWood.blockID, 0, 2);
		world.setBlock(i - 7, j + 43, k + 13, mod_LionKing.rafikiWood.blockID, 0, 2);
		world.setBlock(i - 6, j + 40, k + 12, mod_LionKing.rafikiWood.blockID, 0, 2);
		world.setBlock(i - 6, j + 41, k + 13, mod_LionKing.rafikiWood.blockID, 0, 2);
		world.setBlock(i - 7, j + 41, k + 12, mod_LionKing.rafikiWood.blockID, 0, 2);
		world.setBlock(i - 7, j + 42, k + 12, mod_LionKing.rafikiWood.blockID, 0, 2);
		world.setBlock(i - 5, j + 39, k + 12, mod_LionKing.rafikiWood.blockID, 0, 2);
		world.setBlock(i - 6, j + 39, k + 11, mod_LionKing.rafikiWood.blockID, 0, 2);
		world.setBlock(i - 6, j + 37, k + 10, mod_LionKing.rafikiWood.blockID, 0, 2);
		world.setBlock(i - 6, j + 36, k + 10, mod_LionKing.rafikiWood.blockID, 0, 2);
		world.setBlock(i - 6, j + 36, k + 11, mod_LionKing.rafikiWood.blockID, 0, 2);
		world.setBlock(i - 5, j + 35, k + 11, mod_LionKing.rafikiWood.blockID, 0, 2);
		world.setBlock(i - 6, j + 42, k + 13, mod_LionKing.rafikiWood.blockID, 0, 2);
		world.setBlock(i - 5, j + 40, k + 13, mod_LionKing.rafikiWood.blockID, 0, 2);
		world.setBlock(i - 6, j + 41, k + 14, mod_LionKing.rafikiWood.blockID, 0, 2);
		world.setBlock(i - 7, j + 41, k + 14, mod_LionKing.rafikiWood.blockID, 0, 2);
		world.setBlock(i - 8, j + 41, k + 12, mod_LionKing.rafikiWood.blockID, 0, 2);
		world.setBlock(i - 8, j + 41, k + 13, mod_LionKing.rafikiWood.blockID, 0, 2);
		world.setBlock(i - 8, j + 40, k + 13, mod_LionKing.rafikiWood.blockID, 0, 2);
		world.setBlock(i - 8, j + 42, k + 12, mod_LionKing.rafikiWood.blockID, 0, 2);
		world.setBlock(i - 8, j + 42, k + 13, mod_LionKing.rafikiWood.blockID, 0, 2);
		world.setBlock(i - 8, j + 43, k + 13, mod_LionKing.rafikiWood.blockID, 0, 2);
		world.setBlock(i - 7, j + 42, k + 14, mod_LionKing.rafikiWood.blockID, 0, 2);
		world.setBlock(i - 7, j + 43, k + 14, mod_LionKing.rafikiWood.blockID, 0, 2);
		world.setBlock(i - 7, j + 44, k + 14, mod_LionKing.rafikiWood.blockID, 0, 2);
		world.setBlock(i - 3, j + 37, k + 9, mod_LionKing.rafikiWood.blockID, 0, 2);
		world.setBlock(i - 3, j + 37, k + 10, mod_LionKing.rafikiWood.blockID, 0, 2);
		world.setBlock(i - 2, j + 37, k + 9, mod_LionKing.rafikiWood.blockID, 0, 2);
		world.setBlock(i - 2, j + 37, k + 10, mod_LionKing.rafikiWood.blockID, 0, 2);
		world.setBlock(i - 2, j + 38, k + 9, mod_LionKing.rafikiWood.blockID, 0, 2);
		world.setBlock(i - 4, j + 36, k + 8, mod_LionKing.rafikiWood.blockID, 0, 2);
		world.setBlock(i - 4, j + 37, k + 9, mod_LionKing.rafikiWood.blockID, 0, 2);
		world.setBlock(i - 4, j + 36, k + 7, mod_LionKing.rafikiWood.blockID, 0, 2);
		world.setBlock(i - 4, j + 37, k + 8, mod_LionKing.rafikiWood.blockID, 0, 2);
		world.setBlock(i - 6, j + 35, k + 9, mod_LionKing.rafikiWood.blockID, 0, 2);
		world.setBlock(i - 6, j + 34, k + 8, mod_LionKing.rafikiWood.blockID, 0, 2);
		world.setBlock(i - 6, j + 35, k + 8, mod_LionKing.rafikiWood.blockID, 0, 2);
		world.setBlock(i - 7, j + 40, k + 14, mod_LionKing.rafikiWood.blockID, 0, 2);
		world.setBlock(i - 8, j + 42, k + 14, mod_LionKing.rafikiWood.blockID, 0, 2);
		world.setBlock(i - 8, j + 43, k + 14, mod_LionKing.rafikiWood.blockID, 0, 2);
		world.setBlock(i - 8, j + 44, k + 14, mod_LionKing.rafikiWood.blockID, 0, 2);
		world.setBlock(i - 8, j + 44, k + 13, mod_LionKing.rafikiWood.blockID, 0, 2);
		world.setBlock(i - 3, j + 38, k + 9, mod_LionKing.rafikiWood.blockID, 0, 2);
		world.setBlock(i - 2, j + 39, k + 9, mod_LionKing.rafikiWood.blockID, 0, 2);
		world.setBlock(i - 4, j + 38, k + 10, mod_LionKing.rafikiWood.blockID, 0, 2);
		world.setBlock(i - 9, j + 43, k + 14, mod_LionKing.rafikiWood.blockID, 0, 2);
		world.setBlock(i - 9, j + 44, k + 14, mod_LionKing.rafikiWood.blockID, 0, 2);
		world.setBlock(i - 8, j + 43, k + 15, mod_LionKing.rafikiWood.blockID, 0, 2);
		world.setBlock(i - 8, j + 44, k + 15, mod_LionKing.rafikiWood.blockID, 0, 2);
		world.setBlock(i - 8, j + 45, k + 15, mod_LionKing.rafikiWood.blockID, 0, 2);
		world.setBlock(i - 9, j + 44, k + 15, mod_LionKing.rafikiWood.blockID, 0, 2);
		world.setBlock(i - 9, j + 45, k + 15, mod_LionKing.rafikiWood.blockID, 0, 2);
		world.setBlock(i - 9, j + 46, k + 15, mod_LionKing.rafikiWood.blockID, 0, 2);
		world.setBlock(i - 9, j + 47, k + 15, mod_LionKing.rafikiWood.blockID, 0, 2);
		world.setBlock(i - 9, j + 45, k + 14, mod_LionKing.rafikiWood.blockID, 0, 2);
		world.setBlock(i - 8, j + 45, k + 14, mod_LionKing.rafikiWood.blockID, 0, 2);
		world.setBlock(i - 8, j + 46, k + 15, mod_LionKing.rafikiWood.blockID, 0, 2);
		world.setBlock(i - 8, j + 47, k + 15, mod_LionKing.rafikiWood.blockID, 0, 2);
		world.setBlock(i - 9, j + 46, k + 14, mod_LionKing.rafikiWood.blockID, 0, 2);
		world.setBlock(i - 9, j + 47, k + 14, mod_LionKing.rafikiWood.blockID, 0, 2);
		world.setBlock(i - 9, j + 48, k + 15, mod_LionKing.rafikiWood.blockID, 0, 2);
		world.setBlock(i - 9, j + 49, k + 15, mod_LionKing.rafikiWood.blockID, 0, 2);
		world.setBlock(i - 10, j + 47, k + 15, mod_LionKing.rafikiWood.blockID, 0, 2);
		world.setBlock(i - 10, j + 46, k + 14, mod_LionKing.rafikiWood.blockID, 0, 2);
		world.setBlock(i - 10, j + 46, k + 15, mod_LionKing.rafikiWood.blockID, 0, 2);
		world.setBlock(i - 9, j + 46, k + 16, mod_LionKing.rafikiWood.blockID, 0, 2);
		world.setBlock(i - 9, j + 47, k + 16, mod_LionKing.rafikiWood.blockID, 0, 2);
		world.setBlock(i - 10, j + 46, k + 14, 0, 0, 2);
		world.setBlock(i - 10, j + 47, k + 16, mod_LionKing.rafikiWood.blockID, 0, 2);
		world.setBlock(i - 10, j + 48, k + 15, mod_LionKing.rafikiWood.blockID, 0, 2);
		world.setBlock(i - 10, j + 48, k + 16, mod_LionKing.rafikiWood.blockID, 0, 2);
		world.setBlock(i - 9, j + 48, k + 16, mod_LionKing.rafikiWood.blockID, 0, 2);
		world.setBlock(i - 10, j + 49, k + 15, mod_LionKing.rafikiWood.blockID, 0, 2);
		world.setBlock(i - 10, j + 49, k + 16, mod_LionKing.rafikiWood.blockID, 0, 2);
		world.setBlock(i - 9, j + 49, k + 16, mod_LionKing.rafikiWood.blockID, 0, 2);
		world.setBlock(i - 8, j + 46, k + 16, mod_LionKing.rafikiWood.blockID, 0, 2);
		world.setBlock(i - 8, j + 46, k + 17, mod_LionKing.rafikiWood.blockID, 0, 2);
		world.setBlock(i - 7, j + 46, k + 17, mod_LionKing.rafikiWood.blockID, 0, 2);
		world.setBlock(i - 7, j + 47, k + 17, mod_LionKing.rafikiWood.blockID, 0, 2);
		world.setBlock(i - 7, j + 46, k + 17, 0, 0, 2);
		world.setBlock(i - 7, j + 47, k + 18, mod_LionKing.rafikiWood.blockID, 0, 2);
		world.setBlock(i - 6, j + 47, k + 18, mod_LionKing.rafikiWood.blockID, 0, 2);
		world.setBlock(i - 10, j + 45, k + 14, mod_LionKing.rafikiWood.blockID, 0, 2);
		world.setBlock(i - 11, j + 45, k + 14, mod_LionKing.rafikiWood.blockID, 0, 2);
		world.setBlock(i - 11, j + 45, k + 13, mod_LionKing.rafikiWood.blockID, 0, 2);
		world.setBlock(i - 11, j + 46, k + 13, mod_LionKing.rafikiWood.blockID, 0, 2);
		world.setBlock(i - 12, j + 46, k + 13, mod_LionKing.rafikiWood.blockID, 0, 2);
		world.setBlock(i - 12, j + 46, k + 12, mod_LionKing.rafikiWood.blockID, 0, 2);
		world.setBlock(i - 12, j + 46, k + 13, 0, 0, 2);
		world.setBlock(i - 10, j + 50, k + 16, mod_LionKing.rafikiWood.blockID, 0, 2);
		world.setBlock(i - 3, j + 38, k + 10, mod_LionKing.rafikiWood.blockID, 0, 2);
		world.setBlock(i - 4, j + 38, k + 11, mod_LionKing.rafikiWood.blockID, 0, 2);
		world.setBlock(i - 4, j + 38, k + 9, mod_LionKing.rafikiWood.blockID, 0, 2);
		world.setBlock(i - 5, j + 38, k + 10, mod_LionKing.rafikiWood.blockID, 0, 2);
		world.setBlock(i - 4, j + 38, k + 8, mod_LionKing.rafikiWood.blockID, 0, 2);
		world.setBlock(i - 3, j + 39, k + 9, mod_LionKing.rafikiWood.blockID, 0, 2);
		world.setBlock(i - 4, j + 37, k + 7, mod_LionKing.rafikiWood.blockID, 0, 2);
		world.setBlock(i - 5, j + 37, k + 9, mod_LionKing.rafikiWood.blockID, 0, 2);
		world.setBlock(i - 5, j + 36, k + 8, mod_LionKing.rafikiWood.blockID, 0, 2);
		world.setBlock(i - 6, j + 36, k + 9, mod_LionKing.rafikiWood.blockID, 0, 2);
		world.setBlock(i - 5, j + 39, k + 11, mod_LionKing.rafikiWood.blockID, 0, 2);
		world.setBlock(i - 4, j + 39, k + 10, mod_LionKing.rafikiWood.blockID, 0, 2);
		world.setBlock(i + 5, j + 35, k + 13, mod_LionKing.rafikiWood.blockID, 0, 2);
		world.setBlock(i + 6, j + 35, k + 13, mod_LionKing.rafikiWood.blockID, 0, 2);
		world.setBlock(i + 7, j + 35, k + 13, mod_LionKing.rafikiWood.blockID, 0, 2);
		world.setBlock(i + 8, j + 35, k + 13, mod_LionKing.rafikiWood.blockID, 0, 2);
		world.setBlock(i + 4, j + 35, k + 13, mod_LionKing.rafikiWood.blockID, 0, 2);
		world.setBlock(i + 4, j + 36, k + 12, mod_LionKing.rafikiWood.blockID, 0, 2);
		world.setBlock(i + 4, j + 36, k + 13, mod_LionKing.rafikiWood.blockID, 0, 2);
		world.setBlock(i + 5, j + 36, k + 12, mod_LionKing.rafikiWood.blockID, 0, 2);
		world.setBlock(i + 5, j + 36, k + 13, mod_LionKing.rafikiWood.blockID, 0, 2);
		world.setBlock(i + 6, j + 36, k + 12, mod_LionKing.rafikiWood.blockID, 0, 2);
		world.setBlock(i + 6, j + 36, k + 13, mod_LionKing.rafikiWood.blockID, 0, 2);
		world.setBlock(i + 7, j + 36, k + 12, mod_LionKing.rafikiWood.blockID, 0, 2);
		world.setBlock(i + 7, j + 36, k + 13, mod_LionKing.rafikiWood.blockID, 0, 2);
		world.setBlock(i + 8, j + 36, k + 12, mod_LionKing.rafikiWood.blockID, 0, 2);
		world.setBlock(i + 8, j + 36, k + 13, mod_LionKing.rafikiWood.blockID, 0, 2);
		world.setBlock(i + 4, j + 36, k + 14, mod_LionKing.rafikiWood.blockID, 0, 2);
		world.setBlock(i + 5, j + 36, k + 14, mod_LionKing.rafikiWood.blockID, 0, 2);
		world.setBlock(i + 6, j + 36, k + 14, mod_LionKing.rafikiWood.blockID, 0, 2);
		world.setBlock(i + 7, j + 36, k + 14, mod_LionKing.rafikiWood.blockID, 0, 2);
		world.setBlock(i + 8, j + 36, k + 14, mod_LionKing.rafikiWood.blockID, 0, 2);
		world.setBlock(i + 4, j + 37, k + 12, mod_LionKing.rafikiWood.blockID, 0, 2);
		world.setBlock(i + 4, j + 37, k + 13, mod_LionKing.rafikiWood.blockID, 0, 2);
		world.setBlock(i + 4, j + 37, k + 14, mod_LionKing.rafikiWood.blockID, 0, 2);
		world.setBlock(i + 5, j + 37, k + 12, mod_LionKing.rafikiWood.blockID, 0, 2);
		world.setBlock(i + 5, j + 37, k + 13, mod_LionKing.rafikiWood.blockID, 0, 2);
		world.setBlock(i + 5, j + 37, k + 14, mod_LionKing.rafikiWood.blockID, 0, 2);
		world.setBlock(i + 5, j + 37, k + 15, mod_LionKing.rafikiWood.blockID, 0, 2);
		world.setBlock(i + 4, j + 37, k + 15, mod_LionKing.rafikiWood.blockID, 0, 2);
		world.setBlock(i + 6, j + 37, k + 13, mod_LionKing.rafikiWood.blockID, 0, 2);
		world.setBlock(i + 6, j + 37, k + 14, mod_LionKing.rafikiWood.blockID, 0, 2);
		world.setBlock(i + 6, j + 37, k + 15, mod_LionKing.rafikiWood.blockID, 0, 2);
		world.setBlock(i + 6, j + 37, k + 12, mod_LionKing.rafikiWood.blockID, 0, 2);
		world.setBlock(i + 7, j + 37, k + 12, mod_LionKing.rafikiWood.blockID, 0, 2);
		world.setBlock(i + 7, j + 37, k + 13, mod_LionKing.rafikiWood.blockID, 0, 2);
		world.setBlock(i + 7, j + 37, k + 14, mod_LionKing.rafikiWood.blockID, 0, 2);
		world.setBlock(i + 7, j + 37, k + 15, mod_LionKing.rafikiWood.blockID, 0, 2);
		world.setBlock(i + 8, j + 37, k + 12, mod_LionKing.rafikiWood.blockID, 0, 2);
		world.setBlock(i + 8, j + 37, k + 13, mod_LionKing.rafikiWood.blockID, 0, 2);
		world.setBlock(i + 8, j + 37, k + 14, mod_LionKing.rafikiWood.blockID, 0, 2);
		world.setBlock(i + 8, j + 37, k + 15, mod_LionKing.rafikiWood.blockID, 0, 2);
		world.setBlock(i + 5, j + 38, k + 14, mod_LionKing.rafikiWood.blockID, 0, 2);
		world.setBlock(i + 5, j + 38, k + 15, mod_LionKing.rafikiWood.blockID, 0, 2);
		world.setBlock(i + 6, j + 38, k + 13, mod_LionKing.rafikiWood.blockID, 0, 2);
		world.setBlock(i + 6, j + 38, k + 14, mod_LionKing.rafikiWood.blockID, 0, 2);
		world.setBlock(i + 6, j + 38, k + 15, mod_LionKing.rafikiWood.blockID, 0, 2);
		world.setBlock(i + 7, j + 38, k + 14, mod_LionKing.rafikiWood.blockID, 0, 2);
		world.setBlock(i + 7, j + 38, k + 15, mod_LionKing.rafikiWood.blockID, 0, 2);
		world.setBlock(i + 8, j + 38, k + 12, mod_LionKing.rafikiWood.blockID, 0, 2);
		world.setBlock(i + 8, j + 38, k + 13, mod_LionKing.rafikiWood.blockID, 0, 2);
		world.setBlock(i + 8, j + 38, k + 14, mod_LionKing.rafikiWood.blockID, 0, 2);
		world.setBlock(i + 8, j + 38, k + 15, mod_LionKing.rafikiWood.blockID, 0, 2);
		world.setBlock(i + 7, j + 38, k + 12, mod_LionKing.rafikiWood.blockID, 0, 2);
		world.setBlock(i + 7, j + 38, k + 13, mod_LionKing.rafikiWood.blockID, 0, 2);
		world.setBlock(i + 4, j + 38, k + 12, mod_LionKing.rafikiWood.blockID, 0, 2);
		world.setBlock(i + 4, j + 38, k + 13, mod_LionKing.rafikiWood.blockID, 0, 2);
		world.setBlock(i + 5, j + 38, k + 12, mod_LionKing.rafikiWood.blockID, 0, 2);
		world.setBlock(i + 5, j + 38, k + 13, mod_LionKing.rafikiWood.blockID, 0, 2);
		world.setBlock(i + 6, j + 38, k + 12, mod_LionKing.rafikiWood.blockID, 0, 2);
		world.setBlock(i + 4, j + 38, k + 14, mod_LionKing.rafikiWood.blockID, 0, 2);
		world.setBlock(i + 4, j + 38, k + 15, mod_LionKing.rafikiWood.blockID, 0, 2);
		world.setBlock(i + 3, j + 36, k + 12, mod_LionKing.rafikiWood.blockID, 0, 2);
		world.setBlock(i + 3, j + 37, k + 12, mod_LionKing.rafikiWood.blockID, 0, 2);
		world.setBlock(i + 3, j + 36, k + 13, mod_LionKing.rafikiWood.blockID, 0, 2);
		world.setBlock(i + 3, j + 35, k + 13, mod_LionKing.rafikiWood.blockID, 0, 2);
		world.setBlock(i + 2, j + 34, k + 13, mod_LionKing.rafikiWood.blockID, 0, 2);
		world.setBlock(i + 9, j + 37, k + 12, mod_LionKing.rafikiWood.blockID, 0, 2);
		world.setBlock(i + 9, j + 36, k + 12, mod_LionKing.rafikiWood.blockID, 0, 2);
		world.setBlock(i + 9, j + 35, k + 12, mod_LionKing.rafikiWood.blockID, 0, 2);
		world.setBlock(i + 9, j + 34, k + 12, mod_LionKing.rafikiWood.blockID, 0, 2);
		world.setBlock(i + 9, j + 38, k + 13, mod_LionKing.rafikiWood.blockID, 0, 2);
		world.setBlock(i + 9, j + 37, k + 13, mod_LionKing.rafikiWood.blockID, 0, 2);
		world.setBlock(i + 8, j + 39, k + 12, mod_LionKing.rafikiWood.blockID, 0, 2);
		world.setBlock(i + 8, j + 39, k + 13, mod_LionKing.rafikiWood.blockID, 0, 2);
		world.setBlock(i + 8, j + 39, k + 14, mod_LionKing.rafikiWood.blockID, 0, 2);
		world.setBlock(i + 8, j + 39, k + 15, mod_LionKing.rafikiWood.blockID, 0, 2);
		world.setBlock(i + 6, j + 39, k + 14, mod_LionKing.rafikiWood.blockID, 0, 2);
		world.setBlock(i + 6, j + 39, k + 15, mod_LionKing.rafikiWood.blockID, 0, 2);
		world.setBlock(i + 7, j + 39, k + 15, mod_LionKing.rafikiWood.blockID, 0, 2);
		world.setBlock(i + 5, j + 39, k + 15, mod_LionKing.rafikiWood.blockID, 0, 2);
		world.setBlock(i + 4, j + 39, k + 15, mod_LionKing.rafikiWood.blockID, 0, 2);
		world.setBlock(i + 3, j + 37, k + 13, mod_LionKing.rafikiWood.blockID, 0, 2);
		world.setBlock(i + 3, j + 38, k + 14, mod_LionKing.rafikiWood.blockID, 0, 2);
		world.setBlock(i + 3, j + 38, k + 15, mod_LionKing.rafikiWood.blockID, 0, 2);
		world.setBlock(i + 3, j + 37, k + 14, mod_LionKing.rafikiWood.blockID, 0, 2);
		world.setBlock(i + 3, j + 38, k + 13, mod_LionKing.rafikiWood.blockID, 0, 2);
		world.setBlock(i + 4, j + 38, k + 16, mod_LionKing.rafikiWood.blockID, 0, 2);
		world.setBlock(i + 4, j + 38, k + 17, mod_LionKing.rafikiWood.blockID, 0, 2);
		world.setBlock(i + 5, j + 38, k + 16, mod_LionKing.rafikiWood.blockID, 0, 2);
		world.setBlock(i + 6, j + 38, k + 16, mod_LionKing.rafikiWood.blockID, 0, 2);
		world.setBlock(i + 8, j + 38, k + 16, mod_LionKing.rafikiWood.blockID, 0, 2);
		world.setBlock(i + 7, j + 38, k + 16, mod_LionKing.rafikiWood.blockID, 0, 2);
		world.setBlock(i + 4, j + 38, k + 17, 0, 0, 2);
		world.setBlock(i + 4, j + 39, k + 16, mod_LionKing.rafikiWood.blockID, 0, 2);
		world.setBlock(i + 5, j + 39, k + 16, mod_LionKing.rafikiWood.blockID, 0, 2);
		world.setBlock(i + 6, j + 39, k + 16, mod_LionKing.rafikiWood.blockID, 0, 2);
		world.setBlock(i + 7, j + 39, k + 16, mod_LionKing.rafikiWood.blockID, 0, 2);
		world.setBlock(i + 8, j + 39, k + 16, mod_LionKing.rafikiWood.blockID, 0, 2);
		world.setBlock(i + 4, j + 40, k + 16, mod_LionKing.rafikiWood.blockID, 0, 2);
		world.setBlock(i + 5, j + 40, k + 16, mod_LionKing.rafikiWood.blockID, 0, 2);
		world.setBlock(i + 6, j + 40, k + 16, mod_LionKing.rafikiWood.blockID, 0, 2);
		world.setBlock(i + 6, j + 40, k + 17, mod_LionKing.rafikiWood.blockID, 0, 2);
		world.setBlock(i + 8, j + 40, k + 16, mod_LionKing.rafikiWood.blockID, 0, 2);
		world.setBlock(i + 7, j + 40, k + 16, mod_LionKing.rafikiWood.blockID, 0, 2);
		world.setBlock(i + 6, j + 40, k + 17, 0, 0, 2);
		world.setBlock(i + 3, j + 39, k + 15, mod_LionKing.rafikiWood.blockID, 0, 2);
		world.setBlock(i + 3, j + 40, k + 16, mod_LionKing.rafikiWood.blockID, 0, 2);
		world.setBlock(i + 4, j + 39, k + 12, mod_LionKing.rafikiWood.blockID, 0, 2);
		world.setBlock(i + 4, j + 39, k + 13, mod_LionKing.rafikiWood.blockID, 0, 2);
		world.setBlock(i + 3, j + 39, k + 13, mod_LionKing.rafikiWood.blockID, 0, 2);
		world.setBlock(i + 4, j + 39, k + 14, mod_LionKing.rafikiWood.blockID, 0, 2);
		world.setBlock(i + 3, j + 39, k + 14, mod_LionKing.rafikiWood.blockID, 0, 2);
		world.setBlock(i + 4, j + 40, k + 12, mod_LionKing.rafikiWood.blockID, 0, 2);
		world.setBlock(i + 4, j + 40, k + 13, mod_LionKing.rafikiWood.blockID, 0, 2);
		world.setBlock(i + 3, j + 40, k + 13, mod_LionKing.rafikiWood.blockID, 0, 2);
		world.setBlock(i + 4, j + 40, k + 12, 0, 0, 2);
		world.setBlock(i + 7, j + 39, k + 12, mod_LionKing.rafikiWood.blockID, 0, 2);
		world.setBlock(i + 6, j + 39, k + 12, mod_LionKing.rafikiWood.blockID, 0, 2);
		world.setBlock(i + 6, j + 40, k + 12, mod_LionKing.rafikiWood.blockID, 0, 2);
		world.setBlock(i + 6, j + 40, k + 12, 0, 0, 2);
		world.setBlock(i + 5, j + 39, k + 12, mod_LionKing.rafikiWood.blockID, 0, 2);
		world.setBlock(i + 5, j + 39, k + 13, mod_LionKing.rafikiWood.blockID, 0, 2);
		world.setBlock(i + 5, j + 39, k + 14, mod_LionKing.rafikiWood.blockID, 0, 2);
		world.setBlock(i + 6, j + 39, k + 13, mod_LionKing.rafikiWood.blockID, 0, 2);
		world.setBlock(i + 7, j + 39, k + 14, mod_LionKing.rafikiWood.blockID, 0, 2);
		world.setBlock(i + 7, j + 39, k + 13, mod_LionKing.rafikiWood.blockID, 0, 2);
		world.setBlock(i + 3, j + 40, k + 14, mod_LionKing.rafikiWood.blockID, 0, 2);
		world.setBlock(i + 3, j + 40, k + 15, mod_LionKing.rafikiWood.blockID, 0, 2);
		world.setBlock(i + 4, j + 40, k + 14, mod_LionKing.rafikiWood.blockID, 0, 2);
		world.setBlock(i + 4, j + 40, k + 15, mod_LionKing.rafikiWood.blockID, 0, 2);
		world.setBlock(i + 5, j + 40, k + 14, mod_LionKing.rafikiWood.blockID, 0, 2);
		world.setBlock(i + 6, j + 40, k + 14, mod_LionKing.rafikiWood.blockID, 0, 2);
		world.setBlock(i + 6, j + 40, k + 15, mod_LionKing.rafikiWood.blockID, 0, 2);
		world.setBlock(i + 8, j + 40, k + 13, mod_LionKing.rafikiWood.blockID, 0, 2);
		world.setBlock(i + 7, j + 40, k + 13, mod_LionKing.rafikiWood.blockID, 0, 2);
		world.setBlock(i + 7, j + 40, k + 14, mod_LionKing.rafikiWood.blockID, 0, 2);
		world.setBlock(i + 8, j + 40, k + 14, mod_LionKing.rafikiWood.blockID, 0, 2);
		world.setBlock(i + 8, j + 40, k + 15, mod_LionKing.rafikiWood.blockID, 0, 2);
		world.setBlock(i + 7, j + 40, k + 15, mod_LionKing.rafikiWood.blockID, 0, 2);
		world.setBlock(i + 5, j + 40, k + 15, mod_LionKing.rafikiWood.blockID, 0, 2);
		world.setBlock(i + 4, j + 40, k + 13, 0, 0, 2);
		world.setBlock(i + 7, j + 40, k + 13, 0, 0, 2);
		world.setBlock(i + 4, j + 38, k + 16, 0, 0, 2);
		world.setBlock(i + 8, j + 38, k + 16, 0, 0, 2);
		world.setBlock(i + 9, j + 38, k + 14, mod_LionKing.rafikiWood.blockID, 0, 2);
		world.setBlock(i + 8, j + 34, k + 13, mod_LionKing.rafikiWood.blockID, 0, 2);
		world.setBlock(i + 7, j + 34, k + 13, mod_LionKing.rafikiWood.blockID, 0, 2);
		world.setBlock(i + 3, j + 34, k + 13, mod_LionKing.rafikiWood.blockID, 0, 2);
		world.setBlock(i + 6, j + 34, k + 13, mod_LionKing.rafikiWood.blockID, 0, 2);
		world.setBlock(i + 6, j + 33, k + 13, mod_LionKing.rafikiWood.blockID, 0, 2);
		world.setBlock(i + 4, j + 41, k + 16, mod_LionKing.rafikiWood.blockID, 0, 2);
		world.setBlock(i + 5, j + 41, k + 16, mod_LionKing.rafikiWood.blockID, 0, 2);
		world.setBlock(i + 6, j + 41, k + 16, mod_LionKing.rafikiWood.blockID, 0, 2);
		world.setBlock(i + 7, j + 41, k + 16, mod_LionKing.rafikiWood.blockID, 0, 2);
		world.setBlock(i + 8, j + 41, k + 16, mod_LionKing.rafikiWood.blockID, 0, 2);
		world.setBlock(i + 3, j + 41, k + 16, mod_LionKing.rafikiWood.blockID, 0, 2);
		world.setBlock(i + 3, j + 41, k + 15, mod_LionKing.rafikiWood.blockID, 0, 2);
		world.setBlock(i + 3, j + 41, k + 14, mod_LionKing.rafikiWood.blockID, 0, 2);
		world.setBlock(i + 4, j + 41, k + 15, mod_LionKing.rafikiWood.blockID, 0, 2);
		world.setBlock(i + 5, j + 41, k + 15, mod_LionKing.rafikiWood.blockID, 0, 2);
		world.setBlock(i + 6, j + 41, k + 15, mod_LionKing.rafikiWood.blockID, 0, 2);
		world.setBlock(i + 7, j + 41, k + 15, mod_LionKing.rafikiWood.blockID, 0, 2);
		world.setBlock(i + 8, j + 41, k + 15, mod_LionKing.rafikiWood.blockID, 0, 2);
		world.setBlock(i + 8, j + 41, k + 14, mod_LionKing.rafikiWood.blockID, 0, 2);
		world.setBlock(i + 7, j + 41, k + 14, mod_LionKing.rafikiWood.blockID, 0, 2);
		world.setBlock(i + 5, j + 41, k + 14, mod_LionKing.rafikiWood.blockID, 0, 2);
		world.setBlock(i + 4, j + 41, k + 14, mod_LionKing.rafikiWood.blockID, 0, 2);
		world.setBlock(i + 5, j + 40, k + 13, mod_LionKing.rafikiWood.blockID, 0, 2);
		world.setBlock(i + 4, j + 40, k + 13, mod_LionKing.rafikiWood.blockID, 0, 2);
		world.setBlock(i + 7, j + 42, k + 15, mod_LionKing.rafikiWood.blockID, 0, 2);
		world.setBlock(i + 8, j + 42, k + 15, mod_LionKing.rafikiWood.blockID, 0, 2);
		world.setBlock(i + 7, j + 42, k + 16, mod_LionKing.rafikiWood.blockID, 0, 2);
		world.setBlock(i + 8, j + 42, k + 16, mod_LionKing.rafikiWood.blockID, 0, 2);
		world.setBlock(i + 7, j + 42, k + 17, mod_LionKing.rafikiWood.blockID, 0, 2);
		world.setBlock(i + 6, j + 42, k + 17, mod_LionKing.rafikiWood.blockID, 0, 2);
		world.setBlock(i + 5, j + 42, k + 17, mod_LionKing.rafikiWood.blockID, 0, 2);
		world.setBlock(i + 4, j + 42, k + 17, mod_LionKing.rafikiWood.blockID, 0, 2);
		world.setBlock(i + 3, j + 42, k + 17, mod_LionKing.rafikiWood.blockID, 0, 2);
		world.setBlock(i + 3, j + 42, k + 15, mod_LionKing.rafikiWood.blockID, 0, 2);
		world.setBlock(i + 3, j + 42, k + 16, mod_LionKing.rafikiWood.blockID, 0, 2);
		world.setBlock(i + 6, j + 42, k + 15, mod_LionKing.rafikiWood.blockID, 0, 2);
		world.setBlock(i + 5, j + 42, k + 15, mod_LionKing.rafikiWood.blockID, 0, 2);
		world.setBlock(i + 4, j + 42, k + 15, mod_LionKing.rafikiWood.blockID, 0, 2);
		world.setBlock(i + 6, j + 42, k + 16, mod_LionKing.rafikiWood.blockID, 0, 2);
		world.setBlock(i + 4, j + 42, k + 16, mod_LionKing.rafikiWood.blockID, 0, 2);
		world.setBlock(i + 5, j + 42, k + 16, mod_LionKing.rafikiWood.blockID, 0, 2);
		world.setBlock(i + 5, j + 41, k + 17, mod_LionKing.rafikiWood.blockID, 0, 2);
		world.setBlock(i + 6, j + 41, k + 17, mod_LionKing.rafikiWood.blockID, 0, 2);
		world.setBlock(i + 6, j + 40, k + 17, mod_LionKing.rafikiWood.blockID, 0, 2);
		world.setBlock(i + 7, j + 41, k + 17, mod_LionKing.rafikiWood.blockID, 0, 2);
		world.setBlock(i + 4, j + 43, k + 16, mod_LionKing.rafikiWood.blockID, 0, 2);
		world.setBlock(i + 3, j + 43, k + 17, mod_LionKing.rafikiWood.blockID, 0, 2);
		world.setBlock(i + 5, j + 43, k + 17, mod_LionKing.rafikiWood.blockID, 0, 2);
		world.setBlock(i + 4, j + 43, k + 17, mod_LionKing.rafikiWood.blockID, 0, 2);
		world.setBlock(i + 6, j + 43, k + 16, mod_LionKing.rafikiWood.blockID, 0, 2);
		world.setBlock(i + 6, j + 43, k + 17, mod_LionKing.rafikiWood.blockID, 0, 2);
		world.setBlock(i + 7, j + 43, k + 16, mod_LionKing.rafikiWood.blockID, 0, 2);
		world.setBlock(i + 7, j + 43, k + 17, mod_LionKing.rafikiWood.blockID, 0, 2);
		world.setBlock(i + 8, j + 43, k + 15, mod_LionKing.rafikiWood.blockID, 0, 2);
		world.setBlock(i + 8, j + 43, k + 16, mod_LionKing.rafikiWood.blockID, 0, 2);
		world.setBlock(i + 5, j + 43, k + 16, mod_LionKing.rafikiWood.blockID, 0, 2);
		world.setBlock(i + 3, j + 43, k + 15, mod_LionKing.rafikiWood.blockID, 0, 2);
		world.setBlock(i + 3, j + 43, k + 16, mod_LionKing.rafikiWood.blockID, 0, 2);
		world.setBlock(i + 4, j + 43, k + 18, mod_LionKing.rafikiWood.blockID, 0, 2);
		world.setBlock(i + 5, j + 43, k + 18, mod_LionKing.rafikiWood.blockID, 0, 2);
		world.setBlock(i + 6, j + 43, k + 18, mod_LionKing.rafikiWood.blockID, 0, 2);
		world.setBlock(i + 7, j + 43, k + 18, mod_LionKing.rafikiWood.blockID, 0, 2);
		world.setBlock(i + 8, j + 43, k + 17, mod_LionKing.rafikiWood.blockID, 0, 2);
		world.setBlock(i + 8, j + 43, k + 18, mod_LionKing.rafikiWood.blockID, 0, 2);
		world.setBlock(i + 3, j + 43, k + 18, mod_LionKing.rafikiWood.blockID, 0, 2);
		world.setBlock(i + 4, j + 41, k + 17, mod_LionKing.rafikiWood.blockID, 0, 2);
		world.setBlock(i + 4, j + 42, k + 18, mod_LionKing.rafikiWood.blockID, 0, 2);
		world.setBlock(i + 5, j + 42, k + 18, mod_LionKing.rafikiWood.blockID, 0, 2);
		world.setBlock(i + 6, j + 42, k + 18, mod_LionKing.rafikiWood.blockID, 0, 2);
		world.setBlock(i + 7, j + 42, k + 18, mod_LionKing.rafikiWood.blockID, 0, 2);
		world.setBlock(i + 8, j + 42, k + 17, mod_LionKing.rafikiWood.blockID, 0, 2);
		world.setBlock(i + 6, j + 39, k + 17, mod_LionKing.rafikiWood.blockID, 0, 2);
		world.setBlock(i + 5, j + 40, k + 17, mod_LionKing.rafikiWood.blockID, 0, 2);
		world.setBlock(i + 4, j + 34, k + 13, mod_LionKing.rafikiWood.blockID, 0, 2);
		world.setBlock(i + 5, j + 34, k + 13, mod_LionKing.rafikiWood.blockID, 0, 2);
		world.setBlock(i + 4, j + 32, k + 13, mod_LionKing.rafikiWood.blockID, 0, 2);
		world.setBlock(i + 5, j + 33, k + 13, mod_LionKing.rafikiWood.blockID, 0, 2);
		world.setBlock(i + 4, j + 33, k + 13, mod_LionKing.rafikiWood.blockID, 0, 2);
		world.setBlock(i + 5, j + 32, k + 13, mod_LionKing.rafikiWood.blockID, 0, 2);
		world.setBlock(i + 3, j + 32, k + 13, mod_LionKing.rafikiWood.blockID, 0, 2);
		world.setBlock(i + 6, j + 32, k + 13, mod_LionKing.rafikiWood.blockID, 0, 2);
		world.setBlock(i + 7, j + 32, k + 13, mod_LionKing.rafikiWood.blockID, 0, 2);
		world.setBlock(i + 3, j + 44, k + 18, mod_LionKing.rafikiWood.blockID, 0, 2);
		world.setBlock(i + 4, j + 44, k + 18, mod_LionKing.rafikiWood.blockID, 0, 2);
		world.setBlock(i + 5, j + 44, k + 18, mod_LionKing.rafikiWood.blockID, 0, 2);
		world.setBlock(i + 6, j + 44, k + 18, mod_LionKing.rafikiWood.blockID, 0, 2);
		world.setBlock(i + 7, j + 44, k + 18, mod_LionKing.rafikiWood.blockID, 0, 2);
		world.setBlock(i + 8, j + 44, k + 18, mod_LionKing.rafikiWood.blockID, 0, 2);
		world.setBlock(i + 8, j + 44, k + 17, mod_LionKing.rafikiWood.blockID, 0, 2);
		world.setBlock(i + 8, j + 44, k + 16, mod_LionKing.rafikiWood.blockID, 0, 2);
		world.setBlock(i + 7, j + 44, k + 17, mod_LionKing.rafikiWood.blockID, 0, 2);
		world.setBlock(i + 7, j + 44, k + 16, mod_LionKing.rafikiWood.blockID, 0, 2);
		world.setBlock(i + 6, j + 44, k + 17, mod_LionKing.rafikiWood.blockID, 0, 2);
		world.setBlock(i + 6, j + 44, k + 16, mod_LionKing.rafikiWood.blockID, 0, 2);
		world.setBlock(i + 5, j + 44, k + 16, mod_LionKing.rafikiWood.blockID, 0, 2);
		world.setBlock(i + 5, j + 44, k + 17, mod_LionKing.rafikiWood.blockID, 0, 2);
		world.setBlock(i + 4, j + 44, k + 17, mod_LionKing.rafikiWood.blockID, 0, 2);
		world.setBlock(i + 4, j + 44, k + 16, mod_LionKing.rafikiWood.blockID, 0, 2);
		world.setBlock(i + 3, j + 44, k + 17, mod_LionKing.rafikiWood.blockID, 0, 2);
		world.setBlock(i + 3, j + 44, k + 16, mod_LionKing.rafikiWood.blockID, 0, 2);
		world.setBlock(i + 2, j + 44, k + 18, mod_LionKing.rafikiWood.blockID, 0, 2);
		world.setBlock(i + 9, j + 44, k + 18, mod_LionKing.rafikiWood.blockID, 0, 2);
		world.setBlock(i + 9, j + 45, k + 18, mod_LionKing.rafikiWood.blockID, 0, 2);
		world.setBlock(i + 8, j + 45, k + 18, mod_LionKing.rafikiWood.blockID, 0, 2);
		world.setBlock(i + 7, j + 45, k + 18, mod_LionKing.rafikiWood.blockID, 0, 2);
		world.setBlock(i + 6, j + 45, k + 18, mod_LionKing.rafikiWood.blockID, 0, 2);
		world.setBlock(i + 5, j + 45, k + 18, mod_LionKing.rafikiWood.blockID, 0, 2);
		world.setBlock(i + 4, j + 45, k + 18, mod_LionKing.rafikiWood.blockID, 0, 2);
		world.setBlock(i + 3, j + 45, k + 18, mod_LionKing.rafikiWood.blockID, 0, 2);
		world.setBlock(i + 2, j + 45, k + 18, mod_LionKing.rafikiWood.blockID, 0, 2);
		world.setBlock(i + 2, j + 45, k + 19, mod_LionKing.rafikiWood.blockID, 0, 2);
		world.setBlock(i + 3, j + 45, k + 19, mod_LionKing.rafikiWood.blockID, 0, 2);
		world.setBlock(i + 3, j + 45, k + 20, mod_LionKing.rafikiWood.blockID, 0, 2);
		world.setBlock(i + 5, j + 45, k + 19, mod_LionKing.rafikiWood.blockID, 0, 2);
		world.setBlock(i + 4, j + 45, k + 19, mod_LionKing.rafikiWood.blockID, 0, 2);
		world.setBlock(i + 4, j + 45, k + 20, mod_LionKing.rafikiWood.blockID, 0, 2);
		world.setBlock(i + 6, j + 45, k + 19, mod_LionKing.rafikiWood.blockID, 0, 2);
		world.setBlock(i + 6, j + 45, k + 20, mod_LionKing.rafikiWood.blockID, 0, 2);
		world.setBlock(i + 5, j + 45, k + 20, mod_LionKing.rafikiWood.blockID, 0, 2);
		world.setBlock(i + 7, j + 45, k + 19, mod_LionKing.rafikiWood.blockID, 0, 2);
		world.setBlock(i + 7, j + 45, k + 20, mod_LionKing.rafikiWood.blockID, 0, 2);
		world.setBlock(i + 8, j + 45, k + 19, mod_LionKing.rafikiWood.blockID, 0, 2);
		world.setBlock(i + 4, j + 44, k + 19, mod_LionKing.rafikiWood.blockID, 0, 2);
		world.setBlock(i + 4, j + 43, k + 19, mod_LionKing.rafikiWood.blockID, 0, 2);
		world.setBlock(i + 5, j + 44, k + 19, mod_LionKing.rafikiWood.blockID, 0, 2);
		world.setBlock(i + 5, j + 43, k + 19, mod_LionKing.rafikiWood.blockID, 0, 2);
		world.setBlock(i + 5, j + 44, k + 20, mod_LionKing.rafikiWood.blockID, 0, 2);
		world.setBlock(i + 6, j + 44, k + 19, mod_LionKing.rafikiWood.blockID, 0, 2);
		world.setBlock(i + 6, j + 43, k + 19, mod_LionKing.rafikiWood.blockID, 0, 2);
		world.setBlock(i + 6, j + 44, k + 20, mod_LionKing.rafikiWood.blockID, 0, 2);
		world.setBlock(i + 7, j + 44, k + 19, mod_LionKing.rafikiWood.blockID, 0, 2);
		world.setBlock(i + 3, j + 46, k + 20, mod_LionKing.rafikiWood.blockID, 0, 2);
		world.setBlock(i + 4, j + 46, k + 20, mod_LionKing.rafikiWood.blockID, 0, 2);
		world.setBlock(i + 5, j + 46, k + 20, mod_LionKing.rafikiWood.blockID, 0, 2);
		world.setBlock(i + 6, j + 46, k + 20, mod_LionKing.rafikiWood.blockID, 0, 2);
		world.setBlock(i + 7, j + 46, k + 20, mod_LionKing.rafikiWood.blockID, 0, 2);
		world.setBlock(i + 8, j + 46, k + 19, mod_LionKing.rafikiWood.blockID, 0, 2);
		world.setBlock(i + 7, j + 46, k + 19, mod_LionKing.rafikiWood.blockID, 0, 2);
		world.setBlock(i + 6, j + 46, k + 19, mod_LionKing.rafikiWood.blockID, 0, 2);
		world.setBlock(i + 5, j + 46, k + 19, mod_LionKing.rafikiWood.blockID, 0, 2);
		world.setBlock(i + 4, j + 46, k + 19, mod_LionKing.rafikiWood.blockID, 0, 2);
		world.setBlock(i + 3, j + 46, k + 19, mod_LionKing.rafikiWood.blockID, 0, 2);
		world.setBlock(i + 2, j + 46, k + 19, mod_LionKing.rafikiWood.blockID, 0, 2);
		world.setBlock(i + 8, j + 45, k + 17, mod_LionKing.rafikiWood.blockID, 0, 2);
		world.setBlock(i + 3, j + 45, k + 17, mod_LionKing.rafikiWood.blockID, 0, 2);
		world.setBlock(i + 3, j + 46, k + 18, mod_LionKing.rafikiWood.blockID, 0, 2);
		world.setBlock(i + 8, j + 46, k + 18, mod_LionKing.rafikiWood.blockID, 0, 2);
		world.setBlock(i + 7, j + 46, k + 18, mod_LionKing.rafikiWood.blockID, 0, 2);
		world.setBlock(i + 4, j + 46, k + 18, mod_LionKing.rafikiWood.blockID, 0, 2);
		world.setBlock(i + 2, j + 45, k + 20, mod_LionKing.rafikiWood.blockID, 0, 2);
		world.setBlock(i + 1, j + 46, k + 19, mod_LionKing.rafikiWood.blockID, 0, 2);
		world.setBlock(i + 1, j + 45, k + 20, mod_LionKing.rafikiWood.blockID, 0, 2);
		world.setBlock(i, j + 45, k + 20, mod_LionKing.rafikiWood.blockID, 0, 2);
		world.setBlock(i + 1, j + 45, k + 21, mod_LionKing.rafikiWood.blockID, 0, 2);
		world.setBlock(i, j + 46, k + 20, mod_LionKing.rafikiWood.blockID, 0, 2);
		world.setBlock(i, j + 46, k + 21, mod_LionKing.rafikiWood.blockID, 0, 2);
		world.setBlock(i - 1, j + 46, k + 21, mod_LionKing.rafikiWood.blockID, 0, 2);
		world.setBlock(i - 2, j + 46, k + 21, mod_LionKing.rafikiWood.blockID, 0, 2);
		world.setBlock(i, j + 45, k + 21, mod_LionKing.rafikiWood.blockID, 0, 2);
		world.setBlock(i - 2, j + 46, k + 21, 0, 0, 2);
		world.setBlock(i - 1, j + 46, k + 22, mod_LionKing.rafikiWood.blockID, 0, 2);
		world.setBlock(i - 1, j + 46, k + 22, 0, 0, 2);
		world.setBlock(i, j + 46, k + 22, mod_LionKing.rafikiWood.blockID, 0, 2);
		world.setBlock(i - 1, j + 47, k + 21, mod_LionKing.rafikiWood.blockID, 0, 2);
		world.setBlock(i - 2, j + 47, k + 21, mod_LionKing.rafikiWood.blockID, 0, 2);
		world.setBlock(i - 1, j + 47, k + 21, 0, 0, 2);
		world.setBlock(i, j + 47, k + 22, mod_LionKing.rafikiWood.blockID, 0, 2);
		world.setBlock(i, j + 47, k + 23, mod_LionKing.rafikiWood.blockID, 0, 2);
		world.setBlock(i, j + 47, k + 22, 0, 0, 2);
		world.setBlock(i + 1, j + 46, k + 20, mod_LionKing.rafikiWood.blockID, 0, 2);
		world.setBlock(i, j + 46, k + 23, mod_LionKing.rafikiWood.blockID, 0, 2);
		world.setBlock(i - 2, j + 46, k + 21, mod_LionKing.rafikiWood.blockID, 0, 2);
		world.setBlock(i - 3, j + 47, k + 21, mod_LionKing.rafikiWood.blockID, 0, 2);
		world.setBlock(i - 2, j + 47, k + 22, mod_LionKing.rafikiWood.blockID, 0, 2);
		world.setBlock(i - 1, j + 47, k + 23, mod_LionKing.rafikiWood.blockID, 0, 2);
		world.setBlock(i, j + 47, k + 24, mod_LionKing.rafikiWood.blockID, 0, 2);
		world.setBlock(i + 1, j + 47, k + 23, mod_LionKing.rafikiWood.blockID, 0, 2);
		world.setBlock(i + 1, j + 48, k + 23, mod_LionKing.rafikiWood.blockID, 0, 2);
		world.setBlock(i, j + 46, k + 23, 0, 0, 2);
		world.setBlock(i + 1, j + 47, k + 23, 0, 0, 2);
		world.setBlock(i, j + 46, k + 23, mod_LionKing.rafikiWood.blockID, 0, 2);
		world.setBlock(i - 3, j + 48, k + 21, mod_LionKing.rafikiWood.blockID, 0, 2);
		world.setBlock(i - 3, j + 47, k + 21, 0, 0, 2);
		world.setBlock(i + 1, j + 46, k + 23, mod_LionKing.rafikiWood.blockID, 0, 2);
		world.setBlock(i + 1, j + 46, k + 23, 0, 0, 2);
		world.setBlock(i + 1, j + 47, k + 23, mod_LionKing.rafikiWood.blockID, 0, 2);
		world.setBlock(i, j + 48, k + 23, mod_LionKing.rafikiWood.blockID, 0, 2);
		world.setBlock(i - 3, j + 47, k + 21, mod_LionKing.rafikiWood.blockID, 0, 2);
		world.setBlock(i - 2, j + 48, k + 21, mod_LionKing.rafikiWood.blockID, 0, 2);
		world.setBlock(i - 3, j + 48, k + 22, mod_LionKing.rafikiWood.blockID, 0, 2);
		world.setBlock(i - 4, j + 48, k + 22, mod_LionKing.rafikiWood.blockID, 0, 2);
		world.setBlock(i - 3, j + 48, k + 22, 0, 0, 2);
		world.setBlock(i + 1, j + 47, k + 24, mod_LionKing.rafikiWood.blockID, 0, 2);
		world.setBlock(i + 1, j + 48, k + 24, mod_LionKing.rafikiWood.blockID, 0, 2);
		world.setBlock(i + 1, j + 47, k + 24, 0, 0, 2);
		world.setBlock(i + 2, j + 48, k + 24, mod_LionKing.rafikiWood.blockID, 0, 2);
		world.setBlock(i + 2, j + 48, k + 25, mod_LionKing.rafikiWood.blockID, 0, 2);
		world.setBlock(i + 2, j + 48, k + 25, 0, 0, 2);
		world.setBlock(i + 2, j + 48, k + 25, mod_LionKing.rafikiWood.blockID, 0, 2);
		world.setBlock(i + 3, j + 48, k + 24, mod_LionKing.rafikiWood.blockID, 0, 2);
		world.setBlock(i + 3, j + 48, k + 25, mod_LionKing.rafikiWood.blockID, 0, 2);
		world.setBlock(i + 3, j + 49, k + 25, mod_LionKing.rafikiWood.blockID, 0, 2);
		world.setBlock(i + 2, j + 48, k + 25, 0, 0, 2);
		world.setBlock(i + 3, j + 48, k + 25, 0, 0, 2);
		world.setBlock(i + 3, j + 48, k + 24, 0, 0, 2);
		world.setBlock(i + 3, j + 48, k + 24, mod_LionKing.rafikiWood.blockID, 0, 2);
		world.setBlock(i + 2, j + 48, k + 25, mod_LionKing.rafikiWood.blockID, 0, 2);
		world.setBlock(i, j + 46, k + 23, 0, 0, 2);
		world.setBlock(i - 1, j + 47, k + 23, 0, 0, 2);
		world.setBlock(i, j + 48, k + 23, 0, 0, 2);
		world.setBlock(i, j + 47, k + 24, 0, 0, 2);
		world.setBlock(i + 1, j + 47, k + 23, 0, 0, 2);
		world.setBlock(i + 1, j + 48, k + 24, 0, 0, 2);
		world.setBlock(i + 2, j + 48, k + 24, 0, 0, 2);
		world.setBlock(i + 3, j + 48, k + 24, 0, 0, 2);
		world.setBlock(i + 3, j + 49, k + 25, 0, 0, 2);
		world.setBlock(i + 2, j + 48, k + 25, 0, 0, 2);
		world.setBlock(i - 2, j + 48, k + 21, 0, 0, 2);
		world.setBlock(i - 3, j + 48, k + 21, 0, 0, 2);
		world.setBlock(i - 3, j + 47, k + 21, 0, 0, 2);
		world.setBlock(i - 4, j + 48, k + 22, 0, 0, 2);
		world.setBlock(i - 2, j + 47, k + 22, 0, 0, 2);
		world.setBlock(i - 2, j + 47, k + 21, 0, 0, 2);
		world.setBlock(i - 2, j + 46, k + 21, 0, 0, 2);
		world.setBlock(i, j + 47, k + 23, 0, 0, 2);
		world.setBlock(i + 1, j + 48, k + 23, 0, 0, 2);
		world.setBlock(i - 1, j + 47, k + 21, mod_LionKing.rafikiWood.blockID, 0, 2);
		world.setBlock(i, j + 47, k + 21, mod_LionKing.rafikiWood.blockID, 0, 2);
		world.setBlock(i, j + 47, k + 22, mod_LionKing.rafikiWood.blockID, 0, 2);
		world.setBlock(i + 1, j + 46, k + 21, mod_LionKing.rafikiWood.blockID, 0, 2);
		world.setBlock(i + 1, j + 47, k + 20, mod_LionKing.rafikiWood.blockID, 0, 2);
		world.setBlock(i + 4, j + 46, k + 21, mod_LionKing.rafikiWood.blockID, 0, 2);
		world.setBlock(i + 5, j + 46, k + 21, mod_LionKing.rafikiWood.blockID, 0, 2);
		world.setBlock(i + 6, j + 46, k + 21, mod_LionKing.rafikiWood.blockID, 0, 2);
		world.setBlock(i + 4, j + 47, k + 21, mod_LionKing.rafikiWood.blockID, 0, 2);
		world.setBlock(i + 5, j + 47, k + 21, mod_LionKing.rafikiWood.blockID, 0, 2);
		world.setBlock(i + 6, j + 47, k + 21, mod_LionKing.rafikiWood.blockID, 0, 2);
		world.setBlock(i + 7, j + 47, k + 21, mod_LionKing.rafikiWood.blockID, 0, 2);
		world.setBlock(i + 7, j + 47, k + 22, mod_LionKing.rafikiWood.blockID, 0, 2);
		world.setBlock(i + 8, j + 47, k + 22, mod_LionKing.rafikiWood.blockID, 0, 2);
		world.setBlock(i + 9, j + 47, k + 22, mod_LionKing.rafikiWood.blockID, 0, 2);
		world.setBlock(i + 8, j + 47, k + 21, mod_LionKing.rafikiWood.blockID, 0, 2);
		world.setBlock(i + 7, j + 46, k + 21, mod_LionKing.rafikiWood.blockID, 0, 2);
		world.setBlock(i + 9, j + 48, k + 22, mod_LionKing.rafikiWood.blockID, 0, 2);
		world.setBlock(i + 8, j + 48, k + 22, mod_LionKing.rafikiWood.blockID, 0, 2);
		world.setBlock(i + 8, j + 48, k + 23, mod_LionKing.rafikiWood.blockID, 0, 2);
		world.setBlock(i + 9, j + 48, k + 23, mod_LionKing.rafikiWood.blockID, 0, 2);
		world.setBlock(i + 10, j + 48, k + 22, mod_LionKing.rafikiWood.blockID, 0, 2);
		world.setBlock(i + 9, j + 47, k + 21, mod_LionKing.rafikiWood.blockID, 0, 2);
		world.setBlock(i + 8, j + 47, k + 20, mod_LionKing.rafikiWood.blockID, 0, 2);
		world.setBlock(i + 7, j + 47, k + 20, mod_LionKing.rafikiWood.blockID, 0, 2);
		world.setBlock(i + 8, j + 48, k + 21, mod_LionKing.rafikiWood.blockID, 0, 2);
		world.setBlock(i + 7, j + 48, k + 22, mod_LionKing.rafikiWood.blockID, 0, 2);
		world.setBlock(i + 9, j + 49, k + 23, mod_LionKing.rafikiWood.blockID, 0, 2);
		world.setBlock(i + 8, j + 49, k + 23, mod_LionKing.rafikiWood.blockID, 0, 2);
		world.setBlock(i + 8, j + 49, k + 24, mod_LionKing.rafikiWood.blockID, 0, 2);
		world.setBlock(i + 9, j + 49, k + 24, mod_LionKing.rafikiWood.blockID, 0, 2);
		world.setBlock(i + 10, j + 49, k + 23, mod_LionKing.rafikiWood.blockID, 0, 2);
		world.setBlock(i + 10, j + 49, k + 24, mod_LionKing.rafikiWood.blockID, 0, 2);
		world.setBlock(i + 9, j + 49, k + 25, mod_LionKing.rafikiWood.blockID, 0, 2);
		world.setBlock(i + 10, j + 49, k + 25, mod_LionKing.rafikiWood.blockID, 0, 2);
		world.setBlock(i + 10, j + 50, k + 25, mod_LionKing.rafikiWood.blockID, 0, 2);
		world.setBlock(i + 11, j + 49, k + 24, mod_LionKing.rafikiWood.blockID, 0, 2);
		world.setBlock(i + 11, j + 50, k + 24, mod_LionKing.rafikiWood.blockID, 0, 2);
		world.setBlock(i + 10, j + 50, k + 24, mod_LionKing.rafikiWood.blockID, 0, 2);
		world.setBlock(i + 9, j + 50, k + 24, mod_LionKing.rafikiWood.blockID, 0, 2);
		world.setBlock(i + 9, j + 50, k + 23, mod_LionKing.rafikiWood.blockID, 0, 2);
		world.setBlock(i + 9, j + 49, k + 22, mod_LionKing.rafikiWood.blockID, 0, 2);
		world.setBlock(i + 11, j + 49, k + 24, 0, 0, 2);
		world.setBlock(i + 10, j + 49, k + 25, 0, 0, 2);
		world.setBlock(i - 10, j + 48, k + 17, mod_LionKing.rafikiLeaves.blockID, 0, 2);
		world.setBlock(i - 9, j + 48, k + 17, mod_LionKing.rafikiLeaves.blockID, 0, 2);
		world.setBlock(i - 9, j + 48, k + 18, mod_LionKing.rafikiLeaves.blockID, 0, 2);
		world.setBlock(i - 8, j + 47, k + 16, mod_LionKing.rafikiLeaves.blockID, 0, 2);
		world.setBlock(i - 8, j + 47, k + 17, mod_LionKing.rafikiLeaves.blockID, 0, 2);
		world.setBlock(i - 8, j + 47, k + 18, mod_LionKing.rafikiLeaves.blockID, 0, 2);
		world.setBlock(i - 8, j + 47, k + 19, mod_LionKing.rafikiLeaves.blockID, 0, 2);
		world.setBlock(i - 8, j + 47, k + 20, mod_LionKing.rafikiLeaves.blockID, 0, 2);
		world.setBlock(i - 9, j + 47, k + 17, mod_LionKing.rafikiLeaves.blockID, 0, 2);
		world.setBlock(i - 9, j + 47, k + 18, mod_LionKing.rafikiLeaves.blockID, 0, 2);
		world.setBlock(i - 10, j + 47, k + 17, mod_LionKing.rafikiLeaves.blockID, 0, 2);
		world.setBlock(i - 11, j + 47, k + 17, mod_LionKing.rafikiLeaves.blockID, 0, 2);
		world.setBlock(i - 11, j + 47, k + 16, mod_LionKing.rafikiLeaves.blockID, 0, 2);
		world.setBlock(i - 11, j + 47, k + 15, mod_LionKing.rafikiLeaves.blockID, 0, 2);
		world.setBlock(i - 12, j + 47, k + 15, mod_LionKing.rafikiLeaves.blockID, 0, 2);
		world.setBlock(i - 12, j + 47, k + 14, mod_LionKing.rafikiLeaves.blockID, 0, 2);
		world.setBlock(i - 13, j + 47, k + 14, mod_LionKing.rafikiLeaves.blockID, 0, 2);
		world.setBlock(i - 10, j + 47, k + 14, mod_LionKing.rafikiLeaves.blockID, 0, 2);
		world.setBlock(i - 10, j + 47, k + 13, mod_LionKing.rafikiLeaves.blockID, 0, 2);
		world.setBlock(i - 11, j + 47, k + 14, mod_LionKing.rafikiLeaves.blockID, 0, 2);
		world.setBlock(i - 11, j + 47, k + 13, mod_LionKing.rafikiLeaves.blockID, 0, 2);
		world.setBlock(i - 11, j + 47, k + 12, mod_LionKing.rafikiLeaves.blockID, 0, 2);
		world.setBlock(i - 11, j + 46, k + 12, mod_LionKing.rafikiLeaves.blockID, 0, 2);
		world.setBlock(i - 11, j + 46, k + 11, mod_LionKing.rafikiLeaves.blockID, 0, 2);
		world.setBlock(i - 12, j + 46, k + 11, mod_LionKing.rafikiLeaves.blockID, 0, 2);
		world.setBlock(i - 12, j + 46, k + 13, mod_LionKing.rafikiLeaves.blockID, 0, 2);
		world.setBlock(i - 13, j + 46, k + 13, mod_LionKing.rafikiLeaves.blockID, 0, 2);
		world.setBlock(i - 13, j + 46, k + 12, mod_LionKing.rafikiLeaves.blockID, 0, 2);
		world.setBlock(i - 12, j + 46, k + 14, mod_LionKing.rafikiLeaves.blockID, 0, 2);
		world.setBlock(i - 12, j + 46, k + 15, mod_LionKing.rafikiLeaves.blockID, 0, 2);
		world.setBlock(i - 11, j + 46, k + 15, mod_LionKing.rafikiLeaves.blockID, 0, 2);
		world.setBlock(i - 11, j + 46, k + 16, mod_LionKing.rafikiLeaves.blockID, 0, 2);
		world.setBlock(i - 10, j + 46, k + 16, mod_LionKing.rafikiLeaves.blockID, 0, 2);
		world.setBlock(i - 9, j + 46, k + 17, mod_LionKing.rafikiLeaves.blockID, 0, 2);
		world.setBlock(i - 8, j + 46, k + 18, mod_LionKing.rafikiLeaves.blockID, 0, 2);
		world.setBlock(i - 7, j + 46, k + 18, mod_LionKing.rafikiLeaves.blockID, 0, 2);
		world.setBlock(i - 7, j + 46, k + 17, mod_LionKing.rafikiLeaves.blockID, 0, 2);
		world.setBlock(i - 7, j + 46, k + 16, mod_LionKing.rafikiLeaves.blockID, 0, 2);
		world.setBlock(i - 7, j + 46, k + 15, mod_LionKing.rafikiLeaves.blockID, 0, 2);
		world.setBlock(i - 8, j + 46, k + 14, mod_LionKing.rafikiLeaves.blockID, 0, 2);
		world.setBlock(i - 9, j + 46, k + 13, mod_LionKing.rafikiLeaves.blockID, 0, 2);
		world.setBlock(i - 10, j + 46, k + 13, mod_LionKing.rafikiLeaves.blockID, 0, 2);
		world.setBlock(i - 10, j + 46, k + 12, mod_LionKing.rafikiLeaves.blockID, 0, 2);
		world.setBlock(i - 8, j + 47, k + 15, 0, 0, 2);
		world.setBlock(i - 8, j + 47, k + 15, mod_LionKing.rafikiLeaves.blockID, 0, 2);
		world.setBlock(i - 9, j + 47, k + 14, 0, 0, 2);
		world.setBlock(i - 9, j + 47, k + 14, mod_LionKing.rafikiLeaves.blockID, 0, 2);
		world.setBlock(i - 6, j + 46, k + 17, mod_LionKing.rafikiLeaves.blockID, 0, 2);
		world.setBlock(i - 6, j + 46, k + 16, mod_LionKing.rafikiLeaves.blockID, 0, 2);
		world.setBlock(i - 6, j + 46, k + 15, mod_LionKing.rafikiLeaves.blockID, 0, 2);
		world.setBlock(i - 7, j + 47, k + 16, mod_LionKing.rafikiLeaves.blockID, 0, 2);
		world.setBlock(i - 6, j + 47, k + 15, mod_LionKing.rafikiLeaves.blockID, 0, 2);
		world.setBlock(i - 7, j + 46, k + 14, mod_LionKing.rafikiLeaves.blockID, 0, 2);
		world.setBlock(i - 6, j + 47, k + 15, 0, 0, 2);
		world.setBlock(i - 9, j + 46, k + 12, mod_LionKing.rafikiLeaves.blockID, 0, 2);
		world.setBlock(i - 10, j + 46, k + 11, mod_LionKing.rafikiLeaves.blockID, 0, 2);
		world.setBlock(i - 12, j + 47, k + 13, mod_LionKing.rafikiWood.blockID, 0, 2);
		world.setBlock(i - 12, j + 47, k + 12, mod_LionKing.rafikiWood.blockID, 0, 2);
		world.setBlock(i - 12, j + 47, k + 11, mod_LionKing.rafikiLeaves.blockID, 0, 2);
		world.setBlock(i - 12, j + 47, k + 10, mod_LionKing.rafikiLeaves.blockID, 0, 2);
		world.setBlock(i - 13, j + 47, k + 13, mod_LionKing.rafikiLeaves.blockID, 0, 2);
		world.setBlock(i - 13, j + 47, k + 11, mod_LionKing.rafikiLeaves.blockID, 0, 2);
		world.setBlock(i - 13, j + 47, k + 12, mod_LionKing.rafikiLeaves.blockID, 0, 2);
		world.setBlock(i - 14, j + 47, k + 12, mod_LionKing.rafikiLeaves.blockID, 0, 2);
		world.setBlock(i - 14, j + 47, k + 13, mod_LionKing.rafikiLeaves.blockID, 0, 2);
		world.setBlock(i - 11, j + 48, k + 14, mod_LionKing.rafikiLeaves.blockID, 0, 2);
		world.setBlock(i - 11, j + 48, k + 13, mod_LionKing.rafikiLeaves.blockID, 0, 2);
		world.setBlock(i - 12, j + 48, k + 13, mod_LionKing.rafikiLeaves.blockID, 0, 2);
		world.setBlock(i - 12, j + 48, k + 12, mod_LionKing.rafikiLeaves.blockID, 0, 2);
		world.setBlock(i - 13, j + 48, k + 12, mod_LionKing.rafikiLeaves.blockID, 0, 2);
		world.setBlock(i - 13, j + 48, k + 13, mod_LionKing.rafikiLeaves.blockID, 0, 2);
		world.setBlock(i - 12, j + 48, k + 14, mod_LionKing.rafikiLeaves.blockID, 0, 2);
		world.setBlock(i - 11, j + 48, k + 15, mod_LionKing.rafikiLeaves.blockID, 0, 2);
		world.setBlock(i - 10, j + 48, k + 18, mod_LionKing.rafikiLeaves.blockID, 0, 2);
		world.setBlock(i - 8, j + 48, k + 16, mod_LionKing.rafikiLeaves.blockID, 0, 2);
		world.setBlock(i - 8, j + 48, k + 17, mod_LionKing.rafikiLeaves.blockID, 0, 2);
		world.setBlock(i - 7, j + 48, k + 16, mod_LionKing.rafikiLeaves.blockID, 0, 2);
		world.setBlock(i - 8, j + 47, k + 20, 0, 0, 2);
		world.setBlock(i - 7, j + 47, k + 19, mod_LionKing.rafikiLeaves.blockID, 0, 2);
		world.setBlock(i - 10, j + 51, k + 16, mod_LionKing.rafikiWood.blockID, 0, 2);
		world.setBlock(i - 11, j + 51, k + 16, mod_LionKing.rafikiWood.blockID, 0, 2);
		world.setBlock(i - 10, j + 51, k + 17, mod_LionKing.rafikiWood.blockID, 0, 2);
		world.setBlock(i - 11, j + 52, k + 16, mod_LionKing.rafikiWood.blockID, 0, 2);
		world.setBlock(i - 10, j + 52, k + 17, mod_LionKing.rafikiWood.blockID, 0, 2);
		world.setBlock(i - 11, j + 53, k + 16, mod_LionKing.rafikiWood.blockID, 0, 2);
		world.setBlock(i - 11, j + 53, k + 17, mod_LionKing.rafikiWood.blockID, 0, 2);
		world.setBlock(i - 11, j + 53, k + 17, 0, 0, 2);
		world.setBlock(i - 10, j + 53, k + 17, mod_LionKing.rafikiWood.blockID, 0, 2);
		world.setBlock(i - 12, j + 53, k + 16, mod_LionKing.rafikiLeaves.blockID, 0, 2);
		world.setBlock(i - 11, j + 53, k + 15, mod_LionKing.rafikiLeaves.blockID, 0, 2);
		world.setBlock(i - 11, j + 53, k + 14, mod_LionKing.rafikiLeaves.blockID, 0, 2);
		world.setBlock(i - 10, j + 53, k + 16, mod_LionKing.rafikiLeaves.blockID, 0, 2);
		world.setBlock(i - 9, j + 53, k + 16, mod_LionKing.rafikiLeaves.blockID, 0, 2);
		world.setBlock(i - 10, j + 53, k + 15, mod_LionKing.rafikiLeaves.blockID, 0, 2);
		world.setBlock(i - 9, j + 53, k + 17, mod_LionKing.rafikiLeaves.blockID, 0, 2);
		world.setBlock(i - 9, j + 53, k + 18, mod_LionKing.rafikiLeaves.blockID, 0, 2);
		world.setBlock(i - 10, j + 53, k + 18, mod_LionKing.rafikiLeaves.blockID, 0, 2);
		world.setBlock(i - 12, j + 53, k + 17, mod_LionKing.rafikiLeaves.blockID, 0, 2);
		world.setBlock(i - 11, j + 53, k + 17, mod_LionKing.rafikiLeaves.blockID, 0, 2);
		world.setBlock(i - 11, j + 53, k + 18, mod_LionKing.rafikiLeaves.blockID, 0, 2);
		world.setBlock(i - 13, j + 53, k + 16, mod_LionKing.rafikiLeaves.blockID, 0, 2);
		world.setBlock(i - 12, j + 53, k + 15, mod_LionKing.rafikiLeaves.blockID, 0, 2);
		world.setBlock(i - 11, j + 54, k + 15, mod_LionKing.rafikiLeaves.blockID, 0, 2);
		world.setBlock(i - 12, j + 54, k + 15, mod_LionKing.rafikiLeaves.blockID, 0, 2);
		world.setBlock(i - 12, j + 54, k + 16, mod_LionKing.rafikiLeaves.blockID, 0, 2);
		world.setBlock(i - 10, j + 54, k + 16, mod_LionKing.rafikiLeaves.blockID, 0, 2);
		world.setBlock(i - 11, j + 54, k + 16, mod_LionKing.rafikiLeaves.blockID, 0, 2);
		world.setBlock(i - 10, j + 54, k + 17, mod_LionKing.rafikiLeaves.blockID, 0, 2);
		world.setBlock(i - 10, j + 54, k + 18, mod_LionKing.rafikiLeaves.blockID, 0, 2);
		world.setBlock(i - 11, j + 54, k + 17, mod_LionKing.rafikiLeaves.blockID, 0, 2);
		world.setBlock(i - 9, j + 54, k + 17, mod_LionKing.rafikiLeaves.blockID, 0, 2);
		world.setBlock(i - 9, j + 54, k + 18, mod_LionKing.rafikiLeaves.blockID, 0, 2);
		world.setBlock(i - 9, j + 53, k + 19, mod_LionKing.rafikiLeaves.blockID, 0, 2);
		world.setBlock(i - 8, j + 53, k + 18, mod_LionKing.rafikiLeaves.blockID, 0, 2);
		world.setBlock(i - 9, j + 54, k + 19, mod_LionKing.rafikiLeaves.blockID, 0, 2);
		world.setBlock(i - 10, j + 53, k + 19, mod_LionKing.rafikiLeaves.blockID, 0, 2);
		world.setBlock(i - 8, j + 53, k + 19, mod_LionKing.rafikiLeaves.blockID, 0, 2);
		world.setBlock(i - 9, j + 53, k + 20, mod_LionKing.rafikiLeaves.blockID, 0, 2);
		world.setBlock(i - 8, j + 54, k + 17, mod_LionKing.rafikiLeaves.blockID, 0, 2);
		world.setBlock(i - 8, j + 54, k + 17, 0, 0, 2);
		world.setBlock(i - 8, j + 53, k + 17, mod_LionKing.rafikiLeaves.blockID, 0, 2);
		world.setBlock(i - 7, j + 53, k + 18, mod_LionKing.rafikiLeaves.blockID, 0, 2);
		world.setBlock(i - 7, j + 53, k + 17, mod_LionKing.rafikiLeaves.blockID, 0, 2);
		world.setBlock(i - 8, j + 53, k + 16, mod_LionKing.rafikiLeaves.blockID, 0, 2);
		world.setBlock(i - 8, j + 54, k + 18, mod_LionKing.rafikiLeaves.blockID, 0, 2);
		world.setBlock(i - 8, j + 54, k + 17, mod_LionKing.rafikiLeaves.blockID, 0, 2);
		world.setBlock(i - 9, j + 54, k + 16, mod_LionKing.rafikiLeaves.blockID, 0, 2);
		world.setBlock(i - 9, j + 53, k + 15, mod_LionKing.rafikiLeaves.blockID, 0, 2);
		world.setBlock(i + 1, j + 45, k + 22, mod_LionKing.rafikiLeaves.blockID, 0, 2);
		world.setBlock(i + 1, j + 45, k + 22, 0, 0, 2);
		world.setBlock(i + 1, j + 46, k + 22, mod_LionKing.rafikiLeaves.blockID, 0, 2);
		world.setBlock(i + 1, j + 46, k + 23, mod_LionKing.rafikiLeaves.blockID, 0, 2);
		world.setBlock(i + 1, j + 46, k + 24, mod_LionKing.rafikiLeaves.blockID, 0, 2);
		world.setBlock(i + 1, j + 46, k + 25, mod_LionKing.rafikiLeaves.blockID, 0, 2);
		world.setBlock(i, j + 46, k + 23, mod_LionKing.rafikiLeaves.blockID, 0, 2);
		world.setBlock(i, j + 46, k + 24, mod_LionKing.rafikiLeaves.blockID, 0, 2);
		world.setBlock(i, j + 46, k + 25, mod_LionKing.rafikiLeaves.blockID, 0, 2);
		world.setBlock(i - 1, j + 46, k + 23, mod_LionKing.rafikiLeaves.blockID, 0, 2);
		world.setBlock(i - 2, j + 46, k + 23, mod_LionKing.rafikiLeaves.blockID, 0, 2);
		world.setBlock(i - 1, j + 46, k + 22, mod_LionKing.rafikiLeaves.blockID, 0, 2);
		world.setBlock(i - 2, j + 46, k + 22, mod_LionKing.rafikiLeaves.blockID, 0, 2);
		world.setBlock(i - 3, j + 46, k + 22, mod_LionKing.rafikiLeaves.blockID, 0, 2);
		world.setBlock(i - 3, j + 46, k + 21, mod_LionKing.rafikiLeaves.blockID, 0, 2);
		world.setBlock(i - 2, j + 46, k + 21, mod_LionKing.rafikiLeaves.blockID, 0, 2);
		world.setBlock(i - 2, j + 46, k + 20, mod_LionKing.rafikiLeaves.blockID, 0, 2);
		world.setBlock(i - 1, j + 46, k + 20, mod_LionKing.rafikiLeaves.blockID, 0, 2);
		world.setBlock(i - 1, j + 46, k + 19, mod_LionKing.rafikiLeaves.blockID, 0, 2);
		world.setBlock(i, j + 46, k + 19, mod_LionKing.rafikiLeaves.blockID, 0, 2);
		world.setBlock(i, j + 46, k + 18, mod_LionKing.rafikiLeaves.blockID, 0, 2);
		world.setBlock(i + 2, j + 46, k + 18, mod_LionKing.rafikiLeaves.blockID, 0, 2);
		world.setBlock(i + 1, j + 46, k + 18, mod_LionKing.rafikiLeaves.blockID, 0, 2);
		world.setBlock(i + 1, j + 45, k + 19, mod_LionKing.rafikiLeaves.blockID, 0, 2);
		world.setBlock(i + 1, j + 45, k + 18, mod_LionKing.rafikiLeaves.blockID, 0, 2);
		world.setBlock(i, j + 45, k + 19, mod_LionKing.rafikiLeaves.blockID, 0, 2);
		world.setBlock(i + 1, j + 45, k + 22, mod_LionKing.rafikiLeaves.blockID, 0, 2);
		world.setBlock(i, j + 45, k + 22, mod_LionKing.rafikiLeaves.blockID, 0, 2);
		world.setBlock(i - 1, j + 45, k + 21, mod_LionKing.rafikiLeaves.blockID, 0, 2);
		world.setBlock(i - 1, j + 45, k + 22, mod_LionKing.rafikiLeaves.blockID, 0, 2);
		world.setBlock(i - 1, j + 45, k + 20, mod_LionKing.rafikiLeaves.blockID, 0, 2);
		world.setBlock(i - 2, j + 45, k + 21, mod_LionKing.rafikiLeaves.blockID, 0, 2);
		world.setBlock(i - 2, j + 45, k + 22, mod_LionKing.rafikiLeaves.blockID, 0, 2);
		world.setBlock(i - 1, j + 45, k + 23, mod_LionKing.rafikiLeaves.blockID, 0, 2);
		world.setBlock(i, j + 45, k + 23, mod_LionKing.rafikiLeaves.blockID, 0, 2);
		world.setBlock(i, j + 44, k + 21, mod_LionKing.rafikiLeaves.blockID, 0, 2);
		world.setBlock(i, j + 44, k + 19, mod_LionKing.rafikiLeaves.blockID, 0, 2);
		world.setBlock(i + 1, j + 44, k + 20, mod_LionKing.rafikiLeaves.blockID, 0, 2);
		world.setBlock(i, j + 44, k + 20, mod_LionKing.rafikiLeaves.blockID, 0, 2);
		world.setBlock(i + 1, j + 44, k + 21, mod_LionKing.rafikiLeaves.blockID, 0, 2);
		world.setBlock(i + 1, j + 44, k + 19, mod_LionKing.rafikiLeaves.blockID, 0, 2);
		world.setBlock(i - 1, j + 44, k + 21, mod_LionKing.rafikiLeaves.blockID, 0, 2);
		world.setBlock(i - 1, j + 43, k + 21, mod_LionKing.rafikiLeaves.blockID, 0, 2);
		world.setBlock(i - 1, j + 43, k + 21, 0, 0, 2);
		world.setBlock(i - 1, j + 44, k + 21, 0, 0, 2);
		world.setBlock(i - 1, j + 44, k + 22, mod_LionKing.rafikiLeaves.blockID, 0, 2);
		world.setBlock(i - 1, j + 46, k + 24, mod_LionKing.rafikiLeaves.blockID, 0, 2);
		world.setBlock(i - 3, j + 46, k + 23, mod_LionKing.rafikiLeaves.blockID, 0, 2);
		world.setBlock(i - 3, j + 47, k + 23, mod_LionKing.rafikiLeaves.blockID, 0, 2);
		world.setBlock(i - 2, j + 46, k + 24, mod_LionKing.rafikiLeaves.blockID, 0, 2);
		world.setBlock(i - 3, j + 47, k + 23, 0, 0, 2);
		world.setBlock(i - 1, j + 47, k + 22, mod_LionKing.rafikiLeaves.blockID, 0, 2);
		world.setBlock(i - 1, j + 47, k + 23, mod_LionKing.rafikiLeaves.blockID, 0, 2);
		world.setBlock(i - 2, j + 47, k + 21, mod_LionKing.rafikiLeaves.blockID, 0, 2);
		world.setBlock(i - 2, j + 47, k + 22, mod_LionKing.rafikiLeaves.blockID, 0, 2);
		world.setBlock(i, j + 47, k + 23, mod_LionKing.rafikiLeaves.blockID, 0, 2);
		world.setBlock(i + 1, j + 47, k + 22, mod_LionKing.rafikiLeaves.blockID, 0, 2);
		world.setBlock(i + 1, j + 47, k + 21, mod_LionKing.rafikiLeaves.blockID, 0, 2);
		world.setBlock(i, j + 47, k + 22, 0, 0, 2);
		world.setBlock(i, j + 47, k + 22, mod_LionKing.rafikiLeaves.blockID, 0, 2);
		world.setBlock(i, j + 47, k + 21, 0, 0, 2);
		world.setBlock(i, j + 47, k + 21, mod_LionKing.rafikiLeaves.blockID, 0, 2);
		world.setBlock(i - 1, j + 47, k + 21, 0, 0, 2);
		world.setBlock(i - 1, j + 47, k + 21, mod_LionKing.rafikiLeaves.blockID, 0, 2);
		world.setBlock(i, j + 47, k + 20, mod_LionKing.rafikiLeaves.blockID, 0, 2);
		world.setBlock(i + 2, j + 46, k + 20, mod_LionKing.rafikiLeaves.blockID, 0, 2);
		world.setBlock(i + 2, j + 46, k + 21, mod_LionKing.rafikiLeaves.blockID, 0, 2);
		world.setBlock(i + 2, j + 46, k + 22, mod_LionKing.rafikiLeaves.blockID, 0, 2);
		world.setBlock(i + 2, j + 46, k + 23, mod_LionKing.rafikiLeaves.blockID, 0, 2);
		world.setBlock(i + 2, j + 46, k + 24, mod_LionKing.rafikiLeaves.blockID, 0, 2);
		world.setBlock(i + 3, j + 46, k + 21, mod_LionKing.rafikiLeaves.blockID, 0, 2);
		world.setBlock(i + 3, j + 46, k + 22, mod_LionKing.rafikiLeaves.blockID, 0, 2);
		world.setBlock(i + 3, j + 46, k + 23, mod_LionKing.rafikiLeaves.blockID, 0, 2);
		world.setBlock(i + 4, j + 46, k + 22, mod_LionKing.rafikiLeaves.blockID, 0, 2);
		world.setBlock(i + 5, j + 46, k + 22, mod_LionKing.rafikiLeaves.blockID, 0, 2);
		world.setBlock(i + 3, j + 47, k + 21, mod_LionKing.rafikiLeaves.blockID, 0, 2);
		world.setBlock(i + 5, j + 47, k + 22, mod_LionKing.rafikiLeaves.blockID, 0, 2);
		world.setBlock(i + 6, j + 47, k + 22, mod_LionKing.rafikiLeaves.blockID, 0, 2);
		world.setBlock(i - 8, j + 45, k + 16, mod_LionKing.rafikiLeaves.blockID, 0, 2);
		world.setBlock(i - 9, j + 45, k + 16, mod_LionKing.rafikiLeaves.blockID, 0, 2);
		world.setBlock(i - 8, j + 45, k + 17, mod_LionKing.rafikiLeaves.blockID, 0, 2);
		world.setBlock(i - 10, j + 45, k + 13, mod_LionKing.rafikiLeaves.blockID, 0, 2);
		world.setBlock(i - 9, j + 45, k + 13, mod_LionKing.rafikiLeaves.blockID, 0, 2);
		world.setBlock(i - 9, j + 44, k + 13, mod_LionKing.rafikiLeaves.blockID, 0, 2);
		world.setBlock(i + 10, j + 51, k + 25, mod_LionKing.rafikiWood.blockID, 0, 2);
		world.setBlock(i + 10, j + 51, k + 24, mod_LionKing.rafikiWood.blockID, 0, 2);
		world.setBlock(i + 11, j + 51, k + 24, mod_LionKing.rafikiWood.blockID, 0, 2);
		world.setBlock(i + 10, j + 52, k + 25, mod_LionKing.rafikiWood.blockID, 0, 2);
		world.setBlock(i + 10, j + 52, k + 24, mod_LionKing.rafikiWood.blockID, 0, 2);
		world.setBlock(i + 11, j + 52, k + 24, mod_LionKing.rafikiWood.blockID, 0, 2);
		world.setBlock(i + 11, j + 52, k + 25, mod_LionKing.rafikiWood.blockID, 0, 2);
		world.setBlock(i + 10, j + 53, k + 25, mod_LionKing.rafikiWood.blockID, 0, 2);
		world.setBlock(i + 11, j + 53, k + 25, mod_LionKing.rafikiWood.blockID, 0, 2);
		world.setBlock(i + 11, j + 53, k + 24, mod_LionKing.rafikiWood.blockID, 0, 2);
		world.setBlock(i + 10, j + 53, k + 26, mod_LionKing.rafikiWood.blockID, 0, 2);
		world.setBlock(i + 11, j + 53, k + 26, mod_LionKing.rafikiWood.blockID, 0, 2);
		world.setBlock(i + 12, j + 53, k + 25, mod_LionKing.rafikiWood.blockID, 0, 2);
		world.setBlock(i + 11, j + 54, k + 26, mod_LionKing.rafikiWood.blockID, 0, 2);
		world.setBlock(i + 12, j + 54, k + 25, mod_LionKing.rafikiWood.blockID, 0, 2);
		world.setBlock(i + 12, j + 54, k + 26, mod_LionKing.rafikiWood.blockID, 0, 2);
		world.setBlock(i + 11, j + 55, k + 26, mod_LionKing.rafikiWood.blockID, 0, 2);
		world.setBlock(i + 12, j + 55, k + 26, mod_LionKing.rafikiWood.blockID, 0, 2);
		world.setBlock(i + 12, j + 55, k + 25, mod_LionKing.rafikiWood.blockID, 0, 2);
		world.setBlock(i + 11, j + 56, k + 26, mod_LionKing.rafikiWood.blockID, 0, 2);
		world.setBlock(i + 12, j + 56, k + 26, mod_LionKing.rafikiWood.blockID, 0, 2);
		world.setBlock(i + 12, j + 56, k + 25, mod_LionKing.rafikiWood.blockID, 0, 2);
		world.setBlock(i + 10, j + 50, k + 23, mod_LionKing.rafikiWood.blockID, 0, 2);
		world.setBlock(i + 11, j + 54, k + 25, mod_LionKing.rafikiWood.blockID, 0, 2);
		world.setBlock(i + 11, j + 54, k + 27, mod_LionKing.rafikiWood.blockID, 0, 2);
		world.setBlock(i + 10, j + 54, k + 26, mod_LionKing.rafikiWood.blockID, 0, 2);
		world.setBlock(i + 11, j + 54, k + 27, 0, 0, 2);
		world.setBlock(i + 13, j + 54, k + 25, mod_LionKing.rafikiWood.blockID, 0, 2);
		world.setBlock(i + 13, j + 55, k + 25, mod_LionKing.rafikiWood.blockID, 0, 2);
		world.setBlock(i + 10, j + 48, k + 23, mod_LionKing.rafikiWood.blockID, 0, 2);
		world.setBlock(i + 8, j + 48, k + 24, mod_LionKing.rafikiWood.blockID, 0, 2);
		world.setBlock(i + 9, j + 48, k + 24, mod_LionKing.rafikiWood.blockID, 0, 2);
		world.setBlock(i + 9, j + 47, k + 23, mod_LionKing.rafikiWood.blockID, 0, 2);
		world.setBlock(i + 8, j + 46, k + 20, mod_LionKing.rafikiWood.blockID, 0, 2);
		world.setBlock(i + 8, j + 46, k + 21, mod_LionKing.rafikiWood.blockID, 0, 2);
		world.setBlock(i + 8, j + 45, k + 20, mod_LionKing.rafikiWood.blockID, 0, 2);
		world.setBlock(i + 7, j + 44, k + 20, mod_LionKing.rafikiWood.blockID, 0, 2);
		world.setBlock(i + 7, j + 43, k + 19, mod_LionKing.rafikiWood.blockID, 0, 2);
		world.setBlock(i + 7, j + 42, k + 19, mod_LionKing.rafikiWood.blockID, 0, 2);
		world.setBlock(i + 7, j + 41, k + 18, mod_LionKing.rafikiWood.blockID, 0, 2);
		world.setBlock(i + 6, j + 41, k + 18, mod_LionKing.rafikiWood.blockID, 0, 2);
		world.setBlock(i + 6, j + 40, k + 18, mod_LionKing.rafikiWood.blockID, 0, 2);
		world.setBlock(i + 7, j + 40, k + 17, mod_LionKing.rafikiWood.blockID, 0, 2);
		world.setBlock(i + 7, j + 39, k + 17, mod_LionKing.rafikiWood.blockID, 0, 2);
		world.setBlock(i + 8, j + 44, k + 19, mod_LionKing.rafikiWood.blockID, 0, 2);
		world.setBlock(i + 8, j + 43, k + 19, mod_LionKing.rafikiWood.blockID, 0, 2);
		world.setBlock(i + 8, j + 44, k + 20, mod_LionKing.rafikiWood.blockID, 0, 2);
		world.setBlock(i + 7, j + 45, k + 21, mod_LionKing.rafikiWood.blockID, 0, 2);
		world.setBlock(i + 7, j + 44, k + 21, mod_LionKing.rafikiWood.blockID, 0, 2);
		world.setBlock(i + 8, j + 45, k + 21, mod_LionKing.rafikiWood.blockID, 0, 2);
		world.setBlock(i + 8, j + 44, k + 21, mod_LionKing.rafikiWood.blockID, 0, 2);
		world.setBlock(i + 7, j + 43, k + 20, mod_LionKing.rafikiWood.blockID, 0, 2);
		world.setBlock(i + 6, j + 45, k + 21, mod_LionKing.rafikiWood.blockID, 0, 2);
		world.setBlock(i + 6, j + 43, k + 20, mod_LionKing.rafikiWood.blockID, 0, 2);
		world.setBlock(i + 6, j + 42, k + 19, mod_LionKing.rafikiWood.blockID, 0, 2);
		world.setBlock(i + 5, j + 41, k + 18, mod_LionKing.rafikiWood.blockID, 0, 2);
		world.setBlock(i + 7, j + 40, k + 18, mod_LionKing.rafikiWood.blockID, 0, 2);
		world.setBlock(i + 8, j + 41, k + 17, mod_LionKing.rafikiWood.blockID, 0, 2);
		world.setBlock(i + 8, j + 42, k + 18, mod_LionKing.rafikiWood.blockID, 0, 2);
		world.setBlock(i + 9, j + 43, k + 18, mod_LionKing.rafikiWood.blockID, 0, 2);
		world.setBlock(i + 9, j + 42, k + 17, mod_LionKing.rafikiWood.blockID, 0, 2);
		world.setBlock(i + 9, j + 41, k + 15, mod_LionKing.rafikiWood.blockID, 0, 2);
		world.setBlock(i + 9, j + 41, k + 16, mod_LionKing.rafikiWood.blockID, 0, 2);
		world.setBlock(i + 9, j + 43, k + 17, mod_LionKing.rafikiWood.blockID, 0, 2);
		world.setBlock(i + 9, j + 42, k + 16, mod_LionKing.rafikiWood.blockID, 0, 2);
		world.setBlock(i + 9, j + 46, k + 20, mod_LionKing.rafikiWood.blockID, 0, 2);
		world.setBlock(i + 9, j + 45, k + 19, mod_LionKing.rafikiWood.blockID, 0, 2);
		world.setBlock(i + 9, j + 51, k + 24, mod_LionKing.rafikiWood.blockID, 0, 2);
		world.setBlock(i + 9, j + 50, k + 25, mod_LionKing.rafikiWood.blockID, 0, 2);
		world.setBlock(i + 9, j + 51, k + 25, mod_LionKing.rafikiWood.blockID, 0, 2);
		world.setBlock(i + 9, j + 52, k + 25, mod_LionKing.rafikiWood.blockID, 0, 2);
		world.setBlock(i + 9, j + 53, k + 25, mod_LionKing.rafikiWood.blockID, 0, 2);
		world.setBlock(i + 9, j + 52, k + 24, mod_LionKing.rafikiWood.blockID, 0, 2);
		world.setBlock(i + 10, j + 54, k + 25, mod_LionKing.rafikiWood.blockID, 0, 2);
		world.setBlock(i + 9, j + 54, k + 25, mod_LionKing.rafikiWood.blockID, 0, 2);
		world.setBlock(i + 11, j + 55, k + 25, mod_LionKing.rafikiWood.blockID, 0, 2);
		world.setBlock(i + 10, j + 55, k + 25, mod_LionKing.rafikiWood.blockID, 0, 2);
		world.setBlock(i + 10, j + 55, k + 26, mod_LionKing.rafikiWood.blockID, 0, 2);
		world.setBlock(i + 10, j + 56, k + 26, mod_LionKing.rafikiWood.blockID, 0, 2);
		world.setBlock(i + 9, j + 55, k + 25, mod_LionKing.rafikiWood.blockID, 0, 2);
		world.setBlock(i + 10, j + 54, k + 24, mod_LionKing.rafikiWood.blockID, 0, 2);
		world.setBlock(i + 10, j + 53, k + 24, mod_LionKing.rafikiWood.blockID, 0, 2);
		world.setBlock(i + 9, j + 53, k + 24, mod_LionKing.rafikiWood.blockID, 0, 2);
		world.setBlock(i + 10, j + 51, k + 23, mod_LionKing.rafikiWood.blockID, 0, 2);
		world.setBlock(i + 10, j + 52, k + 23, mod_LionKing.rafikiWood.blockID, 0, 2);
		world.setBlock(i + 11, j + 54, k + 24, mod_LionKing.rafikiWood.blockID, 0, 2);
		world.setBlock(i + 11, j + 54, k + 23, mod_LionKing.rafikiWood.blockID, 0, 2);
		world.setBlock(i + 12, j + 54, k + 24, mod_LionKing.rafikiWood.blockID, 0, 2);
		world.setBlock(i + 11, j + 55, k + 24, mod_LionKing.rafikiWood.blockID, 0, 2);
		world.setBlock(i + 10, j + 55, k + 24, mod_LionKing.rafikiWood.blockID, 0, 2);
		world.setBlock(i + 9, j + 54, k + 24, mod_LionKing.rafikiWood.blockID, 0, 2);
		world.setBlock(i + 9, j + 55, k + 24, mod_LionKing.rafikiWood.blockID, 0, 2);
		world.setBlock(i + 8, j + 54, k + 25, mod_LionKing.rafikiWood.blockID, 0, 2);
		world.setBlock(i + 8, j + 53, k + 24, mod_LionKing.rafikiWood.blockID, 0, 2);
		world.setBlock(i + 8, j + 50, k + 24, mod_LionKing.rafikiWood.blockID, 0, 2);
		world.setBlock(i + 8, j + 51, k + 24, mod_LionKing.rafikiWood.blockID, 0, 2);
		world.setBlock(i + 8, j + 52, k + 24, mod_LionKing.rafikiWood.blockID, 0, 2);
		world.setBlock(i + 8, j + 53, k + 25, mod_LionKing.rafikiWood.blockID, 0, 2);
		world.setBlock(i + 8, j + 52, k + 25, mod_LionKing.rafikiWood.blockID, 0, 2);
		world.setBlock(i + 8, j + 51, k + 25, mod_LionKing.rafikiWood.blockID, 0, 2);
		world.setBlock(i + 8, j + 49, k + 25, mod_LionKing.rafikiWood.blockID, 0, 2);
		world.setBlock(i + 8, j + 50, k + 25, mod_LionKing.rafikiWood.blockID, 0, 2);
		world.setBlock(i + 9, j + 52, k + 26, mod_LionKing.rafikiWood.blockID, 0, 2);
		world.setBlock(i + 9, j + 51, k + 26, mod_LionKing.rafikiWood.blockID, 0, 2);
		world.setBlock(i + 9, j + 50, k + 26, mod_LionKing.rafikiWood.blockID, 0, 2);
		world.setBlock(i + 9, j + 54, k + 26, mod_LionKing.rafikiWood.blockID, 0, 2);
		world.setBlock(i + 9, j + 53, k + 26, mod_LionKing.rafikiWood.blockID, 0, 2);
		world.setBlock(i + 10, j + 52, k + 26, mod_LionKing.rafikiWood.blockID, 0, 2);
		world.setBlock(i + 7, j + 46, k + 22, mod_LionKing.rafikiWood.blockID, 0, 2);
		world.setBlock(i + 8, j + 46, k + 22, mod_LionKing.rafikiWood.blockID, 0, 2);
		world.setBlock(i + 7, j + 45, k + 22, mod_LionKing.rafikiWood.blockID, 0, 2);
		world.setBlock(i + 8, j + 45, k + 22, mod_LionKing.rafikiWood.blockID, 0, 2);
		world.setBlock(i + 8, j + 47, k + 23, mod_LionKing.rafikiWood.blockID, 0, 2);
		world.setBlock(i + 8, j + 46, k + 23, mod_LionKing.rafikiWood.blockID, 0, 2);
		world.setBlock(i + 8, j + 47, k + 24, mod_LionKing.rafikiWood.blockID, 0, 2);
		world.setBlock(i + 7, j + 47, k + 23, mod_LionKing.rafikiWood.blockID, 0, 2);
		world.setBlock(i + 7, j + 46, k + 23, mod_LionKing.rafikiWood.blockID, 0, 2);
		world.setBlock(i + 6, j + 46, k + 22, mod_LionKing.rafikiWood.blockID, 0, 2);
		world.setBlock(i + 8, j + 54, k + 26, mod_LionKing.rafikiLeaves.blockID, 0, 2);
		world.setBlock(i + 7, j + 54, k + 26, mod_LionKing.rafikiLeaves.blockID, 0, 2);
		world.setBlock(i + 6, j + 54, k + 26, mod_LionKing.rafikiLeaves.blockID, 0, 2);
		world.setBlock(i + 6, j + 54, k + 27, mod_LionKing.rafikiLeaves.blockID, 0, 2);
		world.setBlock(i + 7, j + 54, k + 27, mod_LionKing.rafikiLeaves.blockID, 0, 2);
		world.setBlock(i + 8, j + 54, k + 27, mod_LionKing.rafikiLeaves.blockID, 0, 2);
		world.setBlock(i + 9, j + 54, k + 27, mod_LionKing.rafikiLeaves.blockID, 0, 2);
		world.setBlock(i + 10, j + 54, k + 27, mod_LionKing.rafikiLeaves.blockID, 0, 2);
		world.setBlock(i + 11, j + 54, k + 27, mod_LionKing.rafikiLeaves.blockID, 0, 2);
		world.setBlock(i + 12, j + 54, k + 27, mod_LionKing.rafikiLeaves.blockID, 0, 2);
		world.setBlock(i + 12, j + 54, k + 28, mod_LionKing.rafikiLeaves.blockID, 0, 2);
		world.setBlock(i + 11, j + 54, k + 28, mod_LionKing.rafikiLeaves.blockID, 0, 2);
		world.setBlock(i + 9, j + 54, k + 28, mod_LionKing.rafikiLeaves.blockID, 0, 2);
		world.setBlock(i + 8, j + 54, k + 28, mod_LionKing.rafikiLeaves.blockID, 0, 2);
		world.setBlock(i + 7, j + 54, k + 28, mod_LionKing.rafikiLeaves.blockID, 0, 2);
		world.setBlock(i + 7, j + 54, k + 25, mod_LionKing.rafikiLeaves.blockID, 0, 2);
		world.setBlock(i + 6, j + 54, k + 25, mod_LionKing.rafikiLeaves.blockID, 0, 2);
		world.setBlock(i + 8, j + 54, k + 24, mod_LionKing.rafikiLeaves.blockID, 0, 2);
		world.setBlock(i + 7, j + 54, k + 24, mod_LionKing.rafikiLeaves.blockID, 0, 2);
		world.setBlock(i + 6, j + 54, k + 24, mod_LionKing.rafikiLeaves.blockID, 0, 2);
		world.setBlock(i + 6, j + 54, k + 23, mod_LionKing.rafikiLeaves.blockID, 0, 2);
		world.setBlock(i + 5, j + 54, k + 24, mod_LionKing.rafikiLeaves.blockID, 0, 2);
		world.setBlock(i + 4, j + 54, k + 24, mod_LionKing.rafikiLeaves.blockID, 0, 2);
		world.setBlock(i + 5, j + 54, k + 25, mod_LionKing.rafikiLeaves.blockID, 0, 2);
		world.setBlock(i + 4, j + 54, k + 25, mod_LionKing.rafikiLeaves.blockID, 0, 2);
		world.setBlock(i + 5, j + 54, k + 26, mod_LionKing.rafikiLeaves.blockID, 0, 2);
		world.setBlock(i + 5, j + 54, k + 27, mod_LionKing.rafikiLeaves.blockID, 0, 2);
		world.setBlock(i + 6, j + 54, k + 28, mod_LionKing.rafikiLeaves.blockID, 0, 2);
		world.setBlock(i + 10, j + 54, k + 28, mod_LionKing.rafikiLeaves.blockID, 0, 2);
		world.setBlock(i + 9, j + 55, k + 26, mod_LionKing.rafikiLeaves.blockID, 0, 2);
		world.setBlock(i + 8, j + 55, k + 25, mod_LionKing.rafikiLeaves.blockID, 0, 2);
		world.setBlock(i + 8, j + 55, k + 26, mod_LionKing.rafikiLeaves.blockID, 0, 2);
		world.setBlock(i + 8, j + 55, k + 27, mod_LionKing.rafikiLeaves.blockID, 0, 2);
		world.setBlock(i + 7, j + 55, k + 25, mod_LionKing.rafikiLeaves.blockID, 0, 2);
		world.setBlock(i + 7, j + 55, k + 26, mod_LionKing.rafikiLeaves.blockID, 0, 2);
		world.setBlock(i + 7, j + 55, k + 27, mod_LionKing.rafikiLeaves.blockID, 0, 2);
		world.setBlock(i + 6, j + 55, k + 25, mod_LionKing.rafikiLeaves.blockID, 0, 2);
		world.setBlock(i + 6, j + 55, k + 26, mod_LionKing.rafikiLeaves.blockID, 0, 2);
		world.setBlock(i + 5, j + 55, k + 25, mod_LionKing.rafikiLeaves.blockID, 0, 2);
		world.setBlock(i + 8, j + 55, k + 24, mod_LionKing.rafikiLeaves.blockID, 0, 2);
		world.setBlock(i + 7, j + 55, k + 24, mod_LionKing.rafikiLeaves.blockID, 0, 2);
		world.setBlock(i + 6, j + 55, k + 24, mod_LionKing.rafikiLeaves.blockID, 0, 2);
		world.setBlock(i + 7, j + 54, k + 23, mod_LionKing.rafikiLeaves.blockID, 0, 2);
		world.setBlock(i + 8, j + 54, k + 23, mod_LionKing.rafikiLeaves.blockID, 0, 2);
		world.setBlock(i + 9, j + 54, k + 23, mod_LionKing.rafikiLeaves.blockID, 0, 2);
		world.setBlock(i + 10, j + 54, k + 23, mod_LionKing.rafikiLeaves.blockID, 0, 2);
		world.setBlock(i + 10, j + 54, k + 22, mod_LionKing.rafikiLeaves.blockID, 0, 2);
		world.setBlock(i + 11, j + 54, k + 22, mod_LionKing.rafikiLeaves.blockID, 0, 2);
		world.setBlock(i + 12, j + 54, k + 22, mod_LionKing.rafikiLeaves.blockID, 0, 2);
		world.setBlock(i + 12, j + 54, k + 23, mod_LionKing.rafikiLeaves.blockID, 0, 2);
		world.setBlock(i + 13, j + 54, k + 24, mod_LionKing.rafikiLeaves.blockID, 0, 2);
		world.setBlock(i + 13, j + 54, k + 23, mod_LionKing.rafikiLeaves.blockID, 0, 2);
		world.setBlock(i + 14, j + 54, k + 24, mod_LionKing.rafikiLeaves.blockID, 0, 2);
		world.setBlock(i + 14, j + 54, k + 25, mod_LionKing.rafikiLeaves.blockID, 0, 2);
		world.setBlock(i + 14, j + 54, k + 26, mod_LionKing.rafikiLeaves.blockID, 0, 2);
		world.setBlock(i + 13, j + 54, k + 26, mod_LionKing.rafikiLeaves.blockID, 0, 2);
		world.setBlock(i + 13, j + 54, k + 27, mod_LionKing.rafikiLeaves.blockID, 0, 2);
		world.setBlock(i + 14, j + 54, k + 27, mod_LionKing.rafikiLeaves.blockID, 0, 2);
		world.setBlock(i + 15, j + 54, k + 26, mod_LionKing.rafikiLeaves.blockID, 0, 2);
		world.setBlock(i + 15, j + 54, k + 25, mod_LionKing.rafikiLeaves.blockID, 0, 2);
		world.setBlock(i + 16, j + 54, k + 25, mod_LionKing.rafikiLeaves.blockID, 0, 2);
		world.setBlock(i + 15, j + 54, k + 24, mod_LionKing.rafikiLeaves.blockID, 0, 2);
		world.setBlock(i + 16, j + 54, k + 24, mod_LionKing.rafikiLeaves.blockID, 0, 2);
		world.setBlock(i + 15, j + 54, k + 23, mod_LionKing.rafikiLeaves.blockID, 0, 2);
		world.setBlock(i + 14, j + 54, k + 23, mod_LionKing.rafikiLeaves.blockID, 0, 2);
		world.setBlock(i + 13, j + 54, k + 22, mod_LionKing.rafikiLeaves.blockID, 0, 2);
		world.setBlock(i + 14, j + 54, k + 22, mod_LionKing.rafikiLeaves.blockID, 0, 2);
		world.setBlock(i + 12, j + 54, k + 21, mod_LionKing.rafikiLeaves.blockID, 0, 2);
		world.setBlock(i + 11, j + 54, k + 21, mod_LionKing.rafikiLeaves.blockID, 0, 2);
		world.setBlock(i + 10, j + 54, k + 21, mod_LionKing.rafikiLeaves.blockID, 0, 2);
		world.setBlock(i + 9, j + 54, k + 22, mod_LionKing.rafikiLeaves.blockID, 0, 2);
		world.setBlock(i + 8, j + 54, k + 22, mod_LionKing.rafikiLeaves.blockID, 0, 2);
		world.setBlock(i + 7, j + 54, k + 22, mod_LionKing.rafikiLeaves.blockID, 0, 2);
		world.setBlock(i + 11, j + 55, k + 23, mod_LionKing.rafikiLeaves.blockID, 0, 2);
		world.setBlock(i + 10, j + 55, k + 23, mod_LionKing.rafikiLeaves.blockID, 0, 2);
		world.setBlock(i + 9, j + 55, k + 23, mod_LionKing.rafikiLeaves.blockID, 0, 2);
		world.setBlock(i + 8, j + 55, k + 23, mod_LionKing.rafikiLeaves.blockID, 0, 2);
		world.setBlock(i + 7, j + 55, k + 23, mod_LionKing.rafikiLeaves.blockID, 0, 2);
		world.setBlock(i + 10, j + 53, k + 23, mod_LionKing.rafikiLeaves.blockID, 0, 2);
		world.setBlock(i + 11, j + 53, k + 23, mod_LionKing.rafikiLeaves.blockID, 0, 2);
		world.setBlock(i + 12, j + 53, k + 23, mod_LionKing.rafikiLeaves.blockID, 0, 2);
		world.setBlock(i + 12, j + 53, k + 24, mod_LionKing.rafikiLeaves.blockID, 0, 2);
		world.setBlock(i + 13, j + 53, k + 24, mod_LionKing.rafikiLeaves.blockID, 0, 2);
		world.setBlock(i + 13, j + 53, k + 25, mod_LionKing.rafikiLeaves.blockID, 0, 2);
		world.setBlock(i + 12, j + 53, k + 26, mod_LionKing.rafikiLeaves.blockID, 0, 2);
		world.setBlock(i + 11, j + 53, k + 27, mod_LionKing.rafikiLeaves.blockID, 0, 2);
		world.setBlock(i + 9, j + 53, k + 27, mod_LionKing.rafikiLeaves.blockID, 0, 2);
		world.setBlock(i + 10, j + 53, k + 27, mod_LionKing.rafikiLeaves.blockID, 0, 2);
		world.setBlock(i + 12, j + 52, k + 25, mod_LionKing.rafikiLeaves.blockID, 0, 2);
		world.setBlock(i + 12, j + 52, k + 24, mod_LionKing.rafikiLeaves.blockID, 0, 2);
		world.setBlock(i + 11, j + 52, k + 23, mod_LionKing.rafikiLeaves.blockID, 0, 2);
		world.setBlock(i + 9, j + 53, k + 23, mod_LionKing.rafikiLeaves.blockID, 0, 2);
		world.setBlock(i + 11, j + 53, k + 22, mod_LionKing.rafikiLeaves.blockID, 0, 2);
		world.setBlock(i + 10, j + 53, k + 22, mod_LionKing.rafikiLeaves.blockID, 0, 2);
		world.setBlock(i + 8, j + 53, k + 23, mod_LionKing.rafikiLeaves.blockID, 0, 2);
		world.setBlock(i + 7, j + 53, k + 24, mod_LionKing.rafikiLeaves.blockID, 0, 2);
		world.setBlock(i + 9, j + 52, k + 23, mod_LionKing.rafikiLeaves.blockID, 0, 2);
		world.setBlock(i + 7, j + 53, k + 25, mod_LionKing.rafikiLeaves.blockID, 0, 2);
		world.setBlock(i + 8, j + 53, k + 26, mod_LionKing.rafikiLeaves.blockID, 0, 2);
		world.setBlock(i + 8, j + 52, k + 26, mod_LionKing.rafikiLeaves.blockID, 0, 2);
		world.setBlock(i + 9, j + 55, k + 27, mod_LionKing.rafikiLeaves.blockID, 0, 2);
		world.setBlock(i + 10, j + 55, k + 27, mod_LionKing.rafikiLeaves.blockID, 0, 2);
		world.setBlock(i + 6, j + 54, k + 29, mod_LionKing.rafikiLeaves.blockID, 0, 2);
		world.setBlock(i + 7, j + 54, k + 29, mod_LionKing.rafikiLeaves.blockID, 0, 2);
		world.setBlock(i + 7, j + 54, k + 30, mod_LionKing.rafikiLeaves.blockID, 0, 2);
		world.setBlock(i + 9, j + 54, k + 29, mod_LionKing.rafikiLeaves.blockID, 0, 2);
		world.setBlock(i + 8, j + 54, k + 29, mod_LionKing.rafikiLeaves.blockID, 0, 2);
		world.setBlock(i + 10, j + 54, k + 29, mod_LionKing.rafikiLeaves.blockID, 0, 2);
		world.setBlock(i + 10, j + 54, k + 30, mod_LionKing.rafikiLeaves.blockID, 0, 2);
		world.setBlock(i + 8, j + 54, k + 30, mod_LionKing.rafikiLeaves.blockID, 0, 2);
		world.setBlock(i + 9, j + 54, k + 30, mod_LionKing.rafikiLeaves.blockID, 0, 2);
		world.setBlock(i + 11, j + 54, k + 29, mod_LionKing.rafikiLeaves.blockID, 0, 2);
		world.setBlock(i + 12, j + 54, k + 29, mod_LionKing.rafikiLeaves.blockID, 0, 2);
		world.setBlock(i + 11, j + 54, k + 30, mod_LionKing.rafikiLeaves.blockID, 0, 2);
		world.setBlock(i + 13, j + 54, k + 28, mod_LionKing.rafikiLeaves.blockID, 0, 2);
		world.setBlock(i + 13, j + 54, k + 29, mod_LionKing.rafikiLeaves.blockID, 0, 2);
		world.setBlock(i + 11, j + 55, k + 27, mod_LionKing.rafikiLeaves.blockID, 0, 2);
		world.setBlock(i + 12, j + 55, k + 27, mod_LionKing.rafikiLeaves.blockID, 0, 2);
		world.setBlock(i + 8, j + 55, k + 28, mod_LionKing.rafikiLeaves.blockID, 0, 2);
		world.setBlock(i + 9, j + 55, k + 28, mod_LionKing.rafikiLeaves.blockID, 0, 2);
		world.setBlock(i + 10, j + 55, k + 28, mod_LionKing.rafikiLeaves.blockID, 0, 2);
		world.setBlock(i + 8, j + 55, k + 29, mod_LionKing.rafikiLeaves.blockID, 0, 2);
		world.setBlock(i + 9, j + 55, k + 29, mod_LionKing.rafikiLeaves.blockID, 0, 2);
		world.setBlock(i + 10, j + 55, k + 29, mod_LionKing.rafikiLeaves.blockID, 0, 2);
		world.setBlock(i + 11, j + 55, k + 28, mod_LionKing.rafikiLeaves.blockID, 0, 2);
		world.setBlock(i + 11, j + 55, k + 29, mod_LionKing.rafikiLeaves.blockID, 0, 2);
		world.setBlock(i + 12, j + 55, k + 28, mod_LionKing.rafikiLeaves.blockID, 0, 2);
		world.setBlock(i + 13, j + 55, k + 26, mod_LionKing.rafikiLeaves.blockID, 0, 2);
		world.setBlock(i + 13, j + 55, k + 27, mod_LionKing.rafikiLeaves.blockID, 0, 2);
		world.setBlock(i + 14, j + 55, k + 25, mod_LionKing.rafikiLeaves.blockID, 0, 2);
		world.setBlock(i + 14, j + 55, k + 26, mod_LionKing.rafikiLeaves.blockID, 0, 2);
		world.setBlock(i + 12, j + 55, k + 24, mod_LionKing.rafikiLeaves.blockID, 0, 2);
		world.setBlock(i + 13, j + 55, k + 24, mod_LionKing.rafikiLeaves.blockID, 0, 2);
		world.setBlock(i + 12, j + 55, k + 23, mod_LionKing.rafikiLeaves.blockID, 0, 2);
		world.setBlock(i + 13, j + 55, k + 23, mod_LionKing.rafikiLeaves.blockID, 0, 2);
		world.setBlock(i + 14, j + 55, k + 24, mod_LionKing.rafikiLeaves.blockID, 0, 2);
		world.setBlock(i + 14, j + 55, k + 23, mod_LionKing.rafikiLeaves.blockID, 0, 2);
		world.setBlock(i + 15, j + 55, k + 25, mod_LionKing.rafikiLeaves.blockID, 0, 2);
		world.setBlock(i + 15, j + 55, k + 24, mod_LionKing.rafikiLeaves.blockID, 0, 2);
		world.setBlock(i + 7, j + 48, k + 21, mod_LionKing.rafikiLeaves.blockID, 0, 2);
		world.setBlock(i + 6, j + 47, k + 21, 0, 0, 2);
		world.setBlock(i + 6, j + 47, k + 21, mod_LionKing.rafikiLeaves.blockID, 0, 2);
		world.setBlock(i + 5, j + 47, k + 21, 0, 0, 2);
		world.setBlock(i + 5, j + 47, k + 21, mod_LionKing.rafikiLeaves.blockID, 0, 2);
		world.setBlock(i + 6, j + 47, k + 20, mod_LionKing.rafikiLeaves.blockID, 0, 2);
		world.setBlock(i + 4, j + 47, k + 21, 0, 0, 2);
		world.setBlock(i + 4, j + 47, k + 21, mod_LionKing.rafikiLeaves.blockID, 0, 2);
		world.setBlock(i + 3, j + 36, k + 14, mod_LionKing.rafikiWood.blockID, 0, 2);
		world.setBlock(i + 4, j + 35, k + 14, mod_LionKing.rafikiWood.blockID, 0, 2);
		world.setBlock(i + 4, j + 34, k + 14, mod_LionKing.rafikiWood.blockID, 0, 2);
		world.setBlock(i + 5, j + 35, k + 14, mod_LionKing.rafikiWood.blockID, 0, 2);
		world.setBlock(i + 5, j + 34, k + 14, mod_LionKing.rafikiWood.blockID, 0, 2);
		world.setBlock(i + 5, j + 33, k + 14, mod_LionKing.rafikiWood.blockID, 0, 2);
		world.setBlock(i + 6, j + 35, k + 14, mod_LionKing.rafikiWood.blockID, 0, 2);
		world.setBlock(i + 6, j + 34, k + 14, mod_LionKing.rafikiWood.blockID, 0, 2);
		world.setBlock(i + 7, j + 35, k + 14, mod_LionKing.rafikiWood.blockID, 0, 2);
		world.setBlock(i + 7, j + 34, k + 14, mod_LionKing.rafikiWood.blockID, 0, 2);
		world.setBlock(i + 8, j + 35, k + 14, mod_LionKing.rafikiWood.blockID, 0, 2);
		world.setBlock(i + 7, j + 33, k + 13, mod_LionKing.rafikiWood.blockID, 0, 2);
		world.setBlock(i + 5, j + 36, k + 15, mod_LionKing.rafikiWood.blockID, 0, 2);
		world.setBlock(i + 5, j + 35, k + 15, mod_LionKing.rafikiWood.blockID, 0, 2);
		world.setBlock(i + 6, j + 36, k + 15, mod_LionKing.rafikiWood.blockID, 0, 2);
		world.setBlock(i + 6, j + 36, k + 16, mod_LionKing.rafikiWood.blockID, 0, 2);
		world.setBlock(i + 6, j + 35, k + 15, mod_LionKing.rafikiWood.blockID, 0, 2);
		world.setBlock(i + 6, j + 36, k + 16, 0, 0, 2);
		world.setBlock(i + 7, j + 36, k + 15, mod_LionKing.rafikiWood.blockID, 0, 2);
		world.setBlock(i + 7, j + 35, k + 15, mod_LionKing.rafikiWood.blockID, 0, 2);
		world.setBlock(i + 5, j + 37, k + 16, mod_LionKing.rafikiWood.blockID, 0, 2);
		world.setBlock(i + 5, j + 36, k + 16, mod_LionKing.rafikiWood.blockID, 0, 2);
		world.setBlock(i + 6, j + 37, k + 16, mod_LionKing.rafikiWood.blockID, 0, 2);
		world.setBlock(i + 6, j + 36, k + 16, mod_LionKing.rafikiWood.blockID, 0, 2);
		world.setBlock(i - 1, j + 46, k + 25, mod_LionKing.rafikiLeaves.blockID, 0, 2);
		world.setBlock(i, j + 47, k + 24, mod_LionKing.rafikiLeaves.blockID, 0, 2);
		world.setBlock(i + 1, j + 47, k + 23, mod_LionKing.rafikiLeaves.blockID, 0, 2);
		world.setBlock(i + 1, j + 47, k + 24, mod_LionKing.rafikiLeaves.blockID, 0, 2);
		world.setBlock(i + 2, j + 47, k + 21, mod_LionKing.rafikiLeaves.blockID, 0, 2);
		world.setBlock(i + 2, j + 47, k + 22, mod_LionKing.rafikiLeaves.blockID, 0, 2);
		world.setBlock(i + 3, j + 47, k + 22, mod_LionKing.rafikiLeaves.blockID, 0, 2);
		world.setBlock(i + 2, j + 46, k + 25, mod_LionKing.rafikiLeaves.blockID, 0, 2);
		world.setBlock(i + 3, j + 46, k + 24, mod_LionKing.rafikiLeaves.blockID, 0, 2);
		world.setBlock(i + 8, j + 53, k + 27, mod_LionKing.rafikiLeaves.blockID, 0, 2);
		world.setBlock(i + 7, j + 53, k + 26, mod_LionKing.rafikiLeaves.blockID, 0, 2);
		world.setBlock(i + 6, j + 53, k + 25, mod_LionKing.rafikiLeaves.blockID, 0, 2);
		world.setBlock(i + 9, j + 53, k + 28, mod_LionKing.rafikiLeaves.blockID, 0, 2);
		world.setBlock(i + 10, j + 53, k + 28, mod_LionKing.rafikiLeaves.blockID, 0, 2);
		world.setBlock(i + 9, j + 53, k + 29, mod_LionKing.rafikiLeaves.blockID, 0, 2);
		world.setBlock(i + 8, j + 53, k + 28, mod_LionKing.rafikiLeaves.blockID, 0, 2);
		world.setBlock(i + 7, j + 53, k + 27, mod_LionKing.rafikiLeaves.blockID, 0, 2);
		world.setBlock(i + 12, j + 53, k + 27, mod_LionKing.rafikiLeaves.blockID, 0, 2);
		world.setBlock(i + 11, j + 56, k + 25, mod_LionKing.rafikiLeaves.blockID, 0, 2);
		world.setBlock(i + 11, j + 56, k + 24, mod_LionKing.rafikiLeaves.blockID, 0, 2);
		world.setBlock(i + 10, j + 56, k + 25, mod_LionKing.rafikiLeaves.blockID, 0, 2);
		world.setBlock(i + 10, j + 56, k + 24, mod_LionKing.rafikiLeaves.blockID, 0, 2);
		world.setBlock(i + 12, j + 56, k + 25, 0, 0, 2);
		world.setBlock(i + 12, j + 56, k + 25, mod_LionKing.rafikiLeaves.blockID, 0, 2);
		world.setBlock(i + 13, j + 55, k + 25, 0, 0, 2);
		world.setBlock(i + 13, j + 55, k + 25, mod_LionKing.rafikiLeaves.blockID, 0, 2);
		world.setBlock(i + 12, j + 56, k + 26, 0, 0, 2);
		world.setBlock(i + 12, j + 56, k + 26, mod_LionKing.rafikiLeaves.blockID, 0, 2);
		world.setBlock(i + 11, j + 56, k + 26, 0, 0, 2);
		world.setBlock(i + 11, j + 56, k + 26, mod_LionKing.rafikiLeaves.blockID, 0, 2);
		world.setBlock(i + 10, j + 56, k + 26, 0, 0, 2);
		world.setBlock(i + 10, j + 56, k + 26, mod_LionKing.rafikiLeaves.blockID, 0, 2);
		world.setBlock(i + 9, j + 56, k + 26, mod_LionKing.rafikiLeaves.blockID, 0, 2);
		world.setBlock(i + 10, j + 56, k + 27, mod_LionKing.rafikiLeaves.blockID, 0, 2);
		world.setBlock(i + 9, j + 56, k + 27, mod_LionKing.rafikiLeaves.blockID, 0, 2);
		world.setBlock(i + 9, j + 55, k + 24, 0, 0, 2);
		world.setBlock(i + 9, j + 55, k + 24, mod_LionKing.rafikiLeaves.blockID, 0, 2);
		world.setBlock(i + 9, j + 55, k + 25, 0, 0, 2);
		world.setBlock(i + 9, j + 55, k + 25, mod_LionKing.rafikiLeaves.blockID, 0, 2);
		world.setBlock(i + 9, j + 56, k + 24, mod_LionKing.rafikiLeaves.blockID, 0, 2);
		world.setBlock(i + 9, j + 56, k + 25, mod_LionKing.rafikiLeaves.blockID, 0, 2);
		world.setBlock(i + 8, j + 56, k + 25, mod_LionKing.rafikiLeaves.blockID, 0, 2);
		world.setBlock(i + 8, j + 56, k + 26, mod_LionKing.rafikiLeaves.blockID, 0, 2);
		world.setBlock(i - 11, j + 53, k + 19, mod_LionKing.rafikiLeaves.blockID, 0, 2);
		world.setBlock(i - 12, j + 53, k + 18, mod_LionKing.rafikiLeaves.blockID, 0, 2);
		world.setBlock(i - 13, j + 53, k + 17, mod_LionKing.rafikiLeaves.blockID, 0, 2);
		world.setBlock(i - 13, j + 53, k + 15, mod_LionKing.rafikiLeaves.blockID, 0, 2);
		world.setBlock(i - 14, j + 53, k + 15, mod_LionKing.rafikiLeaves.blockID, 0, 2);
		world.setBlock(i - 12, j + 53, k + 14, mod_LionKing.rafikiLeaves.blockID, 0, 2);
		world.setBlock(i - 13, j + 53, k + 14, mod_LionKing.rafikiLeaves.blockID, 0, 2);
		world.setBlock(i - 10, j + 53, k + 14, mod_LionKing.rafikiLeaves.blockID, 0, 2);
		world.setBlock(i - 10, j + 54, k + 15, mod_LionKing.rafikiLeaves.blockID, 0, 2);
		world.setBlock(i - 8, j + 54, k + 16, mod_LionKing.rafikiLeaves.blockID, 0, 2);
		world.setBlock(i - 9, j + 54, k + 15, mod_LionKing.rafikiLeaves.blockID, 0, 2);
		world.setBlock(i - 8, j + 53, k + 15, mod_LionKing.rafikiLeaves.blockID, 0, 2);
		world.setBlock(i - 7, j + 53, k + 15, mod_LionKing.rafikiLeaves.blockID, 0, 2);
		world.setBlock(i - 7, j + 53, k + 16, mod_LionKing.rafikiLeaves.blockID, 0, 2);
		world.setBlock(i - 9, j + 53, k + 14, mod_LionKing.rafikiLeaves.blockID, 0, 2);
		world.setBlock(i - 8, j + 53, k + 14, mod_LionKing.rafikiLeaves.blockID, 0, 2);
		world.setBlock(i - 10, j + 53, k + 20, mod_LionKing.rafikiLeaves.blockID, 0, 2);
		world.setBlock(i - 14, j + 53, k + 16, mod_LionKing.rafikiLeaves.blockID, 0, 2);
		world.setBlock(i - 11, j + 50, k + 16, mod_LionKing.rafikiWood.blockID, 0, 2);
		world.setBlock(i - 10, j + 50, k + 17, mod_LionKing.rafikiWood.blockID, 0, 2);
		world.setBlock(i - 11, j + 49, k + 15, mod_LionKing.rafikiWood.blockID, 0, 2);
		world.setBlock(i - 11, j + 49, k + 16, mod_LionKing.rafikiWood.blockID, 0, 2);
		world.setBlock(i - 11, j + 49, k + 16, 0, 0, 2);
		world.setBlock(i - 10, j + 50, k + 17, 0, 0, 2);
		world.setBlock(i - 9, j + 50, k + 16, mod_LionKing.rafikiWood.blockID, 0, 2);
		world.setBlock(i - 9, j + 50, k + 16, 0, 0, 2);
		world.setBlock(i - 9, j + 50, k + 16, mod_LionKing.rafikiWood.blockID, 0, 2);
		world.setBlock(i - 9, j + 50, k + 17, mod_LionKing.rafikiWood.blockID, 0, 2);
		world.setBlock(i - 9, j + 50, k + 16, 0, 0, 2);
		world.setBlock(i - 9, j + 49, k + 17, mod_LionKing.rafikiWood.blockID, 0, 2);
		world.setBlock(i - 11, j + 52, k + 17, mod_LionKing.rafikiWood.blockID, 0, 2);
		world.setBlock(i - 11, j + 52, k + 17, 0, 0, 2);
		world.setBlock(i - 11, j + 52, k + 17, mod_LionKing.rafikiLeaves.blockID, 0, 2);
		world.setBlock(i - 11, j + 52, k + 16, 0, 0, 2);
		world.setBlock(i - 11, j + 52, k + 16, mod_LionKing.rafikiLeaves.blockID, 0, 2);
		world.setBlock(i - 12, j + 52, k + 16, mod_LionKing.rafikiLeaves.blockID, 0, 2);
		world.setBlock(i - 10, j + 52, k + 16, mod_LionKing.rafikiLeaves.blockID, 0, 2);
		world.setBlock(i - 9, j + 52, k + 17, mod_LionKing.rafikiLeaves.blockID, 0, 2);
		world.setBlock(i - 10, j + 52, k + 15, mod_LionKing.rafikiLeaves.blockID, 0, 2);
		world.setBlock(i - 9, j + 52, k + 16, mod_LionKing.rafikiLeaves.blockID, 0, 2);
		world.setBlock(i - 10, j + 52, k + 18, mod_LionKing.rafikiLeaves.blockID, 0, 2);
		world.setBlock(i - 10, j + 47, k + 18, mod_LionKing.rafikiLeaves.blockID, 0, 2);
		world.setBlock(i - 10, j + 47, k + 19, mod_LionKing.rafikiLeaves.blockID, 0, 2);
		world.setBlock(i - 10, j + 47, k + 20, mod_LionKing.rafikiLeaves.blockID, 0, 2);
		world.setBlock(i - 9, j + 47, k + 19, mod_LionKing.rafikiLeaves.blockID, 0, 2);
		world.setBlock(i - 9, j + 47, k + 20, mod_LionKing.rafikiLeaves.blockID, 0, 2);
		world.setBlock(i - 11, j + 47, k + 18, mod_LionKing.rafikiLeaves.blockID, 0, 2);
		world.setBlock(i - 11, j + 47, k + 19, mod_LionKing.rafikiLeaves.blockID, 0, 2);
		world.setBlock(i - 12, j + 47, k + 19, mod_LionKing.rafikiLeaves.blockID, 0, 2);
		world.setBlock(i - 12, j + 47, k + 16, mod_LionKing.rafikiLeaves.blockID, 0, 2);
		world.setBlock(i - 13, j + 47, k + 16, mod_LionKing.rafikiLeaves.blockID, 0, 2);
		world.setBlock(i - 12, j + 47, k + 17, mod_LionKing.rafikiLeaves.blockID, 0, 2);
		world.setBlock(i - 12, j + 47, k + 18, mod_LionKing.rafikiLeaves.blockID, 0, 2);
		world.setBlock(i - 13, j + 47, k + 17, mod_LionKing.rafikiLeaves.blockID, 0, 2);
		world.setBlock(i - 13, j + 47, k + 18, mod_LionKing.rafikiLeaves.blockID, 0, 2);
		world.setBlock(i - 13, j + 47, k + 15, mod_LionKing.rafikiLeaves.blockID, 0, 2);
		world.setBlock(i - 14, j + 47, k + 14, mod_LionKing.rafikiLeaves.blockID, 0, 2);
		world.setBlock(i - 14, j + 47, k + 15, mod_LionKing.rafikiLeaves.blockID, 0, 2);
		world.setBlock(i - 14, j + 47, k + 16, mod_LionKing.rafikiLeaves.blockID, 0, 2);
