package lionking.common;
import net.minecraft.block.*;
import net.minecraft.block.material.*;
import net.minecraft.creativetab.*;
import net.minecraft.enchantment.*;
import net.minecraft.entity.*;
import net.minecraft.entity.ai.*;
import net.minecraft.entity.item.*;
import net.minecraft.entity.monster.*;
import net.minecraft.entity.passive.*;
import net.minecraft.entity.player.*;
import net.minecraft.entity.projectile.*;
import net.minecraft.inventory.*;
import net.minecraft.item.*;
import net.minecraft.item.crafting.*;
import net.minecraft.nbt.*;
import net.minecraft.network.packet.*;
import net.minecraft.pathfinding.*;
import net.minecraft.potion.*;
import net.minecraft.server.*;
import net.minecraft.server.management.*;
import net.minecraft.src.*;
import net.minecraft.stats.*;
import net.minecraft.tileentity.*;
import net.minecraft.util.*;
import net.minecraft.world.*;
import net.minecraft.world.biome.*;
import net.minecraft.world.gen.feature.*;
import net.minecraft.world.gen.layer.*;
import net.minecraft.world.storage.*;

import java.util.Random;

public class LKWorldGenZiraMound extends WorldGenerator
{
	@Override
	public boolean generate(World world, Random random, int i, int j, int k)
	{
		generate0(world, i, j, k);
		generate1(world, i, j, k);
		generate2(world, i, j, k);
		generate3(world, i, j, k);
		generate4(world, i, j, k);
		generate5(world, i, j, k);
		generate6(world, i, j, k);
		generate7(world, i, j, k);
		generate8(world, i, j, k);
		generate9(world, i, j, k);
		generate10(world, i, j, k);
		generate11(world, i, j, k);
		generate12(world, i, j, k);
		generate13(world, i, j, k);
		generate14(world, i, j, k);
		generate15(world, i, j, k);
		generate16(world, i, j, k);
		generate17(world, i, j, k);
		generate18(world, i, j, k);
		generate19(world, i, j, k);
		generate20(world, i, j, k);
		generate21(world, i, j, k);
		generate22(world, i, j, k);
		generate23(world, i, j, k);
		generate24(world, i, j, k);
		generate25(world, i, j, k);
		generate26(world, i, j, k);
		generate27(world, i, j, k);
		generate28(world, i, j, k);
		generate29(world, i, j, k);
		generate30(world, i, j, k);
		generate31(world, i, j, k);
		generate32(world, i, j, k);
		generatePoolCover(world, i, j, k);
		
		for (int i1 = i - 28; i1 <= i + 28; i1++)
		{
			for (int k1 = k - 28; k1 <= k + 28; k1++)
			{
                int i2 = i1 - i;
                int k2 = k1 - k;
                if (i2 * i2 + k2 * k2 > 28 * 28)
                {
                    continue;
                }
				for (int j1 = 255; j1 >= j + 3; j1--)
				{
					if (canReplace(world, i1, j1, k1))
					{
						world.setBlockToAir(i1, j1, k1);
					}
				}
			}
		}
		
		for (int i1 = i - 28; i1 <= i + 28; i1++)
		{
			for (int k1 = k - 28; k1 <= k + 28; k1++)
			{
                int i2 = i1 - i;
                int k2 = k1 - k;
                if (i2 * i2 + k2 * k2 > 28 * 28)
                {
                    continue;
                }
				world.setBlock(i1, j + 2, k1, mod_LionKing.outlandsPortalFrame.blockID, 1, 2);
				for (int j1 = j + 3; j1 <= j + 51; j1++)
				{
					if (world.isAirBlock(i1, j1, k1) && world.canBlockSeeTheSky(i1, j1, k1))
					{
						int[] blockAndMetadata = new int[2];
						if (j1 > j + 48)
						{
							blockAndMetadata[0] = Block.sand.blockID;
						}
						else if (j1 > j + 46)
						{
							blockAndMetadata[0] = Block.sandStone.blockID;
						}
						else if (j1 > 4)
						{
							blockAndMetadata[0] = mod_LionKing.pridestone.blockID;
							blockAndMetadata[1] = 1;
						}
						else if (j1 <= 4)
						{
							blockAndMetadata[0] = Block.bedrock.blockID;
						}
						world.setBlock(i1, j1, k1, blockAndMetadata[0], blockAndMetadata[1], 2);
					}
				}
			}
		}
		
		for (int x = 1; x < 6; x++)
		{
			for (int i1 = i - (28 + x * 2); i1 <= i + (28 + x * 2); i1++)
			{
				for (int k1 = k - (28 + x * 2); k1 <= k + (28 + x * 2); k1++)
				{
					int i2 = i1 - i;
					int k2 = k1 - k;
					if (i2 * i2 + k2 * k2 > (28 + x * 2) * (28 + x * 2))
					{
						continue;
					}
					for (int j1 = j + 3; j1 <= j + (51 - x); j1++)
					{
						if (j1 > 60 && world.isAirBlock(i1, j1, k1) && world.canBlockSeeTheSky(i1, j1, k1))
						{
							if (j1 > j + 48)
							{
								world.setBlock(i1, j1, k1, Block.sand.blockID, 0, 2);
							}
							else if (j1 > j + 46)
							{
								world.setBlock(i1, j1, k1, Block.sandStone.blockID, 0, 2);
							}
						}
					}
				}
			}
		}
		
		world.setBlock(i, j + 8, k, mod_LionKing.outlandsAltar.blockID, 0, 2);
		LKEntityZira zira = new LKEntityZira(world);
		zira.setLocationAndAngles(i, j + 17, k, 0.0F, 0.0F);
		if (!world.isRemote)
		{
			world.spawnEntityInWorld(zira);
			zira.spawnOutlandersInMound();
		}
		
		LKLevelData.markMoundLocation(i, j, k);
		return true;
	}
	
	private boolean canReplace(World world, int i, int j, int k)
	{
		Block block = Block.blocksList[world.getBlockId(i, j, k)];
		return block != null && block != mod_LionKing.outlandsPortalFrame && block != mod_LionKing.outshroomGlowing && block != mod_LionKing.outlandsPool;
	}
	
	public static void clearPoolCover(World world)
	{
		int i = LKLevelData.moundX;
		int j = LKLevelData.moundY;
		int k = LKLevelData.moundZ;
		world.setBlockToAir(i + -4, j + 17, k + 12);
		world.setBlockToAir(i + -4, j + 17, k + 11);
		world.setBlockToAir(i + -3, j + 17, k + 12);
		world.setBlockToAir(i + -2, j + 17, k + 12);
		world.setBlockToAir(i + -1, j + 17, k + 12);
		world.setBlockToAir(i + -3, j + 17, k + 11);
		world.setBlockToAir(i + -2, j + 17, k + 11);
		world.setBlockToAir(i + -1, j + 17, k + 11);
		world.setBlockToAir(i + -1, j + 17, k + 10);
		world.setBlockToAir(i + -1, j + 18, k + 10);
		world.setBlockToAir(i + -2, j + 17, k + 10);
		world.setBlockToAir(i + -3, j + 17, k + 10);
		world.setBlockToAir(i + -4, j + 17, k + 10);
		world.setBlockToAir(i + -2, j + 17, k + 9);
		world.setBlockToAir(i + -3, j + 17, k + 9);
		world.setBlockToAir(i + -4, j + 17, k + 9);
		world.setBlockToAir(i + -4, j + 17, k + 8);
		world.setBlockToAir(i + -5, j + 17, k + 8);
		world.setBlockToAir(i + -6, j + 17, k + 8);
		world.setBlockToAir(i + -5, j + 17, k + 9);
		world.setBlockToAir(i + -6, j + 17, k + 9);
		world.setBlockToAir(i + -5, j + 17, k + 10);
		world.setBlockToAir(i + -6, j + 17, k + 10);
		world.setBlockToAir(i + -5, j + 17, k + 11);
		world.setBlockToAir(i + -1, j + 18, k + 11);
		world.setBlockToAir(i + -1, j + 18, k + 12);
		world.setBlockToAir(i + -2, j + 18, k + 12);
		world.setBlockToAir(i + -2, j + 18, k + 11);
		world.setBlockToAir(i + -2, j + 18, k + 10);
		world.setBlockToAir(i + -3, j + 18, k + 10);
		world.setBlockToAir(i + -3, j + 18, k + 9);
		world.setBlockToAir(i + -4, j + 18, k + 9);
		world.setBlockToAir(i + -5, j + 18, k + 9);
		world.setBlockToAir(i + -6, j + 18, k + 10);
		world.setBlockToAir(i + -5, j + 18, k + 10);
		world.setBlockToAir(i + -4, j + 18, k + 10);
		world.setBlockToAir(i + -3, j + 18, k + 11);
		world.setBlockToAir(i + -4, j + 18, k + 11);
		world.setBlockToAir(i + -3, j + 18, k + 12);
		world.setBlockToAir(i + -5, j + 19, k + 10);
		world.setBlockToAir(i + -4, j + 19, k + 10);
		world.setBlockToAir(i + -3, j + 19, k + 10);
		world.setBlockToAir(i + -3, j + 19, k + 11);
		world.setBlockToAir(i + -2, j + 19, k + 11);
		world.setBlockToAir(i + -2, j + 19, k + 12);
		world.setBlockToAir(i + -1, j + 19, k + 11);
		world.setBlockToAir(i + -2, j + 19, k + 10);
		world.setBlockToAir(i + -2, j + 20, k + 11);
		world.setBlockToAir(i + -2, j + 21, k + 11);
		world.setBlockToAir(i + -3, j + 20, k + 10);
		world.setBlockToAir(i + -3, j + 21, k + 10);
		world.setBlockToAir(i + -2, j + 20, k + 10);
		world.setBlockToAir(i + -4, j + 20, k + 10);
		world.setBlockToAir(i + -4, j + 19, k + 9);
		world.setBlockToAir(i + -4, j + 21, k + 10);
		world.setBlockToAir(i + -3, j + 22, k + 10);
		world.setBlockToAir(i + -3, j + 23, k + 10);
		world.setBlockToAir(i + -4, j + 22, k + 10);
		world.setBlockToAir(i + -2, j + 22, k + 11);
		world.setBlockToAir(i + -3, j + 24, k + 10);
		world.setBlockToAir(i + -3, j + 25, k + 10);
		world.setBlockToAir(i + -2, j + 21, k + 10);
		world.setBlockToAir(i + -3, j + 20, k + 11);
		world.setBlockToAir(i + -3, j + 21, k + 11);
		world.setBlockToAir(i + -5, j + 20, k + 10);
		world.setBlockToAir(i + -4, j + 19, k + 11);
		world.setBlockToAir(i + -5, j + 18, k + 11);
		world.setBlockToAir(i + -4, j + 20, k + 11);
		world.setBlockToAir(i + -5, j + 21, k + 10);
		world.setBlockToAir(i + -4, j + 23, k + 10);
		world.setBlockToAir(i + -3, j + 22, k + 11);
		world.setBlockToAir(i + -3, j + 23, k + 11);
		world.setBlockToAir(i + -3, j + 24, k + 11);
		world.setBlockToAir(i + -3, j + 26, k + 10);
		world.setBlockToAir(i + -3, j + 27, k + 10);
		world.setBlockToAir(i + -3, j + 28, k + 10);
		world.setBlockToAir(i + -4, j + 20, k + 9);
		world.createExplosion(null, (double)i + -3, (double) j + 20, (double)k + 10, 0F, false);
	}
	
	private void generatePoolCover(World world, int i, int j, int k)
	{
		world.setBlock(i + -4, j + 17, k + 12, mod_LionKing.outlandsPortalFrame.blockID, 1, 2);
		world.setBlock(i + -4, j + 17, k + 11, mod_LionKing.outlandsPortalFrame.blockID, 1, 2);
		world.setBlock(i + -3, j + 17, k + 12, mod_LionKing.outlandsPortalFrame.blockID, 1, 2);
		world.setBlock(i + -2, j + 17, k + 12, mod_LionKing.outlandsPortalFrame.blockID, 1, 2);
		world.setBlock(i + -1, j + 17, k + 12, mod_LionKing.outlandsPortalFrame.blockID, 1, 2);
		world.setBlock(i + -3, j + 17, k + 11, mod_LionKing.outlandsPortalFrame.blockID, 1, 2);
		world.setBlock(i + -2, j + 17, k + 11, mod_LionKing.outlandsPortalFrame.blockID, 1, 2);
		world.setBlock(i + -1, j + 17, k + 11, mod_LionKing.outlandsPortalFrame.blockID, 1, 2);
		world.setBlock(i + -1, j + 17, k + 10, mod_LionKing.outlandsPortalFrame.blockID, 1, 2);
		world.setBlock(i + -1, j + 18, k + 10, mod_LionKing.outlandsPortalFrame.blockID, 1, 2);
		world.setBlock(i + -2, j + 17, k + 10, mod_LionKing.outlandsPortalFrame.blockID, 1, 2);
		world.setBlock(i + -3, j + 17, k + 10, mod_LionKing.outlandsPortalFrame.blockID, 1, 2);
		world.setBlock(i + -4, j + 17, k + 10, mod_LionKing.outlandsPortalFrame.blockID, 1, 2);
		world.setBlock(i + -2, j + 17, k + 9, mod_LionKing.outlandsPortalFrame.blockID, 1, 2);
		world.setBlock(i + -3, j + 17, k + 9, mod_LionKing.outlandsPortalFrame.blockID, 1, 2);
		world.setBlock(i + -4, j + 17, k + 9, mod_LionKing.outlandsPortalFrame.blockID, 1, 2);
		world.setBlock(i + -4, j + 17, k + 8, mod_LionKing.outlandsPortalFrame.blockID, 1, 2);
		world.setBlock(i + -5, j + 17, k + 8, mod_LionKing.outlandsPortalFrame.blockID, 1, 2);
		world.setBlock(i + -6, j + 17, k + 8, mod_LionKing.outlandsPortalFrame.blockID, 1, 2);
		world.setBlock(i + -5, j + 17, k + 9, mod_LionKing.outlandsPortalFrame.blockID, 1, 2);
		world.setBlock(i + -6, j + 17, k + 9, mod_LionKing.outlandsPortalFrame.blockID, 1, 2);
		world.setBlock(i + -5, j + 17, k + 10, mod_LionKing.outlandsPortalFrame.blockID, 1, 2);
		world.setBlock(i + -6, j + 17, k + 10, mod_LionKing.outlandsPortalFrame.blockID, 1, 2);
		world.setBlock(i + -5, j + 17, k + 11, mod_LionKing.outlandsPortalFrame.blockID, 1, 2);
		world.setBlock(i + -1, j + 18, k + 11, mod_LionKing.outlandsPortalFrame.blockID, 1, 2);
		world.setBlock(i + -1, j + 18, k + 12, mod_LionKing.outlandsPortalFrame.blockID, 1, 2);
		world.setBlock(i + -2, j + 18, k + 12, mod_LionKing.outlandsPortalFrame.blockID, 1, 2);
		world.setBlock(i + -2, j + 18, k + 11, mod_LionKing.outlandsPortalFrame.blockID, 1, 2);
		world.setBlock(i + -2, j + 18, k + 10, mod_LionKing.outlandsPortalFrame.blockID, 1, 2);
		world.setBlock(i + -3, j + 18, k + 10, mod_LionKing.outlandsPortalFrame.blockID, 1, 2);
		world.setBlock(i + -3, j + 18, k + 9, mod_LionKing.outlandsPortalFrame.blockID, 1, 2);
		world.setBlock(i + -4, j + 18, k + 9, mod_LionKing.outlandsPortalFrame.blockID, 1, 2);
		world.setBlock(i + -5, j + 18, k + 9, mod_LionKing.outlandsPortalFrame.blockID, 1, 2);
		world.setBlock(i + -6, j + 18, k + 10, mod_LionKing.outlandsPortalFrame.blockID, 1, 2);
		world.setBlock(i + -5, j + 18, k + 10, mod_LionKing.outlandsPortalFrame.blockID, 1, 2);
		world.setBlock(i + -4, j + 18, k + 10, mod_LionKing.outlandsPortalFrame.blockID, 1, 2);
		world.setBlock(i + -3, j + 18, k + 11, mod_LionKing.outlandsPortalFrame.blockID, 1, 2);
		world.setBlock(i + -4, j + 18, k + 11, mod_LionKing.outlandsPortalFrame.blockID, 1, 2);
		world.setBlock(i + -3, j + 18, k + 12, mod_LionKing.outlandsPortalFrame.blockID, 1, 2);
		world.setBlock(i + -5, j + 19, k + 10, mod_LionKing.outlandsPortalFrame.blockID, 1, 2);
		world.setBlock(i + -4, j + 19, k + 10, mod_LionKing.outlandsPortalFrame.blockID, 1, 2);
		world.setBlock(i + -3, j + 19, k + 10, mod_LionKing.outlandsPortalFrame.blockID, 1, 2);
		world.setBlock(i + -3, j + 19, k + 11, mod_LionKing.outlandsPortalFrame.blockID, 1, 2);
		world.setBlock(i + -2, j + 19, k + 11, mod_LionKing.outlandsPortalFrame.blockID, 1, 2);
		world.setBlock(i + -2, j + 19, k + 12, mod_LionKing.outlandsPortalFrame.blockID, 1, 2);
		world.setBlock(i + -1, j + 19, k + 11, mod_LionKing.outlandsPortalFrame.blockID, 1, 2);
		world.setBlock(i + -2, j + 19, k + 10, mod_LionKing.outlandsPortalFrame.blockID, 1, 2);
		world.setBlock(i + -2, j + 20, k + 11, mod_LionKing.outlandsPortalFrame.blockID, 1, 2);
		world.setBlock(i + -2, j + 21, k + 11, mod_LionKing.outlandsPortalFrame.blockID, 1, 2);
		world.setBlock(i + -3, j + 20, k + 10, mod_LionKing.outlandsPortalFrame.blockID, 1, 2);
		world.setBlock(i + -3, j + 21, k + 10, mod_LionKing.outlandsPortalFrame.blockID, 1, 2);
		world.setBlock(i + -2, j + 20, k + 10, mod_LionKing.outlandsPortalFrame.blockID, 1, 2);
		world.setBlock(i + -4, j + 20, k + 10, mod_LionKing.outlandsPortalFrame.blockID, 1, 2);
		world.setBlock(i + -4, j + 19, k + 9, mod_LionKing.outlandsPortalFrame.blockID, 1, 2);
		world.setBlock(i + -4, j + 21, k + 10, mod_LionKing.outlandsPortalFrame.blockID, 1, 2);
		world.setBlock(i + -3, j + 22, k + 10, mod_LionKing.outlandsPortalFrame.blockID, 1, 2);
		world.setBlock(i + -3, j + 23, k + 10, mod_LionKing.outlandsPortalFrame.blockID, 1, 2);
		world.setBlock(i + -4, j + 22, k + 10, mod_LionKing.outlandsPortalFrame.blockID, 1, 2);
		world.setBlock(i + -2, j + 22, k + 11, mod_LionKing.outlandsPortalFrame.blockID, 1, 2);
		world.setBlock(i + -3, j + 24, k + 10, mod_LionKing.outlandsPortalFrame.blockID, 1, 2);
		world.setBlock(i + -3, j + 25, k + 10, mod_LionKing.outlandsPortalFrame.blockID, 1, 2);
		world.setBlock(i + -2, j + 21, k + 10, mod_LionKing.outlandsPortalFrame.blockID, 1, 2);
		world.setBlock(i + -3, j + 20, k + 11, mod_LionKing.outlandsPortalFrame.blockID, 1, 2);
		world.setBlock(i + -3, j + 21, k + 11, mod_LionKing.outlandsPortalFrame.blockID, 1, 2);
		world.setBlock(i + -5, j + 20, k + 10, mod_LionKing.outlandsPortalFrame.blockID, 1, 2);
		world.setBlock(i + -4, j + 19, k + 11, mod_LionKing.outlandsPortalFrame.blockID, 1, 2);
		world.setBlock(i + -5, j + 18, k + 11, mod_LionKing.outlandsPortalFrame.blockID, 1, 2);
		world.setBlock(i + -4, j + 20, k + 11, mod_LionKing.outlandsPortalFrame.blockID, 1, 2);
		world.setBlock(i + -5, j + 21, k + 10, mod_LionKing.outlandsPortalFrame.blockID, 1, 2);
		world.setBlock(i + -4, j + 23, k + 10, mod_LionKing.outlandsPortalFrame.blockID, 1, 2);
		world.setBlock(i + -3, j + 22, k + 11, mod_LionKing.outlandsPortalFrame.blockID, 1, 2);
		world.setBlock(i + -3, j + 23, k + 11, mod_LionKing.outlandsPortalFrame.blockID, 1, 2);
		world.setBlock(i + -3, j + 24, k + 11, mod_LionKing.outlandsPortalFrame.blockID, 1, 2);
		world.setBlock(i + -3, j + 26, k + 10, mod_LionKing.outlandsPortalFrame.blockID, 1, 2);
		world.setBlock(i + -3, j + 27, k + 10, mod_LionKing.outlandsPortalFrame.blockID, 1, 2);
		world.setBlock(i + -3, j + 28, k + 10, mod_LionKing.outlandsPortalFrame.blockID, 1, 2);
		world.setBlock(i + -4, j + 20, k + 9, mod_LionKing.outlandsPortalFrame.blockID, 1, 2);
	}
	
	private void generate0(World world, int i, int j, int k)
	{
		world.setBlock(i + 0, j + 3, k + -1, mod_LionKing.outlandsPortalFrame.blockID, 1, 2);
		world.setBlock(i + 0, j + 3, k + 0, mod_LionKing.outlandsPortalFrame.blockID, 1, 2);
		world.setBlock(i + 0, j + 3, k + 1, mod_LionKing.outlandsPortalFrame.blockID, 1, 2);
		world.setBlock(i + 1, j + 3, k + 0, mod_LionKing.outlandsPortalFrame.blockID, 1, 2);
		world.setBlock(i + -1, j + 3, k + 0, mod_LionKing.outlandsPortalFrame.blockID, 1, 2);
		world.setBlock(i + -1, j + 3, k + -1, mod_LionKing.outlandsPortalFrame.blockID, 1, 2);
		world.setBlock(i + -1, j + 3, k + 1, mod_LionKing.outlandsPortalFrame.blockID, 1, 2);
		world.setBlock(i + 1, j + 3, k + 1, mod_LionKing.outlandsPortalFrame.blockID, 1, 2);
		world.setBlock(i + 1, j + 3, k + -1, mod_LionKing.outlandsPortalFrame.blockID, 1, 2);
		world.setBlock(i + 1, j + 3, k + -2, mod_LionKing.outlandsPortalFrame.blockID, 1, 2);
		world.setBlock(i + 0, j + 3, k + -2, mod_LionKing.outlandsPortalFrame.blockID, 1, 2);
		world.setBlock(i + -1, j + 3, k + -2, mod_LionKing.outlandsPortalFrame.blockID, 1, 2);
		world.setBlock(i + -2, j + 3, k + -2, mod_LionKing.outlandsPortalFrame.blockID, 1, 2);
		world.setBlock(i + -2, j + 3, k + -1, mod_LionKing.outlandsPortalFrame.blockID, 1, 2);
		world.setBlock(i + -2, j + 3, k + 0, mod_LionKing.outlandsPortalFrame.blockID, 1, 2);
		world.setBlock(i + -2, j + 4, k + 2, mod_LionKing.outlandsPortalFrame.blockID, 1, 2);
		world.setBlock(i + -2, j + 4, k + 2, 0, 0, 2);
		world.setBlock(i + -2, j + 3, k + 2, mod_LionKing.outlandsPortalFrame.blockID, 1, 2);
		world.setBlock(i + -2, j + 3, k + 1, mod_LionKing.outlandsPortalFrame.blockID, 1, 2);
		world.setBlock(i + -1, j + 3, k + 2, mod_LionKing.outlandsPortalFrame.blockID, 1, 2);
		world.setBlock(i + 0, j + 3, k + 2, mod_LionKing.outlandsPortalFrame.blockID, 1, 2);
		world.setBlock(i + 1, j + 3, k + 2, mod_LionKing.outlandsPortalFrame.blockID, 1, 2);
		world.setBlock(i + 2, j + 3, k + 2, mod_LionKing.outlandsPortalFrame.blockID, 1, 2);
		world.setBlock(i + 2, j + 3, k + 1, mod_LionKing.outlandsPortalFrame.blockID, 1, 2);
		world.setBlock(i + 2, j + 3, k + 0, mod_LionKing.outlandsPortalFrame.blockID, 1, 2);
		world.setBlock(i + 2, j + 3, k + -1, mod_LionKing.outlandsPortalFrame.blockID, 1, 2);
		world.setBlock(i + 2, j + 3, k + -2, mod_LionKing.outlandsPortalFrame.blockID, 1, 2);
		world.setBlock(i + 0, j + 4, k + -1, mod_LionKing.outlandsPortalFrame.blockID, 1, 2);
		world.setBlock(i + -1, j + 4, k + -1, mod_LionKing.outlandsPortalFrame.blockID, 1, 2);
		world.setBlock(i + -1, j + 4, k + 0, mod_LionKing.outlandsPortalFrame.blockID, 1, 2);
		world.setBlock(i + 0, j + 4, k + 0, mod_LionKing.outlandsPortalFrame.blockID, 1, 2);
		world.setBlock(i + 0, j + 4, k + 1, mod_LionKing.outlandsPortalFrame.blockID, 1, 2);
		world.setBlock(i + -1, j + 4, k + 1, mod_LionKing.outlandsPortalFrame.blockID, 1, 2);
		world.setBlock(i + 1, j + 4, k + -1, mod_LionKing.outlandsPortalFrame.blockID, 1, 2);
		world.setBlock(i + 1, j + 4, k + 0, mod_LionKing.outlandsPortalFrame.blockID, 1, 2);
		world.setBlock(i + 1, j + 4, k + 1, mod_LionKing.outlandsPortalFrame.blockID, 1, 2);
		world.setBlock(i + -1, j + 4, k + -1, 0, 0, 2);
		world.setBlock(i + 1, j + 4, k + -1, 0, 0, 2);
		world.setBlock(i + 1, j + 4, k + 1, 0, 0, 2);
		world.setBlock(i + -1, j + 4, k + 1, 0, 0, 2);
		world.setBlock(i + 1, j + 5, k + 0, mod_LionKing.outlandsPortalFrame.blockID, 1, 2);
		world.setBlock(i + 0, j + 5, k + -1, mod_LionKing.outlandsPortalFrame.blockID, 1, 2);
		world.setBlock(i + 0, j + 5, k + 0, mod_LionKing.outlandsPortalFrame.blockID, 1, 2);
		world.setBlock(i + 0, j + 5, k + 1, mod_LionKing.outlandsPortalFrame.blockID, 1, 2);
		world.setBlock(i + -1, j + 5, k + 0, mod_LionKing.outlandsPortalFrame.blockID, 1, 2);
		world.setBlock(i + -1, j + 6, k + 0, mod_LionKing.outlandsPortalFrame.blockID, 1, 2);
		world.setBlock(i + -1, j + 6, k + -1, mod_LionKing.outlandsPortalFrame.blockID, 1, 2);
		world.setBlock(i + 0, j + 6, k + -1, mod_LionKing.outlandsPortalFrame.blockID, 1, 2);
		world.setBlock(i + 1, j + 6, k + -1, mod_LionKing.outlandsPortalFrame.blockID, 1, 2);
		world.setBlock(i + 0, j + 6, k + 0, mod_LionKing.outlandsPortalFrame.blockID, 1, 2);
		world.setBlock(i + 1, j + 6, k + 0, mod_LionKing.outlandsPortalFrame.blockID, 1, 2);
		world.setBlock(i + 0, j + 6, k + 1, mod_LionKing.outlandsPortalFrame.blockID, 1, 2);
		world.setBlock(i + -1, j + 6, k + 1, mod_LionKing.outlandsPortalFrame.blockID, 1, 2);
		world.setBlock(i + 1, j + 6, k + 1, mod_LionKing.outlandsPortalFrame.blockID, 1, 2);
		world.setBlock(i + 1, j + 7, k + -1, mod_LionKing.outlandsPortalFrame.blockID, 1, 2);
		world.setBlock(i + 0, j + 7, k + -1, mod_LionKing.outlandsPortalFrame.blockID, 1, 2);
		world.setBlock(i + -1, j + 7, k + -1, mod_LionKing.outlandsPortalFrame.blockID, 1, 2);
		world.setBlock(i + -2, j + 6, k + -1, mod_LionKing.outlandsPortalFrame.blockID, 1, 2);
		world.setBlock(i + -2, j + 6, k + -1, 0, 0, 2);
		world.setBlock(i + 0, j + 7, k + 0, mod_LionKing.outlandsPortalFrame.blockID, 1, 2);
		world.setBlock(i + -1, j + 7, k + 0, mod_LionKing.outlandsPortalFrame.blockID, 1, 2);
		world.setBlock(i + -1, j + 7, k + 1, mod_LionKing.outlandsPortalFrame.blockID, 1, 2);
		world.setBlock(i + 1, j + 7, k + 0, mod_LionKing.outlandsPortalFrame.blockID, 1, 2);
		world.setBlock(i + 1, j + 7, k + 1, mod_LionKing.outlandsPortalFrame.blockID, 1, 2);
		world.setBlock(i + 0, j + 7, k + 1, mod_LionKing.outlandsPortalFrame.blockID, 1, 2);
		world.setBlock(i + -2, j + 7, k + 0, mod_LionKing.outlandsPortalFrame.blockID, 1, 2);
		world.setBlock(i + -2, j + 7, k + 0, 0, 0, 2);
		world.setBlock(i + -2, j + 6, k + 0, mod_LionKing.outlandsPortalFrame.blockID, 1, 2);
		world.setBlock(i + -3, j + 6, k + 0, mod_LionKing.outlandsPortalFrame.blockID, 1, 2);
		world.setBlock(i + -7, j + 4, k + 0, mod_LionKing.outlandsPortalFrame.blockID, 1, 2);
		world.setBlock(i + -3, j + 5, k + 0, mod_LionKing.outlandsPortalFrame.blockID, 1, 2);
		world.setBlock(i + -4, j + 5, k + 0, mod_LionKing.outlandsPortalFrame.blockID, 1, 2);
		world.setBlock(i + -3, j + 5, k + 0, 0, 0, 2);
		world.setBlock(i + -5, j + 5, k + 0, mod_LionKing.outlandsPortalFrame.blockID, 1, 2);
		world.setBlock(i + -6, j + 4, k + 0, mod_LionKing.outlandsPortalFrame.blockID, 1, 2);
		world.setBlock(i + 1, j + 7, k + -2, mod_LionKing.outlandsPortalFrame.blockID, 1, 2);
		world.setBlock(i + -1, j + 7, k + -2, mod_LionKing.outlandsPortalFrame.blockID, 1, 2);
		world.setBlock(i + 0, j + 7, k + -2, mod_LionKing.outlandsPortalFrame.blockID, 1, 2);
		world.setBlock(i + 2, j + 7, k + -1, mod_LionKing.outlandsPortalFrame.blockID, 1, 2);
		world.setBlock(i + 2, j + 7, k + -1, 0, 0, 2);
		world.setBlock(i + 1, j + 7, k + -2, 0, 0, 2);
		world.setBlock(i + 0, j + 7, k + -2, 0, 0, 2);
		world.setBlock(i + -1, j + 7, k + -2, 0, 0, 2);
		world.setBlock(i + 1, j + 7, k + -2, mod_LionKing.outlandsPortalFrame.blockID, 1, 2);
		world.setBlock(i + 2, j + 7, k + -2, mod_LionKing.outlandsPortalFrame.blockID, 1, 2);
		world.setBlock(i + 2, j + 8, k + -2, mod_LionKing.outlandsPortalFrame.blockID, 1, 2);
		world.setBlock(i + 1, j + 7, k + -2, 0, 0, 2);
		world.setBlock(i + 2, j + 7, k + -2, 0, 0, 2);
		world.setBlock(i + 2, j + 8, k + -2, 0, 0, 2);
		world.setBlock(i + -1, j + 7, k + 0, 0, 0, 2);
		world.setBlock(i + -1, j + 7, k + 0, mod_LionKing.outlandsPortalFrame.blockID, 1, 2);
		world.setBlock(i + -2, j + 7, k + 0, mod_LionKing.outlandsPortalFrame.blockID, 1, 2);
		world.setBlock(i + -4, j + 6, k + 0, mod_LionKing.outlandsPortalFrame.blockID, 1, 2);
		world.setBlock(i + -2, j + 6, k + 0, 0, 0, 2);
		world.setBlock(i + -4, j + 5, k + 0, 0, 0, 2);
		world.setBlock(i + -6, j + 5, k + 0, mod_LionKing.outlandsPortalFrame.blockID, 1, 2);
		world.setBlock(i + -6, j + 4, k + 0, 0, 0, 2);
		world.setBlock(i + -8, j + 4, k + 0, mod_LionKing.outlandsPortalFrame.blockID, 1, 2);
		world.setBlock(i + 2, j + 3, k + -3, mod_LionKing.outlandsPortalFrame.blockID, 1, 2);
		world.setBlock(i + 2, j + 3, k + -3, 0, 0, 2);
		world.setBlock(i + 3, j + 3, k + -3, mod_LionKing.outlandsPortalFrame.blockID, 1, 2);
		world.setBlock(i + 4, j + 3, k + -4, mod_LionKing.outlandsPortalFrame.blockID, 1, 2);
		world.setBlock(i + 5, j + 3, k + -5, mod_LionKing.outlandsPortalFrame.blockID, 1, 2);
		world.setBlock(i + 6, j + 3, k + -6, mod_LionKing.outlandsPortalFrame.blockID, 1, 2);
		world.setBlock(i + -3, j + 3, k + -3, mod_LionKing.outlandsPortalFrame.blockID, 1, 2);
		world.setBlock(i + -4, j + 3, k + -4, mod_LionKing.outlandsPortalFrame.blockID, 1, 2);
		world.setBlock(i + -5, j + 3, k + -5, mod_LionKing.outlandsPortalFrame.blockID, 1, 2);
		world.setBlock(i + -6, j + 3, k + -6, mod_LionKing.outlandsPortalFrame.blockID, 1, 2);
		world.setBlock(i + -7, j + 3, k + -7, mod_LionKing.outlandsPortalFrame.blockID, 1, 2);
		world.setBlock(i + 7, j + 3, k + -7, mod_LionKing.outlandsPortalFrame.blockID, 1, 2);
		world.setBlock(i + 3, j + 4, k + 3, mod_LionKing.outlandsPortalFrame.blockID, 1, 2);
		world.setBlock(i + 3, j + 4, k + 3, 0, 0, 2);
		world.setBlock(i + 3, j + 3, k + 3, mod_LionKing.outlandsPortalFrame.blockID, 1, 2);
		world.setBlock(i + 4, j + 3, k + 4, mod_LionKing.outlandsPortalFrame.blockID, 1, 2);
		world.setBlock(i + 5, j + 3, k + 5, mod_LionKing.outlandsPortalFrame.blockID, 1, 2);
		world.setBlock(i + 6, j + 3, k + 6, mod_LionKing.outlandsPortalFrame.blockID, 1, 2);
		world.setBlock(i + 7, j + 3, k + 7, mod_LionKing.outlandsPortalFrame.blockID, 1, 2);
		world.setBlock(i + -3, j + 3, k + 3, mod_LionKing.outlandsPortalFrame.blockID, 1, 2);
		world.setBlock(i + -4, j + 3, k + 4, mod_LionKing.outlandsPortalFrame.blockID, 1, 2);
		world.setBlock(i + -5, j + 3, k + 5, mod_LionKing.outlandsPortalFrame.blockID, 1, 2);
		world.setBlock(i + -6, j + 3, k + 6, mod_LionKing.outlandsPortalFrame.blockID, 1, 2);
		world.setBlock(i + -7, j + 3, k + 7, mod_LionKing.outlandsPortalFrame.blockID, 1, 2);
		world.setBlock(i + 2, j + 3, k + -3, mod_LionKing.outlandsPortalFrame.blockID, 1, 2);
		world.setBlock(i + 1, j + 3, k + -3, mod_LionKing.outlandsPortalFrame.blockID, 1, 2);
		world.setBlock(i + 0, j + 3, k + -3, mod_LionKing.outlandsPortalFrame.blockID, 1, 2);
		world.setBlock(i + -1, j + 3, k + -3, mod_LionKing.outlandsPortalFrame.blockID, 1, 2);
		world.setBlock(i + -2, j + 3, k + -3, mod_LionKing.outlandsPortalFrame.blockID, 1, 2);
		world.setBlock(i + -7, j + 3, k + 1, mod_LionKing.outlandsPortalFrame.blockID, 1, 2);
		world.setBlock(i + -7, j + 3, k + 0, mod_LionKing.outlandsPortalFrame.blockID, 1, 2);
		world.setBlock(i + -7, j + 3, k + -1, mod_LionKing.outlandsPortalFrame.blockID, 1, 2);
		world.setBlock(i + -8, j + 3, k + 1, mod_LionKing.outlandsPortalFrame.blockID, 1, 2);
		world.setBlock(i + -8, j + 3, k + 0, mod_LionKing.outlandsPortalFrame.blockID, 1, 2);
		world.setBlock(i + -8, j + 3, k + -1, mod_LionKing.outlandsPortalFrame.blockID, 1, 2);
		world.setBlock(i + -8, j + 3, k + -2, mod_LionKing.outlandsPortalFrame.blockID, 1, 2);
		world.setBlock(i + -8, j + 3, k + -3, mod_LionKing.outlandsPortalFrame.blockID, 1, 2);
		world.setBlock(i + -8, j + 3, k + -4, mod_LionKing.outlandsPortalFrame.blockID, 1, 2);
		world.setBlock(i + -8, j + 3, k + -5, mod_LionKing.outlandsPortalFrame.blockID, 1, 2);
		world.setBlock(i + -8, j + 3, k + -6, mod_LionKing.outlandsPortalFrame.blockID, 1, 2);
		world.setBlock(i + -6, j + 3, k + -8, mod_LionKing.outlandsPortalFrame.blockID, 1, 2);
		world.setBlock(i + -7, j + 3, k + -6, mod_LionKing.outlandsPortalFrame.blockID, 1, 2);
		world.setBlock(i + -6, j + 3, k + -7, mod_LionKing.outlandsPortalFrame.blockID, 1, 2);
		world.setBlock(i + -6, j + 3, k + -5, mod_LionKing.outlandsPortalFrame.blockID, 1, 2);
		world.setBlock(i + -7, j + 3, k + -5, mod_LionKing.outlandsPortalFrame.blockID, 1, 2);
		world.setBlock(i + -6, j + 3, k + -4, mod_LionKing.outlandsPortalFrame.blockID, 1, 2);
		world.setBlock(i + -7, j + 3, k + -4, mod_LionKing.outlandsPortalFrame.blockID, 1, 2);
		world.setBlock(i + -7, j + 3, k + -3, mod_LionKing.outlandsPortalFrame.blockID, 1, 2);
		world.setBlock(i + -7, j + 3, k + -2, mod_LionKing.outlandsPortalFrame.blockID, 1, 2);
		world.setBlock(i + -6, j + 3, k + -1, mod_LionKing.outlandsPortalFrame.blockID, 1, 2);
		world.setBlock(i + -6, j + 3, k + -2, mod_LionKing.outlandsPortalFrame.blockID, 1, 2);
		world.setBlock(i + -6, j + 3, k + -3, mod_LionKing.outlandsPortalFrame.blockID, 1, 2);
		world.setBlock(i + -5, j + 3, k + -4, mod_LionKing.outlandsPortalFrame.blockID, 1, 2);
		world.setBlock(i + -5, j + 3, k + -3, mod_LionKing.outlandsPortalFrame.blockID, 1, 2);
		world.setBlock(i + -4, j + 3, k + -3, mod_LionKing.outlandsPortalFrame.blockID, 1, 2);
		world.setBlock(i + -3, j + 3, k + -2, mod_LionKing.outlandsPortalFrame.blockID, 1, 2);
		world.setBlock(i + -5, j + 3, k + -2, mod_LionKing.outlandsPortalFrame.blockID, 1, 2);
		world.setBlock(i + -4, j + 3, k + -2, mod_LionKing.outlandsPortalFrame.blockID, 1, 2);
		world.setBlock(i + -3, j + 3, k + -1, mod_LionKing.outlandsPortalFrame.blockID, 1, 2);
		world.setBlock(i + -4, j + 3, k + -1, mod_LionKing.outlandsPortalFrame.blockID, 1, 2);
		world.setBlock(i + -5, j + 3, k + -1, mod_LionKing.outlandsPortalFrame.blockID, 1, 2);
		world.setBlock(i + -6, j + 3, k + 0, mod_LionKing.outlandsPortalFrame.blockID, 1, 2);
		world.setBlock(i + -5, j + 3, k + 0, mod_LionKing.outlandsPortalFrame.blockID, 1, 2);
		world.setBlock(i + -4, j + 3, k + 0, mod_LionKing.outlandsPortalFrame.blockID, 1, 2);
		world.setBlock(i + -3, j + 3, k + 0, mod_LionKing.outlandsPortalFrame.blockID, 1, 2);
		world.setBlock(i + -3, j + 3, k + 1, mod_LionKing.outlandsPortalFrame.blockID, 1, 2);
		world.setBlock(i + -4, j + 3, k + 1, mod_LionKing.outlandsPortalFrame.blockID, 1, 2);
		world.setBlock(i + -5, j + 3, k + 1, mod_LionKing.outlandsPortalFrame.blockID, 1, 2);
		world.setBlock(i + -6, j + 3, k + 1, mod_LionKing.outlandsPortalFrame.blockID, 1, 2);
		world.setBlock(i + -8, j + 3, k + 2, mod_LionKing.outlandsPortalFrame.blockID, 1, 2);
		world.setBlock(i + -7, j + 3, k + 2, mod_LionKing.outlandsPortalFrame.blockID, 1, 2);
		world.setBlock(i + -6, j + 3, k + 2, mod_LionKing.outlandsPortalFrame.blockID, 1, 2);
		world.setBlock(i + -5, j + 3, k + 2, mod_LionKing.outlandsPortalFrame.blockID, 1, 2);
		world.setBlock(i + -4, j + 3, k + 2, mod_LionKing.outlandsPortalFrame.blockID, 1, 2);
		world.setBlock(i + -3, j + 3, k + 2, mod_LionKing.outlandsPortalFrame.blockID, 1, 2);
		world.setBlock(i + -8, j + 3, k + 3, mod_LionKing.outlandsPortalFrame.blockID, 1, 2);
		world.setBlock(i + -8, j + 3, k + 4, mod_LionKing.outlandsPortalFrame.blockID, 1, 2);
		world.setBlock(i + -8, j + 3, k + 5, mod_LionKing.outlandsPortalFrame.blockID, 1, 2);
		world.setBlock(i + -8, j + 3, k + 6, mod_LionKing.outlandsPortalFrame.blockID, 1, 2);
		world.setBlock(i + -7, j + 3, k + 6, mod_LionKing.outlandsPortalFrame.blockID, 1, 2);
		world.setBlock(i + -7, j + 3, k + 5, mod_LionKing.outlandsPortalFrame.blockID, 1, 2);
		world.setBlock(i + -7, j + 3, k + 4, mod_LionKing.outlandsPortalFrame.blockID, 1, 2);
		world.setBlock(i + -7, j + 3, k + 3, mod_LionKing.outlandsPortalFrame.blockID, 1, 2);
		world.setBlock(i + -6, j + 3, k + 3, mod_LionKing.outlandsPortalFrame.blockID, 1, 2);
		world.setBlock(i + -6, j + 3, k + 4, mod_LionKing.outlandsPortalFrame.blockID, 1, 2);
		world.setBlock(i + -6, j + 3, k + 5, mod_LionKing.outlandsPortalFrame.blockID, 1, 2);
		world.setBlock(i + -5, j + 3, k + 4, mod_LionKing.outlandsPortalFrame.blockID, 1, 2);
		world.setBlock(i + -5, j + 3, k + 3, mod_LionKing.outlandsPortalFrame.blockID, 1, 2);
		world.setBlock(i + -4, j + 3, k + 3, mod_LionKing.outlandsPortalFrame.blockID, 1, 2);
		world.setBlock(i + -5, j + 3, k + -8, mod_LionKing.outlandsPortalFrame.blockID, 1, 2);
		world.setBlock(i + -4, j + 3, k + -8, mod_LionKing.outlandsPortalFrame.blockID, 1, 2);
		world.setBlock(i + -3, j + 3, k + -8, mod_LionKing.outlandsPortalFrame.blockID, 1, 2);
		world.setBlock(i + -2, j + 3, k + -8, mod_LionKing.outlandsPortalFrame.blockID, 1, 2);
		world.setBlock(i + -1, j + 3, k + -8, mod_LionKing.outlandsPortalFrame.blockID, 1, 2);
		world.setBlock(i + 0, j + 3, k + -8, mod_LionKing.outlandsPortalFrame.blockID, 1, 2);
		world.setBlock(i + 1, j + 3, k + -8, mod_LionKing.outlandsPortalFrame.blockID, 1, 2);
		world.setBlock(i + 2, j + 3, k + -8, mod_LionKing.outlandsPortalFrame.blockID, 1, 2);
		world.setBlock(i + 3, j + 3, k + -8, mod_LionKing.outlandsPortalFrame.blockID, 1, 2);
		world.setBlock(i + 4, j + 3, k + -8, mod_LionKing.outlandsPortalFrame.blockID, 1, 2);
		world.setBlock(i + 5, j + 3, k + -8, mod_LionKing.outlandsPortalFrame.blockID, 1, 2);
		world.setBlock(i + 6, j + 3, k + -8, mod_LionKing.outlandsPortalFrame.blockID, 1, 2);
		world.setBlock(i + 6, j + 3, k + -7, mod_LionKing.outlandsPortalFrame.blockID, 1, 2);
		world.setBlock(i + 5, j + 3, k + -7, mod_LionKing.outlandsPortalFrame.blockID, 1, 2);
		world.setBlock(i + 5, j + 3, k + -6, mod_LionKing.outlandsPortalFrame.blockID, 1, 2);
		world.setBlock(i + 4, j + 3, k + -6, mod_LionKing.outlandsPortalFrame.blockID, 1, 2);
		world.setBlock(i + 4, j + 3, k + -5, mod_LionKing.outlandsPortalFrame.blockID, 1, 2);
		world.setBlock(i + 4, j + 3, k + -7, mod_LionKing.outlandsPortalFrame.blockID, 1, 2);
		world.setBlock(i + 3, j + 3, k + -7, mod_LionKing.outlandsPortalFrame.blockID, 1, 2);
		world.setBlock(i + 3, j + 3, k + -6, mod_LionKing.outlandsPortalFrame.blockID, 1, 2);
		world.setBlock(i + 3, j + 3, k + -5, mod_LionKing.outlandsPortalFrame.blockID, 1, 2);
		world.setBlock(i + 3, j + 3, k + -4, mod_LionKing.outlandsPortalFrame.blockID, 1, 2);
		world.setBlock(i + 2, j + 3, k + -4, mod_LionKing.outlandsPortalFrame.blockID, 1, 2);
		world.setBlock(i + 2, j + 3, k + -5, mod_LionKing.outlandsPortalFrame.blockID, 1, 2);
		world.setBlock(i + 2, j + 3, k + -6, mod_LionKing.outlandsPortalFrame.blockID, 1, 2);
		world.setBlock(i + 2, j + 3, k + -7, mod_LionKing.outlandsPortalFrame.blockID, 1, 2);
		world.setBlock(i + 1, j + 3, k + -7, mod_LionKing.outlandsPortalFrame.blockID, 1, 2);
		world.setBlock(i + 1, j + 3, k + -6, mod_LionKing.outlandsPortalFrame.blockID, 1, 2);
		world.setBlock(i + 0, j + 4, k + -5, mod_LionKing.outlandsPortalFrame.blockID, 1, 2);
		world.setBlock(i + 1, j + 3, k + -4, mod_LionKing.outlandsPortalFrame.blockID, 1, 2);
		world.setBlock(i + 0, j + 4, k + -5, 0, 0, 2);
		world.setBlock(i + 1, j + 3, k + -5, mod_LionKing.outlandsPortalFrame.blockID, 1, 2);
		world.setBlock(i + 0, j + 3, k + -5, mod_LionKing.outlandsPortalFrame.blockID, 1, 2);
		world.setBlock(i + 0, j + 3, k + -4, mod_LionKing.outlandsPortalFrame.blockID, 1, 2);
		world.setBlock(i + -1, j + 3, k + -4, mod_LionKing.outlandsPortalFrame.blockID, 1, 2);
		world.setBlock(i + -1, j + 3, k + -5, mod_LionKing.outlandsPortalFrame.blockID, 1, 2);
		world.setBlock(i + -1, j + 3, k + -6, mod_LionKing.outlandsPortalFrame.blockID, 1, 2);
		world.setBlock(i + 0, j + 3, k + -6, mod_LionKing.outlandsPortalFrame.blockID, 1, 2);
		world.setBlock(i + 0, j + 3, k + -7, mod_LionKing.outlandsPortalFrame.blockID, 1, 2);
		world.setBlock(i + -1, j + 3, k + -7, mod_LionKing.outlandsPortalFrame.blockID, 1, 2);
		world.setBlock(i + -2, j + 3, k + -7, mod_LionKing.outlandsPortalFrame.blockID, 1, 2);
		world.setBlock(i + -2, j + 3, k + -6, mod_LionKing.outlandsPortalFrame.blockID, 1, 2);
		world.setBlock(i + -2, j + 3, k + -5, mod_LionKing.outlandsPortalFrame.blockID, 1, 2);
		world.setBlock(i + -2, j + 3, k + -4, mod_LionKing.outlandsPortalFrame.blockID, 1, 2);
		world.setBlock(i + -3, j + 3, k + -4, mod_LionKing.outlandsPortalFrame.blockID, 1, 2);
		world.setBlock(i + -3, j + 3, k + -5, mod_LionKing.outlandsPortalFrame.blockID, 1, 2);
		world.setBlock(i + -4, j + 3, k + -5, mod_LionKing.outlandsPortalFrame.blockID, 1, 2);
		world.setBlock(i + -4, j + 3, k + -6, mod_LionKing.outlandsPortalFrame.blockID, 1, 2);
		world.setBlock(i + -3, j + 3, k + -6, mod_LionKing.outlandsPortalFrame.blockID, 1, 2);
		world.setBlock(i + -3, j + 3, k + -7, mod_LionKing.outlandsPortalFrame.blockID, 1, 2);
		world.setBlock(i + -4, j + 3, k + -7, mod_LionKing.outlandsPortalFrame.blockID, 1, 2);
		world.setBlock(i + -5, j + 3, k + -7, mod_LionKing.outlandsPortalFrame.blockID, 1, 2);
		world.setBlock(i + -5, j + 3, k + -6, mod_LionKing.outlandsPortalFrame.blockID, 1, 2);
		world.setBlock(i + -9, j + 4, k + 0, mod_LionKing.outlandsPortalFrame.blockID, 1, 2);
		world.setBlock(i + -10, j + 4, k + 0, mod_LionKing.outlandsPortalFrame.blockID, 1, 2);
		world.setBlock(i + -9, j + 4, k + 0, 0, 0, 2);
		world.setBlock(i + -10, j + 4, k + 0, 0, 0, 2);
		world.setBlock(i + -6, j + 3, k + 7, mod_LionKing.outlandsPortalFrame.blockID, 1, 2);
		world.setBlock(i + -5, j + 3, k + 7, mod_LionKing.outlandsPortalFrame.blockID, 1, 2);
		world.setBlock(i + -4, j + 3, k + 7, mod_LionKing.outlandsPortalFrame.blockID, 1, 2);
		world.setBlock(i + -3, j + 3, k + 7, mod_LionKing.outlandsPortalFrame.blockID, 1, 2);
		world.setBlock(i + -2, j + 3, k + 7, mod_LionKing.outlandsPortalFrame.blockID, 1, 2);
		world.setBlock(i + -3, j + 3, k + 6, mod_LionKing.outlandsPortalFrame.blockID, 1, 2);
		world.setBlock(i + -4, j + 3, k + 6, mod_LionKing.outlandsPortalFrame.blockID, 1, 2);
		world.setBlock(i + -5, j + 3, k + 6, mod_LionKing.outlandsPortalFrame.blockID, 1, 2);
		world.setBlock(i + -4, j + 3, k + 5, mod_LionKing.outlandsPortalFrame.blockID, 1, 2);
		world.setBlock(i + -3, j + 3, k + 5, mod_LionKing.outlandsPortalFrame.blockID, 1, 2);
		world.setBlock(i + -3, j + 3, k + 4, mod_LionKing.outlandsPortalFrame.blockID, 1, 2);
		world.setBlock(i + -2, j + 3, k + 4, mod_LionKing.outlandsPortalFrame.blockID, 1, 2);
		world.setBlock(i + -2, j + 3, k + 5, mod_LionKing.outlandsPortalFrame.blockID, 1, 2);
		world.setBlock(i + -2, j + 3, k + 6, mod_LionKing.outlandsPortalFrame.blockID, 1, 2);
		world.setBlock(i + -1, j + 3, k + 7, mod_LionKing.outlandsPortalFrame.blockID, 1, 2);
		world.setBlock(i + 0, j + 3, k + 7, mod_LionKing.outlandsPortalFrame.blockID, 1, 2);
		world.setBlock(i + 1, j + 3, k + 7, mod_LionKing.outlandsPortalFrame.blockID, 1, 2);
		world.setBlock(i + 2, j + 3, k + 7, mod_LionKing.outlandsPortalFrame.blockID, 1, 2);
		world.setBlock(i + -6, j + 3, k + 8, mod_LionKing.outlandsPortalFrame.blockID, 1, 2);
		world.setBlock(i + -5, j + 3, k + 8, mod_LionKing.outlandsPortalFrame.blockID, 1, 2);
		world.setBlock(i + -4, j + 3, k + 8, mod_LionKing.outlandsPortalFrame.blockID, 1, 2);
		world.setBlock(i + -4, j + 3, k + 8, 0, 0, 2);
		world.setBlock(i + -3, j + 4, k + 8, mod_LionKing.outlandsPortalFrame.blockID, 1, 2);
		world.setBlock(i + -3, j + 4, k + 8, 0, 0, 2);
		world.setBlock(i + -4, j + 3, k + 8, mod_LionKing.outlandsPortalFrame.blockID, 1, 2);
		world.setBlock(i + -3, j + 3, k + 8, mod_LionKing.outlandsPortalFrame.blockID, 1, 2);
		world.setBlock(i + -2, j + 3, k + 8, mod_LionKing.outlandsPortalFrame.blockID, 1, 2);
		world.setBlock(i + -1, j + 3, k + 8, mod_LionKing.outlandsPortalFrame.blockID, 1, 2);
		world.setBlock(i + 0, j + 3, k + 8, mod_LionKing.outlandsPortalFrame.blockID, 1, 2);
		world.setBlock(i + 1, j + 3, k + 8, mod_LionKing.outlandsPortalFrame.blockID, 1, 2);
		world.setBlock(i + 2, j + 3, k + 8, mod_LionKing.outlandsPortalFrame.blockID, 1, 2);
		world.setBlock(i + 3, j + 3, k + 8, mod_LionKing.outlandsPortalFrame.blockID, 1, 2);
		world.setBlock(i + 4, j + 3, k + 8, mod_LionKing.outlandsPortalFrame.blockID, 1, 2);
		world.setBlock(i + 5, j + 3, k + 8, mod_LionKing.outlandsPortalFrame.blockID, 1, 2);
		world.setBlock(i + 6, j + 3, k + 8, mod_LionKing.outlandsPortalFrame.blockID, 1, 2);
		world.setBlock(i + 8, j + 3, k + 6, mod_LionKing.outlandsPortalFrame.blockID, 1, 2);
		world.setBlock(i + 8, j + 4, k + 4, mod_LionKing.outlandsPortalFrame.blockID, 1, 2);
		world.setBlock(i + 8, j + 4, k + 4, 0, 0, 2);
		world.setBlock(i + 8, j + 3, k + 4, mod_LionKing.outlandsPortalFrame.blockID, 1, 2);
		world.setBlock(i + 8, j + 3, k + 5, mod_LionKing.outlandsPortalFrame.blockID, 1, 2);
		world.setBlock(i + 8, j + 3, k + 3, mod_LionKing.outlandsPortalFrame.blockID, 1, 2);
		world.setBlock(i + 8, j + 3, k + 2, mod_LionKing.outlandsPortalFrame.blockID, 1, 2);
		world.setBlock(i + 8, j + 3, k + 1, mod_LionKing.outlandsPortalFrame.blockID, 1, 2);
		world.setBlock(i + 8, j + 3, k + 1, 0, 0, 2);
		world.setBlock(i + 8, j + 4, k + 0, mod_LionKing.outlandsPortalFrame.blockID, 1, 2);
		world.setBlock(i + 8, j + 4, k + 1, mod_LionKing.outlandsPortalFrame.blockID, 1, 2);
		world.setBlock(i + 8, j + 4, k + 1, 0, 0, 2);
		world.setBlock(i + 8, j + 4, k + 0, 0, 0, 2);
		world.setBlock(i + 8, j + 3, k + 1, mod_LionKing.outlandsPortalFrame.blockID, 1, 2);
		world.setBlock(i + 8, j + 3, k + 0, mod_LionKing.outlandsPortalFrame.blockID, 1, 2);
		world.setBlock(i + 8, j + 3, k + -1, mod_LionKing.outlandsPortalFrame.blockID, 1, 2);
		world.setBlock(i + 8, j + 3, k + -2, mod_LionKing.outlandsPortalFrame.blockID, 1, 2);
		world.setBlock(i + 8, j + 3, k + -3, mod_LionKing.outlandsPortalFrame.blockID, 1, 2);
		world.setBlock(i + 8, j + 3, k + -4, mod_LionKing.outlandsPortalFrame.blockID, 1, 2);
		world.setBlock(i + 8, j + 3, k + -5, mod_LionKing.outlandsPortalFrame.blockID, 1, 2);
		world.setBlock(i + 8, j + 3, k + -6, mod_LionKing.outlandsPortalFrame.blockID, 1, 2);
		world.setBlock(i + 7, j + 3, k + -6, mod_LionKing.outlandsPortalFrame.blockID, 1, 2);
		world.setBlock(i + 7, j + 3, k + -5, mod_LionKing.outlandsPortalFrame.blockID, 1, 2);
		world.setBlock(i + 6, j + 3, k + -5, mod_LionKing.outlandsPortalFrame.blockID, 1, 2);
		world.setBlock(i + 7, j + 3, k + -4, mod_LionKing.outlandsPortalFrame.blockID, 1, 2);
		world.setBlock(i + 7, j + 3, k + -3, mod_LionKing.outlandsPortalFrame.blockID, 1, 2);
		world.setBlock(i + 7, j + 3, k + -2, mod_LionKing.outlandsPortalFrame.blockID, 1, 2);
		world.setBlock(i + 7, j + 3, k + -1, mod_LionKing.outlandsPortalFrame.blockID, 1, 2);
		world.setBlock(i + 7, j + 3, k + 0, mod_LionKing.outlandsPortalFrame.blockID, 1, 2);
		world.setBlock(i + 7, j + 3, k + 1, mod_LionKing.outlandsPortalFrame.blockID, 1, 2);
		world.setBlock(i + 7, j + 3, k + 2, mod_LionKing.outlandsPortalFrame.blockID, 1, 2);
		world.setBlock(i + 7, j + 3, k + 3, mod_LionKing.outlandsPortalFrame.blockID, 1, 2);
		world.setBlock(i + 7, j + 3, k + 4, mod_LionKing.outlandsPortalFrame.blockID, 1, 2);
		world.setBlock(i + 7, j + 3, k + 5, mod_LionKing.outlandsPortalFrame.blockID, 1, 2);
		world.setBlock(i + 7, j + 3, k + 6, mod_LionKing.outlandsPortalFrame.blockID, 1, 2);
		world.setBlock(i + 6, j + 3, k + 7, mod_LionKing.outlandsPortalFrame.blockID, 1, 2);
		world.setBlock(i + 5, j + 3, k + 7, mod_LionKing.outlandsPortalFrame.blockID, 1, 2);
		world.setBlock(i + 5, j + 3, k + 6, mod_LionKing.outlandsPortalFrame.blockID, 1, 2);
		world.setBlock(i + 4, j + 3, k + 6, mod_LionKing.outlandsPortalFrame.blockID, 1, 2);
		world.setBlock(i + 4, j + 3, k + 7, mod_LionKing.outlandsPortalFrame.blockID, 1, 2);
		world.setBlock(i + 3, j + 3, k + 7, mod_LionKing.outlandsPortalFrame.blockID, 1, 2);
		world.setBlock(i + 3, j + 3, k + 6, mod_LionKing.outlandsPortalFrame.blockID, 1, 2);
		world.setBlock(i + 2, j + 3, k + 6, mod_LionKing.outlandsPortalFrame.blockID, 1, 2);
		world.setBlock(i + 2, j + 3, k + 6, 0, 0, 2);
		world.setBlock(i + 1, j + 4, k + 6, mod_LionKing.outlandsPortalFrame.blockID, 1, 2);
		world.setBlock(i + 1, j + 4, k + 6, 0, 0, 2);
		world.setBlock(i + 2, j + 3, k + 6, mod_LionKing.outlandsPortalFrame.blockID, 1, 2);
		world.setBlock(i + 1, j + 3, k + 6, mod_LionKing.outlandsPortalFrame.blockID, 1, 2);
		world.setBlock(i + 0, j + 3, k + 6, mod_LionKing.outlandsPortalFrame.blockID, 1, 2);
		world.setBlock(i + -1, j + 3, k + 6, mod_LionKing.outlandsPortalFrame.blockID, 1, 2);
		world.setBlock(i + -1, j + 3, k + 5, mod_LionKing.outlandsPortalFrame.blockID, 1, 2);
		world.setBlock(i + 0, j + 3, k + 5, mod_LionKing.outlandsPortalFrame.blockID, 1, 2);
		world.setBlock(i + -1, j + 3, k + 4, mod_LionKing.outlandsPortalFrame.blockID, 1, 2);
		world.setBlock(i + 0, j + 3, k + 4, mod_LionKing.outlandsPortalFrame.blockID, 1, 2);
		world.setBlock(i + 0, j + 3, k + 3, mod_LionKing.outlandsPortalFrame.blockID, 1, 2);
		world.setBlock(i + -1, j + 3, k + 3, mod_LionKing.outlandsPortalFrame.blockID, 1, 2);
		world.setBlock(i + -2, j + 3, k + 3, mod_LionKing.outlandsPortalFrame.blockID, 1, 2);
		world.setBlock(i + 1, j + 3, k + 3, mod_LionKing.outlandsPortalFrame.blockID, 1, 2);
		world.setBlock(i + 2, j + 3, k + 3, mod_LionKing.outlandsPortalFrame.blockID, 1, 2);
		world.setBlock(i + 2, j + 3, k + 4, mod_LionKing.outlandsPortalFrame.blockID, 1, 2);
		world.setBlock(i + 1, j + 3, k + 4, mod_LionKing.outlandsPortalFrame.blockID, 1, 2);
		world.setBlock(i + 1, j + 3, k + 5, mod_LionKing.outlandsPortalFrame.blockID, 1, 2);
		world.setBlock(i + 2, j + 3, k + 5, mod_LionKing.outlandsPortalFrame.blockID, 1, 2);
		world.setBlock(i + 3, j + 3, k + 5, mod_LionKing.outlandsPortalFrame.blockID, 1, 2);
		world.setBlock(i + 3, j + 3, k + 4, mod_LionKing.outlandsPortalFrame.blockID, 1, 2);
		world.setBlock(i + 4, j + 3, k + 5, mod_LionKing.outlandsPortalFrame.blockID, 1, 2);
		world.setBlock(i + 3, j + 3, k + 2, mod_LionKing.outlandsPortalFrame.blockID, 1, 2);
		world.setBlock(i + 4, j + 3, k + 3, mod_LionKing.outlandsPortalFrame.blockID, 1, 2);
		world.setBlock(i + 4, j + 3, k + 2, mod_LionKing.outlandsPortalFrame.blockID, 1, 2);
		world.setBlock(i + 5, j + 3, k + 3, mod_LionKing.outlandsPortalFrame.blockID, 1, 2);
		world.setBlock(i + 5, j + 3, k + 4, mod_LionKing.outlandsPortalFrame.blockID, 1, 2);
		world.setBlock(i + 6, j + 3, k + 3, mod_LionKing.outlandsPortalFrame.blockID, 1, 2);
		world.setBlock(i + 6, j + 3, k + 4, mod_LionKing.outlandsPortalFrame.blockID, 1, 2);
		world.setBlock(i + 6, j + 3, k + 5, mod_LionKing.outlandsPortalFrame.blockID, 1, 2);
		world.setBlock(i + 6, j + 3, k + 2, mod_LionKing.outlandsPortalFrame.blockID, 1, 2);
		world.setBlock(i + 5, j + 3, k + 2, mod_LionKing.outlandsPortalFrame.blockID, 1, 2);
		world.setBlock(i + 5, j + 3, k + 1, mod_LionKing.outlandsPortalFrame.blockID, 1, 2);
		world.setBlock(i + 4, j + 3, k + 1, mod_LionKing.outlandsPortalFrame.blockID, 1, 2);
		world.setBlock(i + 3, j + 3, k + 1, mod_LionKing.outlandsPortalFrame.blockID, 1, 2);
		world.setBlock(i + 3, j + 3, k + -1, mod_LionKing.outlandsPortalFrame.blockID, 1, 2);
		world.setBlock(i + 3, j + 3, k + 0, mod_LionKing.outlandsPortalFrame.blockID, 1, 2);
		world.setBlock(i + 4, j + 3, k + 0, mod_LionKing.outlandsPortalFrame.blockID, 1, 2);
		world.setBlock(i + 5, j + 3, k + 0, mod_LionKing.outlandsPortalFrame.blockID, 1, 2);
		world.setBlock(i + 6, j + 3, k + 0, mod_LionKing.outlandsPortalFrame.blockID, 1, 2);
		world.setBlock(i + 6, j + 3, k + 1, mod_LionKing.outlandsPortalFrame.blockID, 1, 2);
		world.setBlock(i + 6, j + 3, k + -1, mod_LionKing.outlandsPortalFrame.blockID, 1, 2);
		world.setBlock(i + 5, j + 3, k + -1, mod_LionKing.outlandsPortalFrame.blockID, 1, 2);
		world.setBlock(i + 4, j + 3, k + -1, mod_LionKing.outlandsPortalFrame.blockID, 1, 2);
		world.setBlock(i + 3, j + 3, k + -2, mod_LionKing.outlandsPortalFrame.blockID, 1, 2);
		world.setBlock(i + 4, j + 3, k + -2, mod_LionKing.outlandsPortalFrame.blockID, 1, 2);
		world.setBlock(i + 4, j + 3, k + -3, mod_LionKing.outlandsPortalFrame.blockID, 1, 2);
		world.setBlock(i + 5, j + 3, k + -3, mod_LionKing.outlandsPortalFrame.blockID, 1, 2);
		world.setBlock(i + 5, j + 3, k + -2, mod_LionKing.outlandsPortalFrame.blockID, 1, 2);
		world.setBlock(i + 6, j + 3, k + -2, mod_LionKing.outlandsPortalFrame.blockID, 1, 2);
		world.setBlock(i + 6, j + 3, k + -3, mod_LionKing.outlandsPortalFrame.blockID, 1, 2);
		world.setBlock(i + 6, j + 3, k + -4, mod_LionKing.outlandsPortalFrame.blockID, 1, 2);
		world.setBlock(i + 5, j + 3, k + -4, mod_LionKing.outlandsPortalFrame.blockID, 1, 2);
		world.setBlock(i + -9, j + 3, k + 0, mod_LionKing.outlandsPortalFrame.blockID, 1, 2);
		world.setBlock(i + -10, j + 3, k + 0, mod_LionKing.outlandsPortalFrame.blockID, 1, 2);
		world.setBlock(i + -9, j + 3, k + -1, mod_LionKing.outlandsPortalFrame.blockID, 1, 2);
		world.setBlock(i + -10, j + 3, k + -1, mod_LionKing.outlandsPortalFrame.blockID, 1, 2);
		world.setBlock(i + -9, j + 3, k + -2, mod_LionKing.outlandsPortalFrame.blockID, 1, 2);
		world.setBlock(i + -10, j + 3, k + -2, mod_LionKing.outlandsPortalFrame.blockID, 1, 2);
		world.setBlock(i + -9, j + 3, k + 1, mod_LionKing.outlandsPortalFrame.blockID, 1, 2);
		world.setBlock(i + -10, j + 3, k + 1, mod_LionKing.outlandsPortalFrame.blockID, 1, 2);
		world.setBlock(i + -9, j + 3, k + 2, mod_LionKing.outlandsPortalFrame.blockID, 1, 2);
		world.setBlock(i + -10, j + 3, k + 2, mod_LionKing.outlandsPortalFrame.blockID, 1, 2);
		world.setBlock(i + -9, j + 3, k + -3, mod_LionKing.outlandsPortalFrame.blockID, 1, 2);
		world.setBlock(i + -10, j + 3, k + -4, mod_LionKing.outlandsPortalFrame.blockID, 1, 2);
		world.setBlock(i + -10, j + 3, k + -3, mod_LionKing.outlandsPortalFrame.blockID, 1, 2);
		world.setBlock(i + -9, j + 3, k + 3, mod_LionKing.outlandsPortalFrame.blockID, 1, 2);
		world.setBlock(i + -10, j + 3, k + 3, mod_LionKing.outlandsPortalFrame.blockID, 1, 2);
		world.setBlock(i + -9, j + 3, k + 4, mod_LionKing.outlandsPortalFrame.blockID, 1, 2);
		world.setBlock(i + -9, j + 3, k + 5, mod_LionKing.outlandsPortalFrame.blockID, 1, 2);
		world.setBlock(i + -10, j + 3, k + -4, 0, 0, 2);
		world.setBlock(i + -9, j + 4, k + 0, mod_LionKing.outlandsPortalFrame.blockID, 1, 2);
		world.setBlock(i + -10, j + 4, k + 0, mod_LionKing.outlandsPortalFrame.blockID, 1, 2);
		world.setBlock(i + -9, j + 4, k + -1, mod_LionKing.outlandsPortalFrame.blockID, 1, 2);
		world.setBlock(i + -9, j + 4, k + -2, mod_LionKing.outlandsPortalFrame.blockID, 1, 2);
		world.setBlock(i + -9, j + 4, k + -3, mod_LionKing.outlandsPortalFrame.blockID, 1, 2);
		world.setBlock(i + -10, j + 4, k + -2, mod_LionKing.outlandsPortalFrame.blockID, 1, 2);
	}
	
	private void generate1(World world, int i, int j, int k)
	{
		world.setBlock(i + -10, j + 4, k + -3, mod_LionKing.outlandsPortalFrame.blockID, 1, 2);
		world.setBlock(i + -10, j + 4, k + -1, mod_LionKing.outlandsPortalFrame.blockID, 1, 2);
		world.setBlock(i + -9, j + 4, k + 1, mod_LionKing.outlandsPortalFrame.blockID, 1, 2);
		world.setBlock(i + -10, j + 4, k + 1, mod_LionKing.outlandsPortalFrame.blockID, 1, 2);
		world.setBlock(i + -9, j + 4, k + 2, mod_LionKing.outlandsPortalFrame.blockID, 1, 2);
		world.setBlock(i + -10, j + 4, k + 2, mod_LionKing.outlandsPortalFrame.blockID, 1, 2);
		world.setBlock(i + -9, j + 4, k + 3, mod_LionKing.outlandsPortalFrame.blockID, 1, 2);
		world.setBlock(i + -10, j + 4, k + 3, mod_LionKing.outlandsPortalFrame.blockID, 1, 2);
		world.setBlock(i + -9, j + 3, k + -4, mod_LionKing.outlandsPortalFrame.blockID, 1, 2);
		world.setBlock(i + -8, j + 4, k + -4, mod_LionKing.outlandsPortalFrame.blockID, 1, 2);
		world.setBlock(i + -9, j + 4, k + -4, mod_LionKing.outlandsPortalFrame.blockID, 1, 2);
		world.setBlock(i + -9, j + 3, k + -5, mod_LionKing.outlandsPortalFrame.blockID, 1, 2);
		world.setBlock(i + -9, j + 4, k + -5, mod_LionKing.outlandsPortalFrame.blockID, 1, 2);
		world.setBlock(i + -8, j + 4, k + -5, mod_LionKing.outlandsPortalFrame.blockID, 1, 2);
		world.setBlock(i + 0, j + 3, k + -9, mod_LionKing.outlandsPortalFrame.blockID, 1, 2);
		world.setBlock(i + 0, j + 3, k + -10, mod_LionKing.outlandsPortalFrame.blockID, 1, 2);
		world.setBlock(i + -1, j + 3, k + -9, mod_LionKing.outlandsPortalFrame.blockID, 1, 2);
		world.setBlock(i + -1, j + 3, k + -10, mod_LionKing.outlandsPortalFrame.blockID, 1, 2);
		world.setBlock(i + 1, j + 3, k + -9, mod_LionKing.outlandsPortalFrame.blockID, 1, 2);
		world.setBlock(i + 1, j + 3, k + -10, mod_LionKing.outlandsPortalFrame.blockID, 1, 2);
		world.setBlock(i + 2, j + 3, k + -10, mod_LionKing.outlandsPortalFrame.blockID, 1, 2);
		world.setBlock(i + 2, j + 3, k + -9, mod_LionKing.outlandsPortalFrame.blockID, 1, 2);
		world.setBlock(i + -2, j + 4, k + -10, mod_LionKing.outlandsPortalFrame.blockID, 1, 2);
		world.setBlock(i + -2, j + 5, k + -10, mod_LionKing.outlandsPortalFrame.blockID, 1, 2);
		world.setBlock(i + -2, j + 5, k + -10, 0, 0, 2);
		world.setBlock(i + -2, j + 4, k + -10, 0, 0, 2);
		world.setBlock(i + -2, j + 3, k + -9, mod_LionKing.outlandsPortalFrame.blockID, 1, 2);
		world.setBlock(i + -2, j + 3, k + -10, mod_LionKing.outlandsPortalFrame.blockID, 1, 2);
		world.setBlock(i + -3, j + 3, k + -9, mod_LionKing.outlandsPortalFrame.blockID, 1, 2);
		world.setBlock(i + -3, j + 3, k + -10, mod_LionKing.outlandsPortalFrame.blockID, 1, 2);
		world.setBlock(i + 3, j + 3, k + -9, mod_LionKing.outlandsPortalFrame.blockID, 1, 2);
		world.setBlock(i + 3, j + 3, k + -10, mod_LionKing.outlandsPortalFrame.blockID, 1, 2);
		world.setBlock(i + 3, j + 4, k + -9, mod_LionKing.outlandsPortalFrame.blockID, 1, 2);
		world.setBlock(i + 2, j + 4, k + -10, mod_LionKing.outlandsPortalFrame.blockID, 1, 2);
		world.setBlock(i + 1, j + 4, k + -10, mod_LionKing.outlandsPortalFrame.blockID, 1, 2);
		world.setBlock(i + 3, j + 4, k + -10, mod_LionKing.outlandsPortalFrame.blockID, 1, 2);
		world.setBlock(i + 2, j + 4, k + -9, mod_LionKing.outlandsPortalFrame.blockID, 1, 2);
		world.setBlock(i + 0, j + 4, k + -9, mod_LionKing.outlandsPortalFrame.blockID, 1, 2);
		world.setBlock(i + 1, j + 4, k + -9, mod_LionKing.outlandsPortalFrame.blockID, 1, 2);
		world.setBlock(i + -1, j + 4, k + -10, mod_LionKing.outlandsPortalFrame.blockID, 1, 2);
		world.setBlock(i + 0, j + 4, k + -10, mod_LionKing.outlandsPortalFrame.blockID, 1, 2);
		world.setBlock(i + -1, j + 4, k + -9, mod_LionKing.outlandsPortalFrame.blockID, 1, 2);
		world.setBlock(i + -3, j + 4, k + -9, mod_LionKing.outlandsPortalFrame.blockID, 1, 2);
		world.setBlock(i + -2, j + 4, k + -9, mod_LionKing.outlandsPortalFrame.blockID, 1, 2);
		world.setBlock(i + -3, j + 4, k + -10, mod_LionKing.outlandsPortalFrame.blockID, 1, 2);
		world.setBlock(i + -2, j + 4, k + -10, mod_LionKing.outlandsPortalFrame.blockID, 1, 2);
		world.setBlock(i + -4, j + 3, k + -9, mod_LionKing.outlandsPortalFrame.blockID, 1, 2);
		world.setBlock(i + -4, j + 4, k + -8, mod_LionKing.outlandsPortalFrame.blockID, 1, 2);
		world.setBlock(i + -4, j + 4, k + -9, mod_LionKing.outlandsPortalFrame.blockID, 1, 2);
		world.setBlock(i + -5, j + 3, k + -9, mod_LionKing.outlandsPortalFrame.blockID, 1, 2);
		world.setBlock(i + -5, j + 4, k + -8, mod_LionKing.outlandsPortalFrame.blockID, 1, 2);
		world.setBlock(i + -5, j + 4, k + -9, mod_LionKing.outlandsPortalFrame.blockID, 1, 2);
		world.setBlock(i + -6, j + 4, k + -6, mod_LionKing.outlandsPortalFrame.blockID, 1, 2);
		world.setBlock(i + -6, j + 4, k + -7, mod_LionKing.outlandsPortalFrame.blockID, 1, 2);
		world.setBlock(i + -7, j + 4, k + -6, mod_LionKing.outlandsPortalFrame.blockID, 1, 2);
		world.setBlock(i + -7, j + 4, k + -7, mod_LionKing.outlandsPortalFrame.blockID, 1, 2);
		world.setBlock(i + -6, j + 4, k + -8, mod_LionKing.outlandsPortalFrame.blockID, 1, 2);
		world.setBlock(i + -8, j + 4, k + -6, mod_LionKing.outlandsPortalFrame.blockID, 1, 2);
		world.setBlock(i + -7, j + 4, k + -5, mod_LionKing.outlandsPortalFrame.blockID, 1, 2);
		world.setBlock(i + -5, j + 4, k + -7, mod_LionKing.outlandsPortalFrame.blockID, 1, 2);
		world.setBlock(i + -8, j + 4, k + -3, mod_LionKing.outlandsPortalFrame.blockID, 1, 2);
		world.setBlock(i + -3, j + 4, k + -8, mod_LionKing.outlandsPortalFrame.blockID, 1, 2);
		world.setBlock(i + -8, j + 4, k + -3, 0, 0, 2);
		world.setBlock(i + -3, j + 4, k + -8, 0, 0, 2);
		world.setBlock(i + -4, j + 3, k + -10, mod_LionKing.outlandsPortalFrame.blockID, 1, 2);
		world.setBlock(i + -4, j + 4, k + -10, mod_LionKing.outlandsPortalFrame.blockID, 1, 2);
		world.setBlock(i + -10, j + 3, k + -4, mod_LionKing.outlandsPortalFrame.blockID, 1, 2);
		world.setBlock(i + -10, j + 4, k + -4, mod_LionKing.outlandsPortalFrame.blockID, 1, 2);
		world.setBlock(i + -7, j + 3, k + -8, mod_LionKing.outlandsPortalFrame.blockID, 1, 2);
		world.setBlock(i + -7, j + 4, k + -8, mod_LionKing.outlandsPortalFrame.blockID, 1, 2);
		world.setBlock(i + -8, j + 3, k + -7, mod_LionKing.outlandsPortalFrame.blockID, 1, 2);
		world.setBlock(i + -8, j + 4, k + -7, mod_LionKing.outlandsPortalFrame.blockID, 1, 2);
		world.setBlock(i + -9, j + 3, k + -6, mod_LionKing.outlandsPortalFrame.blockID, 1, 2);
		world.setBlock(i + -9, j + 4, k + -6, mod_LionKing.outlandsPortalFrame.blockID, 1, 2);
		world.setBlock(i + -6, j + 3, k + -9, mod_LionKing.outlandsPortalFrame.blockID, 1, 2);
		world.setBlock(i + -6, j + 4, k + -9, mod_LionKing.outlandsPortalFrame.blockID, 1, 2);
		world.setBlock(i + -10, j + 3, k + -5, mod_LionKing.outlandsPortalFrame.blockID, 1, 2);
		world.setBlock(i + -10, j + 4, k + -5, mod_LionKing.outlandsPortalFrame.blockID, 1, 2);
		world.setBlock(i + -5, j + 3, k + -10, mod_LionKing.outlandsPortalFrame.blockID, 1, 2);
		world.setBlock(i + -5, j + 4, k + -10, mod_LionKing.outlandsPortalFrame.blockID, 1, 2);
		world.setBlock(i + -11, j + 3, k + 0, mod_LionKing.outlandsPortalFrame.blockID, 1, 2);
		world.setBlock(i + -11, j + 4, k + 0, mod_LionKing.outlandsPortalFrame.blockID, 1, 2);
		world.setBlock(i + -11, j + 3, k + -1, mod_LionKing.outlandsPortalFrame.blockID, 1, 2);
		world.setBlock(i + -11, j + 4, k + -1, mod_LionKing.outlandsPortalFrame.blockID, 1, 2);
		world.setBlock(i + -11, j + 3, k + -2, mod_LionKing.outlandsPortalFrame.blockID, 1, 2);
		world.setBlock(i + -11, j + 4, k + -2, mod_LionKing.outlandsPortalFrame.blockID, 1, 2);
		world.setBlock(i + -11, j + 3, k + -3, mod_LionKing.outlandsPortalFrame.blockID, 1, 2);
		world.setBlock(i + -11, j + 4, k + -3, mod_LionKing.outlandsPortalFrame.blockID, 1, 2);
		world.setBlock(i + -11, j + 3, k + 1, mod_LionKing.outlandsPortalFrame.blockID, 1, 2);
		world.setBlock(i + -11, j + 4, k + 1, mod_LionKing.outlandsPortalFrame.blockID, 1, 2);
		world.setBlock(i + -11, j + 3, k + 2, mod_LionKing.outlandsPortalFrame.blockID, 1, 2);
		world.setBlock(i + -11, j + 4, k + 2, mod_LionKing.outlandsPortalFrame.blockID, 1, 2);
		world.setBlock(i + -11, j + 3, k + 3, mod_LionKing.outlandsPortalFrame.blockID, 1, 2);
		world.setBlock(i + -11, j + 4, k + 3, mod_LionKing.outlandsPortalFrame.blockID, 1, 2);
		world.setBlock(i + -3, j + 3, k + -11, mod_LionKing.outlandsPortalFrame.blockID, 1, 2);
		world.setBlock(i + -3, j + 4, k + -11, mod_LionKing.outlandsPortalFrame.blockID, 1, 2);
		world.setBlock(i + -2, j + 3, k + -11, mod_LionKing.outlandsPortalFrame.blockID, 1, 2);
		world.setBlock(i + -2, j + 4, k + -11, mod_LionKing.outlandsPortalFrame.blockID, 1, 2);
		world.setBlock(i + -1, j + 3, k + -11, mod_LionKing.outlandsPortalFrame.blockID, 1, 2);
		world.setBlock(i + -1, j + 4, k + -11, mod_LionKing.outlandsPortalFrame.blockID, 1, 2);
		world.setBlock(i + 0, j + 3, k + -11, mod_LionKing.outlandsPortalFrame.blockID, 1, 2);
		world.setBlock(i + 0, j + 4, k + -11, mod_LionKing.outlandsPortalFrame.blockID, 1, 2);
		world.setBlock(i + 1, j + 3, k + -11, mod_LionKing.outlandsPortalFrame.blockID, 1, 2);
		world.setBlock(i + 1, j + 4, k + -11, mod_LionKing.outlandsPortalFrame.blockID, 1, 2);
		world.setBlock(i + 2, j + 3, k + -11, mod_LionKing.outlandsPortalFrame.blockID, 1, 2);
		world.setBlock(i + 2, j + 4, k + -11, mod_LionKing.outlandsPortalFrame.blockID, 1, 2);
		world.setBlock(i + 3, j + 3, k + -11, mod_LionKing.outlandsPortalFrame.blockID, 1, 2);
		world.setBlock(i + 3, j + 4, k + -11, mod_LionKing.outlandsPortalFrame.blockID, 1, 2);
		world.setBlock(i + 4, j + 3, k + -9, mod_LionKing.outlandsPortalFrame.blockID, 1, 2);
		world.setBlock(i + 4, j + 4, k + -9, mod_LionKing.outlandsPortalFrame.blockID, 1, 2);
		world.setBlock(i + 4, j + 3, k + -10, mod_LionKing.outlandsPortalFrame.blockID, 1, 2);
		world.setBlock(i + 4, j + 4, k + -10, mod_LionKing.outlandsPortalFrame.blockID, 1, 2);
		world.setBlock(i + 5, j + 3, k + -9, mod_LionKing.outlandsPortalFrame.blockID, 1, 2);
		world.setBlock(i + 5, j + 4, k + -9, mod_LionKing.outlandsPortalFrame.blockID, 1, 2);
		world.setBlock(i + 5, j + 3, k + -10, mod_LionKing.outlandsPortalFrame.blockID, 1, 2);
		world.setBlock(i + 5, j + 4, k + -10, mod_LionKing.outlandsPortalFrame.blockID, 1, 2);
		world.setBlock(i + 6, j + 3, k + -9, mod_LionKing.outlandsPortalFrame.blockID, 1, 2);
		world.setBlock(i + 6, j + 4, k + -9, mod_LionKing.outlandsPortalFrame.blockID, 1, 2);
		world.setBlock(i + 6, j + 4, k + -8, mod_LionKing.outlandsPortalFrame.blockID, 1, 2);
		world.setBlock(i + 7, j + 3, k + -8, mod_LionKing.outlandsPortalFrame.blockID, 1, 2);
		world.setBlock(i + 7, j + 4, k + -8, mod_LionKing.outlandsPortalFrame.blockID, 1, 2);
		world.setBlock(i + 7, j + 4, k + -7, mod_LionKing.outlandsPortalFrame.blockID, 1, 2);
		world.setBlock(i + 8, j + 4, k + -8, mod_LionKing.outlandsPortalFrame.blockID, 1, 2);
		world.setBlock(i + 8, j + 4, k + -8, 0, 0, 2);
		world.setBlock(i + 8, j + 3, k + -7, mod_LionKing.outlandsPortalFrame.blockID, 1, 2);
		world.setBlock(i + 8, j + 4, k + -7, mod_LionKing.outlandsPortalFrame.blockID, 1, 2);
		world.setBlock(i + 8, j + 4, k + -6, mod_LionKing.outlandsPortalFrame.blockID, 1, 2);
		world.setBlock(i + 5, j + 4, k + -8, mod_LionKing.outlandsPortalFrame.blockID, 1, 2);
		world.setBlock(i + 4, j + 4, k + -8, mod_LionKing.outlandsPortalFrame.blockID, 1, 2);
		world.setBlock(i + 6, j + 4, k + -7, mod_LionKing.outlandsPortalFrame.blockID, 1, 2);
		world.setBlock(i + 5, j + 4, k + -7, mod_LionKing.outlandsPortalFrame.blockID, 1, 2);
		world.setBlock(i + 7, j + 4, k + -6, mod_LionKing.outlandsPortalFrame.blockID, 1, 2);
		world.setBlock(i + 6, j + 4, k + -6, mod_LionKing.outlandsPortalFrame.blockID, 1, 2);
		world.setBlock(i + 7, j + 4, k + -5, mod_LionKing.outlandsPortalFrame.blockID, 1, 2);
		world.setBlock(i + 8, j + 4, k + -5, mod_LionKing.outlandsPortalFrame.blockID, 1, 2);
		world.setBlock(i + 8, j + 4, k + -4, mod_LionKing.outlandsPortalFrame.blockID, 1, 2);
		world.setBlock(i + 9, j + 3, k + -4, mod_LionKing.outlandsPortalFrame.blockID, 1, 2);
		world.setBlock(i + 10, j + 3, k + -4, mod_LionKing.outlandsPortalFrame.blockID, 1, 2);
		world.setBlock(i + 9, j + 3, k + -5, mod_LionKing.outlandsPortalFrame.blockID, 1, 2);
		world.setBlock(i + 10, j + 3, k + -5, mod_LionKing.outlandsPortalFrame.blockID, 1, 2);
		world.setBlock(i + 9, j + 4, k + -5, mod_LionKing.outlandsPortalFrame.blockID, 1, 2);
		world.setBlock(i + 9, j + 4, k + -4, mod_LionKing.outlandsPortalFrame.blockID, 1, 2);
		world.setBlock(i + 10, j + 4, k + -4, mod_LionKing.outlandsPortalFrame.blockID, 1, 2);
		world.setBlock(i + 10, j + 4, k + -5, mod_LionKing.outlandsPortalFrame.blockID, 1, 2);
		world.setBlock(i + 9, j + 3, k + -6, mod_LionKing.outlandsPortalFrame.blockID, 1, 2);
		world.setBlock(i + 9, j + 4, k + -6, mod_LionKing.outlandsPortalFrame.blockID, 1, 2);
		world.setBlock(i + 9, j + 3, k + -3, mod_LionKing.outlandsPortalFrame.blockID, 1, 2);
		world.setBlock(i + 9, j + 3, k + 0, mod_LionKing.outlandsPortalFrame.blockID, 1, 2);
		world.setBlock(i + 10, j + 3, k + 0, mod_LionKing.outlandsPortalFrame.blockID, 1, 2);
		world.setBlock(i + 9, j + 3, k + -2, mod_LionKing.outlandsPortalFrame.blockID, 1, 2);
		world.setBlock(i + 9, j + 3, k + -1, mod_LionKing.outlandsPortalFrame.blockID, 1, 2);
		world.setBlock(i + 10, j + 3, k + -1, mod_LionKing.outlandsPortalFrame.blockID, 1, 2);
		world.setBlock(i + 10, j + 3, k + -3, mod_LionKing.outlandsPortalFrame.blockID, 1, 2);
		world.setBlock(i + 10, j + 3, k + -2, mod_LionKing.outlandsPortalFrame.blockID, 1, 2);
		world.setBlock(i + 9, j + 4, k + -3, mod_LionKing.outlandsPortalFrame.blockID, 1, 2);
		world.setBlock(i + 10, j + 4, k + -3, mod_LionKing.outlandsPortalFrame.blockID, 1, 2);
		world.setBlock(i + 9, j + 4, k + -2, mod_LionKing.outlandsPortalFrame.blockID, 1, 2);
		world.setBlock(i + 10, j + 4, k + -2, mod_LionKing.outlandsPortalFrame.blockID, 1, 2);
		world.setBlock(i + 9, j + 4, k + -1, mod_LionKing.outlandsPortalFrame.blockID, 1, 2);
		world.setBlock(i + 10, j + 4, k + -1, mod_LionKing.outlandsPortalFrame.blockID, 1, 2);
		world.setBlock(i + 10, j + 4, k + 0, mod_LionKing.outlandsPortalFrame.blockID, 1, 2);
		world.setBlock(i + 9, j + 4, k + 0, mod_LionKing.outlandsPortalFrame.blockID, 1, 2);
		world.setBlock(i + 11, j + 3, k + -3, mod_LionKing.outlandsPortalFrame.blockID, 1, 2);
		world.setBlock(i + 11, j + 4, k + -3, mod_LionKing.outlandsPortalFrame.blockID, 1, 2);
		world.setBlock(i + 11, j + 3, k + -2, mod_LionKing.outlandsPortalFrame.blockID, 1, 2);
		world.setBlock(i + 11, j + 4, k + -2, mod_LionKing.outlandsPortalFrame.blockID, 1, 2);
		world.setBlock(i + 11, j + 3, k + -1, mod_LionKing.outlandsPortalFrame.blockID, 1, 2);
		world.setBlock(i + 11, j + 4, k + -1, mod_LionKing.outlandsPortalFrame.blockID, 1, 2);
		world.setBlock(i + 11, j + 3, k + 0, mod_LionKing.outlandsPortalFrame.blockID, 1, 2);
		world.setBlock(i + 11, j + 4, k + 0, mod_LionKing.outlandsPortalFrame.blockID, 1, 2);
		world.setBlock(i + 9, j + 3, k + 1, mod_LionKing.outlandsPortalFrame.blockID, 1, 2);
		world.setBlock(i + 10, j + 3, k + 1, mod_LionKing.outlandsPortalFrame.blockID, 1, 2);
		world.setBlock(i + 11, j + 3, k + 1, mod_LionKing.outlandsPortalFrame.blockID, 1, 2);
		world.setBlock(i + 9, j + 4, k + 1, mod_LionKing.outlandsPortalFrame.blockID, 1, 2);
		world.setBlock(i + 10, j + 4, k + 1, mod_LionKing.outlandsPortalFrame.blockID, 1, 2);
		world.setBlock(i + 11, j + 4, k + 1, mod_LionKing.outlandsPortalFrame.blockID, 1, 2);
		world.setBlock(i + 9, j + 3, k + 2, mod_LionKing.outlandsPortalFrame.blockID, 1, 2);
		world.setBlock(i + 10, j + 3, k + 2, mod_LionKing.outlandsPortalFrame.blockID, 1, 2);
		world.setBlock(i + 11, j + 3, k + 2, mod_LionKing.outlandsPortalFrame.blockID, 1, 2);
		world.setBlock(i + 9, j + 3, k + 3, mod_LionKing.outlandsPortalFrame.blockID, 1, 2);
		world.setBlock(i + 10, j + 3, k + 3, mod_LionKing.outlandsPortalFrame.blockID, 1, 2);
		world.setBlock(i + 11, j + 3, k + 3, mod_LionKing.outlandsPortalFrame.blockID, 1, 2);
		world.setBlock(i + 9, j + 4, k + 2, mod_LionKing.outlandsPortalFrame.blockID, 1, 2);
		world.setBlock(i + 9, j + 4, k + 3, mod_LionKing.outlandsPortalFrame.blockID, 1, 2);
		world.setBlock(i + 10, j + 4, k + 2, mod_LionKing.outlandsPortalFrame.blockID, 1, 2);
		world.setBlock(i + 10, j + 4, k + 3, mod_LionKing.outlandsPortalFrame.blockID, 1, 2);
		world.setBlock(i + 11, j + 4, k + 2, mod_LionKing.outlandsPortalFrame.blockID, 1, 2);
		world.setBlock(i + 11, j + 4, k + 3, mod_LionKing.outlandsPortalFrame.blockID, 1, 2);
		world.setBlock(i + 9, j + 3, k + 4, mod_LionKing.outlandsPortalFrame.blockID, 1, 2);
		world.setBlock(i + 9, j + 3, k + 5, mod_LionKing.outlandsPortalFrame.blockID, 1, 2);
		world.setBlock(i + 10, j + 3, k + 4, mod_LionKing.outlandsPortalFrame.blockID, 1, 2);
		world.setBlock(i + 10, j + 3, k + 5, mod_LionKing.outlandsPortalFrame.blockID, 1, 2);
		world.setBlock(i + 9, j + 4, k + 4, mod_LionKing.outlandsPortalFrame.blockID, 1, 2);
		world.setBlock(i + 8, j + 4, k + 4, mod_LionKing.outlandsPortalFrame.blockID, 1, 2);
		world.setBlock(i + 8, j + 4, k + 5, mod_LionKing.outlandsPortalFrame.blockID, 1, 2);
		world.setBlock(i + 9, j + 4, k + 5, mod_LionKing.outlandsPortalFrame.blockID, 1, 2);
		world.setBlock(i + 10, j + 4, k + 4, mod_LionKing.outlandsPortalFrame.blockID, 1, 2);
		world.setBlock(i + 10, j + 4, k + 5, mod_LionKing.outlandsPortalFrame.blockID, 1, 2);
		world.setBlock(i + 9, j + 3, k + 6, mod_LionKing.outlandsPortalFrame.blockID, 1, 2);
		world.setBlock(i + 9, j + 4, k + 6, mod_LionKing.outlandsPortalFrame.blockID, 1, 2);
		world.setBlock(i + 8, j + 4, k + 6, mod_LionKing.outlandsPortalFrame.blockID, 1, 2);
		world.setBlock(i + 7, j + 4, k + 6, mod_LionKing.outlandsPortalFrame.blockID, 1, 2);
		world.setBlock(i + 8, j + 3, k + 7, mod_LionKing.outlandsPortalFrame.blockID, 1, 2);
		world.setBlock(i + 8, j + 4, k + 7, mod_LionKing.outlandsPortalFrame.blockID, 1, 2);
		world.setBlock(i + 7, j + 4, k + 7, mod_LionKing.outlandsPortalFrame.blockID, 1, 2);
		world.setBlock(i + 6, j + 4, k + 7, mod_LionKing.outlandsPortalFrame.blockID, 1, 2);
		world.setBlock(i + 7, j + 4, k + 8, mod_LionKing.outlandsPortalFrame.blockID, 1, 2);
		world.setBlock(i + 7, j + 4, k + 8, 0, 0, 2);
		world.setBlock(i + 7, j + 3, k + 8, mod_LionKing.outlandsPortalFrame.blockID, 1, 2);
		world.setBlock(i + 7, j + 4, k + 8, mod_LionKing.outlandsPortalFrame.blockID, 1, 2);
		world.setBlock(i + 6, j + 4, k + 8, mod_LionKing.outlandsPortalFrame.blockID, 1, 2);
		world.setBlock(i + 5, j + 4, k + 8, mod_LionKing.outlandsPortalFrame.blockID, 1, 2);
		world.setBlock(i + 7, j + 4, k + 5, mod_LionKing.outlandsPortalFrame.blockID, 1, 2);
		world.setBlock(i + 6, j + 4, k + 6, mod_LionKing.outlandsPortalFrame.blockID, 1, 2);
		world.setBlock(i + 5, j + 4, k + 7, mod_LionKing.outlandsPortalFrame.blockID, 1, 2);
		world.setBlock(i + 5, j + 3, k + 9, mod_LionKing.outlandsPortalFrame.blockID, 1, 2);
		world.setBlock(i + 6, j + 3, k + 9, mod_LionKing.outlandsPortalFrame.blockID, 1, 2);
		world.setBlock(i + 6, j + 4, k + 9, mod_LionKing.outlandsPortalFrame.blockID, 1, 2);
		world.setBlock(i + 5, j + 4, k + 9, mod_LionKing.outlandsPortalFrame.blockID, 1, 2);
		world.setBlock(i + 4, j + 3, k + 9, mod_LionKing.outlandsPortalFrame.blockID, 1, 2);
		world.setBlock(i + 4, j + 3, k + 10, mod_LionKing.outlandsPortalFrame.blockID, 1, 2);
		world.setBlock(i + 4, j + 4, k + 8, mod_LionKing.outlandsPortalFrame.blockID, 1, 2);
		world.setBlock(i + 4, j + 4, k + 9, mod_LionKing.outlandsPortalFrame.blockID, 1, 2);
		world.setBlock(i + 4, j + 4, k + 10, mod_LionKing.outlandsPortalFrame.blockID, 1, 2);
		world.setBlock(i + 3, j + 3, k + 9, mod_LionKing.outlandsPortalFrame.blockID, 1, 2);
		world.setBlock(i + 3, j + 3, k + 10, mod_LionKing.outlandsPortalFrame.blockID, 1, 2);
		world.setBlock(i + 3, j + 4, k + 9, mod_LionKing.outlandsPortalFrame.blockID, 1, 2);
		world.setBlock(i + 3, j + 4, k + 10, mod_LionKing.outlandsPortalFrame.blockID, 1, 2);
		world.setBlock(i + 2, j + 3, k + 9, mod_LionKing.outlandsPortalFrame.blockID, 1, 2);
		world.setBlock(i + 2, j + 3, k + 10, mod_LionKing.outlandsPortalFrame.blockID, 1, 2);
		world.setBlock(i + 2, j + 4, k + 9, mod_LionKing.outlandsPortalFrame.blockID, 1, 2);
		world.setBlock(i + 2, j + 4, k + 10, mod_LionKing.outlandsPortalFrame.blockID, 1, 2);
		world.setBlock(i + 1, j + 3, k + 9, mod_LionKing.outlandsPortalFrame.blockID, 1, 2);
		world.setBlock(i + 1, j + 3, k + 10, mod_LionKing.outlandsPortalFrame.blockID, 1, 2);
		world.setBlock(i + 0, j + 3, k + 9, mod_LionKing.outlandsPortalFrame.blockID, 1, 2);
		world.setBlock(i + 0, j + 3, k + 10, mod_LionKing.outlandsPortalFrame.blockID, 1, 2);
		world.setBlock(i + 0, j + 4, k + 9, mod_LionKing.outlandsPortalFrame.blockID, 1, 2);
		world.setBlock(i + 1, j + 4, k + 10, mod_LionKing.outlandsPortalFrame.blockID, 1, 2);
		world.setBlock(i + 1, j + 4, k + 9, mod_LionKing.outlandsPortalFrame.blockID, 1, 2);
		world.setBlock(i + 0, j + 4, k + 10, mod_LionKing.outlandsPortalFrame.blockID, 1, 2);
		world.setBlock(i + -1, j + 3, k + 9, mod_LionKing.outlandsPortalFrame.blockID, 1, 2);
		world.setBlock(i + -1, j + 3, k + 10, mod_LionKing.outlandsPortalFrame.blockID, 1, 2);
		world.setBlock(i + -1, j + 4, k + 9, mod_LionKing.outlandsPortalFrame.blockID, 1, 2);
		world.setBlock(i + -1, j + 4, k + 10, mod_LionKing.outlandsPortalFrame.blockID, 1, 2);
		world.setBlock(i + -2, j + 3, k + 9, mod_LionKing.outlandsPortalFrame.blockID, 1, 2);
		world.setBlock(i + -2, j + 3, k + 10, mod_LionKing.outlandsPortalFrame.blockID, 1, 2);
		world.setBlock(i + -2, j + 4, k + 9, mod_LionKing.outlandsPortalFrame.blockID, 1, 2);
		world.setBlock(i + -2, j + 4, k + 10, mod_LionKing.outlandsPortalFrame.blockID, 1, 2);
		world.setBlock(i + -3, j + 3, k + 9, mod_LionKing.outlandsPortalFrame.blockID, 1, 2);
		world.setBlock(i + -3, j + 3, k + 10, mod_LionKing.outlandsPortalFrame.blockID, 1, 2);
		world.setBlock(i + -3, j + 4, k + 9, mod_LionKing.outlandsPortalFrame.blockID, 1, 2);
		world.setBlock(i + -3, j + 4, k + 10, mod_LionKing.outlandsPortalFrame.blockID, 1, 2);
		world.setBlock(i + -4, j + 3, k + 9, mod_LionKing.outlandsPortalFrame.blockID, 1, 2);
		world.setBlock(i + -10, j + 3, k + 4, mod_LionKing.outlandsPortalFrame.blockID, 1, 2);
		world.setBlock(i + -10, j + 4, k + 4, mod_LionKing.outlandsPortalFrame.blockID, 1, 2);
		world.setBlock(i + -9, j + 4, k + 4, mod_LionKing.outlandsPortalFrame.blockID, 1, 2);
		world.setBlock(i + -8, j + 4, k + 4, mod_LionKing.outlandsPortalFrame.blockID, 1, 2);
		world.setBlock(i + -9, j + 4, k + 5, mod_LionKing.outlandsPortalFrame.blockID, 1, 2);
		world.setBlock(i + -8, j + 4, k + 5, mod_LionKing.outlandsPortalFrame.blockID, 1, 2);
		world.setBlock(i + -7, j + 4, k + 5, mod_LionKing.outlandsPortalFrame.blockID, 1, 2);
		world.setBlock(i + -10, j + 3, k + 5, mod_LionKing.outlandsPortalFrame.blockID, 1, 2);
		world.setBlock(i + -10, j + 4, k + 5, mod_LionKing.outlandsPortalFrame.blockID, 1, 2);
		world.setBlock(i + -9, j + 3, k + 6, mod_LionKing.outlandsPortalFrame.blockID, 1, 2);
		world.setBlock(i + -9, j + 4, k + 6, mod_LionKing.outlandsPortalFrame.blockID, 1, 2);
		world.setBlock(i + -8, j + 3, k + 7, mod_LionKing.outlandsPortalFrame.blockID, 1, 2);
		world.setBlock(i + -8, j + 4, k + 7, mod_LionKing.outlandsPortalFrame.blockID, 1, 2);
		world.setBlock(i + -7, j + 3, k + 8, mod_LionKing.outlandsPortalFrame.blockID, 1, 2);
		world.setBlock(i + -7, j + 4, k + 8, mod_LionKing.outlandsPortalFrame.blockID, 1, 2);
		world.setBlock(i + -6, j + 3, k + 9, mod_LionKing.outlandsPortalFrame.blockID, 1, 2);
		world.setBlock(i + -6, j + 4, k + 9, mod_LionKing.outlandsPortalFrame.blockID, 1, 2);
		world.setBlock(i + -8, j + 5, k + 5, mod_LionKing.outlandsPortalFrame.blockID, 1, 2);
		world.setBlock(i + -8, j + 4, k + 6, mod_LionKing.outlandsPortalFrame.blockID, 1, 2);
		world.setBlock(i + -8, j + 5, k + 5, 0, 0, 2);
		world.setBlock(i + -7, j + 4, k + 6, mod_LionKing.outlandsPortalFrame.blockID, 1, 2);
		world.setBlock(i + -6, j + 4, k + 6, mod_LionKing.outlandsPortalFrame.blockID, 1, 2);
		world.setBlock(i + -7, j + 4, k + 7, mod_LionKing.outlandsPortalFrame.blockID, 1, 2);
		world.setBlock(i + -6, j + 4, k + 7, mod_LionKing.outlandsPortalFrame.blockID, 1, 2);
		world.setBlock(i + -5, j + 4, k + 7, mod_LionKing.outlandsPortalFrame.blockID, 1, 2);
		world.setBlock(i + -6, j + 4, k + 8, mod_LionKing.outlandsPortalFrame.blockID, 1, 2);
		world.setBlock(i + -5, j + 4, k + 8, mod_LionKing.outlandsPortalFrame.blockID, 1, 2);
		world.setBlock(i + -4, j + 4, k + 8, mod_LionKing.outlandsPortalFrame.blockID, 1, 2);
		world.setBlock(i + -5, j + 3, k + 9, mod_LionKing.outlandsPortalFrame.blockID, 1, 2);
		world.setBlock(i + -4, j + 4, k + 9, mod_LionKing.outlandsPortalFrame.blockID, 1, 2);
		world.setBlock(i + -5, j + 4, k + 9, mod_LionKing.outlandsPortalFrame.blockID, 1, 2);
		world.setBlock(i + -4, j + 3, k + 10, mod_LionKing.outlandsPortalFrame.blockID, 1, 2);
		world.setBlock(i + -4, j + 4, k + 10, mod_LionKing.outlandsPortalFrame.blockID, 1, 2);
		world.setBlock(i + -5, j + 3, k + 10, mod_LionKing.outlandsPortalFrame.blockID, 1, 2);
		world.setBlock(i + -5, j + 4, k + 10, mod_LionKing.outlandsPortalFrame.blockID, 1, 2);
		world.setBlock(i + 5, j + 3, k + 10, mod_LionKing.outlandsPortalFrame.blockID, 1, 2);
		world.setBlock(i + 5, j + 4, k + 10, mod_LionKing.outlandsPortalFrame.blockID, 1, 2);
		world.setBlock(i + -3, j + 3, k + 11, mod_LionKing.outlandsPortalFrame.blockID, 1, 2);
		world.setBlock(i + -3, j + 4, k + 11, mod_LionKing.outlandsPortalFrame.blockID, 1, 2);
		world.setBlock(i + -2, j + 3, k + 11, mod_LionKing.outlandsPortalFrame.blockID, 1, 2);
		world.setBlock(i + -2, j + 4, k + 11, mod_LionKing.outlandsPortalFrame.blockID, 1, 2);
		world.setBlock(i + -1, j + 3, k + 11, mod_LionKing.outlandsPortalFrame.blockID, 1, 2);
		world.setBlock(i + -1, j + 4, k + 11, mod_LionKing.outlandsPortalFrame.blockID, 1, 2);
		world.setBlock(i + 0, j + 3, k + 11, mod_LionKing.outlandsPortalFrame.blockID, 1, 2);
		world.setBlock(i + 0, j + 4, k + 11, mod_LionKing.outlandsPortalFrame.blockID, 1, 2);
		world.setBlock(i + 1, j + 3, k + 11, mod_LionKing.outlandsPortalFrame.blockID, 1, 2);
		world.setBlock(i + 1, j + 4, k + 11, mod_LionKing.outlandsPortalFrame.blockID, 1, 2);
		world.setBlock(i + 2, j + 3, k + 11, mod_LionKing.outlandsPortalFrame.blockID, 1, 2);
		world.setBlock(i + 2, j + 4, k + 11, mod_LionKing.outlandsPortalFrame.blockID, 1, 2);
		world.setBlock(i + 3, j + 3, k + 11, mod_LionKing.outlandsPortalFrame.blockID, 1, 2);
		world.setBlock(i + 3, j + 4, k + 11, mod_LionKing.outlandsPortalFrame.blockID, 1, 2);
		world.setBlock(i + -3, j + 4, k + -3, mod_LionKing.outlandsPool.blockID, 0, 2);
		world.setBlock(i + -4, j + 4, k + -3, mod_LionKing.outlandsPool.blockID, 0, 2);
		world.setBlock(i + -3, j + 4, k + -4, mod_LionKing.outlandsPool.blockID, 0, 2);
		world.setBlock(i + -4, j + 4, k + -4, mod_LionKing.outlandsPool.blockID, 0, 2);
		world.setBlock(i + -3, j + 4, k + -5, mod_LionKing.outlandsPool.blockID, 0, 2);
		world.setBlock(i + -4, j + 4, k + -5, mod_LionKing.outlandsPool.blockID, 0, 2);
		world.setBlock(i + -3, j + 4, k + -6, mod_LionKing.outlandsPool.blockID, 0, 2);
		world.setBlock(i + -4, j + 4, k + -6, mod_LionKing.outlandsPool.blockID, 0, 2);
		world.setBlock(i + -5, j + 4, k + -6, mod_LionKing.outlandsPool.blockID, 0, 2);
		world.setBlock(i + -5, j + 4, k + -5, mod_LionKing.outlandsPool.blockID, 0, 2);
		world.setBlock(i + -6, j + 4, k + -5, mod_LionKing.outlandsPool.blockID, 0, 2);
		world.setBlock(i + -5, j + 4, k + -4, mod_LionKing.outlandsPool.blockID, 0, 2);
		world.setBlock(i + -6, j + 4, k + -4, mod_LionKing.outlandsPool.blockID, 0, 2);
		world.setBlock(i + -7, j + 4, k + -4, mod_LionKing.outlandsPool.blockID, 0, 2);
		world.setBlock(i + -5, j + 4, k + -3, mod_LionKing.outlandsPool.blockID, 0, 2);
		world.setBlock(i + -6, j + 4, k + -3, mod_LionKing.outlandsPool.blockID, 0, 2);
		world.setBlock(i + -7, j + 4, k + -3, mod_LionKing.outlandsPool.blockID, 0, 2);
		world.setBlock(i + -8, j + 4, k + -3, mod_LionKing.outlandsPool.blockID, 0, 2);
		world.setBlock(i + -7, j + 4, k + -2, mod_LionKing.outlandsPool.blockID, 0, 2);
		world.setBlock(i + -7, j + 4, k + -1, mod_LionKing.outlandsPool.blockID, 0, 2);
		world.setBlock(i + -8, j + 4, k + -1, mod_LionKing.outlandsPool.blockID, 0, 2);
		world.setBlock(i + -8, j + 4, k + -2, mod_LionKing.outlandsPool.blockID, 0, 2);
		world.setBlock(i + -6, j + 4, k + -2, mod_LionKing.outlandsPool.blockID, 0, 2);
		world.setBlock(i + -5, j + 4, k + -2, mod_LionKing.outlandsPool.blockID, 0, 2);
		world.setBlock(i + -5, j + 4, k + -1, mod_LionKing.outlandsPool.blockID, 0, 2);
		world.setBlock(i + -6, j + 4, k + -1, mod_LionKing.outlandsPool.blockID, 0, 2);
		world.setBlock(i + -6, j + 4, k + 0, mod_LionKing.outlandsPool.blockID, 0, 2);
		world.setBlock(i + -5, j + 4, k + 0, mod_LionKing.outlandsPool.blockID, 0, 2);
		world.setBlock(i + -8, j + 4, k + 1, mod_LionKing.outlandsPool.blockID, 0, 2);
		world.setBlock(i + -7, j + 4, k + 1, mod_LionKing.outlandsPool.blockID, 0, 2);
		world.setBlock(i + -6, j + 4, k + 1, mod_LionKing.outlandsPool.blockID, 0, 2);
		world.setBlock(i + -5, j + 4, k + 1, mod_LionKing.outlandsPool.blockID, 0, 2);
		world.setBlock(i + -8, j + 4, k + 2, mod_LionKing.outlandsPool.blockID, 0, 2);
		world.setBlock(i + -8, j + 4, k + 3, mod_LionKing.outlandsPool.blockID, 0, 2);
		world.setBlock(i + -7, j + 4, k + 2, mod_LionKing.outlandsPool.blockID, 0, 2);
		world.setBlock(i + -7, j + 4, k + 3, mod_LionKing.outlandsPool.blockID, 0, 2);
		world.setBlock(i + -7, j + 4, k + 4, mod_LionKing.outlandsPool.blockID, 0, 2);
		world.setBlock(i + -6, j + 4, k + 4, mod_LionKing.outlandsPool.blockID, 0, 2);
		world.setBlock(i + -6, j + 4, k + 5, mod_LionKing.outlandsPool.blockID, 0, 2);
		world.setBlock(i + -6, j + 4, k + 3, mod_LionKing.outlandsPool.blockID, 0, 2);
		world.setBlock(i + -6, j + 4, k + 2, mod_LionKing.outlandsPool.blockID, 0, 2);
		world.setBlock(i + -5, j + 4, k + 2, mod_LionKing.outlandsPool.blockID, 0, 2);
		world.setBlock(i + -5, j + 4, k + 3, mod_LionKing.outlandsPool.blockID, 0, 2);
		world.setBlock(i + -5, j + 4, k + 4, mod_LionKing.outlandsPool.blockID, 0, 2);
		world.setBlock(i + -5, j + 4, k + 5, mod_LionKing.outlandsPool.blockID, 0, 2);
		world.setBlock(i + -5, j + 4, k + 6, mod_LionKing.outlandsPool.blockID, 0, 2);
		world.setBlock(i + -4, j + 3, k + 7, 0, 0, 2);
		world.setBlock(i + -4, j + 3, k + 7, mod_LionKing.outlandsPool.blockID, 0, 2);
		world.setBlock(i + -4, j + 4, k + 6, mod_LionKing.outlandsPool.blockID, 0, 2);
		world.setBlock(i + -4, j + 3, k + 7, 0, 0, 2);
		world.setBlock(i + -4, j + 3, k + 7, mod_LionKing.outlandsPortalFrame.blockID, 1, 2);
		world.setBlock(i + -4, j + 4, k + 7, mod_LionKing.outlandsPool.blockID, 0, 2);
		world.setBlock(i + -4, j + 4, k + 5, mod_LionKing.outlandsPool.blockID, 0, 2);
		world.setBlock(i + -4, j + 4, k + 4, mod_LionKing.outlandsPool.blockID, 0, 2);
		world.setBlock(i + -4, j + 4, k + 3, mod_LionKing.outlandsPool.blockID, 0, 2);
		world.setBlock(i + -4, j + 4, k + 2, mod_LionKing.outlandsPool.blockID, 0, 2);
		world.setBlock(i + -4, j + 4, k + 1, mod_LionKing.outlandsPool.blockID, 0, 2);
		world.setBlock(i + -4, j + 4, k + 0, mod_LionKing.outlandsPool.blockID, 0, 2);
		world.setBlock(i + -4, j + 4, k + -2, mod_LionKing.outlandsPool.blockID, 0, 2);
		world.setBlock(i + -4, j + 4, k + -1, mod_LionKing.outlandsPool.blockID, 0, 2);
		world.setBlock(i + -3, j + 4, k + -1, mod_LionKing.outlandsPool.blockID, 0, 2);
		world.setBlock(i + -3, j + 4, k + -2, mod_LionKing.outlandsPool.blockID, 0, 2);
		world.setBlock(i + -2, j + 4, k + -1, mod_LionKing.outlandsPool.blockID, 0, 2);
		world.setBlock(i + -2, j + 4, k + -2, mod_LionKing.outlandsPool.blockID, 0, 2);
		world.setBlock(i + -2, j + 4, k + -3, mod_LionKing.outlandsPool.blockID, 0, 2);
		world.setBlock(i + -2, j + 4, k + -4, mod_LionKing.outlandsPool.blockID, 0, 2);
		world.setBlock(i + -2, j + 4, k + -5, mod_LionKing.outlandsPool.blockID, 0, 2);
		world.setBlock(i + -2, j + 4, k + -6, mod_LionKing.outlandsPool.blockID, 0, 2);
		world.setBlock(i + -4, j + 4, k + -7, mod_LionKing.outlandsPool.blockID, 0, 2);
		world.setBlock(i + -3, j + 4, k + -7, mod_LionKing.outlandsPool.blockID, 0, 2);
		world.setBlock(i + -2, j + 4, k + -7, mod_LionKing.outlandsPool.blockID, 0, 2);
		world.setBlock(i + -3, j + 4, k + -8, mod_LionKing.outlandsPool.blockID, 0, 2);
		world.setBlock(i + -2, j + 4, k + -8, mod_LionKing.outlandsPool.blockID, 0, 2);
		world.setBlock(i + -1, j + 4, k + -8, mod_LionKing.outlandsPool.blockID, 0, 2);
		world.setBlock(i + -1, j + 4, k + -7, mod_LionKing.outlandsPool.blockID, 0, 2);
		world.setBlock(i + -1, j + 4, k + -1, mod_LionKing.outlandsPool.blockID, 0, 2);
		world.setBlock(i + -1, j + 4, k + -2, mod_LionKing.outlandsPool.blockID, 0, 2);
		world.setBlock(i + 0, j + 4, k + -2, mod_LionKing.outlandsPool.blockID, 0, 2);
		world.setBlock(i + -1, j + 4, k + -3, mod_LionKing.outlandsPool.blockID, 0, 2);
		world.setBlock(i + 0, j + 4, k + -3, mod_LionKing.outlandsPool.blockID, 0, 2);
		world.setBlock(i + -1, j + 4, k + -4, mod_LionKing.outlandsPool.blockID, 0, 2);
		world.setBlock(i + -1, j + 4, k + -5, mod_LionKing.outlandsPool.blockID, 0, 2);
		world.setBlock(i + 0, j + 4, k + -5, mod_LionKing.outlandsPool.blockID, 0, 2);
		world.setBlock(i + -1, j + 4, k + -6, mod_LionKing.outlandsPool.blockID, 0, 2);
		world.setBlock(i + 0, j + 4, k + -6, mod_LionKing.outlandsPool.blockID, 0, 2);
		world.setBlock(i + 0, j + 4, k + -4, mod_LionKing.outlandsPool.blockID, 0, 2);
		world.setBlock(i + 0, j + 4, k + -7, mod_LionKing.outlandsPool.blockID, 0, 2);
		world.setBlock(i + 0, j + 4, k + -8, mod_LionKing.outlandsPool.blockID, 0, 2);
		world.setBlock(i + 1, j + 4, k + -8, mod_LionKing.outlandsPool.blockID, 0, 2);
		world.setBlock(i + 1, j + 4, k + -7, mod_LionKing.outlandsPool.blockID, 0, 2);
		world.setBlock(i + 1, j + 4, k + -6, mod_LionKing.outlandsPool.blockID, 0, 2);
		world.setBlock(i + 1, j + 4, k + -5, mod_LionKing.outlandsPool.blockID, 0, 2);
		world.setBlock(i + 1, j + 4, k + -4, mod_LionKing.outlandsPool.blockID, 0, 2);
		world.setBlock(i + 1, j + 4, k + -2, mod_LionKing.outlandsPool.blockID, 0, 2);
		world.setBlock(i + 1, j + 4, k + -1, mod_LionKing.outlandsPool.blockID, 0, 2);
		world.setBlock(i + 1, j + 4, k + -3, mod_LionKing.outlandsPool.blockID, 0, 2);
	}
	
	private void generate2(World world, int i, int j, int k)
	{
		world.setBlock(i + 2, j + 4, k + -1, mod_LionKing.outlandsPool.blockID, 0, 2);
		world.setBlock(i + 2, j + 4, k + -2, mod_LionKing.outlandsPool.blockID, 0, 2);
		world.setBlock(i + 2, j + 4, k + -3, mod_LionKing.outlandsPool.blockID, 0, 2);
		world.setBlock(i + 2, j + 4, k + -4, mod_LionKing.outlandsPool.blockID, 0, 2);
		world.setBlock(i + 2, j + 4, k + -5, mod_LionKing.outlandsPool.blockID, 0, 2);
		world.setBlock(i + 2, j + 4, k + -6, mod_LionKing.outlandsPool.blockID, 0, 2);
		world.setBlock(i + 2, j + 4, k + -7, mod_LionKing.outlandsPool.blockID, 0, 2);
		world.setBlock(i + 2, j + 4, k + -8, mod_LionKing.outlandsPool.blockID, 0, 2);
		world.setBlock(i + 3, j + 4, k + -8, mod_LionKing.outlandsPool.blockID, 0, 2);
		world.setBlock(i + 3, j + 4, k + -7, mod_LionKing.outlandsPool.blockID, 0, 2);
		world.setBlock(i + 3, j + 4, k + -6, mod_LionKing.outlandsPool.blockID, 0, 2);
		world.setBlock(i + 3, j + 4, k + -5, mod_LionKing.outlandsPool.blockID, 0, 2);
		world.setBlock(i + 3, j + 4, k + -4, mod_LionKing.outlandsPool.blockID, 0, 2);
		world.setBlock(i + 3, j + 4, k + -3, mod_LionKing.outlandsPool.blockID, 0, 2);
		world.setBlock(i + 3, j + 4, k + -2, mod_LionKing.outlandsPool.blockID, 0, 2);
		world.setBlock(i + 3, j + 4, k + -1, mod_LionKing.outlandsPool.blockID, 0, 2);
		world.setBlock(i + 2, j + 4, k + 0, mod_LionKing.outlandsPool.blockID, 0, 2);
		world.setBlock(i + 3, j + 4, k + 0, mod_LionKing.outlandsPool.blockID, 0, 2);
		world.setBlock(i + 1, j + 4, k + 1, mod_LionKing.outlandsPool.blockID, 0, 2);
		world.setBlock(i + 3, j + 4, k + 1, mod_LionKing.outlandsPool.blockID, 0, 2);
		world.setBlock(i + 2, j + 4, k + 1, mod_LionKing.outlandsPool.blockID, 0, 2);
		world.setBlock(i + 0, j + 4, k + 2, mod_LionKing.outlandsPool.blockID, 0, 2);
		world.setBlock(i + 1, j + 4, k + 2, mod_LionKing.outlandsPool.blockID, 0, 2);
		world.setBlock(i + 2, j + 4, k + 2, mod_LionKing.outlandsPool.blockID, 0, 2);
		world.setBlock(i + 3, j + 4, k + 2, mod_LionKing.outlandsPool.blockID, 0, 2);
		world.setBlock(i + 3, j + 4, k + 3, mod_LionKing.outlandsPool.blockID, 0, 2);
		world.setBlock(i + 2, j + 4, k + 3, mod_LionKing.outlandsPool.blockID, 0, 2);
		world.setBlock(i + 1, j + 4, k + 3, mod_LionKing.outlandsPool.blockID, 0, 2);
		world.setBlock(i + 0, j + 4, k + 3, mod_LionKing.outlandsPool.blockID, 0, 2);
		world.setBlock(i + -1, j + 4, k + 3, mod_LionKing.outlandsPool.blockID, 0, 2);
		world.setBlock(i + -2, j + 4, k + 1, mod_LionKing.outlandsPool.blockID, 0, 2);
		world.setBlock(i + -3, j + 4, k + 0, mod_LionKing.outlandsPool.blockID, 0, 2);
		world.setBlock(i + -3, j + 4, k + 1, mod_LionKing.outlandsPool.blockID, 0, 2);
		world.setBlock(i + -2, j + 4, k + 0, mod_LionKing.outlandsPool.blockID, 0, 2);
		world.setBlock(i + -1, j + 4, k + 1, mod_LionKing.outlandsPool.blockID, 0, 2);
		world.setBlock(i + -1, j + 4, k + 2, mod_LionKing.outlandsPool.blockID, 0, 2);
		world.setBlock(i + -2, j + 4, k + 2, mod_LionKing.outlandsPool.blockID, 0, 2);
		world.setBlock(i + -3, j + 4, k + 2, mod_LionKing.outlandsPool.blockID, 0, 2);
		world.setBlock(i + -3, j + 4, k + 3, mod_LionKing.outlandsPool.blockID, 0, 2);
		world.setBlock(i + -3, j + 4, k + 4, mod_LionKing.outlandsPool.blockID, 0, 2);
		world.setBlock(i + -3, j + 4, k + 5, mod_LionKing.outlandsPool.blockID, 0, 2);
		world.setBlock(i + -3, j + 4, k + 6, mod_LionKing.outlandsPool.blockID, 0, 2);
		world.setBlock(i + -3, j + 4, k + 8, mod_LionKing.outlandsPool.blockID, 0, 2);
		world.setBlock(i + -3, j + 4, k + 7, mod_LionKing.outlandsPool.blockID, 0, 2);
		world.setBlock(i + -2, j + 4, k + 3, mod_LionKing.outlandsPool.blockID, 0, 2);
		world.setBlock(i + -2, j + 4, k + 4, mod_LionKing.outlandsPool.blockID, 0, 2);
		world.setBlock(i + -2, j + 4, k + 5, mod_LionKing.outlandsPool.blockID, 0, 2);
		world.setBlock(i + -2, j + 4, k + 6, mod_LionKing.outlandsPool.blockID, 0, 2);
		world.setBlock(i + -2, j + 4, k + 8, mod_LionKing.outlandsPool.blockID, 0, 2);
		world.setBlock(i + -2, j + 4, k + 7, mod_LionKing.outlandsPool.blockID, 0, 2);
		world.setBlock(i + -1, j + 4, k + 4, mod_LionKing.outlandsPool.blockID, 0, 2);
		world.setBlock(i + 0, j + 4, k + 4, mod_LionKing.outlandsPool.blockID, 0, 2);
		world.setBlock(i + 1, j + 4, k + 4, mod_LionKing.outlandsPool.blockID, 0, 2);
		world.setBlock(i + 2, j + 4, k + 4, mod_LionKing.outlandsPool.blockID, 0, 2);
		world.setBlock(i + 3, j + 4, k + 4, mod_LionKing.outlandsPool.blockID, 0, 2);
		world.setBlock(i + 4, j + 4, k + -7, mod_LionKing.outlandsPool.blockID, 0, 2);
		world.setBlock(i + 4, j + 4, k + -6, mod_LionKing.outlandsPool.blockID, 0, 2);
		world.setBlock(i + 5, j + 4, k + -6, mod_LionKing.outlandsPool.blockID, 0, 2);
		world.setBlock(i + 4, j + 4, k + -5, mod_LionKing.outlandsPool.blockID, 0, 2);
		world.setBlock(i + 5, j + 4, k + -5, mod_LionKing.outlandsPool.blockID, 0, 2);
		world.setBlock(i + 6, j + 4, k + -5, mod_LionKing.outlandsPool.blockID, 0, 2);
		world.setBlock(i + 7, j + 4, k + -3, mod_LionKing.outlandsPool.blockID, 0, 2);
		world.setBlock(i + 7, j + 4, k + -4, mod_LionKing.outlandsPool.blockID, 0, 2);
		world.setBlock(i + 6, j + 4, k + -4, mod_LionKing.outlandsPool.blockID, 0, 2);
		world.setBlock(i + 5, j + 4, k + -4, mod_LionKing.outlandsPool.blockID, 0, 2);
		world.setBlock(i + 4, j + 4, k + -4, mod_LionKing.outlandsPool.blockID, 0, 2);
		world.setBlock(i + 4, j + 4, k + -3, mod_LionKing.outlandsPool.blockID, 0, 2);
		world.setBlock(i + 5, j + 4, k + -3, mod_LionKing.outlandsPool.blockID, 0, 2);
		world.setBlock(i + 6, j + 4, k + -3, mod_LionKing.outlandsPool.blockID, 0, 2);
		world.setBlock(i + 8, j + 4, k + -3, mod_LionKing.outlandsPool.blockID, 0, 2);
		world.setBlock(i + 8, j + 4, k + -2, mod_LionKing.outlandsPool.blockID, 0, 2);
		world.setBlock(i + 7, j + 4, k + -2, mod_LionKing.outlandsPool.blockID, 0, 2);
		world.setBlock(i + 8, j + 4, k + -1, mod_LionKing.outlandsPool.blockID, 0, 2);
		world.setBlock(i + 8, j + 4, k + 0, mod_LionKing.outlandsPool.blockID, 0, 2);
		world.setBlock(i + 8, j + 4, k + 1, mod_LionKing.outlandsPool.blockID, 0, 2);
		world.setBlock(i + 8, j + 4, k + 2, mod_LionKing.outlandsPool.blockID, 0, 2);
		world.setBlock(i + 8, j + 4, k + 3, mod_LionKing.outlandsPool.blockID, 0, 2);
		world.setBlock(i + 7, j + 4, k + 4, mod_LionKing.outlandsPool.blockID, 0, 2);
		world.setBlock(i + 7, j + 4, k + 3, mod_LionKing.outlandsPool.blockID, 0, 2);
		world.setBlock(i + 4, j + 4, k + -2, mod_LionKing.outlandsPool.blockID, 0, 2);
		world.setBlock(i + 5, j + 4, k + -2, mod_LionKing.outlandsPool.blockID, 0, 2);
		world.setBlock(i + 6, j + 4, k + -2, mod_LionKing.outlandsPool.blockID, 0, 2);
		world.setBlock(i + 7, j + 4, k + -1, mod_LionKing.outlandsPool.blockID, 0, 2);
		world.setBlock(i + 6, j + 4, k + -1, mod_LionKing.outlandsPool.blockID, 0, 2);
		world.setBlock(i + 5, j + 4, k + -1, mod_LionKing.outlandsPool.blockID, 0, 2);
		world.setBlock(i + 4, j + 4, k + 0, mod_LionKing.outlandsPool.blockID, 0, 2);
		world.setBlock(i + 5, j + 4, k + 0, mod_LionKing.outlandsPool.blockID, 0, 2);
		world.setBlock(i + 4, j + 4, k + -1, mod_LionKing.outlandsPool.blockID, 0, 2);
		world.setBlock(i + 7, j + 4, k + 1, mod_LionKing.outlandsPool.blockID, 0, 2);
		world.setBlock(i + 6, j + 4, k + 0, mod_LionKing.outlandsPool.blockID, 0, 2);
		world.setBlock(i + 7, j + 4, k + 0, mod_LionKing.outlandsPool.blockID, 0, 2);
		world.setBlock(i + 7, j + 4, k + 2, mod_LionKing.outlandsPool.blockID, 0, 2);
		world.setBlock(i + 6, j + 4, k + 1, mod_LionKing.outlandsPool.blockID, 0, 2);
		world.setBlock(i + 5, j + 4, k + 1, mod_LionKing.outlandsPool.blockID, 0, 2);
		world.setBlock(i + 4, j + 4, k + 1, mod_LionKing.outlandsPool.blockID, 0, 2);
		world.setBlock(i + 4, j + 4, k + 2, mod_LionKing.outlandsPool.blockID, 0, 2);
		world.setBlock(i + 5, j + 4, k + 2, mod_LionKing.outlandsPool.blockID, 0, 2);
		world.setBlock(i + 6, j + 4, k + 2, mod_LionKing.outlandsPool.blockID, 0, 2);
		world.setBlock(i + 6, j + 4, k + 3, mod_LionKing.outlandsPool.blockID, 0, 2);
		world.setBlock(i + 5, j + 4, k + 3, mod_LionKing.outlandsPool.blockID, 0, 2);
		world.setBlock(i + 4, j + 4, k + 3, mod_LionKing.outlandsPool.blockID, 0, 2);
		world.setBlock(i + 6, j + 4, k + 4, mod_LionKing.outlandsPool.blockID, 0, 2);
		world.setBlock(i + 5, j + 4, k + 4, mod_LionKing.outlandsPool.blockID, 0, 2);
		world.setBlock(i + 4, j + 4, k + 4, mod_LionKing.outlandsPool.blockID, 0, 2);
		world.setBlock(i + 6, j + 4, k + 5, mod_LionKing.outlandsPool.blockID, 0, 2);
		world.setBlock(i + 5, j + 4, k + 5, mod_LionKing.outlandsPool.blockID, 0, 2);
		world.setBlock(i + 5, j + 4, k + 6, mod_LionKing.outlandsPool.blockID, 0, 2);
		world.setBlock(i + 4, j + 4, k + 5, mod_LionKing.outlandsPool.blockID, 0, 2);
		world.setBlock(i + 4, j + 4, k + 6, mod_LionKing.outlandsPool.blockID, 0, 2);
		world.setBlock(i + 4, j + 4, k + 7, mod_LionKing.outlandsPool.blockID, 0, 2);
		world.setBlock(i + 3, j + 4, k + 7, mod_LionKing.outlandsPool.blockID, 0, 2);
		world.setBlock(i + 3, j + 4, k + 6, mod_LionKing.outlandsPool.blockID, 0, 2);
		world.setBlock(i + 3, j + 4, k + 5, mod_LionKing.outlandsPool.blockID, 0, 2);
		world.setBlock(i + 3, j + 4, k + 8, mod_LionKing.outlandsPool.blockID, 0, 2);
		world.setBlock(i + 2, j + 4, k + 8, mod_LionKing.outlandsPool.blockID, 0, 2);
		world.setBlock(i + 2, j + 4, k + 7, mod_LionKing.outlandsPool.blockID, 0, 2);
		world.setBlock(i + 2, j + 4, k + 6, mod_LionKing.outlandsPool.blockID, 0, 2);
		world.setBlock(i + 2, j + 4, k + 5, mod_LionKing.outlandsPool.blockID, 0, 2);
		world.setBlock(i + 1, j + 4, k + 6, mod_LionKing.outlandsPool.blockID, 0, 2);
		world.setBlock(i + 1, j + 4, k + 8, mod_LionKing.outlandsPool.blockID, 0, 2);
		world.setBlock(i + 1, j + 4, k + 7, mod_LionKing.outlandsPool.blockID, 0, 2);
		world.setBlock(i + 1, j + 4, k + 5, mod_LionKing.outlandsPool.blockID, 0, 2);
		world.setBlock(i + 0, j + 4, k + 5, mod_LionKing.outlandsPool.blockID, 0, 2);
		world.setBlock(i + -1, j + 4, k + 5, mod_LionKing.outlandsPool.blockID, 0, 2);
		world.setBlock(i + 0, j + 4, k + 6, mod_LionKing.outlandsPool.blockID, 0, 2);
		world.setBlock(i + -1, j + 4, k + 6, mod_LionKing.outlandsPool.blockID, 0, 2);
		world.setBlock(i + 0, j + 4, k + 7, mod_LionKing.outlandsPool.blockID, 0, 2);
		world.setBlock(i + -1, j + 4, k + 7, mod_LionKing.outlandsPool.blockID, 0, 2);
		world.setBlock(i + 0, j + 4, k + 8, mod_LionKing.outlandsPool.blockID, 0, 2);
		world.setBlock(i + -1, j + 4, k + 8, mod_LionKing.outlandsPool.blockID, 0, 2);
		world.setBlock(i + 1, j + 4, k + -12, mod_LionKing.outlandsPortalFrame.blockID, 1, 2);
		world.setBlock(i + 0, j + 4, k + -12, mod_LionKing.outlandsPortalFrame.blockID, 1, 2);
		world.setBlock(i + 1, j + 5, k + -12, mod_LionKing.outlandsPortalFrame.blockID, 1, 2);
		world.setBlock(i + 0, j + 5, k + -12, mod_LionKing.outlandsPortalFrame.blockID, 1, 2);
		world.setBlock(i + 1, j + 5, k + -13, mod_LionKing.outlandsPortalFrame.blockID, 1, 2);
		world.setBlock(i + 0, j + 5, k + -13, mod_LionKing.outlandsPortalFrame.blockID, 1, 2);
		world.setBlock(i + 1, j + 5, k + -13, 0, 0, 2);
		world.setBlock(i + 0, j + 6, k + -13, mod_LionKing.outlandsPortalFrame.blockID, 1, 2);
		world.setBlock(i + 0, j + 5, k + -13, 0, 0, 2);
		world.setBlock(i + 1, j + 6, k + -13, mod_LionKing.outlandsPortalFrame.blockID, 1, 2);
		world.setBlock(i + 0, j + 7, k + -13, mod_LionKing.outlandsPortalFrame.blockID, 1, 2);
		world.setBlock(i + 1, j + 7, k + -13, mod_LionKing.outlandsPortalFrame.blockID, 1, 2);
		world.setBlock(i + 1, j + 6, k + -12, mod_LionKing.outlandsPortalFrame.blockID, 1, 2);
		world.setBlock(i + 0, j + 6, k + -12, mod_LionKing.outlandsPortalFrame.blockID, 1, 2);
		world.setBlock(i + 1, j + 8, k + -13, mod_LionKing.outlandsPortalFrame.blockID, 1, 2);
		world.setBlock(i + 0, j + 8, k + -13, mod_LionKing.outlandsPortalFrame.blockID, 1, 2);
		world.setBlock(i + 0, j + 6, k + -13, 0, 0, 2);
		world.setBlock(i + 1, j + 6, k + -13, 0, 0, 2);
		world.setBlock(i + 0, j + 4, k + -12, 0, 0, 2);
		world.setBlock(i + 1, j + 4, k + -12, 0, 0, 2);
		world.setBlock(i + 1, j + 9, k + -13, mod_LionKing.outlandsPortalFrame.blockID, 2, 2);
		world.setBlock(i + 0, j + 9, k + -13, mod_LionKing.outlandsPortalFrame.blockID, 2, 2);
		world.setBlock(i + 0, j + 9, k + -13, 0, 0, 2);
		world.setBlock(i + 1, j + 9, k + -13, 0, 0, 2);
		world.setBlock(i + 1, j + 9, k + -13, mod_LionKing.outlandsPortalFrame.blockID, 1, 2);
		world.setBlock(i + 0, j + 9, k + -13, mod_LionKing.outlandsPortalFrame.blockID, 1, 2);
		world.setBlock(i + 1, j + 9, k + -14, mod_LionKing.outlandsPortalFrame.blockID, 1, 2);
		world.setBlock(i + 1, j + 10, k + -14, mod_LionKing.outlandsPortalFrame.blockID, 1, 2);
		world.setBlock(i + 1, j + 9, k + -14, 0, 0, 2);
		world.setBlock(i + 0, j + 10, k + -14, mod_LionKing.outlandsPortalFrame.blockID, 1, 2);
		world.setBlock(i + 1, j + 11, k + -14, mod_LionKing.outlandsPortalFrame.blockID, 1, 2);
		world.setBlock(i + 0, j + 11, k + -14, mod_LionKing.outlandsPortalFrame.blockID, 1, 2);
		world.setBlock(i + 1, j + 12, k + -14, mod_LionKing.outlandsPortalFrame.blockID, 1, 2);
		world.setBlock(i + 0, j + 12, k + -14, mod_LionKing.outlandsPortalFrame.blockID, 1, 2);
		world.setBlock(i + 1, j + 13, k + -14, mod_LionKing.outlandsPortalFrame.blockID, 1, 2);
		world.setBlock(i + 0, j + 13, k + -14, mod_LionKing.outlandsPortalFrame.blockID, 1, 2);
		world.setBlock(i + -1, j + 5, k + -12, mod_LionKing.outlandsPortalFrame.blockID, 1, 2);
		world.setBlock(i + -1, j + 6, k + -12, mod_LionKing.outlandsPortalFrame.blockID, 1, 2);
		world.setBlock(i + -1, j + 7, k + -13, mod_LionKing.outlandsPortalFrame.blockID, 1, 2);
		world.setBlock(i + -1, j + 8, k + -13, mod_LionKing.outlandsPortalFrame.blockID, 1, 2);
		world.setBlock(i + 0, j + 10, k + -13, mod_LionKing.outlandsPortalFrame.blockID, 1, 2);
		world.setBlock(i + -1, j + 9, k + -13, mod_LionKing.outlandsPortalFrame.blockID, 1, 2);
		world.setBlock(i + 0, j + 10, k + -13, 0, 0, 2);
		world.setBlock(i + -1, j + 10, k + -14, mod_LionKing.outlandsPortalFrame.blockID, 1, 2);
		world.setBlock(i + -1, j + 11, k + -14, mod_LionKing.outlandsPortalFrame.blockID, 1, 2);
		world.setBlock(i + -1, j + 12, k + -14, mod_LionKing.outlandsPortalFrame.blockID, 1, 2);
		world.setBlock(i + -1, j + 13, k + -14, mod_LionKing.outlandsPortalFrame.blockID, 1, 2);
		world.setBlock(i + 2, j + 5, k + -12, mod_LionKing.outlandsPortalFrame.blockID, 1, 2);
		world.setBlock(i + 2, j + 6, k + -12, mod_LionKing.outlandsPortalFrame.blockID, 1, 2);
		world.setBlock(i + 2, j + 7, k + -13, mod_LionKing.outlandsPortalFrame.blockID, 1, 2);
		world.setBlock(i + 2, j + 8, k + -13, mod_LionKing.outlandsPortalFrame.blockID, 1, 2);
		world.setBlock(i + 2, j + 9, k + -13, mod_LionKing.outlandsPortalFrame.blockID, 1, 2);
		world.setBlock(i + 2, j + 10, k + -14, mod_LionKing.outlandsPortalFrame.blockID, 1, 2);
		world.setBlock(i + 2, j + 11, k + -14, mod_LionKing.outlandsPortalFrame.blockID, 1, 2);
		world.setBlock(i + 2, j + 12, k + -14, mod_LionKing.outlandsPortalFrame.blockID, 1, 2);
		world.setBlock(i + 2, j + 13, k + -14, mod_LionKing.outlandsPortalFrame.blockID, 1, 2);
		world.setBlock(i + -2, j + 6, k + -12, mod_LionKing.outlandsPortalFrame.blockID, 1, 2);
		world.setBlock(i + -2, j + 6, k + -13, mod_LionKing.outlandsPortalFrame.blockID, 1, 2);
		world.setBlock(i + -2, j + 6, k + -13, 0, 0, 2);
		world.setBlock(i + -2, j + 5, k + -12, mod_LionKing.outlandsPortalFrame.blockID, 1, 2);
		world.setBlock(i + -2, j + 7, k + -13, mod_LionKing.outlandsPortalFrame.blockID, 1, 2);
		world.setBlock(i + -2, j + 8, k + -13, mod_LionKing.outlandsPortalFrame.blockID, 1, 2);
